Workbook

Sheet ALL ITEM CODE
A1: Column2 | B1: Column1 | C1: LENGTH FOAM | D1: WEIGHT | E1: WIDTH FOAM | F1: WEIGHT2 | G1: TOP FOAM1 & REBOUND1 | H1: WEIGHT3 | I1: TOP FOAM2 & REBOUND2 | J1: WEIGHT4 | M1: VARIETY | N1: SAMPLES
A2: GP06 | B2: RTUPGPBW72X30X06 | C2: 40D-PU-FOAM-71.50x115MMx40MM | D2: 0.334 | E2: 40D-PU-FOAM-26.50x115MMx40MM | F2: 0.124 | G2: 18D-PU-FOAM-71.50X29.50X09MM | H2: 0.22 | M2: SKSGSR | N2: SPG
A3: GP06 | B3: RTUPGPBW72X36X06 | C3: 40D-PU-FOAM-71.50x115MMx40MM | D3: 0.334 | E3: 40D-PU-FOAM-32.50X115MMX40MM | F3: 0.152 | G3: 18D-PU-FOAM-71.50X35.50X09MM | H3: 0.265 | M3: RTUPGPBW | N3: GP
A4: GP06 | B4: RTUPGPBW72X42X06 | C4: 40D-PU-FOAM-71.50x115MMx40MM | D4: 0.334 | E4: 40D-PU-FOAM-38.50X115MMX40MM | F4: 0.18 | G4: 18D-PU-FOAM-71.50X41.50X09MM | H4: 0.31 | M4: RTUPGPGR | N4: GP
A5: GP06 | B5: RTUPGPBW72X48X06 | C5: 40D-PU-FOAM-71.50x115MMx40MM | D5: 0.334 | E5: 40D-PU-FOAM-44.50X115MMX40MM | F5: 0.208 | G5: 18D-PU-FOAM-71.50X47.50X09MM | H5: 0.355 | M5: RTGPCSBG | N5: CRYSTAL
A6: GP06 | B6: RTUPGPBW72X60X06 | C6: 40D-PU-FOAM-71.50x115MMx40MM | D6: 0.334 | E6: 40D-PU-FOAM-56.50X115MMX40MM | F6: 0.264 | G6: 18D-PU-FOAM-71.50X59.50X09MM | H6: 0.445 | M6: RTGPCSPW | N6: CRYSTAL
A7: GP06 | B7: RTUPGPBW72X66X06 | C7: 40D-PU-FOAM-71.50x115MMx40MM | D7: 0.334 | E7: 40D-PU-FOAM-62.50X115MMX40MM | F7: 0.292 | G7: 18D-PU-FOAM-71.50X65.50X09MM | H7: 0.489 | M7: PEPSPKORGBW | N7: ORG
A8: GP06 | B8: RTUPGPBW72X72X06 | C8: 40D-PU-FOAM-71.50x115MMx40MM | D8: 0.334 | E8: 40D-PU-FOAM-68.50X115MMX40MM | F8: 0.32 | G8: 18D-PU-FOAM-71.50X71.50X09MM | H8: 0.534 | M8: RTVHETPT | N8: VIVAH
A9: GP06 | B9: RTUPGPBW75X30X06 | C9: 40D-PU-FOAM-74.50x115MMx40MM | D9: 0.348 | E9: 40D-PU-FOAM-26.50x115MMx40MM | F9: 0.124 | G9: 18D-PU-FOAM-74.50X29.50X09MM | H9: 0.23 | M9: RTPKCMSTCS | N9: CAMEO
A10: GP06 | B10: RTUPGPBW75X36X06 | C10: 40D-PU-FOAM-74.50x115MMx40MM | D10: 0.348 | E10: 40D-PU-FOAM-32.50X115MMX40MM | F10: 0.152 | G10: 18D-PU-FOAM-74.50X35.50X09MM | H10: 0.276 | M10: RTPKCMULTSTCS | N10: CAMEO
A11: GP06 | B11: RTUPGPBW75X42X06 | C11: 40D-PU-FOAM-74.50x115MMx40MM | D11: 0.348 | E11: 40D-PU-FOAM-38.50X115MMX40MM | F11: 0.18 | G11: 18D-PU-FOAM-74.50X41.50X09MM | H11: 0.323 | M11: HYPALRPKNLBLOR | N11: ALU
A12: GP06 | B12: RTUPGPBW75X48X06 | C12: 40D-PU-FOAM-74.50x115MMx40MM | D12: 0.348 | E12: 40D-PU-FOAM-44.50X115MMX40MM | F12: 0.208 | G12: 18D-PU-FOAM-74.50X47.50X09MM | H12: 0.37 | M12: HYPALRPKNLSTGR | N12: ALU
A13: GP06 | B13: RTUPGPBW75X60X06 | C13: 40D-PU-FOAM-74.50x115MMx40MM | D13: 0.348 | E13: 40D-PU-FOAM-56.50X115MMX40MM | F13: 0.264 | G13: 18D-PU-FOAM-74.50X59.50X09MM | H13: 0.463
A14: GP06 | B14: RTUPGPBW75X66X06 | C14: 40D-PU-FOAM-74.50x115MMx40MM | D14: 0.348 | E14: 40D-PU-FOAM-62.50X115MMX40MM | F14: 0.292 | G14: 18D-PU-FOAM-74.50X65.50X09MM | H14: 0.51
A15: GP06 | B15: RTUPGPBW75X72X06 | C15: 40D-PU-FOAM-74.50x115MMx40MM | D15: 0.348 | E15: 40D-PU-FOAM-68.50X115MMX40MM | F15: 0.32 | G15: 18D-PU-FOAM-74.50X71.50X09MM | H15: 0.557
A16: GP06 | B16: RTUPGPBW78X30X06 | C16: 40D-PU-FOAM-77.50x115MMx40MM | D16: 0.362 | E16: 40D-PU-FOAM-26.50x115MMx40MM | F16: 0.124 | G16: 18D-PU-FOAM-77.50X29.50X09MM | H16: 0.239
A17: GP06 | B17: RTUPGPBW78X36X06 | C17: 40D-PU-FOAM-77.50x115MMx40MM | D17: 0.362 | E17: 40D-PU-FOAM-32.50X115MMX40MM | F17: 0.152 | G17: 18D-PU-FOAM-77.50X35.50X09MM | H17: 0.288
A18: GP06 | B18: RTUPGPBW78X42X06 | C18: 40D-PU-FOAM-77.50x115MMx40MM | D18: 0.362 | E18: 40D-PU-FOAM-38.50X115MMX40MM | F18: 0.18 | G18: 18D-PU-FOAM-77.50X41.50X09MM | H18: 0.336
A19: GP06 | B19: RTUPGPBW78X48X06 | C19: 40D-PU-FOAM-77.50x115MMx40MM | D19: 0.362 | E19: 40D-PU-FOAM-44.50X115MMX40MM | F19: 0.208 | G19: 18D-PU-FOAM-77.50X47.50X09MM | H19: 0.385
A20: GP06 | B20: RTUPGPBW78X60X06 | C20: 40D-PU-FOAM-77.50x115MMx40MM | D20: 0.362 | E20: 40D-PU-FOAM-56.50X115MMX40MM | F20: 0.264 | G20: 18D-PU-FOAM-77.50X59.50X09MM | H20: 0.482
A21: GP06 | B21: RTUPGPBW78X66X06 | C21: 40D-PU-FOAM-77.50x115MMx40MM | D21: 0.362 | E21: 40D-PU-FOAM-62.50X115MMX40MM | F21: 0.292 | G21: 18D-PU-FOAM-77.50X65.50X09MM | H21: 0.531
A22: GP06 | B22: RTUPGPBW78X72X06 | C22: 40D-PU-FOAM-77.50x115MMx40MM | D22: 0.362 | E22: 40D-PU-FOAM-68.50X115MMX40MM | F22: 0.32 | G22: 18D-PU-FOAM-77.50X71.50X09MM | H22: 0.579
A23: GP06 | B23: RTUPGPBW80X30X06 | C23: 40D-PU-FOAM-79.50x115MMx40MM | D23: 0.372 | E23: 40D-PU-FOAM-26.50x115MMx40MM | F23: 0.124 | G23: 18D-PU-FOAM-79.50X29.50X09MM | H23: 0.245
A24: GP06 | B24: RTUPGPBW80X36X06 | C24: 40D-PU-FOAM-79.50x115MMx40MM | D24: 0.372 | E24: 40D-PU-FOAM-32.50X115MMX40MM | F24: 0.152 | G24: 18D-PU-FOAM-79.50X35.50X09MM | H24: 0.295
... A37: GP06 | B37: RTUPGPBW20X18X06 | C37: 40D-PU-FOAM-19.50x115MMx40MM | D37: 0.091 | E37: 40D-PU-FOAM-14.50X115MMX40MM | F37: 0.068 | G37: 18D-PU-FOAM-19.50X17.50X09MM | H37: 0.036
A38: GP06 | B38: RTUPGPBW13X13X06 | C38: 40D-PU-FOAM-12.50x115MMx40MM | E38: 40D-PU-FOAM-09.50X115MMX40MM | G38: 18D-PU-FOAM-12.50X12.50X09MM | H38: 0.016
A39: GP08 | B39: RTUPGPBW72X30X08 | C39: 40D-PU-FOAM-71.50x145MMx40MM | D39: 0.421 | E39: 40D-PU-FOAM-26.50x145MMx40MM | F39: 0.156 | G39: 18D-PU-FOAM-71.50X29.50X09MM | H39: 0.22
A40: GP08 | B40: RTUPGPBW72X36X08 | C40: 40D-PU-FOAM-71.50x145MMx40MM | D40: 0.421 | E40: 40D-PU-FOAM-32.50X145MMX40MM | F40: 0.192 | G40: 18D-PU-FOAM-71.50X35.50X09MM | H40: 0.265
A41: GP08 | B41: RTUPGPBW72X42X08 | C41: 40D-PU-FOAM-71.50x145MMx40MM | D41: 0.421 | E41: 40D-PU-FOAM-38.50X145MMX40MM | F41: 0.227 | G41: 18D-PU-FOAM-71.50X41.50X09MM | H41: 0.31
A42: GP08 | B42: RTUPGPBW72X48X08 | C42: 40D-PU-FOAM-71.50x145MMx40MM | D42: 0.421 | E42: 40D-PU-FOAM-44.50X145MMX40MM | F42: 0.262 | G42: 18D-PU-FOAM-71.50X47.50X09MM | H42: 0.355
A43: GP08 | B43: RTUPGPBW72X60X08 | C43: 40D-PU-FOAM-71.50x145MMx40MM | D43: 0.421 | E43: 40D-PU-FOAM-56.50X145MMX40MM | F43: 0.333 | G43: 18D-PU-FOAM-71.50X59.50X09MM | H43: 0.445
A44: GP08 | B44: RTUPGPBW72X66X08 | C44: 40D-PU-FOAM-71.50x145MMx40MM | D44: 0.421 | E44: 40D-PU-FOAM-62.50X145MMX40MM | F44: 0.368 | G44: 18D-PU-FOAM-71.50X65.50X09MM | H44: 0.489
A45: GP08 | B45: RTUPGPBW72X72X08 | C45: 40D-PU-FOAM-71.50x145MMx40MM | D45: 0.421 | E45: 40D-PU-FOAM-68.50X145MMX40MM | F45: 0.404 | G45: 18D-PU-FOAM-71.50X71.50X09MM | H45: 0.534
A46: GP08 | B46: RTUPGPBW75X30X08 | C46: 40D-PU-FOAM-74.50x145MMx40MM | D46: 0.439 | E46: 40D-PU-FOAM-26.50x145MMx40MM | F46: 0.156 | G46: 18D-PU-FOAM-74.50X29.50X09MM | H46: 0.23
A47: GP08 | B47: RTUPGPBW75X36X08 | C47: 40D-PU-FOAM-74.50x145MMx40MM | D47: 0.439 | E47: 40D-PU-FOAM-32.50X145MMX40MM | F47: 0.192 | G47: 18D-PU-FOAM-74.50X35.50X09MM | H47: 0.276
A48: GP08 | B48: RTUPGPBW75X42X08 | C48: 40D-PU-FOAM-74.50x145MMx40MM | D48: 0.439 | E48: 40D-PU-FOAM-38.50X145MMX40MM | F48: 0.227 | G48: 18D-PU-FOAM-74.50X41.50X09MM | H48: 0.323
A49: GP08 | B49: RTUPGPBW75X48X08 | C49: 40D-PU-FOAM-74.50x145MMx40MM | D49: 0.439 | E49: 40D-PU-FOAM-44.50X145MMX40MM | F49: 0.262 | G49: 18D-PU-FOAM-74.50X47.50X09MM | H49: 0.37
A50: GP08 | B50: RTUPGPBW75X60X08 | C50: 40D-PU-FOAM-74.50x145MMx40MM | D50: 0.439 | E50: 40D-PU-FOAM-56.50X145MMX40MM | F50: 0.333 | G50: 18D-PU-FOAM-74.50X59.50X09MM | H50: 0.463
... A148: GP06 | B148: RTUPGPGR20X18X06 | C148: 40D-PU-FOAM-19.50x115MMx40MM | D148: 0.091 | E148: 40D-PU-FOAM-14.50X115MMX40MM | F148: 0.068 | G148: 18D-PU-FOAM-19.50X17.50X09MM | H148: 0.036
A149: GP06 | B149: RTUPGPGR13X13X06 | C149: 40D-PU-FOAM-12.50x115MMx40MM | E149: 40D-PU-FOAM-09.50X115MMX40MM | G149: 18D-PU-FOAM-12.50X12.50X09MM | H149: 0.016
...

Sheet MATTRESS DETAILS
B3: BOX MATTRESS FOAM DETAILS
B4: S.NO | C4: BOX TYPES | D4: INCHES | E4: HEIGHT | F4: SIDEWALL | K4: TOP FOAM | P4: REBOUND
F5: DENSITY | G5: MM | H5: LENGTH | I5: WIDTH | J5: QTY | K5: DENSITY | L5: MM | M5: LENGTH | N5: WIDTH | O5: QTY | P5: DENSITY | Q5: MM | R5: LENGTH | S5: WIDTH | T5: QTY
B6: 1 | C6: GP | D6: 6 | E6: 110 | F6: 40-D | G6: 40MM | H6: ACTUAL SIZE-0.5MM | I6: ACTUAL SIZE - 3.5MM | J6: LENGTH-2NOS, WIDTH- 2NOS | K6: 18-D | L6: 9MM | M6: ACTUAL SIZE-0.5MM | N6: ACTUAL SIZE-0.5MM | O6: 1NO | P6: - | Q6: - | R6: - | S6: - | T6: -
B7: 2 | C7: GP | D7: 8 | E7: 140 | F7: 40-D | G7: 40MM | H7: ACTUAL SIZE-0.5MM | I7: ACTUAL SIZE - 3.5MM | J7: LENGTH-2NOS, WIDTH- 2NOS | K7: 18-D | L7: 9MM | M7: ACTUAL SIZE-0.5MM | N7: ACTUAL SIZE-0.5MM | O7: 1NO | P7: - | Q7: - | R7: - | S7: - | T7: -
B8: 3 | C8: GP | D8: 10 | E8: 160 | F8: 40-D | G8: 40MM | H8: ACTUAL SIZE-0.5MM | I8: ACTUAL SIZE - 3.5MM | J8: LENGTH-2NOS, WIDTH- 2NOS | K8: 18-D | L8: 9MM | M8: ACTUAL SIZE-0.5MM | N8: ACTUAL SIZE-0.5MM | O8: 1NO | P8: - | Q8: - | R8: - | S8: - | T8: -
B9: 4 | C9: CAMEO | D9: 6 | E9: 140 | F9: 40-D | G9: 40MM | H9: ACTUAL SIZE-0.5MM | I9: ACTUAL SIZE - 3.5MM | J9: LENGTH-2NOS, WIDTH- 2NOS | K9: 18-D | L9: 9MM | M9: ACTUAL SIZE-0.5MM | N9: ACTUAL SIZE-0.5MM | O9: 1NO | P9: - | Q9: - | R9: - | S9: - | T9: -
B10: 5 | C10: CAMEO | D10: 8 | E10: 140 | F10: 40-D | G10: 40MM | H10: ACTUAL SIZE-0.5MM | I10: ACTUAL SIZE - 3.5MM | J10: LENGTH-2NOS, WIDTH- 2NOS | K10: 18-D | L10: 9MM | M10: ACTUAL SIZE-0.5MM | N10: ACTUAL SIZE-0.5MM | O10: 1NO | P10: - | Q10: - | R10: - | S10: - | T10: -
B11: 6 | C11: VIVAH | D11: 10 | E11: 110 | F11: 40-D | G11: 40MM | H11: ACTUAL SIZE-0.5MM | I11: ACTUAL SIZE - 3.5MM | J11: LENGTH-2NOS, WIDTH- 2NOS | K11: 18-D | L11: 15MM | M11: ACTUAL SIZE-0.5MM | N11: ACTUAL SIZE-0.5MM | O11: 1NO | P11: - | Q11: - | R11: - | S11: - | T11: -
B12: 7 | C12: VIVAH | D12: 12 | E12: 160 | F12: 40-D | G12: 40MM | H12: ACTUAL SIZE-0.5MM | I12: ACTUAL SIZE - 3.5MM | J12: LENGTH-2NOS, WIDTH- 2NOS | K12: 18-D | L12: 9MM | M12: ACTUAL SIZE-0.5MM | N12: ACTUAL SIZE-0.5MM | O12: 1NO | P12: - | Q12: - | R12: - | S12: - | T12: -
B13: 8 | C13: ORGANIGA | D13: 6 | E13: 110 | F13: 40-D | G13: 75MM | H13: ACTUAL SIZE-0.5MM | I13: ACTUAL SIZE - 6MM | J13: LENGTH-2NOS, WIDTH- 2NOS | K13: 32-D | L13: 10MM | M13: ACTUAL SIZE-0.5MM | N13: ACTUAL SIZE-0.5MM | O13: 1NO | P13: - | Q13: - | R13: - | S13: - | T13: -
B14: 9 | C14: ORGANIGA | D14: 8 | E14: 140 | F14: 40-D | G14: 75MM | H14: ACTUAL SIZE-0.5MM | I14: ACTUAL SIZE - 6MM | J14: LENGTH-2NOS, WIDTH- 2NOS | K14: 32-D | L14: 20MM | M14: ACTUAL SIZE-0.5MM | N14: ACTUAL SIZE-0.5MM | O14: 1NO | P14: - | Q14: - | R14: - | S14: - | T14: -
B15: 10 | C15: ORGANIGA | D15: 10 | E15: 160 | F15: 40-D | G15: 75MM | H15: ACTUAL SIZE-0.5MM | I15: ACTUAL SIZE - 6MM | J15: LENGTH-2NOS, WIDTH- 2NOS | K15: 32-D | L15: 30MM | M15: ACTUAL SIZE-0.5MM | N15: ACTUAL SIZE-0.5MM | O15: 1NO | P15: - | Q15: - | R15: - | S15: - | T15: -
B16: 11 | C16: CRYSTAL | D16: 8 | E16: 160 | F16: 40-D | G16: 75MM | H16: ACTUAL SIZE-0.5MM | I16: ACTUAL SIZE - 6MM | J16: LENGTH-2NOS, WIDTH- 2NOS | K16: 18-D | L16: 09MM | M16: ACTUAL SIZE-0.5MM | N16: ACTUAL SIZE-0.5MM | O16: 1NO | P16: - | Q16: - | R16: - | S16: - | T16: -
B17: 14 | C17: ITALINO FAUXTOP | D17: 8 | E17: 110 | F17: 40-D | G17: 75MM | H17: ACTUAL SIZE-0.5MM | I17: ACTUAL SIZE - 6MM | J17: LENGTH-2NOS, WIDTH- 2NOS | K17: 23-D | L17: 15MM | M17: ACTUAL SIZE-0.5MM | N17: ACTUAL SIZE-0.5MM | O17: 1NO | P17: - | Q17: - | R17: - | S17: - | T17: -
... B27: 15 | C27: SPG | D27: 10 | E27: 150 | F27: 40-D | G27: 75MM | H27: ACTUAL SIZE-0.5MM | I27: ACTUAL SIZE - 6MM | J27: LENGTH-2NOS, WIDTH- 2NOS | K27: - | L27: - | M27: - | N27: - | O27: - | P27: 100-D | Q27: 25MM & 30MM | R27: ACTUAL SIZE-0.5MM | S27: ACTUAL SIZE-0.5MM | T27: 25MM-1, 30MM-1

Sheet SIDE WALL FOAM WEIGHT DETAILS
C2: ITEM CODE | D2: WEIGHT
C3: 40D-PU-FOAM-71.50x115MMx40MM | D3: 0.334
C4: 40D-PU-FOAM-74.50x115MMx40MM | D4: 0.348
C5: 40D-PU-FOAM-77.50x115MMx40MM | D5: 0.362
C6: 40D-PU-FOAM-79.50x115MMx40MM | D6: 0.372
C7: 40D-PU-FOAM-83.50x115MMx40MM | D7: 0.39
C8: 40D-PU-FOAM-26.50x115MMx40MM | D8: 0.124
C9: 40D-PU-FOAM-32.50X115MMX40MM | D9: 0.152
C10: 40D-PU-FOAM-38.50X115MMX40MM | D10: 0.18
C11: 40D-PU-FOAM-44.50X115MMX40MM | D11: 0.208
C12: 40D-PU-FOAM-56.50X115MMX40MM | D12: 0.264
C13: 40D-PU-FOAM-62.50X115MMX40MM | D13: 0.292
C14: 40D-PU-FOAM-68.50X115MMX40MM | D14: 0.32
... C134: 40D-PU-FOAM-07X115MMX75MM | D134: 0.061

Sheet TOP FOAM WEIGHT DETAILS
C2: 18D-PU-FOAM-71.50X29.50X09MM | D2: 0.22
C3: 18D-PU-FOAM-71.50X35.50X09MM | D3: 0.265
C4: 18D-PU-FOAM-71.50X41.50X09MM | D4: 0.31
C5: 18D-PU-FOAM-71.50X47.50X09MM | D5: 0.355
C6: 18D-PU-FOAM-71.50X59.50X09MM | D6: 0.445
C7: 18D-PU-FOAM-71.50X65.50X09MM | D7: 0.489
C8: 18D-PU-FOAM-71.50X71.50X09MM | D8: 0.534
C9: 18D-PU-FOAM-74.50X29.50X09MM | D9: 0.23
C10: 18D-PU-FOAM-74.50X35.50X09MM | D10: 0.276
C11: 18D-PU-FOAM-74.50X41.50X09MM | D11: 0.323
C12: 18D-PU-FOAM-74.50X47.50X09MM | D12: 0.37
C13: 18D-PU-FOAM-74.50X59.50X09MM | D13: 0.463
... C36: 18D-PU-FOAM-83.50X71.50X09MM | D36: 0.624
C37: 18D-PU-FOAM-12.50X12.50X09MM | D37: =1.188/74.25 -> 0.016
C38: 18D-PU-FOAM-71.50X29.50X15MM | D38: 0.367
C39: 18D-PU-FOAM-71.50X35.50X15MM | D39: 0.442
C40: 18D-PU-FOAM-71.50X41.50X15MM | D40: 0.517
C41: 18D-PU-FOAM-71.50X47.50X15MM | D41: 0.592
C42: 18D-PU-FOAM-71.50X59.50X15MM | D42: 0.741
C43: 18D-PU-FOAM-71.50X65.50X15MM | D43: 0.816
C44: 18D-PU-FOAM-71.50X71.50X15MM | D44: 0.891
C45: 18D-PU-FOAM-74.50X29.50X15MM | D45: 0.383
C46: 18D-PU-FOAM-74.50X35.50X15MM | D46: 0.461
C47: 18D-PU-FOAM-74.50X41.50X15MM | D47: 0.539
C48: 18D-PU-FOAM-74.50X47.50X15MM | D48: 0.616
C49: 18D-PU-FOAM-74.50X59.50X15MM | D49: 0.772
... C258: 32D-PU-FOAM-83.50X71.50X30MM | D258: 3.698

Sheet REBOUND WEIGHT DETAILS
C1: ITEM CODE | D1: QTY
C2: 100D-RB-FOAM-71.50X29.50X20MM | D2: 2.722
C3: 100D-RB-FOAM-71.50X35.50X20MM | D3: 3.275
C4: 100D-RB-FOAM-71.50X41.50X20MM | D4: 3.829
C5: 100D-RB-FOAM-71.50X47.50X20MM | D5: 4.382
C6: 100D-RB-FOAM-71.50X59.50X20MM | D6: 5.489
C7: 100D-RB-FOAM-71.50X65.50X20MM | D7: 6.043
C8: 100D-RB-FOAM-71.50X71.50X20MM | D8: 6.596
C9: 100D-RB-FOAM-74.50X29.50X20MM | D9: 2.836
C10: 100D-RB-FOAM-74.50X35.50X20MM | D10: 3.413
C11: 100D-RB-FOAM-74.50X41.50X20MM | D11: 3.989
C12: 100D-RB-FOAM-74.50X47.50X20MM | D12: 4.566
C13: 100D-RB-FOAM-74.50X59.50X20MM | D13: 5.72
... C57: 100D-RB-FOAM-77.50X65.50X25MM | D57: 8.187
C58: 100D-RB-FOAM-77.50X71.50X25MM | D58: 8.937 | E58: =+D58*26 -> 232.362
C59: 100D-RB-FOAM-79.50X29.50X25MM | D59: 3.783
C60: 100D-RB-FOAM-79.50X35.50X25MM | D60: 4.552
C61: 100D-RB-FOAM-79.50X41.50X25MM | D61: 5.321
C62: 100D-RB-FOAM-79.50X47.50X25MM | D62: 6.091
C63: 100D-RB-FOAM-79.50X59.50X25MM | D63: 7.629
C64: 100D-RB-FOAM-79.50X65.50X25MM | D64: 8.399
C65: 100D-RB-FOAM-79.50X71.50X25MM | D65: 9.168
C66: 100D-RB-FOAM-83.50X29.50X25MM | D66: 3.973
C67: 100D-RB-FOAM-83.50X35.50X25MM | D67: 4.781
C68: 100D-RB-FOAM-83.50X41.50X25MM | D68: 5.589
C69: 100D-RB-FOAM-83.50X47.50X25MM | D69: 6.397
C70: 100D-RB-FOAM-83.50X59.50X25MM | D70: 8.013
... C145: 100D-RB-FOAM-12.50X12.50X40MM | D145: 0.403

Sheet OVERALL WEIGHTS
A1: ITEM CODE | B1: WEIGHT | C1: VARIETY
A2: 40D-PU-FOAM-71.50x115MMx40MM | B2: 0.334 | C2: GP06
A3: 40D-PU-FOAM-74.50x115MMx40MM | B3: 0.348 | C3: GP06
A4: 40D-PU-FOAM-77.50x115MMx40MM | B4: 0.362 | C4: GP06
A5: 40D-PU-FOAM-79.50x115MMx40MM | B5: 0.372 | C5: GP06
A6: 40D-PU-FOAM-83.50x115MMx40MM | B6: 0.39 | C6: GP06
A7: 40D-PU-FOAM-26.50x115MMx40MM | B7: 0.124 | C7: GP06
A8: 40D-PU-FOAM-32.50X115MMX40MM | B8: 0.152 | C8: GP06
A9: 40D-PU-FOAM-38.50X115MMX40MM | B9: 0.18 | C9: GP06
A10: 40D-PU-FOAM-44.50X115MMX40MM | B10: 0.208 | C10: GP06
A11: 40D-PU-FOAM-56.50X115MMX40MM | B11: 0.264 | C11: GP06
A12: 40D-PU-FOAM-62.50X115MMX40MM | B12: 0.292 | C12: GP06
A13: 40D-PU-FOAM-68.50X115MMX40MM | B13: 0.32 | C13: GP06
... A205: 18D-PU-FOAM-83.50X71.50X09MM | B205: 0.624 | C205: GP06
A206: 18D-PU-FOAM-12.50X12.50X09MM | B206: =1.188/74.25 -> 0.016 | C206: MINIGP06
A207: 18D-PU-FOAM-71.50X29.50X09MM | B207: 0.22 | C207: GP08
A208: 18D-PU-FOAM-71.50X35.50X09MM | B208: 0.265 | C208: GP08
A209: 18D-PU-FOAM-71.50X41.50X09MM | B209: 0.31 | C209: GP08
A210: 18D-PU-FOAM-71.50X47.50X09MM | B210: 0.355 | C210: GP08
A211: 18D-PU-FOAM-71.50X59.50X09MM | B211: 0.445 | C211: GP08
A212: 18D-PU-FOAM-71.50X65.50X09MM | B212: 0.489 | C212: GP08
A213: 18D-PU-FOAM-71.50X71.50X09MM | B213: 0.534 | C213: GP08
A214: 18D-PU-FOAM-74.50X29.50X09MM | B214: 0.23 | C214: GP08
A215: 18D-PU-FOAM-74.50X35.50X09MM | B215: 0.276 | C215: GP08
A216: 18D-PU-FOAM-74.50X41.50X09MM | B216: 0.323 | C216: GP08
A217: 18D-PU-FOAM-74.50X47.50X09MM | B217: 0.37 | C217: GP08
A218: 18D-PU-FOAM-74.50X59.50X09MM | B218: 0.463 | C218: GP08
... A241: 18D-PU-FOAM-83.50X71.50X09MM | B241: 0.624 | C241: GP08
A242: 18D-PU-FOAM-12.50X12.50X09MM | B242: =1.188/74.25 -> 0.016 | C242: MINIGP08
A243: 18D-PU-FOAM-71.50X29.50X09MM | B243: 0.22 | C243: GP10
A244: 18D-PU-FOAM-71.50X35.50X09MM | B244: 0.265 | C244: GP10
A245: 18D-PU-FOAM-71.50X41.50X09MM | B245: 0.31 | C245: GP10
A246: 18D-PU-FOAM-71.50X47.50X09MM | B246: 0.355 | C246: GP10
A247: 18D-PU-FOAM-71.50X59.50X09MM | B247: 0.445 | C247: GP10
A248: 18D-PU-FOAM-71.50X65.50X09MM | B248: 0.489 | C248: GP10
A249: 18D-PU-FOAM-71.50X71.50X09MM | B249: 0.534 | C249: GP10
A250: 18D-PU-FOAM-74.50X29.50X09MM | B250: 0.23 | C250: GP10
A251: 18D-PU-FOAM-74.50X35.50X09MM | B251: 0.276 | C251: GP10
A252: 18D-PU-FOAM-74.50X41.50X09MM | B252: 0.323 | C252: GP10
A253: 18D-PU-FOAM-74.50X47.50X09MM | B253: 0.37 | C253: GP10
...

Sheet Sheet5
B1: VARIETY | C1: SAMPLES
B2: SKSGSR | C2: SPG
B3: RTUPGPBW | C3: GP
B4: RTUPGPGR | C4: GP
B5: RTGPCSBG | C5: CRYSTAL
B6: RTGPCSPW | C6: CRYSTAL
B7: PEPSPKORGBW | C7: ORG
B8: RTVHETPT | C8: VIVAH
B9: RTPKCMSTCS | C9: CAMEO
B10: RTPKCMULTSTCS | C10: CAMEO
B11: HYPALRPKNLBLOR | C11: ALU
B12: HYPALRPKNLSTGR | C12: ALU
... B36: RTPKARPLMFNLGR | C36: ARDMEMNL

Sheet Sheet1
C2: 44 | D2: 18D-PU-FOAM-71.50X29.50X06MM | E2: 18D-Pure Foam Sheet-71.50X29.50X06MM | F2: HYP-EXT-PURE-18D | G2: 265 | H2: 0.147
C3: 45 | D3: 18D-PU-FOAM-71.50X32.50X06MM | E3: 18D-Pure Foam Sheet-71.50X32.50X06MM | F3: HYP-EXT-PURE-18D | G3: 265 | H3: 0.162
C4: 46 | D4: 18D-PU-FOAM-71.50X35.50X06MM | E4: 18D-Pure Foam Sheet-71.50X35.50X06MM | F4: HYP-EXT-PURE-18D | G4: 265 | H4: 0.177
C5: 47 | D5: 18D-PU-FOAM-71.50X38.50X06MM | E5: 18D-Pure Foam Sheet-71.50X38.50X06MM | F5: HYP-EXT-PURE-18D | G5: 265 | H5: 0.192
C6: 48 | D6: 18D-PU-FOAM-71.50X41.50X06MM | E6: 18D-Pure Foam Sheet-71.50X41.50X06MM | F6: HYP-EXT-PURE-18D | G6: 265 | H6: 0.207
C7: 49 | D7: 18D-PU-FOAM-71.50X44.50X06MM | E7: 18D-Pure Foam Sheet-71.50X44.50X06MM | F7: HYP-EXT-PURE-18D | G7: 265 | H7: 0.222
C8: 50 | D8: 18D-PU-FOAM-71.50X47.50X06MM | E8: 18D-Pure Foam Sheet-71.50X47.50X06MM | F8: HYP-EXT-PURE-18D | G8: 265 | H8: 0.237
C9: 51 | D9: 18D-PU-FOAM-71.50X50.50X06MM | E9: 18D-Pure Foam Sheet-71.50X50.50X06MM | F9: HYP-EXT-PURE-18D | G9: 265 | H9: 0.252
C10: 52 | D10: 18D-PU-FOAM-71.50X53.50X06MM | E10: 18D-Pure Foam Sheet-71.50X53.50X06MM | F10: HYP-EXT-PURE-18D | G10: 265 | H10: 0.267
C11: 53 | D11: 18D-PU-FOAM-71.50X56.50X06MM | E11: 18D-Pure Foam Sheet-71.50X56.50X06MM | F11: HYP-EXT-PURE-18D | G11: 265 | H11: 0.281
C12: 54 | D12: 18D-PU-FOAM-71.50X59.50X06MM | E12: 18D-Pure Foam Sheet-71.50X59.50X06MM | F12: HYP-EXT-PURE-18D | G12: 265 | H12: 0.296
C13: 55 | D13: 18D-PU-FOAM-71.50X62.50X06MM | E13: 18D-Pure Foam Sheet-71.50X62.50X06MM | F13: HYP-EXT-PURE-18D | G13: 265 | H13: 0.311
... C78: 120 | D78: 18D-PU-FOAM-12.50X12.50X06MM | E78: 18D-Pure Foam Sheet-12.50X12.50X06MM | F78: HYP-EXT-PURE-18D | G78: 265 | H78: 0.011

Sheet ALL NEW ITEM 
A2: DENSITY | B2: LENGTH | C2: HEIGHT | D2: FOAM SIZE | E2: ITEM CODE | F2: WEIGHT
A3: 32 | B3: 71.5 | C3: 115 | D3: 40 | E3: 32D-HARD-FOAM-71.50X115MMX40MM | F3: =ROUND(A3*B3*0.0254*C3/1000*D3/1000,3) -> 0.267
A4: 32 | B4: 74.5 | C4: 115 | D4: 40 | E4: 32D-HARD-FOAM-74.50X115MMX40MM | F4: =ROUND(A4*B4*0.0254*C4/1000*D4/1000,3) -> 0.279
A5: 32 | B5: 77.5 | C5: 115 | D5: 40 | E5: 32D-HARD-FOAM-77.50X115MMX40MM | F5: =ROUND(A5*B5*0.0254*C5/1000*D5/1000,3) -> 0.29
A6: 32 | B6: 79.5 | C6: 115 | D6: 40 | E6: 32D-HARD-FOAM-79.50X115MMX40MM | F6: =ROUND(A6*B6*0.0254*C6/1000*D6/1000,3) -> 0.297
A7: 32 | B7: 83.5 | C7: 115 | D7: 40 | E7: 32D-HARD-FOAM-83.50X115MMX40MM | F7: =ROUND(A7*B7*0.0254*C7/1000*D7/1000,3) -> 0.312
A8: 32 | B8: 12.5 | C8: 115 | D8: 40 | E8: 32D-HARD-FOAM-12.50X115MMX40MM | F8: =ROUND(A8*B8*0.0254*C8/1000*D8/1000,3) -> 0.047
A9: 32 | B9: 19.5 | C9: 115 | D9: 40 | E9: 32D-HARD-FOAM-19.50X115MMX40MM | F9: =ROUND(A9*B9*0.0254*C9/1000*D9/1000,3) -> 0.073
A10: 32 | B10: 71.5 | C10: 135 | D10: 40 | E10: 32D-HARD-FOAM-71.50X135MMX40MM | F10: =ROUND(A10*B10*0.0254*C10/1000*D10/1000,3) -> 0.314
A11: 32 | B11: 74.5 | C11: 135 | D11: 40 | E11: 32D-HARD-FOAM-74.50X135MMX40MM | F11: =ROUND(A11*B11*0.0254*C11/1000*D11/1000,3) -> 0.327
A12: 32 | B12: 77.5 | C12: 135 | D12: 40 | E12: 32D-HARD-FOAM-77.50X135MMX40MM | F12: =ROUND(A12*B12*0.0254*C12/1000*D12/1000,3) -> 0.34
A13: 32 | B13: 79.5 | C13: 135 | D13: 40 | E13: 32D-HARD-FOAM-79.50X135MMX40MM | F13: =ROUND(A13*B13*0.0254*C13/1000*D13/1000,3) -> 0.349
A14: 32 | B14: 83.5 | C14: 135 | D14: 40 | E14: 32D-HARD-FOAM-83.50X135MMX40MM | F14: =ROUND(A14*B14*0.0254*C14/1000*D14/1000,3) -> 0.366
... A362: 32 | B362: 12 | C362: 95 | D362: 70 | E362: 32D-HARD-FOAM-12X95MMX70MM | F362: =ROUND(A362*B362*0.0254*C362/1000*D362/1000,3) -> 0.065
A363: 32 | B363: 71.5 | C363: 29.5 | D363: 10 | E363: 32D-PU-FOAM-71.50X29.50X10MM | F363: =+ROUND((A363*B363*0.0254*C363*0.0254*(D363/1000)),3) -> 0.435
A364: 32 | B364: 71.5 | C364: 32.5 | D364: 10 | E364: 32D-PU-FOAM-71.50X32.50X10MM | F364: =+ROUND((A364*B364*0.0254*C364*0.0254*(D364/1000)),3) -> 0.48
A365: 32 | B365: 71.5 | C365: 35.5 | D365: 10 | E365: 32D-PU-FOAM-71.50X35.50X10MM | F365: =+ROUND((A365*B365*0.0254*C365*0.0254*(D365/1000)),3) -> 0.524
A366: 32 | B366: 71.5 | C366: 38.5 | D366: 10 | E366: 32D-PU-FOAM-71.50X38.50X10MM | F366: =+ROUND((A366*B366*0.0254*C366*0.0254*(D366/1000)),3) -> 0.568
A367: 32 | B367: 71.5 | C367: 41.5 | D367: 10 | E367: 32D-PU-FOAM-71.50X41.50X10MM | F367: =+ROUND((A367*B367*0.0254*C367*0.0254*(D367/1000)),3) -> 0.613
A368: 32 | B368: 71.5 | C368: 44.5 | D368: 10 | E368: 32D-PU-FOAM-71.50X44.50X10MM | F368: =+ROUND((A368*B368*0.0254*C368*0.0254*(D368/1000)),3) -> 0.657
A369: 32 | B369: 71.5 | C369: 47.5 | D369: 10 | E369: 32D-PU-FOAM-71.50X47.50X10MM | F369: =+ROUND((A369*B369*0.0254*C369*0.0254*(D369/1000)),3) -> 0.701
A370: 32 | B370: 71.5 | C370: 50.5 | D370: 10 | E370: 32D-PU-FOAM-71.50X50.50X10MM | F370: =+ROUND((A370*B370*0.0254*C370*0.0254*(D370/1000)),3) -> 0.745
A371: 32 | B371: 71.5 | C371: 53.5 | D371: 10 | E371: 32D-PU-FOAM-71.50X53.50X10MM | F371: =+ROUND((A371*B371*0.0254*C371*0.0254*(D371/1000)),3) -> 0.79
A372: 32 | B372: 71.5 | C372: 56.5 | D372: 10 | E372: 32D-PU-FOAM-71.50X56.50X10MM | F372: =+ROUND((A372*B372*0.0254*C372*0.0254*(D372/1000)),3) -> 0.834
A373: 32 | B373: 71.5 | C373: 59.5 | D373: 10 | E373: 32D-PU-FOAM-71.50X59.50X10MM | F373: =+ROUND((A373*B373*0.0254*C373*0.0254*(D373/1000)),3) -> 0.878
A374: 32 | B374: 71.5 | C374: 62.5 | D374: 10 | E374: 32D-PU-FOAM-71.50X62.50X10MM | F374: =+ROUND((A374*B374*0.0254*C374*0.0254*(D374/1000)),3) -> 0.923
... A901: 25 | B901: 19.5 | C901: 17.5 | D901: 50 | E901: 25D-HELIXA-FOAM-19.50X17.50X50MM | F901: =+ROUND((A901*B901*0.0254*C901*0.0254*(D901/1000)),3) -> 0.275
A902: 32 | B902: 71.5 | C902: 175 | D902: 75 | E902: 32D-PU-FOAM-71.50X175MMX75MM | F902: =ROUND(A902*B902*0.0254*C902/1000*D902/1000,3) -> 0.763
A903: 32 | B903: 74.5 | C903: 175 | D903: 75 | E903: 32D-PU-FOAM-74.50X175MMX75MM | F903: =ROUND(A903*B903*0.0254*C903/1000*D903/1000,3) -> 0.795
A904: 32 | B904: 77.5 | C904: 175 | D904: 75 | E904: 32D-PU-FOAM-77.50X175MMX75MM | F904: =ROUND(A904*B904*0.0254*C904/1000*D904/1000,3) -> 0.827
A905: 32 | B905: 79.5 | C905: 175 | D905: 75 | E905: 32D-PU-FOAM-79.50X175MMX75MM | F905: =ROUND(A905*B905*0.0254*C905/1000*D905/1000,3) -> 0.848
A906: 32 | B906: 83.5 | C906: 175 | D906: 75 | E906: 32D-PU-FOAM-83.50X175MMX75MM | F906: =ROUND(A906*B906*0.0254*C906/1000*D906/1000,3) -> 0.891
A907: 32 | B907: 24 | C907: 175 | D907: 75 | E907: 32D-PU-FOAM-24X175MMX75MM | F907: =ROUND(A907*B907*0.0254*C907/1000*D907/1000,3) -> 0.256
A908: 32 | B908: 27 | C908: 175 | D908: 75 | E908: 32D-PU-FOAM-27X175MMX75MM | F908: =ROUND(A908*B908*0.0254*C908/1000*D908/1000,3) -> 0.288
A909: 32 | B909: 30 | C909: 175 | D909: 75 | E909: 32D-PU-FOAM-30X175MMX75MM | F909: =ROUND(A909*B909*0.0254*C909/1000*D909/1000,3) -> 0.32
A910: 32 | B910: 33 | C910: 175 | D910: 75 | E910: 32D-PU-FOAM-33X175MMX75MM | F910: =ROUND(A910*B910*0.0254*C910/1000*D910/1000,3) -> 0.352
A911: 32 | B911: 36 | C911: 175 | D911: 75 | E911: 32D-PU-FOAM-36X175MMX75MM | F911: =ROUND(A911*B911*0.0254*C911/1000*D911/1000,3) -> 0.384
A912: 32 | B912: 39 | C912: 175 | D912: 75 | E912: 32D-PU-FOAM-39X175MMX75MM | F912: =ROUND(A912*B912*0.0254*C912/1000*D912/1000,3) -> 0.416
A913: 32 | B913: 42 | C913: 175 | D913: 75 | E913: 32D-PU-FOAM-42X175MMX75MM | F913: =ROUND(A913*B913*0.0254*C913/1000*D913/1000,3) -> 0.448
... A980: 32 | B980: 7 | C980: 225 | D980: 75 | E980: 32D-HARD-FOAM-07X175MMX75MM | F980: =ROUND(A980*B980*0.0254*C980/1000*D980/1000,3) -> 0.096

Sheet FORMULAS
B2: LENGTH /WIDTH FOAM SIDEWALL WEIGHT FORMULA
B4: ROUND(DENSITY*LENGTH*0.0254*FOAM HEIGHT/1000*FOAM SIZE/1000,3)
B6: EXAMPLE:
B7: 40MM SIDEWALL ,40 DENSITY, LENGTH SIZE -74.5 , HEIGHT-155
B9: ROUND(40*74.5*0.0254*155/1000*40/1000,3)
B12: TOP FOAM /REBOUND WEIGHT FORMULA
B14: ROUND((DENSITY*LENGTH*0.0254*WIDTH*0.0254*(THICKNESS/1000)),3)
B16: EXAMPLE:
B17: 100 DENSITY, LENGTH SIZE -74.5 , WIDTH SIZE-59.5 THICKNESS-20MM
B19: ROUND((100*74.5*0.0254*59.5*0.0254*(20/1000)),3)

Sheet MASTER
A1: SNO | B1: ITEM | C1: HEIGHT | D1: VAREITY NAME | E1: LENGTH | F1: WIDTH | G1: HIGHT | H1: DENSITY | I1: SIDEWALL MM | J1: TOPFOAM DENSITY | K1: TOPFOAM & REBOUND 1 MM | L1: TOPFOAM & REBOUND 2 MM | M1: TOP FOAM/ REBOUND | N1: TOP FOAM/ REBOUND
A2: 1 | B2: HYPALRPKNLBLOR06 | C2: 130 | D2: ALLURA | E2: 0.5 | F2: 6 | G2: 135MM | H2: 32D-HARD-FOAM- | I2: 75MM | J2: 25D-HELIXA-FOAM- | K2: 15MM | L2: 15MM | M2: 0.5 | N2: 0.5
A3: 2 | B3: HYPALRPKNLBLOR08 | C3: 150 | D3: ALLURA | E3: 0.5 | F3: 6 | G3: 155MM | H3: 32D-HARD-FOAM- | I3: 75MM | J3: 25D-HELIXA-FOAM- | K3: 25MM | L3: 15MM | M3: 0.5 | N3: 0.5
A4: 3 | B4: HYPALRPKNLSTGR06 | C4: 130 | D4: ALLURA | E4: 0.5 | F4: 6 | G4: 135MM | H4: 32D-HARD-FOAM- | I4: 75MM | J4: 25D-HELIXA-FOAM- | K4: 15MM | L4: 15MM | M4: 0.5 | N4: 0.5
A5: 4 | B5: HYPALRPKNLSTGR08 | C5: 150 | D5: ALLURA | E5: 0.5 | F5: 6 | G5: 155MM | H5: 32D-HARD-FOAM- | I5: 75MM | J5: 25D-HELIXA-FOAM- | K5: 25MM | L5: 15MM | M5: 0.5 | N5: 0.5
A6: 5 | B6: HYPALRPKNLBLOR10 | C6: 170 | D6: ALLURA | E6: 0.5 | F6: 6 | G6: 175MM | H6: 32D-HARD-FOAM- | I6: 75MM | J6: 25D-HELIXA-FOAM- | K6: 50MM | L6: 25MM | M6: 0.5 | N6: 0.5
A7: 6 | B7: HYPALRPKNLSTGR10 | C7: 170 | D7: ALLURA | E7: 0.5 | F7: 6 | G7: 175MM | H7: 32D-HARD-FOAM- | I7: 75MM | J7: 25D-HELIXA-FOAM- | K7: 50MM | L7: 25MM | M7: 0.5 | N7: 0.5
A8: 7 | B8: SKPKLTGN06 | C8: 130 | D8: SPK POCKETED LATEX | E8: 0.5 | F8: 6 | G8: 135MM | H8: 32D-HARD-FOAM- | I8: 75MM | J8: 25D-HELIXA-FOAM- | K8: 15MM | L8: 15MM | M8: 0.5 | N8: 0.5
A9: 8 | B9: SKPKLTGN08 | C9: 150 | D9: SPK POCKETED LATEX | E9: 0.5 | F9: 6 | G9: 155MM | H9: 32D-HARD-FOAM- | I9: 75MM | J9: 25D-HELIXA-FOAM- | K9: 25MM | L9: 15MM | M9: 0.5 | N9: 0.5
A10: 9 | B10: SKPKLTGN10 | C10: 170 | D10: SPK POCKETED LATEX | E10: 0.5 | F10: 6 | G10: 175MM | H10: 32D-HARD-FOAM- | I10: 75MM | J10: 25D-HELIXA-FOAM- | K10: 50MM | L10: 25MM | M10: 0.5 | N10: 0.5
A11: 10 | B11: SKPKMFBL06 | C11: 130 | D11: SPK POCKETED MEMORY | E11: 0.5 | F11: 6 | G11: 135MM | H11: 32D-HARD-FOAM- | I11: 75MM | J11: 25D-HELIXA-FOAM- | K11: 15MM | L11: 15MM | M11: 0.5 | N11: 0.5
A12: 11 | B12: SKPKMFBL08 | C12: 150 | D12: SPK POCKETED MEMORY | E12: 0.5 | F12: 6 | G12: 155MM | H12: 32D-HARD-FOAM- | I12: 75MM | J12: 25D-HELIXA-FOAM- | K12: 25MM | L12: 15MM | M12: 0.5 | N12: 0.5
A13: 12 | B13: SKPKMFBL10 | C13: 170 | D13: SPK POCKETED MEMORY | E13: 0.5 | F13: 6 | G13: 175MM | H13: 32D-HARD-FOAM- | I13: 75MM | J13: 25D-HELIXA-FOAM- | K13: 50MM | L13: 25MM | M13: 0.5 | N13: 0.5
A14: 13 | B14: PEPSPKORGBW06 | C14: 110 | D14: ORGANIGA | E14: 0.5 | F14: 6 | G14: 115MM | H14: 32D-HARD-FOAM- | I14: 70MM | J14: 0 | K14: 0 | L14: 0 | M14: 0 | N14: 0
A15: 14 | B15: PEPSPKORGBW08 | C15: 130 | D15: ORGANIGA | E15: 0.5 | F15: 6 | G15: 135MM | H15: 32D-HARD-FOAM- | I15: 70MM | J15: 0 | K15: 0 | L15: 0 | M15: 0 | N15: 0
A16: 15 | B16: PEPSPKORGBW10 | C16: 150 | D16: ORGANIGA | E16: 0.5 | F16: 6 | G16: 155MM | H16: 32D-HARD-FOAM- | I16: 70MM | J16: 0 | K16: 0 | L16: 0 | M16: 0 | N16: 0
A17: 16 | B17: PEPSZENPKNLDB06 | C17: 110 | D17: ZENIMO NORMAL | E17: 0.5 | F17: 6 | G17: 115MM | H17: 32D-HARD-FOAM- | I17: 70MM | J17: 0 | K17: 0 | L17: 0 | M17: 0 | N17: 0
A18: 17 | B18: PEPSZENPKNLDB08 | C18: 130 | D18: ZENIMO NORMAL | E18: 0.5 | F18: 6 | G18: 135MM | H18: 32D-HARD-FOAM- | I18: 70MM | J18: 0 | K18: 0 | L18: 0 | M18: 0 | N18: 0
A19: 20 | B19: RTHTMTPKMFRG06 | C19: 110 | D19: POCKETED FR MEMORY FOAM REGULAR | E19: 0.5 | F19: 6 | G19: 115MM | H19: 32D-HARD-FOAM- | I19: 70MM | J19: 0 | K19: 0 | L19: 0 | M19: 0 | N19: 0
A20: 21 | B20: RTHTMTPKMFRG08 | C20: 150 | D20: POCKETED FR MEMORY FOAM REGULAR | E20: 0.5 | F20: 6 | G20: 155MM | H20: 32D-HARD-FOAM- | I20: 70MM | J20: 0 | K20: 0 | L20: 0 | M20: 0 | N20: 0
A21: 18 | B21: RTHTMTPKMFRG10 | C21: 170 | D21: POCKETED FR MEMORY FOAM REGULAR | E21: 0.5 | F21: 6 | G21: 175MM | H21: 32D-HARD-FOAM- | I21: 70MM | J21: 0 | K21: 0 | L21: 0 | M21: 0 | N21: 0
A22: 19 | B22: RTHTMTPKMFRG12 | C22: 170 | D22: POCKETED FR MEMORY FOAM REGULAR | E22: 0.5 | F22: 6 | G22: 175MM | H22: 32D-HARD-FOAM- | I22: 70MM | J22: 0 | K22: 0 | L22: 0 | M22: 0 | N22: 0
A23: 24 | B23: RTHTMTPKRG06 | C23: 110 | D23: POCKETED FR REGULAR | E23: 0.5 | F23: 6 | G23: 115MM | H23: 32D-HARD-FOAM- | I23: 70MM | J23: 0 | K23: 0 | L23: 0 | M23: 0 | N23: 0
A24: 25 | B24: RTHTMTPKRG08 | C24: 130 | D24: POCKETED FR REGULAR | E24: 0.5 | F24: 6 | G24: 135MM | H24: 32D-HARD-FOAM- | I24: 70MM | J24: 0 | K24: 0 | L24: 0 | M24: 0 | N24: 0
A25: 22 | B25: RTHTMTPKRG10 | C25: 150 | D25: POCKETED FR REGULAR | E25: 0.5 | F25: 6 | G25: 155MM | H25: 32D-HARD-FOAM- | I25: 70MM | J25: 0 | K25: 0 | L25: 0 | M25: 0 | N25: 0
... A28: 27 | B28: PEPSITSTPKNL06 | C28: 110 | D28: SERNITO NORMAL | E28: 0.5 | F28: 6 | G28: 115MM | H28: 32D-HARD-FOAM- | I28: 70MM | J28: 0 | K28: 0 | L28: 0 | M28: 0 | N28: 0
B29: PEPSPKSUPNLBL06 | C29: 130 | D29: SUPREME | E29: 0.5 | F29: 6 | G29: 135MM | H29: 32D-HARD-FOAM- | I29: 70MM | J29: 0 | K29: 0 | L29: 0 | M29: 0 | N29: 0
B30: PEPSPKSUPNLBL08 | C30: 150 | D30: SUPREME | E30: 0.5 | F30: 6 | G30: 155MM | H30: 32D-HARD-FOAM- | I30: 70MM | J30: 0 | K30: 0 | L30: 0 | M30: 0 | N30: 0
B31: PEPSPKSUPNLBL10 | C31: 170 | D31: SUPREME | E31: 0.5 | F31: 6 | G31: 175MM | H31: 32D-HARD-FOAM- | I31: 70MM | J31: 0 | K31: 0 | L31: 0 | M31: 0 | N31: 0
A32: 28 | B32: PEPSPKSUPNLGR06 | C32: 130 | D32: SUPREME | E32: 0.5 | F32: 6 | G32: 135MM | H32: 32D-HARD-FOAM- | I32: 70MM | J32: 0 | K32: 0 | L32: 0 | M32: 0 | N32: 0
A33: 29 | B33: PEPSPKSUPNLGR08 | C33: 150 | D33: SUPREME | E33: 0.5 | F33: 6 | G33: 155MM | H33: 32D-HARD-FOAM- | I33: 70MM | J33: 0 | K33: 0 | L33: 0 | M33: 0 | N33: 0
A34: 30 | B34: PEPSPKSUPNLGR10 | C34: 170 | D34: SUPREME | E34: 0.5 | F34: 6 | G34: 175MM | H34: 32D-HARD-FOAM- | I34: 70MM | J34: 0 | K34: 0 | L34: 0 | M34: 0 | N34: 0
A35: 31 | B35: PEPSPKSUPNLBG06 | C35: 130 | D35: SUPREME | E35: 0.5 | F35: 6 | G35: 135MM | H35: 32D-HARD-FOAM- | I35: 70MM | J35: 0 | K35: 0 | L35: 0 | M35: 0 | N35: 0
A36: 32 | B36: PEPSPKSUPNLBG08 | C36: 150 | D36: SUPREME | E36: 0.5 | F36: 6 | G36: 155MM | H36: 32D-HARD-FOAM- | I36: 70MM | J36: 0 | K36: 0 | L36: 0 | M36: 0 | N36: 0
A37: 33 | B37: PEPSPKSUPNLBG10 | C37: 170 | D37: SUPREME | E37: 0.5 | F37: 6 | G37: 175MM | H37: 32D-HARD-FOAM- | I37: 70MM | J37: 0 | K37: 0 | L37: 0 | M37: 0 | N37: 0
A38: 34 | B38: RTPKARPLMFNLBL06 | C38: 130 | D38: ARDENE MEMORY PLUS NORMAL | E38: 0.5 | F38: 6 | G38: 135MM | H38: 32D-HARD-FOAM- | I38: 70MM | J38: 0 | K38: 0 | L38: 0 | M38: 0 | N38: 0
A39: 35 | B39: RTPKARPLMFNLBL08 | C39: 150 | D39: ARDENE MEMORY PLUS NORMAL | E39: 0.5 | F39: 6 | G39: 155MM | H39: 32D-HARD-FOAM- | I39: 70MM | J39: 0 | K39: 0 | L39: 0 | M39: 0 | N39: 0
A40: 36 | B40: RTPKARPLMFNLBL10 | C40: 170 | D40: ARDENE MEMORY PLUS NORMAL | E40: 0.5 | F40: 6 | G40: 175MM | H40: 32D-HARD-FOAM- | I40: 70MM | J40: 0 | K40: 0 | L40: 0 | M40: 0 | N40: 0
A41: 37 | B41: RTPKARPLMFNLGR06 | C41: 130 | D41: ARDENE MEMORY PLUS NORMAL | E41: 0.5 | F41: 6 | G41: 135MM | H41: 32D-HARD-FOAM- | I41: 70MM | J41: 0 | K41: 0 | L41: 0 | M41: 0 | N41: 0
A42: 38 | B42: RTPKARPLMFNLGR08 | C42: 150 | D42: ARDENE MEMORY PLUS NORMAL | E42: 0.5 | F42: 6 | G42: 155MM | H42: 32D-HARD-FOAM- | I42: 70MM | J42: 0 | K42: 0 | L42: 0 | M42: 0 | N42: 0
...

Sheet ALL ITEM CODE1
A1: S.NO | B1: UNIT SIZE | C1: DENSITY | D1: LENGTH | E1: HEIGHT | F1: FOAM SIZE | G1: ITEM CODE | H1: WEIGHT | I1: QTY | J1: TOTAL WEIGHT | L1: S.NO | M1: UNIT SIZE | N1: DENSITY | O1: LENGTH | P1: HEIGHT | Q1: FOAM SIZE | R1: ITEM CODE | S1: WEIGHT | T1: QTY | U1: TOTAL WEIGHT | W1: S.NO | X1: UNIT SIZE | Y1: DENSITY | Z1: LENGTH | AA1: WIDTH | AB1: THICKNESS | AC1: ITEM CODE | AD1: WEIGHT | AE1: QTY | AF1: TOTAL WEIGHT | AH1: S.NO | AI1: UNIT SIZE | AJ1: DENSITY | AK1: LENGTH | AL1: WIDTH | AM1: THICKNESS | AN1: ITEM CODE | AO1: WEIGHT | AP1: QTY | AQ1: TOTAL WEIGHT
A2: 1 | B2: 72 | C2: 40 | D2: 71.5 | E2: 115 | F2: 40 | G2: 40D-PU-FOAM-71.50X115MMX40MM | H2: =ROUND(C2*D2*0.0254*E2/1000*F2/1000,3) -> 0.334 | J2: =+H2*I2 -> 0 | L2: 1 | M2: 30 | N2: 40 | O2: 26.5 | P2: 115 | Q2: 40 | R2: 40D-PU-FOAM-26.50X115MMX40MM | S2: =ROUND(N2*O2*0.0254*P2/1000*Q2/1000,3) -> 0.124 | U2: =+S2*T2 -> 0 | W2: 1 | X2: 72X30 | Y2: 32 | Z2: 71.5 | AA2: 29.5 | AB2: 10 | AC2: 32D-PU-FOAM-71.50X29.50X10MM | AD2: =+ROUND((Y2*Z2*0.0254*AA2*0.0254*(AB2/1000)),3) -> 0.435 | AF2: =+AD2*AE2 -> 0 | AH2: 1 | AI2: 72X30 | AJ2: 100 | AK2: 71.5 | AL2: 29.5 | AM2: 20 | AN2: 100D-RB-FOAM-71.50X29.50X20MM | AO2: =+ROUND((AJ2*AK2*0.0254*AL2*0.0254*(AM2/1000)),3) -> 2.722 | AQ2: =+AO2*AP2 -> 0
A3: 2 | B3: 75 | C3: 40 | D3: 74.5 | E3: 115 | F3: 40 | G3: 40D-PU-FOAM-74.50X115MMX40MM | H3: =ROUND(C3*D3*0.0254*E3/1000*F3/1000,3) -> 0.348 | J3: =+H3*I3 -> 0 | L3: 2 | M3: 33 | N3: 40 | O3: 29.5 | P3: 115 | Q3: 40 | R3: 40D-PU-FOAM-29.50X115MMX40MM | S3: =ROUND(N3*O3*0.0254*P3/1000*Q3/1000,3) -> 0.138 | U3: =+S3*T3 -> 0 | W3: 2 | X3: 72X33 | Y3: 32 | Z3: 71.5 | AA3: 32.5 | AB3: 10 | AC3: 32D-PU-FOAM-71.50X32.50X10MM | AD3: =+ROUND((Y3*Z3*0.0254*AA3*0.0254*(AB3/1000)),3) -> 0.48 | AF3: =+AD3*AE3 -> 0 | AH3: 2 | AI3: 72X33 | AJ3: 100 | AK3: 71.5 | AL3: 32.5 | AM3: 20 | AN3: 100D-RB-FOAM-71.50X32.50X20MM | AO3: =+ROUND((AJ3*AK3*0.0254*AL3*0.0254*(AM3/1000)),3) -> 2.998 | AQ3: =+AO3*AP3 -> 0
A4: 3 | B4: 78 | C4: 40 | D4: 77.5 | E4: 115 | F4: 40 | G4: 40D-PU-FOAM-77.50X115MMX40MM | H4: =ROUND(C4*D4*0.0254*E4/1000*F4/1000,3) -> 0.362 | J4: =+H4*I4 -> 0 | L4: 3 | M4: 36 | N4: 40 | O4: 32.5 | P4: 115 | Q4: 40 | R4: 40D-PU-FOAM-32.50X115MMX40MM | S4: =ROUND(N4*O4*0.0254*P4/1000*Q4/1000,3) -> 0.152 | U4: =+S4*T4 -> 0 | W4: 3 | X4: 72X36 | Y4: 32 | Z4: 71.5 | AA4: 35.5 | AB4: 10 | AC4: 32D-PU-FOAM-71.50X35.50X10MM | AD4: =+ROUND((Y4*Z4*0.0254*AA4*0.0254*(AB4/1000)),3) -> 0.524 | AF4: =+AD4*AE4 -> 0 | AH4: 3 | AI4: 72X36 | AJ4: 100 | AK4: 71.5 | AL4: 35.5 | AM4: 20 | AN4: 100D-RB-FOAM-71.50X35.50X20MM | AO4: =+ROUND((AJ4*AK4*0.0254*AL4*0.0254*(AM4/1000)),3) -> 3.275 | AQ4: =+AO4*AP4 -> 0
A5: 4 | B5: 80 | C5: 40 | D5: 79.5 | E5: 115 | F5: 40 | G5: 40D-PU-FOAM-79.50X115MMX40MM | H5: =ROUND(C5*D5*0.0254*E5/1000*F5/1000,3) -> 0.372 | J5: =+H5*I5 -> 0 | L5: 4 | M5: 39 | N5: 40 | O5: 35.5 | P5: 115 | Q5: 40 | R5: 40D-PU-FOAM-35.50X115MMX40MM | S5: =ROUND(N5*O5*0.0254*P5/1000*Q5/1000,3) -> 0.166 | U5: =+S5*T5 -> 0 | W5: 4 | X5: 72X39 | Y5: 32 | Z5: 71.5 | AA5: 38.5 | AB5: 10 | AC5: 32D-PU-FOAM-71.50X38.50X10MM | AD5: =+ROUND((Y5*Z5*0.0254*AA5*0.0254*(AB5/1000)),3) -> 0.568 | AF5: =+AD5*AE5 -> 0 | AH5: 4 | AI5: 72X39 | AJ5: 100 | AK5: 71.5 | AL5: 38.5 | AM5: 20 | AN5: 100D-RB-FOAM-71.50X38.50X20MM | AO5: =+ROUND((AJ5*AK5*0.0254*AL5*0.0254*(AM5/1000)),3) -> 3.552 | AQ5: =+AO5*AP5 -> 0
A6: 5 | B6: 84 | C6: 40 | D6: 83.5 | E6: 115 | F6: 40 | G6: 40D-PU-FOAM-83.50X115MMX40MM | H6: =ROUND(C6*D6*0.0254*E6/1000*F6/1000,3) -> 0.39 | J6: =+H6*I6 -> 0 | L6: 5 | M6: 42 | N6: 40 | O6: 38.5 | P6: 115 | Q6: 40 | R6: 40D-PU-FOAM-38.50X115MMX40MM | S6: =ROUND(N6*O6*0.0254*P6/1000*Q6/1000,3) -> 0.18 | U6: =+S6*T6 -> 0 | W6: 5 | X6: 72X42 | Y6: 32 | Z6: 71.5 | AA6: 41.5 | AB6: 10 | AC6: 32D-PU-FOAM-71.50X41.50X10MM | AD6: =+ROUND((Y6*Z6*0.0254*AA6*0.0254*(AB6/1000)),3) -> 0.613 | AF6: =+AD6*AE6 -> 0 | AH6: 5 | AI6: 72X42 | AJ6: 100 | AK6: 71.5 | AL6: 41.5 | AM6: 20 | AN6: 100D-RB-FOAM-71.50X41.50X20MM | AO6: =+ROUND((AJ6*AK6*0.0254*AL6*0.0254*(AM6/1000)),3) -> 3.829 | AQ6: =+AO6*AP6 -> 0
A7: 6 | B7: 13 | C7: 40 | D7: 12.5 | E7: 115 | F7: 40 | G7: 40D-PU-FOAM-12.50X115MMX40MM | H7: =ROUND(C7*D7*0.0254*E7/1000*F7/1000,3) -> 0.058 | J7: =+H7*I7 -> 0 | L7: 6 | M7: 45 | N7: 40 | O7: 41.5 | P7: 115 | Q7: 40 | R7: 40D-PU-FOAM-41.50X115MMX40MM | S7: =ROUND(N7*O7*0.0254*P7/1000*Q7/1000,3) -> 0.194 | U7: =+S7*T7 -> 0 | W7: 6 | X7: 72X45 | Y7: 32 | Z7: 71.5 | AA7: 44.5 | AB7: 10 | AC7: 32D-PU-FOAM-71.50X44.50X10MM | AD7: =+ROUND((Y7*Z7*0.0254*AA7*0.0254*(AB7/1000)),3) -> 0.657 | AF7: =+AD7*AE7 -> 0 | AH7: 6 | AI7: 72X45 | AJ7: 100 | AK7: 71.5 | AL7: 44.5 | AM7: 20 | AN7: 100D-RB-FOAM-71.50X44.50X20MM | AO7: =+ROUND((AJ7*AK7*0.0254*AL7*0.0254*(AM7/1000)),3) -> 4.105 | AQ7: =+AO7*AP7 -> 0
A8: 7 | B8: 20 | C8: 40 | D8: 19.5 | E8: 115 | F8: 40 | G8: 40D-PU-FOAM-19.50X115MMX40MM | H8: =ROUND(C8*D8*0.0254*E8/1000*F8/1000,3) -> 0.091 | J8: =+H8*I8 -> 0 | L8: 7 | M8: 48 | N8: 40 | O8: 44.5 | P8: 115 | Q8: 40 | R8: 40D-PU-FOAM-44.50X115MMX40MM | S8: =ROUND(N8*O8*0.0254*P8/1000*Q8/1000,3) -> 0.208 | U8: =+S8*T8 -> 0 | W8: 7 | X8: 72X48 | Y8: 32 | Z8: 71.5 | AA8: 47.5 | AB8: 10 | AC8: 32D-PU-FOAM-71.50X47.50X10MM | AD8: =+ROUND((Y8*Z8*0.0254*AA8*0.0254*(AB8/1000)),3) -> 0.701 | AF8: =+AD8*AE8 -> 0 | AH8: 7 | AI8: 72X48 | AJ8: 100 | AK8: 71.5 | AL8: 47.5 | AM8: 20 | AN8: 100D-RB-FOAM-71.50X47.50X20MM | AO8: =+ROUND((AJ8*AK8*0.0254*AL8*0.0254*(AM8/1000)),3) -> 4.382 | AQ8: =+AO8*AP8 -> 0
A9: 8 | B9: 72 | C9: 40 | D9: 71.5 | E9: 135 | F9: 40 | G9: 40D-PU-FOAM-71.50X135MMX40MM | H9: =ROUND(C9*D9*0.0254*E9/1000*F9/1000,3) -> 0.392 | J9: =+H9*I9 -> 0 | L9: 8 | M9: 51 | N9: 40 | O9: 47.5 | P9: 115 | Q9: 40 | R9: 40D-PU-FOAM-47.50X115MMX40MM | S9: =ROUND(N9*O9*0.0254*P9/1000*Q9/1000,3) -> 0.222 | U9: =+S9*T9 -> 0 | W9: 8 | X9: 72X51 | Y9: 32 | Z9: 71.5 | AA9: 50.5 | AB9: 10 | AC9: 32D-PU-FOAM-71.50X50.50X10MM | AD9: =+ROUND((Y9*Z9*0.0254*AA9*0.0254*(AB9/1000)),3) -> 0.745 | AF9: =+AD9*AE9 -> 0 | AH9: 8 | AI9: 72X51 | AJ9: 100 | AK9: 71.5 | AL9: 50.5 | AM9: 20 | AN9: 100D-RB-FOAM-71.50X50.50X20MM | AO9: =+ROUND((AJ9*AK9*0.0254*AL9*0.0254*(AM9/1000)),3) -> 4.659 | AQ9: =+AO9*AP9 -> 0
A10: 9 | B10: 75 | C10: 40 | D10: 74.5 | E10: 135 | F10: 40 | G10: 40D-PU-FOAM-74.50X135MMX40MM | H10: =ROUND(C10*D10*0.0254*E10/1000*F10/1000,3) -> 0.409 | J10: =+H10*I10 -> 0 | L10: 9 | M10: 54 | N10: 40 | O10: 50.5 | P10: 115 | Q10: 40 | R10: 40D-PU-FOAM-50.50X115MMX40MM | S10: =ROUND(N10*O10*0.0254*P10/1000*Q10/1000,3) -> 0.236 | U10: =+S10*T10 -> 0 | W10: 9 | X10: 72X54 | Y10: 32 | Z10: 71.5 | AA10: 53.5 | AB10: 10 | AC10: 32D-PU-FOAM-71.50X53.50X10MM | AD10: =+ROUND((Y10*Z10*0.0254*AA10*0.0254*(AB10/1000)),3) -> 0.79 | AF10: =+AD10*AE10 -> 0 | AH10: 9 | AI10: 72X54 | AJ10: 100 | AK10: 71.5 | AL10: 53.5 | AM10: 20 | AN10: 100D-RB-FOAM-71.50X53.50X20MM | AO10: =+ROUND((AJ10*AK10*0.0254*AL10*0.0254*(AM10/1000)),3) -> 4.936 | AQ10: =+AO10*AP10 -> 0
A11: 10 | B11: 78 | C11: 40 | D11: 77.5 | E11: 135 | F11: 40 | G11: 40D-PU-FOAM-77.50X135MMX40MM | H11: =ROUND(C11*D11*0.0254*E11/1000*F11/1000,3) -> 0.425 | J11: =+H11*I11 -> 0 | L11: 10 | M11: 57 | N11: 40 | O11: 53.5 | P11: 115 | Q11: 40 | R11: 40D-PU-FOAM-53.50X115MMX40MM | S11: =ROUND(N11*O11*0.0254*P11/1000*Q11/1000,3) -> 0.25 | U11: =+S11*T11 -> 0 | W11: 10 | X11: 72X57 | Y11: 32 | Z11: 71.5 | AA11: 56.5 | AB11: 10 | AC11: 32D-PU-FOAM-71.50X56.50X10MM | AD11: =+ROUND((Y11*Z11*0.0254*AA11*0.0254*(AB11/1000)),3) -> 0.834 | AF11: =+AD11*AE11 -> 0 | AH11: 10 | AI11: 72X57 | AJ11: 100 | AK11: 71.5 | AL11: 56.5 | AM11: 20 | AN11: 100D-RB-FOAM-71.50X56.50X20MM | AO11: =+ROUND((AJ11*AK11*0.0254*AL11*0.0254*(AM11/1000)),3) -> 5.213 | AQ11: =+AO11*AP11 -> 0
A12: 11 | B12: 80 | C12: 40 | D12: 79.5 | E12: 135 | F12: 40 | G12: 40D-PU-FOAM-79.50X135MMX40MM | H12: =ROUND(C12*D12*0.0254*E12/1000*F12/1000,3) -> 0.436 | J12: =+H12*I12 -> 0 | L12: 11 | M12: 60 | N12: 40 | O12: 56.5 | P12: 115 | Q12: 40 | R12: 40D-PU-FOAM-56.50X115MMX40MM | S12: =ROUND(N12*O12*0.0254*P12/1000*Q12/1000,3) -> 0.264 | U12: =+S12*T12 -> 0 | W12: 11 | X12: 72X60 | Y12: 32 | Z12: 71.5 | AA12: 59.5 | AB12: 10 | AC12: 32D-PU-FOAM-71.50X59.50X10MM | AD12: =+ROUND((Y12*Z12*0.0254*AA12*0.0254*(AB12/1000)),3) -> 0.878 | AF12: =+AD12*AE12 -> 0 | AH12: 11 | AI12: 72X60 | AJ12: 100 | AK12: 71.5 | AL12: 59.5 | AM12: 20 | AN12: 100D-RB-FOAM-71.50X59.50X20MM | AO12: =+ROUND((AJ12*AK12*0.0254*AL12*0.0254*(AM12/1000)),3) -> 5.489 | AQ12: =+AO12*AP12 -> 0
A13: 12 | B13: 84 | C13: 40 | D13: 83.5 | E13: 135 | F13: 40 | G13: 40D-PU-FOAM-83.50X135MMX40MM | H13: =ROUND(C13*D13*0.0254*E13/1000*F13/1000,3) -> 0.458 | J13: =+H13*I13 -> 0 | L13: 12 | M13: 63 | N13: 40 | O13: 59.5 | P13: 115 | Q13: 40 | R13: 40D-PU-FOAM-59.50X115MMX40MM | S13: =ROUND(N13*O13*0.0254*P13/1000*Q13/1000,3) -> 0.278 | U13: =+S13*T13 -> 0 | W13: 12 | X13: 72X63 | Y13: 32 | Z13: 71.5 | AA13: 62.5 | AB13: 10 | AC13: 32D-PU-FOAM-71.50X62.50X10MM | AD13: =+ROUND((Y13*Z13*0.0254*AA13*0.0254*(AB13/1000)),3) -> 0.923 | AF13: =+AD13*AE13 -> 0 | AH13: 12 | AI13: 72X63 | AJ13: 100 | AK13: 71.5 | AL13: 62.5 | AM13: 20 | AN13: 100D-RB-FOAM-71.50X62.50X20MM | AO13: =+ROUND((AJ13*AK13*0.0254*AL13*0.0254*(AM13/1000)),3) -> 5.766 | AQ13: =+AO13*AP13 -> 0
... A78: 77 | B78: 20 | C78: 32 | D78: 19.5 | E78: 115 | F78: 75 | G78: 32D-PU-FOAM-19.50X115MMX75MM | H78: =ROUND(C78*D78*0.0254*E78/1000*F78/1000,3) -> 0.137 | J78: =+H78*I78 -> 0 | L78: 77 | M78: 54 | N78: 40 | O78: 50.5 | P78: 205 | Q78: 40 | R78: 40D-PU-FOAM-50.50X205MMX40MM | S78: =ROUND(N78*O78*0.0254*P78/1000*Q78/1000,3) -> 0.421 | U78: =+S78*T78 -> 0 | W78: 77 | X78: 20X18 | Y78: 32 | Z78: 19.5 | AA78: 17.5 | AB78: 10 | AC78: 32D-PU-FOAM-19.50X17.50X10MM | AD78: =+ROUND((Y78*Z78*0.0254*AA78*0.0254*(AB78/1000)),3) -> 0.07 | AF78: =+AD78*AE78 -> 0 | AH78: 77 | AI78: 20X18 | AJ78: 100 | AK78: 19.5 | AL78: 17.5 | AM78: 20 | AN78: 100D-RB-FOAM-19.50X17.50X20MM | AO78: =+ROUND((AJ78*AK78*0.0254*AL78*0.0254*(AM78/1000)),3) -> 0.44 | AQ78: =+AO78*AP78 -> 0
A79: 78 | B79: 72 | C79: 32 | D79: 71.5 | E79: 155 | F79: 75 | G79: 32D-PU-FOAM-71.50X155MMX75MM | H79: =ROUND(C79*D79*0.0254*E79/1000*F79/1000,3) -> 0.676 | J79: =+H79*I79 -> 0 | L79: 78 | M79: 57 | N79: 40 | O79: 53.5 | P79: 205 | Q79: 40 | R79: 40D-PU-FOAM-53.50X205MMX40MM | S79: =ROUND(N79*O79*0.0254*P79/1000*Q79/1000,3) -> 0.446 | U79: =+S79*T79 -> 0 | W79: 1 | X79: 72X30 | Y79: 18 | Z79: 71.5 | AA79: 29.5 | AB79: 10 | AC79: 18D-PU-FOAM-71.50X29.50X10MM | AD79: =+ROUND((Y79*Z79*0.0254*AA79*0.0254*(AB79/1000)),3) -> 0.245 | AF79: =+AD79*AE79 -> 0
A80: 79 | B80: 75 | C80: 32 | D80: 74.5 | E80: 155 | F80: 75 | G80: 32D-PU-FOAM-74.50X155MMX75MM | H80: =ROUND(C80*D80*0.0254*E80/1000*F80/1000,3) -> 0.704 | J80: =+H80*I80 -> 0 | L80: 79 | M80: 60 | N80: 40 | O80: 56.5 | P80: 205 | Q80: 40 | R80: 40D-PU-FOAM-56.50X205MMX40MM | S80: =ROUND(N80*O80*0.0254*P80/1000*Q80/1000,3) -> 0.471 | U80: =+S80*T80 -> 0 | W80: 2 | X80: 72X33 | Y80: 18 | Z80: 71.5 | AA80: 32.5 | AB80: 10 | AC80: 18D-PU-FOAM-71.50X32.50X10MM | AD80: =+ROUND((Y80*Z80*0.0254*AA80*0.0254*(AB80/1000)),3) -> 0.27 | AF80: =+AD80*AE80 -> 0
A81: 80 | B81: 78 | C81: 32 | D81: 77.5 | E81: 155 | F81: 75 | G81: 32D-PU-FOAM-77.50X155MMX75MM | H81: =ROUND(C81*D81*0.0254*E81/1000*F81/1000,3) -> 0.732 | J81: =+H81*I81 -> 0 | L81: 80 | M81: 63 | N81: 40 | O81: 59.5 | P81: 205 | Q81: 40 | R81: 40D-PU-FOAM-59.50X205MMX40MM | S81: =ROUND(N81*O81*0.0254*P81/1000*Q81/1000,3) -> 0.496 | U81: =+S81*T81 -> 0 | W81: 3 | X81: 72X36 | Y81: 18 | Z81: 71.5 | AA81: 35.5 | AB81: 10 | AC81: 18D-PU-FOAM-71.50X35.50X10MM | AD81: =+ROUND((Y81*Z81*0.0254*AA81*0.0254*(AB81/1000)),3) -> 0.295 | AF81: =+AD81*AE81 -> 0
A82: 81 | B82: 80 | C82: 32 | D82: 79.5 | E82: 155 | F82: 75 | G82: 32D-PU-FOAM-79.50X155MMX75MM | H82: =ROUND(C82*D82*0.0254*E82/1000*F82/1000,3) -> 0.751 | J82: =+H82*I82 -> 0 | L82: 81 | M82: 66 | N82: 40 | O82: 62.5 | P82: 205 | Q82: 40 | R82: 40D-PU-FOAM-62.50X205MMX40MM | S82: =ROUND(N82*O82*0.0254*P82/1000*Q82/1000,3) -> 0.521 | U82: =+S82*T82 -> 0 | W82: 4 | X82: 72X39 | Y82: 18 | Z82: 71.5 | AA82: 38.5 | AB82: 10 | AC82: 18D-PU-FOAM-71.50X38.50X10MM | AD82: =+ROUND((Y82*Z82*0.0254*AA82*0.0254*(AB82/1000)),3) -> 0.32 | AF82: =+AD82*AE82 -> 0
A83: 82 | B83: 84 | C83: 32 | D83: 83.5 | E83: 155 | F83: 75 | G83: 32D-PU-FOAM-83.50X155MMX75MM | H83: =ROUND(C83*D83*0.0254*E83/1000*F83/1000,3) -> 0.789 | J83: =+H83*I83 -> 0 | L83: 82 | M83: 69 | N83: 40 | O83: 65.5 | P83: 205 | Q83: 40 | R83: 40D-PU-FOAM-65.50X205MMX40MM | S83: =ROUND(N83*O83*0.0254*P83/1000*Q83/1000,3) -> 0.546 | U83: =+S83*T83 -> 0 | W83: 5 | X83: 72X42 | Y83: 18 | Z83: 71.5 | AA83: 41.5 | AB83: 10 | AC83: 18D-PU-FOAM-71.50X41.50X10MM | AD83: =+ROUND((Y83*Z83*0.0254*AA83*0.0254*(AB83/1000)),3) -> 0.345 | AF83: =+AD83*AE83 -> 0
A84: 83 | B84: 13 | C84: 32 | D84: 12.5 | E84: 155 | F84: 75 | G84: 32D-PU-FOAM-12.50X155MMX75MM | H84: =ROUND(C84*D84*0.0254*E84/1000*F84/1000,3) -> 0.118 | J84: =+H84*I84 -> 0 | L84: 83 | M84: 72 | N84: 40 | O84: 68.5 | P84: 205 | Q84: 40 | R84: 40D-PU-FOAM-68.50X205MMX40MM | S84: =ROUND(N84*O84*0.0254*P84/1000*Q84/1000,3) -> 0.571 | U84: =+S84*T84 -> 0 | W84: 6 | X84: 72X45 | Y84: 18 | Z84: 71.5 | AA84: 44.5 | AB84: 10 | AC84: 18D-PU-FOAM-71.50X44.50X10MM | AD84: =+ROUND((Y84*Z84*0.0254*AA84*0.0254*(AB84/1000)),3) -> 0.369 | AF84: =+AD84*AE84 -> 0 | AN84: =+AO79*2 -> 0
A85: 84 | B85: 20 | C85: 32 | D85: 19.5 | E85: 155 | F85: 75 | G85: 32D-PU-FOAM-19.50X155MMX75MM | H85: =ROUND(C85*D85*0.0254*E85/1000*F85/1000,3) -> 0.184 | J85: =+H85*I85 -> 0 | L85: 84 | M85: 13 | N85: 40 | O85: 9.5 | P85: 205 | Q85: 40 | R85: 40D-PU-FOAM-9.50X205MMX40MM | S85: =ROUND(N85*O85*0.0254*P85/1000*Q85/1000,3) -> 0.079 | U85: =+S85*T85 -> 0 | W85: 7 | X85: 72X48 | Y85: 18 | Z85: 71.5 | AA85: 47.5 | AB85: 10 | AC85: 18D-PU-FOAM-71.50X47.50X10MM | AD85: =+ROUND((Y85*Z85*0.0254*AA85*0.0254*(AB85/1000)),3) -> 0.394 | AF85: =+AD85*AE85 -> 0
A86: 85 | B86: 72 | C86: 32 | D86: 71.5 | E86: 135 | F86: 75 | G86: 32D-PU-FOAM-71.50X135MMX75MM | H86: =ROUND(C86*D86*0.0254*E86/1000*F86/1000,3) -> 0.588 | J86: =+H86*I86 -> 0 | L86: 85 | M86: 18 | N86: 40 | O86: 14.5 | P86: 205 | Q86: 40 | R86: 40D-PU-FOAM-14.50X205MMX40MM | S86: =ROUND(N86*O86*0.0254*P86/1000*Q86/1000,3) -> 0.121 | U86: =+S86*T86 -> 0 | W86: 8 | X86: 72X51 | Y86: 18 | Z86: 71.5 | AA86: 50.5 | AB86: 10 | AC86: 18D-PU-FOAM-71.50X50.50X10MM | AD86: =+ROUND((Y86*Z86*0.0254*AA86*0.0254*(AB86/1000)),3) -> 0.419 | AF86: =+AD86*AE86 -> 0
A87: 86 | B87: 75 | C87: 32 | D87: 74.5 | E87: 135 | F87: 75 | G87: 32D-PU-FOAM-74.50X135MMX75MM | H87: =ROUND(C87*D87*0.0254*E87/1000*F87/1000,3) -> 0.613 | J87: =+H87*I87 -> 0 | L87: 1 | M87: 30 | N87: 40 | O87: 24 | P87: 115 | Q87: 75 | R87: 40D-PU-FOAM-24X115MMX75MM | S87: =ROUND(N87*O87*0.0254*P87/1000*Q87/1000,3) -> 0.21 | U87: =+S87*T87 -> 0 | W87: 9 | X87: 72X54 | Y87: 18 | Z87: 71.5 | AA87: 53.5 | AB87: 10 | AC87: 18D-PU-FOAM-71.50X53.50X10MM | AD87: =+ROUND((Y87*Z87*0.0254*AA87*0.0254*(AB87/1000)),3) -> 0.444 | AF87: =+AD87*AE87 -> 0
A88: 87 | B88: 78 | C88: 32 | D88: 77.5 | E88: 135 | F88: 75 | G88: 32D-PU-FOAM-77.50X135MMX75MM | H88: =ROUND(C88*D88*0.0254*E88/1000*F88/1000,3) -> 0.638 | J88: =+H88*I88 -> 0 | L88: 2 | M88: 33 | N88: 40 | O88: 27 | P88: 115 | Q88: 75 | R88: 40D-PU-FOAM-27X115MMX75MM | S88: =ROUND(N88*O88*0.0254*P88/1000*Q88/1000,3) -> 0.237 | U88: =+S88*T88 -> 0 | W88: 10 | X88: 72X57 | Y88: 18 | Z88: 71.5 | AA88: 56.5 | AB88: 10 | AC88: 18D-PU-FOAM-71.50X56.50X10MM | AD88: =+ROUND((Y88*Z88*0.0254*AA88*0.0254*(AB88/1000)),3) -> 0.469 | AF88: =+AD88*AE88 -> 0
A89: 88 | B89: 80 | C89: 32 | D89: 79.5 | E89: 135 | F89: 75 | G89: 32D-PU-FOAM-79.50X135MMX75MM | H89: =ROUND(C89*D89*0.0254*E89/1000*F89/1000,3) -> 0.654 | J89: =+H89*I89 -> 0 | L89: 3 | M89: 36 | N89: 40 | O89: 30 | P89: 115 | Q89: 75 | R89: 40D-PU-FOAM-30X115MMX75MM | S89: =ROUND(N89*O89*0.0254*P89/1000*Q89/1000,3) -> 0.263 | U89: =+S89*T89 -> 0 | W89: 11 | X89: 72X60 | Y89: 18 | Z89: 71.5 | AA89: 59.5 | AB89: 10 | AC89: 18D-PU-FOAM-71.50X59.50X10MM | AD89: =+ROUND((Y89*Z89*0.0254*AA89*0.0254*(AB89/1000)),3) -> 0.494 | AF89: =+AD89*AE89 -> 0
A90: 89 | B90: 84 | C90: 32 | D90: 83.5 | E90: 135 | F90: 75 | G90: 32D-PU-FOAM-83.50X135MMX75MM | H90: =ROUND(C90*D90*0.0254*E90/1000*F90/1000,3) -> 0.687 | J90: =+H90*I90 -> 0 | L90: 4 | M90: 39 | N90: 40 | O90: 33 | P90: 115 | Q90: 75 | R90: 40D-PU-FOAM-33X115MMX75MM | S90: =ROUND(N90*O90*0.0254*P90/1000*Q90/1000,3) -> 0.289 | U90: =+S90*T90 -> 0 | W90: 12 | X90: 72X63 | Y90: 18 | Z90: 71.5 | AA90: 62.5 | AB90: 10 | AC90: 18D-PU-FOAM-71.50X62.50X10MM | AD90: =+ROUND((Y90*Z90*0.0254*AA90*0.0254*(AB90/1000)),3) -> 0.519 | AF90: =+AD90*AE90 -> 0
A91: 90 | B91: 13 | C91: 32 | D91: 12.5 | E91: 135 | F91: 75 | G91: 32D-PU-FOAM-12.50X135MMX75MM | H91: =ROUND(C91*D91*0.0254*E91/1000*F91/1000,3) -> 0.103 | J91: =+H91*I91 -> 0 | L91: 5 | M91: 42 | N91: 40 | O91: 36 | P91: 115 | Q91: 75 | R91: 40D-PU-FOAM-36X115MMX75MM | S91: =ROUND(N91*O91*0.0254*P91/1000*Q91/1000,3) -> 0.315 | U91: =+S91*T91 -> 0 | W91: 13 | X91: 72X66 | Y91: 18 | Z91: 71.5 | AA91: 65.5 | AB91: 10 | AC91: 18D-PU-FOAM-71.50X65.50X10MM | AD91: =+ROUND((Y91*Z91*0.0254*AA91*0.0254*(AB91/1000)),3) -> 0.544 | AF91: =+AD91*AE91 -> 0
A92: 91 | B92: 20 | C92: 32 | D92: 19.5 | E92: 135 | F92: 75 | G92: 32D-PU-FOAM-19.50X135MMX75MM | H92: =ROUND(C92*D92*0.0254*E92/1000*F92/1000,3) -> 0.16 | J92: =+H92*I92 -> 0 | L92: 6 | M92: 45 | N92: 40 | O92: 39 | P92: 115 | Q92: 75 | R92: 40D-PU-FOAM-39X115MMX75MM | S92: =ROUND(N92*O92*0.0254*P92/1000*Q92/1000,3) -> 0.342 | U92: =+S92*T92 -> 0 | W92: 14 | X92: 72X69 | Y92: 18 | Z92: 71.5 | AA92: 68.5 | AB92: 10 | AC92: 18D-PU-FOAM-71.50X68.50X10MM | AD92: =+ROUND((Y92*Z92*0.0254*AA92*0.0254*(AB92/1000)),3) -> 0.569 | AF92: =+AD92*AE92 -> 0
A93: 92 | B93: 72 | C93: 32 | D93: 71.5 | E93: 205 | F93: 75 | G93: 32D-PU-FOAM-71.50X205MMX75MM | H93: =ROUND(C93*D93*0.0254*E93/1000*F93/1000,3) -> 0.894 | J93: =+H93*I93 -> 0 | L93: 7 | M93: 48 | N93: 40 | O93: 42 | P93: 115 | Q93: 75 | R93: 40D-PU-FOAM-42X115MMX75MM | S93: =ROUND(N93*O93*0.0254*P93/1000*Q93/1000,3) -> 0.368 | U93: =+S93*T93 -> 0 | W93: 15 | X93: 72X72 | Y93: 18 | Z93: 71.5 | AA93: 71.5 | AB93: 10 | AC93: 18D-PU-FOAM-71.50X71.50X10MM | AD93: =+ROUND((Y93*Z93*0.0254*AA93*0.0254*(AB93/1000)),3) -> 0.594 | AF93: =+AD93*AE93 -> 0
A94: 93 | B94: 75 | C94: 32 | D94: 74.5 | E94: 205 | F94: 75 | G94: 32D-PU-FOAM-74.50X205MMX75MM | H94: =ROUND(C94*D94*0.0254*E94/1000*F94/1000,3) -> 0.931 | J94: =+H94*I94 -> 0 | L94: 8 | M94: 51 | N94: 40 | O94: 45 | P94: 115 | Q94: 75 | R94: 40D-PU-FOAM-45X115MMX75MM | S94: =ROUND(N94*O94*0.0254*P94/1000*Q94/1000,3) -> 0.394 | U94: =+S94*T94 -> 0 | W94: 16 | X94: 75X30 | Y94: 18 | Z94: 74.5 | AA94: 29.5 | AB94: 10 | AC94: 18D-PU-FOAM-74.50X29.50X10MM | AD94: =+ROUND((Y94*Z94*0.0254*AA94*0.0254*(AB94/1000)),3) -> 0.255 | AF94: =+AD94*AE94 -> 0
A95: 94 | B95: 78 | C95: 32 | D95: 77.5 | E95: 205 | F95: 75 | G95: 32D-PU-FOAM-77.50X205MMX75MM | H95: =ROUND(C95*D95*0.0254*E95/1000*F95/1000,3) -> 0.969 | J95: =+H95*I95 -> 0 | L95: 9 | M95: 54 | N95: 40 | O95: 48 | P95: 115 | Q95: 75 | R95: 40D-PU-FOAM-48X115MMX75MM | S95: =ROUND(N95*O95*0.0254*P95/1000*Q95/1000,3) -> 0.421 | U95: =+S95*T95 -> 0 | W95: 17 | X95: 75X33 | Y95: 18 | Z95: 74.5 | AA95: 32.5 | AB95: 10 | AC95: 18D-PU-FOAM-74.50X32.50X10MM | AD95: =+ROUND((Y95*Z95*0.0254*AA95*0.0254*(AB95/1000)),3) -> 0.281 | AF95: =+AD95*AE95 -> 0
A96: 95 | B96: 80 | C96: 32 | D96: 79.5 | E96: 205 | F96: 75 | G96: 32D-PU-FOAM-79.50X205MMX75MM | H96: =ROUND(C96*D96*0.0254*E96/1000*F96/1000,3) -> 0.993 | J96: =+H96*I96 -> 0 | L96: 10 | M96: 57 | N96: 40 | O96: 51 | P96: 115 | Q96: 75 | R96: 40D-PU-FOAM-51X115MMX75MM | S96: =ROUND(N96*O96*0.0254*P96/1000*Q96/1000,3) -> 0.447 | U96: =+S96*T96 -> 0 | W96: 18 | X96: 75X36 | Y96: 18 | Z96: 74.5 | AA96: 35.5 | AB96: 10 | AC96: 18D-PU-FOAM-74.50X35.50X10MM | AD96: =+ROUND((Y96*Z96*0.0254*AA96*0.0254*(AB96/1000)),3) -> 0.307 | AF96: =+AD96*AE96 -> 0
... A106: 105 | B106: 20 | C106: 40 | D106: 19.5 | E106: 95 | F106: 75 | G106: 40D-PU-FOAM-19.50X95MMX75MM | H106: =ROUND(C106*D106*0.0254*E106/1000*F106/1000,3) -> 0.141 | J106: =+H106*I106 -> 0 | L106: 20 | M106: 36 | N106: 40 | O106: 30 | P106: 135 | Q106: 75 | R106: 40D-PU-FOAM-30X135MMX75MM | S106: =ROUND(N106*O106*0.0254*P106/1000*Q106/1000,3) -> 0.309 | U106: =+S106*T106 -> 0 | W106: 28 | X106: 75X66 | Y106: 18 | Z106: 74.5 | AA106: 65.5 | AB106: 10 | AC106: 18D-PU-FOAM-74.50X65.50X10MM | AD106: =+ROUND((Y106*Z106*0.0254*AA106*0.0254*(AB106/1000)),3) -> 0.567 | AF106: =+AD106*AE106 -> 0
L107: 21 | M107: 39 | N107: 40 | O107: 33 | P107: 135 | Q107: 75 | R107: 40D-PU-FOAM-33X135MMX75MM | S107: =ROUND(N107*O107*0.0254*P107/1000*Q107/1000,3) -> 0.339 | U107: =+S107*T107 -> 0 | W107: 29 | X107: 75X69 | Y107: 18 | Z107: 74.5 | AA107: 68.5 | AB107: 10 | AC107: 18D-PU-FOAM-74.50X68.50X10MM | AD107: =+ROUND((Y107*Z107*0.0254*AA107*0.0254*(AB107/1000)),3) -> 0.593 | AF107: =+AD107*AE107 -> 0
L108: 22 | M108: 42 | N108: 40 | O108: 36 | P108: 135 | Q108: 75 | R108: 40D-PU-FOAM-36X135MMX75MM | S108: =ROUND(N108*O108*0.0254*P108/1000*Q108/1000,3) -> 0.37 | U108: =+S108*T108 -> 0 | W108: 30 | X108: 75X72 | Y108: 18 | Z108: 74.5 | AA108: 71.5 | AB108: 10 | AC108: 18D-PU-FOAM-74.50X71.50X10MM | AD108: =+ROUND((Y108*Z108*0.0254*AA108*0.0254*(AB108/1000)),3) -> 0.619 | AF108: =+AD108*AE108 -> 0
L109: 23 | M109: 45 | N109: 40 | O109: 39 | P109: 135 | Q109: 75 | R109: 40D-PU-FOAM-39X135MMX75MM | S109: =ROUND(N109*O109*0.0254*P109/1000*Q109/1000,3) -> 0.401 | U109: =+S109*T109 -> 0 | W109: 31 | X109: 78X30 | Y109: 18 | Z109: 77.5 | AA109: 29.5 | AB109: 10 | AC109: 18D-PU-FOAM-77.50X29.50X10MM | AD109: =+ROUND((Y109*Z109*0.0254*AA109*0.0254*(AB109/1000)),3) -> 0.265 | AF109: =+AD109*AE109 -> 0
L110: 24 | M110: 48 | N110: 40 | O110: 42 | P110: 135 | Q110: 75 | R110: 40D-PU-FOAM-42X135MMX75MM | S110: =ROUND(N110*O110*0.0254*P110/1000*Q110/1000,3) -> 0.432 | U110: =+S110*T110 -> 0 | W110: 32 | X110: 78X33 | Y110: 18 | Z110: 77.5 | AA110: 32.5 | AB110: 10 | AC110: 18D-PU-FOAM-77.50X32.50X10MM | AD110: =+ROUND((Y110*Z110*0.0254*AA110*0.0254*(AB110/1000)),3) -> 0.292 | AF110: =+AD110*AE110 -> 0
L111: 25 | M111: 51 | N111: 40 | O111: 45 | P111: 135 | Q111: 75 | R111: 40D-PU-FOAM-45X135MMX75MM | S111: =ROUND(N111*O111*0.0254*P111/1000*Q111/1000,3) -> 0.463 | U111: =+S111*T111 -> 0 | W111: 33 | X111: 78X36 | Y111: 18 | Z111: 77.5 | AA111: 35.5 | AB111: 10 | AC111: 18D-PU-FOAM-77.50X35.50X10MM | AD111: =+ROUND((Y111*Z111*0.0254*AA111*0.0254*(AB111/1000)),3) -> 0.319 | AF111: =+AD111*AE111 -> 0
L112: 26 | M112: 54 | N112: 40 | O112: 48 | P112: 135 | Q112: 75 | R112: 40D-PU-FOAM-48X135MMX75MM | S112: =ROUND(N112*O112*0.0254*P112/1000*Q112/1000,3) -> 0.494 | U112: =+S112*T112 -> 0 | W112: 34 | X112: 78X39 | Y112: 18 | Z112: 77.5 | AA112: 38.5 | AB112: 10 | AC112: 18D-PU-FOAM-77.50X38.50X10MM | AD112: =+ROUND((Y112*Z112*0.0254*AA112*0.0254*(AB112/1000)),3) -> 0.346 | AF112: =+AD112*AE112 -> 0
L113: 27 | M113: 57 | N113: 40 | O113: 51 | P113: 135 | Q113: 75 | R113: 40D-PU-FOAM-51X135MMX75MM | S113: =ROUND(N113*O113*0.0254*P113/1000*Q113/1000,3) -> 0.525 | U113: =+S113*T113 -> 0 | W113: 35 | X113: 78X42 | Y113: 18 | Z113: 77.5 | AA113: 41.5 | AB113: 10 | AC113: 18D-PU-FOAM-77.50X41.50X10MM | AD113: =+ROUND((Y113*Z113*0.0254*AA113*0.0254*(AB113/1000)),3) -> 0.373 | AF113: =+AD113*AE113 -> 0
...

Sheet Sheet3
A1: SIDE WALL FOAM CUTTING SIZE
A2: S.NO | B2: FINISHING SIZE | C2: DENSITY | D2: LENGTH CUTTING SIZE / INCHS | E2: WIDTH /MM | F2: HEIGHT /MM
A3: 1 | B3: 72 | C3: 32D HARD | D3: 71.5 | E3: 70 | F3: 95,115,135,155,175, 225
A4: 2 | B4: 75 | C4: 32D HARD | D4: 74.5 | E4: 70
A5: 3 | B5: 78 | C5: 32D HARD | D5: 77.5 | E5: 70
A6: 4 | B6: 80 | C6: 32D HARD | D6: 79.5 | E6: 70
A7: 5 | B7: 84 | C7: 32D HARD | D7: 83.5 | E7: 70
A8: 1 | B8: 36 | C8: 32D HARD | D8: 30 | E8: 70
A9: 2 | B9: 42 | C9: 32D HARD | D9: 36 | E9: 70
A10: 3 | B10: 48 | C10: 32D HARD | D10: 42 | E10: 70
A11: 4 | B11: 60 | C11: 32D HARD | D11: 54 | E11: 70
A12: 5 | B12: 66 | C12: 32D HARD | D12: 60 | E12: 70
A13: 6 | B13: 72 | C13: 32D HARD | D13: 66 | E13: 70

Sheet VARIETY
A1: SNO | B1: VARIETY | C1: MATTRESS VARIETY | D1: INCH | E1: HEIGHT | F1: FOAM SIZE | G1: MATRESS SIZE | H1: QTY
A2: 1 | B2: BONNELL | C2: SPG | D2: 06" | E2: 110 | F2: 75MM | G2: SKSGSR80X60X06 | H2: 1
A3: 2 | B3: BONNELL | C3: SPG | D3: 08" | E3: 130 | F3: 75MM | G3: SKSGSR80X60X08 | H3: 1
A4: 3 | B4: BONNELL | C4: SPG | D4: 10" | E4: 170 | F4: 75MM | G4: SKSGSR80X60X10 | H4: 1
A5: 4 | B5: BONNELL | C5: CASPIA | D5: 06" | E5: 130 | F5: 75MM | G5: HYPCASBNNLMR80X60X06 | H5: 1
A6: 5 | B6: BONNELL | C6: CASPIA | D6: 08" | E6: 150 | F6: 75MM | G6: HYPCASBNNLMR80X60X08 | H6: 1
A7: 6 | B7: BONNELL | C7: CASPIA | D7: 10" | E7: 170 | F7: 75MM | G7: HYPCASBNNLMR80X60X10 | H7: 1
A8: 7 | B8: BONNELL | C8: GENEVA NORMAL | D8: 08" | E8: 130 | F8: 75MM | G8: RTBNGVBG80X60X08 | H8: 1
A9: 8 | B9: BONNELL | C9: GENEVA EURO TOP | D9: 08" | E9: 130 | F9: 75MM | G9: RTBNGVBG80X60X08 | H9: 1
A10: 9 | B10: BONNELL | C10: GENEVA PILLOW TOP | D10: 08" | E10: 130 | F10: 75MM | G10: RTBNGVBG80X60X08 | H10: 1
A11: 10 | B11: BONNELL | C11: OPULENCE NORMAL | D11: 10" | E11: 150 | F11: 75MM | G11: RTBNOPBG80X60X10 | H11: 1
A12: 11 | B12: BONNELL | C12: OPULENCE EURO TOP | D12: 10" | E12: 150 | F12: 75MM | G12: RTBNOPETBG80X60X10 | H12: 1
A13: 12 | B13: BONNELL | C13: OPULENCE PILLOW TOP | D13: 10" | E13: 150 | F13: 75MM | G13: RTBNOPPTBG80X60X10 | H13: 1
... A61: 60 | B61: BONNELL | C61: ONESIDE PILLOW TOP | D61: 10" | E61: 150 | F61: 75MM | G61: RTHTMTBNOPT80X60X10 | H61: 1
B63: POC | C63: ALLURA | D63: 06" | E63: 130 | F63: 75MM | G63: HYPALRPKNLBLOR80X60X06 | H63: 1
B64: POC | C64: ALLURA | D64: 08" | E64: 150 | F64: 75MM | G64: HYPALRPKNLBLOR80X60X08 | H64: 1
B65: POC | C65: ALLURA | D65: 10" | E65: 170 | F65: 75MM | G65: HYPALRPKNLBLOR80X60X10 | H65: 1
B66: POC | C66: SPK POCKETED LATEX | D66: 06" | E66: 130 | F66: 75MM | G66: SKPKLTGN80X60X06 | H66: 1
B67: POC | C67: SPK POCKETED LATEX | D67: 08" | E67: 150 | F67: 75MM | G67: SKPKLTGN80X60X08 | H67: 1
B68: POC | C68: SPK POCKETED LATEX | D68: 10" | E68: 170 | F68: 75MM | G68: SKPKLTGN80X60X10 | H68: 1
B69: POC | C69: SPK POCKETED MEMORY | D69: 06" | E69: 130 | F69: 75MM | G69: SKPKMFBL80X60X06 | H69: 1
B70: POC | C70: SPK POCKETED MEMORY | D70: 08" | E70: 150 | F70: 75MM | G70: SKPKMFBL80X60X08 | H70: 1
B71: POC | C71: SPK POCKETED MEMORY | D71: 10" | E71: 170 | F71: 75MM | G71: SKPKMFBL80X60X10 | H71: 1
B72: POC | C72: ORGANIGA | D72: 06" | E72: 110 | F72: 75MM | G72: PEPSPKORGBW80X60X06 | H72: 1
B73: POC | C73: ORGANIGA | D73: 08" | E73: 130 | F73: 75MM | G73: PEPSPKORGBW80X60X08 | H73: 1
B74: POC | C74: ORGANIGA | D74: 10" | E74: 150 | F74: 75MM | G74: PEPSPKORGBW80X60X10 | H74: 1
... B80: POC | C80: POC FR REGULAR | D80: 12" | E80: 200 | F80: 75MM | G80: RTHTMTPKMFRG80X60X12 | H80: 1

Sheet INPUT
A1: SL.NO | B1: ITEM CODE | C1: QTY
A2: 1 | B2: PEPSBNCOMNLBG75X60X06 | C2: 50
A3: 2 | B3: PEPSBNCOMNLBG78X60X06 | C3: 50
A4: 3
A5: 4
A6: 5
A7: 6
A8: 7
A9: 8
A10: 9
A11: 10
A12: 11
A13: 12
A14: 13
A15: 14
... A51: 50

Sheet STEP-1
