Workbook

Sheet STORE  CODE
A1: STORE MR
A2: FROM WAREHOUSE:CBERM
A3: TO WAREHOUSE: CBEWIP
A4: S.NO | B4: CODE | C4: ITEM CODE | D4: ITEM DESCRIPTION | E4: UOM | F4: TATA | G4: ARADHYA | H4: PYARELAL | I4: MIN STOCK
A5: =ROW()-4 -> 1 | B5: 1.4 | C5: RML-STW-1.4MM | D5: Steel Wire 1.4 mmdia. | E5: KGS | F5: 145 | G5: - | I5: 1200
A6: =ROW()-4 -> 2 | B6: 1.8 | C6: RML-STW-1.8MM | D6: Steel Wire 1.8 mmdia. | E6: KGS | F6: 200 | G6: 200 | I6: 1500
A7: =ROW()-4 -> 3 | B7: 1.7 | C7: RML-STW-1.7MM | D7: Steel Wire 1.7 mmdia. | E7: KGS | F7: 200 | G7: 200 | I7: 0
A8: =ROW()-4 -> 4 | B8: 1.9 | C8: RML-STW-1.9MM | D8: Steel Wire 1.9 mmdia. | E8: KGS | F8: 200 | G8: 200 | I8: 2000
A9: =ROW()-4 -> 5 | B9: 2.3 | C9: RML-STW-2.3MM | D9: 2.3 MM Spring Steel Wire-Grade II | E9: KGS | F9: 280 | G9: 220 | I9: 6000
A10: =ROW()-4 -> 6 | B10: 2.1 | C10: RML-STW-2.1MM | D10: 2.1 MM Spring Steel Wire-Grade II | E10: KGS | F10: 200 | G10: 200 | I10: 0
A11: =ROW()-4 -> 7 | B11: 2.2 | C11: RML-STW-2.2MM | D11: Steel Wire -2.2MM Dia | E11: KGS | F11: 200 | G11: 200 | I11: 1000
A12: =ROW()-4 -> 8 | B12: 3.6 | C12: RML-STW-3.6MM | D12: Steel Wire 3.6 MM Dia | E12: KGS | F12: 380 | G12: 190 | I12: 1000
A13: =ROW()-4 -> 9 | B13: 3.8 | C13: RML-STW-3.8MM | D13: 3.8 MM Spring Steel Wire-Grade II | E13: KGS | F13: 380 | G13: 190 | I13: 1200
B14: 4 | C14: RML-STW-4.0MM | E14: KGS
A15: =ROW()-4 -> 11 | B15: 85 | C15: RML-CL85 | D15: Clips CL-85 (8500 Pcs/Box) | E15: BOX | F15: 8500 | I15: 85000
A16: =ROW()-4 -> 12 | B16: 12B | C16: RML-CL12B | D16: Clips CL-12B (13025 Pcs/Box) | E16: BOX | F16: 13025 | I16: 78150
A17: =ROW()-4 -> 13 | B17: 24 | C17: RML-HR24 | D17: C-RINGS HR24 (10000 PCS/CTN) | E17: BOX | F17: 10000 | I17: 60000
A18: =ROW()-4 -> 14 | B18: GUM | C18: RML-POLY-GUM | D18: YELLOW-7 | E18: LTR | F18: 25KG/CANE | I18: 120 | L18: =12*12 -> 144
A19: =ROW()-4 -> 15 | B19: GLUE | C19: RMI-HGLUE | D19: HOTMELT GLUE 25kg bag (LUNTACK 3310) | E19: KGS | F19: 30KGS/BAG | I19: 180
A20: =ROW()-4 -> 16 | B20: 38 | C20: RM-NWN-POS-38CMX70GSM | D20: NON WOVEN FABRIC 37 cm 70GSM | E20: KGS | F20: 26KG/ROLL | I20: 350
A21: =ROW()-4 -> 17 | B21: 43 | C21: RM-NWN-POS-43CMX70GSM | D21: NON WOVEN FABRIC 45 cm 70GSM | E21: KGS | F21: 26KG/ROLL | I21: 350
A22: =ROW()-4 -> 18 | B22: 43G | C22: RM-NWN-POS-43CMX70GSM-GRN | D22: NON WOVEN FABRIC 45 cm 70GSM GREEN | E22: KGS
A23: =ROW()-4 -> 19 | B23: 48 | C23: RM-NWN-POS-48CMX70GSM | D23: NON WOVEN FABRIC 50 cm 70GSM | E23: KGS | F23: 26KG/ROLL | I23: 350
A24: =ROW()-4 -> 20 | B24: 58 | C24: RM-NWN-POS-58CMX70GSM | D24: NON WOVEN FABRIC 58 cm 70GSM | E24: KGS | F24: 28KG/ROLL | I24: 350
A25: =ROW()-4 -> 21 | B25: 8 | C25: RML-NWN-80GSMX8" | D25: NON WOVEN FABRIC 8" 80GSM | E25: KGS | F25: 50KG/ROLL | I25: 350
A26: =ROW()-4 -> 22 | B26: 79 | C26: RML-NWN-70GSMX79" | D26: NON WOVEN FABRIC WHITE 70 GSM 79 INCH | E26: KGS | F26: 40KG/ROLL | I26: 200
A27: =ROW()-4 -> 23 | B27: 48G | C27: RM-NWN-POS-48CMX70GSM-GRN | D27: NON WOVEN FABRIC 50 cm 70GSM GREEN | E27: KGS | F27: 25KGS/ROLL
A28: =ROW()-4 -> 24 | B28: 38G | C28: RM-NWN-POS-38CMX70GSM-GRN | D28: NON WOVEN FABRIC 37 cm 70GSM GREEN | E28: KGS | F28: 25KGS/ROLL
A29: 12 | B29: 62 | C29: RM-NWN-POS-62CMX70GSM | D29: NON WOVEN FABRIC 70 GSM x 62 CM - WHITE | E29: KGS | F29: CBERM
A30: =ROW()-4 -> 26 | B30: S | C30: RML-STRAP-ROLL | D30: STRAP ROLL | E30: NOS | F30: 2 ROLLS | I30: 4
A31: =ROW()-4 -> 27 | B31: G | C31: RML-TAG-GRN | D31: GREEN COLOUR TAG | E31: NOS | F31: 250/BUNDLE | I31: 1000
A32: =ROW()-4 -> 28 | B32: Y | C32: RML-TAG-YELLOW | D32: YELLOW COLOUR TAG | E32: NOS | F32: 250/BUNDLE | I32: 500
A33: =ROW()-4 -> 29 | B33: P | C33: RML-TAG-PINK | D33: PINK COLOUR TAG | E33: NOS | F33: 250/BUNDLE | I33: 500 | K33: =12*12 -> 144
A34: =ROW()-4 -> 30 | B34: W | C34: RML-TAG-WHIT | D34: WHITE COLOUR TAG | E34: NOS | F34: 250/BUNDLE | I34: 250
A35: =ROW()-4 -> 31 | B35: T | C35: RML-PAK-THRD | D35: BAG STITCHING THREAD | E35: NOS | F35: 6 CONES / PKT | I35: 6
A36: =ROW()-4 -> 32 | B36: H | C36: RML-HAND-GLOVES | D36: HAND GLOVES | E36: PAIRS | F36: 12 PAIR/PKT | I36: 144
A37: =ROW()-4 -> 33 | C37: RML-HAND-GLOVES-LIQ-RESI | D37: HAND GLOVES ( LIQUID RESISTANT ) | E37: PAIRS | F37: 1 PAIRS | I37: 0
A38: =ROW()-4 -> 34 | B38: SG | C38: RML-SURGI-GLOVES | E38: BOX | F38: 100PAIRS | I38: 0
A39: =ROW()-4 -> 35 | B39: EP | C39: RML-EPE-1880X1750X40MM | D39: DOUBLE DEKER EPSHEET | E39: NOS | F39: 1NOS | I39: 1
A40: =ROW()-4 -> 36 | B40: OIL | C40: RML-LUB-OIL | D40: lubricant Oil | E40: LTR | F40: 209LITRES/ BARREL | I40: 209
...

Sheet STATIONEY ITEM CODE
A1: STATIONERY ITEM CODE
A2: S.No | B2: Item Code | C2: Item Variant Desc.
A3: 7104 | B3: STY-A3-BOX-FL | C3: A3 BOX FILE
A4: 7105 | B4: STY-A3-SHT | C4: A3 SHEET (500 NOS/BOX)
A5: 7106 | B5: STY-A4-BOX-FL | C5: A4 BOX FILE
A6: 7107 | B6: STY-A4-L-FOL-GR | C6: A4 L FOLDER GREEN
A7: 7108 | B7: STY-A4-L-FOL-WH | C7: A4 L FOLDER WHITE
A8: 7109 | B8: STY-A4-L-FOL-YLW | C8: A4 L FOLDER YELLOW
A9: 7110 | B9: STY-A4-SHT | C9: A4 SHEET (500 NOS/BUNDLE)
A10: 7111 | B10: STY-A5-BOX-FL | C10: A5 BOX FILE
A11: 7112 | B11: STY-ATN-NOTE | C11: ATTANTANCE NOTE
A12: 7113 | B12: STY-BIN-CLIP-BIG | C12: BINDER CLIP BIG
A13: 7114 | B13: STY-BIN-CLIP-SML | C13: BINDER CLIP SMALL
A14: 7115 | B14: STY-BLK-PEN-RS3 | C14: BLACK PEN RS3
... A104: 61655 | B104: RML-HYP-BROUCHER | C104: HYPNOS BROUCHER ( FOAM)
B105: STY-GLASS-CLEAN | C105: colin
B106: STY-WIRE-CUT | C106: 1.4 CUTTER
B107: RML-YEL-MASK | C107: YELLOW MASK
B108: STY-STEEL-KNIFE | C108: KNIFE
B109: STY-SCISSOR-10 | C109: SCISSOR - 10"
B110: STY-SCISSOR-12 | C110: SCISSOR - 12"
B111: STY-CRBN-SHT | C111: CARBON SHEET (100 PER POCKET)
B112: RML-MEAS-TAPE-3MTR | C112: MEASURING TAPE - 3MTR
B113: STY-REG-BOK | C113: REGISTER BOOK
B114: STY-TAILR-MRKR | C114: TAILORING CHALK MARKER (MULTI COLOUR)
B115: STY-L-FLE | C115: LEAF FILE (20 LEAF)
B116: STY-L-FLE-100 | C116: LEAF FILE ( 100 LEAF)
... B120: STY-OUT-PAS-PER-WORK | C120: OUTPASS BOOK FOR PERSONAL WORK

Sheet NON-WOVEN NEW ITEM CODE
A1: SI.No | B1: Item Code | C1: Item Desc | D1: UOM | E1: Warehouse | F1: Rate
A2: 1 | B2: RM-NWN-POS-32CMX70GSM | C2: NON WOVEN FABRIC 70 GSM x 32 CM - WHITE | D2: KGS | E2: CBERM | F2: 120.5
A3: 2 | B3: RM-NWN-POS-38CMX70GSM | C3: NON WOVEN FABRIC 70 GSM x 38 CM - WHITE | D3: KGS | E3: CBERM | F3: 120.5
A4: 1 | B4: RM-NWN-POS-38CMX70GSM-GRN | C4: NON WOVEN FABRIC 70 GSM x 38 CM - GREEN | D4: KGS | E4: CBERM | F4: 120.5
A5: 3 | B5: RM-NWN-POS-43CMX70GSM | C5: NON WOVEN FABRIC 70 GSM x 43 CM - WHITE | D5: KGS | E5: CBERM | F5: 120.5
A6: 4 | B6: RM-NWN-POS-48CMX70GSM | C6: NON WOVEN FABRIC 70 GSM x 48 CM - WHITE | D6: KGS | E6: CBERM | F6: 120.5
A7: 2 | B7: RM-NWN-POS-48CMX70GSM-GRN | C7: NON WOVEN FABRIC 70 GSM x 48 CM - GREEN | D7: KGS | E7: CBERM | F7: 120.5
A8: 5 | B8: RM-NWN-POS-53CMX70GSM | C8: NON WOVEN FABRIC 70 GSM x 53 CM - WHITE | D8: KGS | E8: CBERM | F8: 120.5
A9: 6 | B9: RM-NWN-POS-62CMX70GSM | C9: NON WOVEN FABRIC 70 GSM x 62 CM - WHITE | D9: KGS | E9: CBERM | F9: 120.5

Sheet INPUT
A1: S.NO | B1: CODE | C1: ITEM CODE | D1: UOM | E1: QTY | F1: Column1
A2: 1 | B2: 1.4 | C2: =IFERROR(VLOOKUP(B2,'STORE CODE'!$B:$C,2,0),"") -> RML-STW-1.4MM | D2: =IFERROR(VLOOKUP(B2,'STORE CODE'!$B:$E,4,0),"") -> KGS | E2: 1000
A3: 2 | B3: 1.8 | C3: =IFERROR(VLOOKUP(B3,'STORE CODE'!$B:$C,2,0),"") -> RML-STW-1.8MM | D3: =IFERROR(VLOOKUP(B3,'STORE CODE'!$B:$E,4,0),"") -> KGS | E3: 20000
A4: 3 | B4: 2.2 | C4: =IFERROR(VLOOKUP(B4,'STORE CODE'!$B:$C,2,0),"") -> RML-STW-2.2MM | D4: =IFERROR(VLOOKUP(B4,'STORE CODE'!$B:$E,4,0),"") -> KGS | E4: 12600
A5: 4 | B5: 4 | C5: =IFERROR(VLOOKUP(B5,'STORE CODE'!$B:$C,2,0),"") -> RML-STW-4.0MM | D5: =IFERROR(VLOOKUP(B5,'STORE CODE'!$B:$E,4,0),"") -> KGS | E5: 500
A6: 5 | B6: 60X110 | C6: =IFERROR(VLOOKUP(B6,'STORE CODE'!$B:$C,2,0),"") -> RML-EPE-1345MMX105MMX25MM | D6: =IFERROR(VLOOKUP(B6,'STORE CODE'!$B:$E,4,0),"") -> Nos | E6: 100
A7: 6 | B7: 72X110 | C7: =IFERROR(VLOOKUP(B7,'STORE CODE'!$B:$C,2,0),"") -> RML-EPE-1650MMX105MMX25MM | D7: =IFERROR(VLOOKUP(B7,'STORE CODE'!$B:$E,4,0),"") -> Nos | E7: 100
A8: 7 | B8: 60X130 | C8: =IFERROR(VLOOKUP(B8,'STORE CODE'!$B:$C,2,0),"") -> RML-EPE-1345MMX125MMX25MM | D8: =IFERROR(VLOOKUP(B8,'STORE CODE'!$B:$E,4,0),"") -> Nos | E8: 300
A9: 8 | B9: 72X130 | C9: =IFERROR(VLOOKUP(B9,'STORE CODE'!$B:$C,2,0),"") -> RML-EPE-1650MMX125MMX25MM | D9: =IFERROR(VLOOKUP(B9,'STORE CODE'!$B:$E,4,0),"") -> Nos | E9: 100
A10: 9 | B10: 85 | C10: =IFERROR(VLOOKUP(B10,'STORE CODE'!$B:$C,2,0),"") -> RML-CL85 | D10: =IFERROR(VLOOKUP(B10,'STORE CODE'!$B:$E,4,0),"") -> BOX | E10: 15
A11: 10 | B11: 24 | C11: =IFERROR(VLOOKUP(B11,'STORE CODE'!$B:$C,2,0),"") -> RML-HR24 | D11: =IFERROR(VLOOKUP(B11,'STORE CODE'!$B:$E,4,0),"") -> BOX | E11: 8
A12: 11 | B12: GLUE | C12: =IFERROR(VLOOKUP(B12,'STORE CODE'!$B:$C,2,0),"") -> RMI-HGLUE | D12: =IFERROR(VLOOKUP(B12,'STORE CODE'!$B:$E,4,0),"") -> KGS | E12: 400
A13: 12 | B13: GUM | C13: =IFERROR(VLOOKUP(B13,'STORE CODE'!$B:$C,2,0),"") -> RML-POLY-GUM | D13: =IFERROR(VLOOKUP(B13,'STORE CODE'!$B:$E,4,0),"") -> LTR | E13: 400
A14: 13 | B14: 79 | C14: =IFERROR(VLOOKUP(B14,'STORE CODE'!$B:$C,2,0),"") -> RML-NWN-70GSMX79" | D14: =IFERROR(VLOOKUP(B14,'STORE CODE'!$B:$E,4,0),"") -> KGS | E14: 240 | F14: 80
A15: 14 | B15: 43 | C15: =IFERROR(VLOOKUP(B15,'STORE CODE'!$B:$C,2,0),"") -> RM-NWN-POS-43CMX70GSM | D15: =IFERROR(VLOOKUP(B15,'STORE CODE'!$B:$E,4,0),"") -> KGS | E15: 200 | F15: 1000
A16: 15 | B16: 48G | C16: =IFERROR(VLOOKUP(B16,'STORE CODE'!$B:$C,2,0),"") -> RM-NWN-POS-48CMX70GSM-GRN | D16: =IFERROR(VLOOKUP(B16,'STORE CODE'!$B:$E,4,0),"") -> KGS | F16: 500
A17: 16 | B17: 38 | C17: =IFERROR(VLOOKUP(B17,'STORE CODE'!$B:$C,2,0),"") -> RM-NWN-POS-38CMX70GSM | D17: =IFERROR(VLOOKUP(B17,'STORE CODE'!$B:$E,4,0),"") -> KGS
A18: 17 | C18: =IFERROR(VLOOKUP(B18,'STORE CODE'!$B:$C,2,0),"") | D18: =IFERROR(VLOOKUP(B18,'STORE CODE'!$B:$E,4,0),"")
A19: 18 | C19: =IFERROR(VLOOKUP(B19,'STORE CODE'!$B:$C,2,0),"") | D19: =IFERROR(VLOOKUP(B19,'STORE CODE'!$B:$E,4,0),"")
A20: 19 | C20: =IFERROR(VLOOKUP(B20,'STORE CODE'!$B:$C,2,0),"") | D20: =IFERROR(VLOOKUP(B20,'STORE CODE'!$B:$E,4,0),"")
A21: 20 | C21: =IFERROR(VLOOKUP(B21,'STORE CODE'!$B:$C,2,0),"") | D21: =IFERROR(VLOOKUP(B21,'STORE CODE'!$B:$E,4,0),"")
A22: 21 | C22: =IFERROR(VLOOKUP(B22,'STORE CODE'!$B:$C,2,0),"") | D22: =IFERROR(VLOOKUP(B22,'STORE CODE'!$B:$E,4,0),"")
A23: 22 | C23: =IFERROR(VLOOKUP(B23,'STORE CODE'!$B:$C,2,0),"") | D23: =IFERROR(VLOOKUP(B23,'STORE CODE'!$B:$E,4,0),"")
A24: 23 | C24: =IFERROR(VLOOKUP(B24,'STORE CODE'!$B:$C,2,0),"") | D24: =IFERROR(VLOOKUP(B24,'STORE CODE'!$B:$E,4,0),"")
A25: 24 | C25: =IFERROR(VLOOKUP(B25,'STORE CODE'!$B:$C,2,0),"") | D25: =IFERROR(VLOOKUP(B25,'STORE CODE'!$B:$E,4,0),"")
A26: 25 | C26: =IFERROR(VLOOKUP(B26,'STORE CODE'!$B:$C,2,0),"") | D26: =IFERROR(VLOOKUP(B26,'STORE CODE'!$B:$E,4,0),"")
A27: 26 | C27: =IFERROR(VLOOKUP(B27,'STORE CODE'!$B:$C,2,0),"") | D27: =IFERROR(VLOOKUP(B27,'STORE CODE'!$B:$E,4,0),"")
A28: 27 | C28: =IFERROR(VLOOKUP(B28,'STORE CODE'!$B:$C,2,0),"") | D28: =IFERROR(VLOOKUP(B28,'STORE CODE'!$B:$E,4,0),"")
A29: 28 | C29: =IFERROR(VLOOKUP(B29,'STORE CODE'!$B:$C,2,0),"") | D29: =IFERROR(VLOOKUP(B29,'STORE CODE'!$B:$E,4,0),"")
... A51: 48 | C51: =IFERROR(VLOOKUP(B51,'STORE CODE'!$B:$C,2,0),"") | D51: =IFERROR(VLOOKUP(B51,'STORE CODE'!$B:$E,4,0),"")

Sheet COTTON FELT MR
A1: COTTON FELT SIZE | E1: PER COTTON FELT WEIGHT | F1: REQUIRED QTY | G1: UOM | H1: TOTAL WEIGHT
A2: 72X30 | B2: 71.5 | C2: 29.5 | D2: RMI-HCTNF-71.50X29.50. | E2: =700*(B2)*(C2)*0.0254*0.0254/1000 -> 0.95256261 | G2: KGS | H2: =F2*E2 -> 0
A3: 72X36 | B3: 71.5 | C3: 35.5 | D3: RMI-HCTNF-71.50X35.50. | E3: =700*(B3)*(C3)*0.0254*0.0254/1000 -> 1.1463042 | F3: 100 | G3: KGS | H3: =F3*E3 -> 114.63042
A4: 72X42 | B4: 71.5 | C4: 41.5 | D4: RMI-HCTNF-71.50X41.50. | E4: =700*(B4)*(C4)*0.0254*0.0254/1000 -> 1.3400457 | G4: KGS | H4: =F4*E4 -> 0
A5: 72X48 | B5: 71.5 | C5: 47.5 | D5: RMI-HCTNF-71.50X47.50. | E5: =700*(B5)*(C5)*0.0254*0.0254/1000 -> 1.5337873 | F5: 300 | G5: KGS | H5: =F5*E5 -> 460.13618
A6: 72X60 | B6: 71.5 | C6: 59.5 | D6: RMI-HCTNF-71.50X59.50. | E6: =700*(B6)*(C6)*0.0254*0.0254/1000 -> 1.9212704 | G6: KGS | H6: =F6*E6 -> 0
A7: 72X66 | B7: 71.5 | C7: 65.5 | D7: RMI-HCTNF-71.50X65.50. | E7: =700*(B7)*(C7)*0.0254*0.0254/1000 -> 2.1150119 | G7: KGS | H7: =F7*E7 -> 0
A8: 72X72 | B8: 71.5 | C8: 71.5 | D8: RMI-HCTNF-71.50X71.50. | E8: =700*(B8)*(C8)*0.0254*0.0254/1000 -> 2.3087534 | G8: KGS | H8: =F8*E8 -> 0
A9: 75X30 | B9: 74.5 | C9: 29.5 | D9: RMI-HCTNF-74.50X29.50. | E9: =700*(B9)*(C9)*0.0254*0.0254/1000 -> 0.99253027 | G9: KGS | H9: =F9*E9 -> 0
A10: 75X36 | B10: 74.5 | C10: 35.5 | D10: RMI-HCTNF-74.50X35.50. | E10: =700*(B10)*(C10)*0.0254*0.0254/1000 -> 1.1944008 | F10: 100 | G10: KGS | H10: =F10*E10 -> 119.44008
A11: 75X42 | B11: 74.5 | C11: 41.5 | D11: RMI-HCTNF-74.50X41.50. | E11: =700*(B11)*(C11)*0.0254*0.0254/1000 -> 1.3962714 | G11: KGS | H11: =F11*E11 -> 0
A12: 75X48 | B12: 74.50 | C12: 47.5 | D12: RMI-HCTNF-74.50X47.50 | E12: =700*(B12)*(C12)*0.0254*0.0254/1000 -> 1.598142 | F12: 400 | G12: KGS | H12: =F12*E12 -> 639.25679
A13: 75X60 | B13: 74.50 | C13: 59.5 | D13: RMI-HCTNF-74.50x59.50. | E13: =700*(B13)*(C13)*0.0254*0.0254/1000 -> 2.0018831 | F13: 1000 | G13: KGS | H13: =F13*E13 -> 2001.8831
A14: 75X66 | B14: 74.5 | C14: 65.5 | D14: RMI-HCTNF-74.50x65.50. | E14: =700*(B14)*(C14)*0.0254*0.0254/1000 -> 2.2037537 | G14: KGS | H14: =F14*E14 -> 0
A15: 75X72 | B15: 74.5 | C15: 71.5 | D15: RMI-HCTNF-74.50x71.50. | E15: =700*(B15)*(C15)*0.0254*0.0254/1000 -> 2.4056242 | F15: 100 | G15: KGS | H15: =F15*E15 -> 240.56242
A16: 78X30 | B16: 77.5 | C16: 29.5 | D16: RMI-HCTNF-77.50X29.50 | E16: =700*(B16)*(C16)*0.0254*0.0254/1000 -> 1.0324979 | G16: KGS | H16: =F16*E16 -> 0
A17: 78X36 | B17: 77.5 | C17: 35.5 | D17: RMI-HCTNF-77.50X35.50. | E17: =700*(B17)*(C17)*0.0254*0.0254/1000 -> 1.2424975 | G17: KGS | H17: =F17*E17 -> 0
A18: 78X42 | B18: 77.5 | C18: 41.5 | D18: RMI-HCTNF-77.50X41.50. | E18: =700*(B18)*(C18)*0.0254*0.0254/1000 -> 1.4524971 | G18: KGS | H18: =F18*E18 -> 0
A19: 78X48 | B19: 77.5 | C19: 47.5 | D19: RMI-HCTNF-77.50X47.50. | E19: =700*(B19)*(C19)*0.0254*0.0254/1000 -> 1.6624967 | G19: KGS | H19: =F19*E19 -> 0
A20: 78X60 | B20: 77.50 | C20: 59.50 | D20: RMI-HCTNF-77.50x59.50. | E20: =700*(B20)*(C20)*0.0254*0.0254/1000 -> 2.0824958 | F20: 250 | G20: KGS | H20: =F20*E20 -> 520.62396
A21: 78X66 | B21: 77.5 | C21: 65.5 | D21: RMI-HCTNF-77.50X65.50. | E21: =700*(B21)*(C21)*0.0254*0.0254/1000 -> 2.2924954 | G21: KGS | H21: =F21*E21 -> 0
A22: 78X72 | B22: 77.50 | C22: 71.50 | D22: RMI-HCTNF-77.50x71.50. | E22: =700*(B22)*(C22)*0.0254*0.0254/1000 -> 2.502495 | F22: 200 | G22: KGS | H22: =F22*E22 -> 500.499
A23: 84X72 | B23: 83.5 | C23: 71.5 | D23: RMI-HCTNF-83.50X71.50. | E23: =700*(B23)*(C23)*0.0254*0.0254/1000 -> 2.6962365 | G23: KGS | H23: =F23*E23 -> 0
