Workbook

Sheet ITEM LIST
A1: ITEM CODE | B1: ITEM DESCRIPTION | C1: BLOCK CODES | D1: ITEM
A2: HYPFOMFMMR72X30X04 | B2: Peps Hypnos Foamera Soft Top Maroon 72X30X04 | C2: FOAMERA-FOAM-BLOCK-72X30X04 | D2: FOAMERA
A3: HYPFOMFMMR72X33X04 | B3: Peps Hypnos Foamera Soft Top Maroon 72X33X04 | C3: FOAMERA-FOAM-BLOCK-72X33X04 | D3: FOAMERA
A4: HYPFOMFMMR72X36X04 | B4: Peps Hypnos Foamera Soft Top Maroon 72X36X04 | C4: FOAMERA-FOAM-BLOCK-72X36X04 | D4: FOAMERA
A5: HYPFOMFMMR72X39X04 | B5: Peps Hypnos Foamera Soft Top Maroon 72X39X04 | C5: FOAMERA-FOAM-BLOCK-72X39X04 | D5: FOAMERA
A6: HYPFOMFMMR72X42X04 | B6: Peps Hypnos Foamera Soft Top Maroon 72X42X04 | C6: FOAMERA-FOAM-BLOCK-72X42X04 | D6: FOAMERA
A7: HYPFOMFMMR72X45X04 | B7: Peps Hypnos Foamera Soft Top Maroon 72X45X04 | C7: FOAMERA-FOAM-BLOCK-72X45X04 | D7: FOAMERA
A8: HYPFOMFMMR72X48X04 | B8: Peps Hypnos Foamera Soft Top Maroon 72X48X04 | C8: FOAMERA-FOAM-BLOCK-72X48X04 | D8: FOAMERA
A9: HYPFOMFMMR72X51X04 | B9: Peps Hypnos Foamera Soft Top Maroon 72X51X04 | C9: FOAMERA-FOAM-BLOCK-72X51X04 | D9: FOAMERA
A10: HYPFOMFMMR72X54X04 | B10: Peps Hypnos Foamera Soft Top Maroon 72X54X04 | C10: FOAMERA-FOAM-BLOCK-72X54X04 | D10: FOAMERA
A11: HYPFOMFMMR72X57X04 | B11: Peps Hypnos Foamera Soft Top Maroon 72X57X04 | C11: FOAMERA-FOAM-BLOCK-72X57X04 | D11: FOAMERA
A12: HYPFOMFMMR72X60X04 | B12: Peps Hypnos Foamera Soft Top Maroon 72X60X04 | C12: FOAMERA-FOAM-BLOCK-72X60X04 | D12: FOAMERA
... A2193: HYPMULTFMGR72X48X08 | B2193: Peps Hypnos Memorio-Ultra Grey 72X48X08 | C2193: MEM-ULTRA-FOAM-BLOCK-72X48X08 | D2193: MEM ULTRA
A2194: HYPMULTFMGR72X51X06 | C2194: MEM-ULTRA-FOAM-BLOCK-72X51X06 | D2194: MEM ULTRA
A2195: HYPMULTFMGR72X51X08 | C2195: MEM-ULTRA-FOAM-BLOCK-72X51X08 | D2195: MEM ULTRA
A2196: HYPMULTFMGR72X60X08 | B2196: Peps Hypnos Memorio-Ultra Grey 72X60X08 | C2196: MEM-ULTRA-FOAM-BLOCK-72X60X08 | D2196: MEM ULTRA
A2197: HYPMULTFMGR72X66X08 | B2197: Peps Hypnos Memorio-Ultra Grey 72X66X08 | C2197: MEM-ULTRA-FOAM-BLOCK-72X66X08 | D2197: MEM ULTRA
A2198: HYPMULTFMGR72X72X08 | B2198: Peps Hypnos Memorio-Ultra Grey 72X72X08 | C2198: MEM-ULTRA-FOAM-BLOCK-72X72X08 | D2198: MEM ULTRA
A2199: HYPMULTFMGR75X30X08 | B2199: Peps Hypnos Memorio-Ultra Grey 75X30X08 | C2199: MEM-ULTRA-FOAM-BLOCK-75X30X08 | D2199: MEM ULTRA
A2200: HYPMULTFMGR75X36X08 | B2200: Peps Hypnos Memorio-Ultra Grey 75X36X08 | C2200: MEM-ULTRA-FOAM-BLOCK-75X36X08 | D2200: MEM ULTRA
A2201: HYPMULTFMGR75X42X08 | B2201: Peps Hypnos Memorio-Ultra Grey 75X42X08 | C2201: MEM-ULTRA-FOAM-BLOCK-75X42X08 | D2201: MEM ULTRA
A2202: HYPMULTFMGR75X48X08 | B2202: Peps Hypnos Memorio-Ultra Grey 75X48X08 | C2202: MEM-ULTRA-FOAM-BLOCK-75X48X08 | D2202: MEM ULTRA
A2203: HYPMULTFMGR75X60X08 | B2203: Peps Hypnos Memorio-Ultra Grey 75X60X08 | C2203: MEM-ULTRA-FOAM-BLOCK-75X60X08 | D2203: MEM ULTRA
A2204: HYPMULTFMGR75X66X08 | B2204: Peps Hypnos Memorio-Ultra Grey 75X66X08 | C2204: MEM-ULTRA-FOAM-BLOCK-75X66X08 | D2204: MEM ULTRA
A2205: HYPMULTFMGR75X72X08 | B2205: Peps Hypnos Memorio-Ultra Grey 75X72X08 | C2205: MEM-ULTRA-FOAM-BLOCK-75X72X08 | D2205: MEM ULTRA
A2206: HYPMULTFMGR78X30X08 | B2206: Peps Hypnos Memorio-Ultra Grey 78X30X08 | C2206: MEM-ULTRA-FOAM-BLOCK-78X30X08 | D2206: MEM ULTRA
A2207: HYPMULTFMGR78X36X08 | B2207: Peps Hypnos Memorio-Ultra Grey 78X36X08 | C2207: MEM-ULTRA-FOAM-BLOCK-78X36X08 | D2207: MEM ULTRA
... A2277: HYPMULTFMDGR20X18X08 | B2277: MEMORIO ULTRA GREY 20X18X08 | C2277: MEM-ULTRA-FOAM-BLOCK-20X18X08 | D2277: MEM ULTRA
A2278: HYPKBRZFMDB20X18X06 | C2278: KOZY-BREEZE-FOAM-BLOCK-20X18X06 | D2278: KOZY
A2279: HYPKBRZFMMR20X18X06 | C2279: KOZY-BREEZE-FOAM-BLOCK-20X18X06 | D2279: KOZY
A2280: HYPKBRZFMDB72X30X04 | C2280: KOZY-BREEZE-FOAM-BLOCK-72X30X04 | D2280: KOZY
A2281: HYPKBRZFMDB72X30X05 | C2281: KOZY-BREEZE-FOAM-BLOCK-72X30X05 | D2281: KOZY
A2282: HYPKBRZFMDB72X30X06 | C2282: KOZY-BREEZE-FOAM-BLOCK-72X30X06 | D2282: KOZY
A2283: HYPKBRZFMDB72X36X04 | C2283: KOZY-BREEZE-FOAM-BLOCK-72X36X04 | D2283: KOZY
A2284: HYPKBRZFMDB72X36X05 | C2284: KOZY-BREEZE-FOAM-BLOCK-72X36X05 | D2284: KOZY
A2285: HYPKBRZFMDB72X36X06 | C2285: KOZY-BREEZE-FOAM-BLOCK-72X36X06 | D2285: KOZY
A2286: HYPKBRZFMDB72X48X04 | C2286: KOZY-BREEZE-FOAM-BLOCK-72X48X04 | D2286: KOZY
A2287: HYPKBRZFMDB72X48X05 | C2287: KOZY-BREEZE-FOAM-BLOCK-72X48X05 | D2287: KOZY
A2288: HYPKBRZFMDB72X48X06 | C2288: KOZY-BREEZE-FOAM-BLOCK-72X48X06 | D2288: KOZY
A2289: HYPKBRZFMDB72X60X04 | C2289: KOZY-BREEZE-FOAM-BLOCK-72X60X04 | D2289: KOZY
...

Sheet PIVOT
A3: Row Labels | B3: Sum of QTY
A4: 90D-HYP-INSPREE-BLOCK-72X30X05 | B4: 1
A5: 90D-HYP-INSPREE-BLOCK-72X36X06 | B5: 2
A6: 90D-HYP-INSPREE-BLOCK-72X60X06 | B6: 2
A7: 90D-HYP-INSPREE-BLOCK-75X36X06 | B7: 2
A8: 90D-HYP-INSPREE-BLOCK-75X60X06 | B8: 5
A9: 90D-HYP-INSPREE-BLOCK-75X60X08 | B9: 2
A10: 90D-HYP-INSPREE-BLOCK-78X60X06 | B10: 4
A11: 90D-HYP-INSPREE-BLOCK-78X72X06 | B11: 4
A12: 90D-HYP-INSPREE-BLOCK-78X72X08 | B12: 2
A13: KOZY-BREEZE-FOAM-BLOCK-72X30X04 | B13: 4
A14: KOZY-BREEZE-FOAM-BLOCK-72X30X05 | B14: 10
A15: KOZY-BREEZE-FOAM-BLOCK-72X48X04 | B15: 6
... A28: #N/A | B28: 0
A29: (blank)
A30: VISTA-BOND-FOAM-BLOCK-72X60X05 | B30: 5
A31: KOZY-BREEZE-FOAM-BLOCK-72X48X05 | B31: 3
A32: KOZY-BREEZE-FOAM-BLOCK-75X60X05 | B32: 4
A33: KOZY-BREEZE-FOAM-BLOCK-78X60X05 | B33: 3
A34: 90D-HYP-INSPREE-BLOCK-75X48X06 | B34: 1
A35: KOZY-BREEZE-FOAM-BLOCK-75X48X04 | B35: 3
A36: 90D-HYP-INSPREE-BLOCK-75X66X06 | B36: 1
A37: 90D-HYP-INSPREE-BLOCK-75X30X05 | B37: 2
A38: 90D-HYP-INSPREE-BLOCK-20X18X06 | B38: 5
A39: KOZY-BREEZE-FOAM-BLOCK-75X36X04 | B39: 2
A40: 90D-HYP-INSPREE-BLOCK-72X36X05 | B40: 2
A41: KOZY-BREEZE-FOAM-BLOCK-20X18X06 | B41: 1
... A54: Grand Total | B54: 264

Sheet WORK ORDER
A1: ITEM | B1: QTY | C1: SFG ITEM | D1: QTY
A2: HYPINSFMMR72X30X04-90D | B2: 1 | C2: =VLOOKUP(A:A,'ITEM LIST'!A:C,3,0) -> 90D-HYP-INSPREE-BLOCK-72X30X04 | D2: =B2 -> 1
A3: HYPINSFMMR75X48X06-90D | B3: 1 | C3: =VLOOKUP(A:A,'ITEM LIST'!A:C,3,0) -> 90D-HYP-INSPREE-BLOCK-75X48X06 | D3: =B3 -> 1
A4: HYPINSFMMR84X72X05-90D | B4: 1 | C4: =VLOOKUP(A:A,'ITEM LIST'!A:C,3,0) -> 90D-HYP-INSPREE-BLOCK-84X72X05 | D4: =B4 -> 1
A5: HYPINSFMETMR75X66X06-90D | B5: 1 | C5: =VLOOKUP(A:A,'ITEM LIST'!A:C,3,0) -> 90D-HYP-INSPREE-BLOCK-75X66X06 | D5: =B5 -> 1
A6: HYPINSFMETMR72X36X05-90D | B6: 2 | C6: =VLOOKUP(A:A,'ITEM LIST'!A:C,3,0) -> 90D-HYP-INSPREE-BLOCK-72X36X05 | D6: =B6 -> 2 | E6: 75*45
A7: HYPINSFMETMR78X60X06-90D | B7: 1 | C7: =VLOOKUP(A:A,'ITEM LIST'!A:C,3,0) -> 90D-HYP-INSPREE-BLOCK-78X60X06 | D7: =B7 -> 1 | E7: 75*51
A8: HYPINSFMETMR78X60X06-90D | B8: 3 | C8: =VLOOKUP(A:A,'ITEM LIST'!A:C,3,0) -> 90D-HYP-INSPREE-BLOCK-78X60X06 | D8: =B8 -> 3
A9: HYPINSFMETMR20X18X06-90D | B9: 1 | C9: =VLOOKUP(A:A,'ITEM LIST'!A:C,3,0) -> 90D-HYP-INSPREE-BLOCK-20X18X06 | D9: =B9 -> 1
A10: HYPINSFMMR20X18X06-90D | B10: 1 | C10: =VLOOKUP(A:A,'ITEM LIST'!A:C,3,0) -> 90D-HYP-INSPREE-BLOCK-20X18X06 | D10: =B10 -> 1
A11: HYPINSFMMR75X30X05-90D | B11: 2 | C11: =VLOOKUP(A:A,'ITEM LIST'!A:C,3,0) -> 90D-HYP-INSPREE-BLOCK-75X30X05 | D11: =B11 -> 2
A12: HYPINSFMMR72X30X05-90D | B12: 1 | C12: =VLOOKUP(A:A,'ITEM LIST'!A:C,3,0) -> 90D-HYP-INSPREE-BLOCK-72X30X05 | D12: =B12 -> 1
A13: HYPINSFMLTETGRN78X72X06-90D | B13: 2 | C13: =VLOOKUP(A:A,'ITEM LIST'!A:C,3,0) -> 90D-HYP-INSPREE-BLOCK-78X72X06 | D13: =B13 -> 2
A14: HYPINSFMLTETGRN75X36X06-90D | B14: 1 | C14: =VLOOKUP(A:A,'ITEM LIST'!A:C,3,0) -> 90D-HYP-INSPREE-BLOCK-75X36X06 | D14: =B14 -> 1
A15: HYPINSFMLTGRN75X36X06-90D | B15: 1 | C15: =VLOOKUP(A:A,'ITEM LIST'!A:C,3,0) -> 90D-HYP-INSPREE-BLOCK-75X36X06 | D15: =B15 -> 1
A16: HYPINSFMLTGRN75X60X06-90D | B16: 1 | C16: =VLOOKUP(A:A,'ITEM LIST'!A:C,3,0) -> 90D-HYP-INSPREE-BLOCK-75X60X06 | D16: =B16 -> 1
A17: HYPINSFMLTETPNK72X60X06-90D | B17: 1 | C17: =VLOOKUP(A:A,'ITEM LIST'!A:C,3,0) -> 90D-HYP-INSPREE-BLOCK-72X60X06 | D17: =B17 -> 1
A18: HYPINSFMLTETGRN75X60X06-90D | B18: 2 | C18: =VLOOKUP(A:A,'ITEM LIST'!A:C,3,0) -> 90D-HYP-INSPREE-BLOCK-75X60X06 | D18: =B18 -> 2
A19: HYPINSFMLTETGRN75X60X08-90D | B19: 1 | C19: =VLOOKUP(A:A,'ITEM LIST'!A:C,3,0) -> 90D-HYP-INSPREE-BLOCK-75X60X08 | D19: =B19 -> 1
... A71: HYPPANFMDB78X48X08 | B71: 1 | C71: =VLOOKUP(A:A,'ITEM LIST'!A:C,3,0) -> PANORAMA-FOAM-BLOCK-78X48X08 | D71: =B71 -> 1
C72: =VLOOKUP(A:A,'ITEM LIST'!A:C,3,0) -> #N/A | D72: =B72 -> 0
C73: =VLOOKUP(A:A,'ITEM LIST'!A:C,3,0) -> #N/A | D73: =B73 -> 0
C74: =VLOOKUP(A:A,'ITEM LIST'!A:C,3,0) -> #N/A | D74: =B74 -> 0
C75: =VLOOKUP(A:A,'ITEM LIST'!A:C,3,0) -> #N/A | D75: =B75 -> 0
C76: =VLOOKUP(A:A,'ITEM LIST'!A:C,3,0) -> #N/A | D76: =B76 -> 0
C77: =VLOOKUP(A:A,'ITEM LIST'!A:C,3,0) -> #N/A | D77: =B77 -> 0
C78: =VLOOKUP(A:A,'ITEM LIST'!A:C,3,0) -> #N/A | D78: =B78 -> 0
C79: =VLOOKUP(A:A,'ITEM LIST'!A:C,3,0) -> #N/A | D79: =B79 -> 0
C80: =VLOOKUP(A:A,'ITEM LIST'!A:C,3,0) -> #N/A | D80: =B80 -> 0
C81: =VLOOKUP(A:A,'ITEM LIST'!A:C,3,0) -> #N/A | D81: =B81 -> 0
C82: =VLOOKUP(A:A,'ITEM LIST'!A:C,3,0) -> #N/A | D82: =B82 -> 0
C83: =VLOOKUP(A:A,'ITEM LIST'!A:C,3,0) -> #N/A | D83: =B83 -> 0
... C19604: =VLOOKUP(A:A,'ITEM LIST'!A:C,3,0) -> #N/A | D19604: =B19604 -> 0
C19605: =VLOOKUP(A:A,'ITEM LIST'!A:C,3,0) -> #N/A
C19606: =VLOOKUP(A:A,'ITEM LIST'!A:C,3,0) -> #N/A
C19607: =VLOOKUP(A:A,'ITEM LIST'!A:C,3,0) -> #N/A
C19608: =VLOOKUP(A:A,'ITEM LIST'!A:C,3,0) -> #N/A
C19609: =VLOOKUP(A:A,'ITEM LIST'!A:C,3,0) -> #N/A
C19610: =VLOOKUP(A:A,'ITEM LIST'!A:C,3,0) -> #N/A
C19611: =VLOOKUP(A:A,'ITEM LIST'!A:C,3,0) -> #N/A
...

Sheet Sheet2
A1: CK | B1: CK-2 | C1: CK3 | D1: CK4 | F1: HYPINSFMLTGRN | G1: HYPINSFMLTPNK | H1: ET | J1: HYPINSFMMR | K1: HYPINSFMETMR | L1: CK4
A2: HYPINSFMLTGRN72X30X05-90D | B2: HYPINSFMMFBL72X30X05-90D | C2: HYPINSFMMR72X30X05-90D | D2: HYPVISBND72X30X04 | F2: HYPINSFMMFGR | G2: HYPINSFMMFBL | H2: HYPINSFMMFETBL | I2: HYPINSFMMFETGR | L2: SKSGFM72X30X06 | N2: 25D-HELIXA-FOAM-72X30X119MM | O2: 40D-MDI-MEM-FOAM-72X30X25MM
A3: HYPINSFMLTGRN72X33X05-90D | B3: HYPINSFMMFBL72X33X05-90D | C3: HYPINSFMMR72X33X05-90D | D3: HYPVISBND72X33X04 | L3: SKSGFM72X33X06 | N3: 25D-HELIXA-FOAM-72X33X119MM | O3: 40D-MDI-MEM-FOAM-72X33X25MM
A4: HYPINSFMLTGRN72X36X05-90D | B4: HYPINSFMMFBL72X36X05-90D | C4: HYPINSFMMR72X36X05-90D | D4: HYPVISBND72X36X04 | G4: 25D-HELIXA-FOAM-78X66X119MM | L4: SKSGFM72X36X06 | N4: 25D-HELIXA-FOAM-72X36X119MM | O4: 40D-MDI-MEM-FOAM-72X36X25MM
A5: HYPINSFMLTGRN72X39X05-90D | B5: HYPINSFMMFBL72X39X05-90D | C5: HYPINSFMMR72X39X05-90D | D5: HYPVISBND72X39X04 | G5: 40D-MDI-MEM-FOAM | L5: SKSGFM72X39X06 | N5: 25D-HELIXA-FOAM-72X39X119MM | O5: 40D-MDI-MEM-FOAM-72X39X25MM
A6: HYPINSFMLTGRN72X42X05-90D | B6: HYPINSFMMFBL72X42X05-90D | C6: HYPINSFMMR72X42X05-90D | D6: HYPVISBND72X42X04 | L6: SKSGFM72X42X06 | N6: 25D-HELIXA-FOAM-72X42X119MM | O6: 40D-MDI-MEM-FOAM-72X42X25MM
A7: HYPINSFMLTGRN72X45X05-90D | B7: HYPINSFMMFBL72X45X05-90D | C7: HYPINSFMMR72X45X05-90D | D7: HYPVISBND72X45X04 | L7: SKSGFM72X45X06 | N7: 25D-HELIXA-FOAM-72X45X119MM | O7: 40D-MDI-MEM-FOAM-72X45X25MM
A8: HYPINSFMLTGRN72X48X05-90D | B8: HYPINSFMMFBL72X48X05-90D | C8: HYPINSFMMR72X48X05-90D | D8: HYPVISBND72X48X04 | L8: SKSGFM72X48X06 | N8: 25D-HELIXA-FOAM-72X48X119MM | O8: 40D-MDI-MEM-FOAM-72X48X25MM
A9: HYPINSFMLTGRN72X51X05-90D | B9: HYPINSFMMFBL72X51X05-90D | C9: HYPINSFMMR72X51X05-90D | D9: HYPVISBND72X51X04 | L9: SKSGFM72X51X06 | N9: 25D-HELIXA-FOAM-72X51X119MM | O9: 40D-MDI-MEM-FOAM-72X51X25MM
A10: HYPINSFMLTGRN72X54X05-90D | B10: HYPINSFMMFBL72X54X05-90D | C10: HYPINSFMMR72X54X05-90D | D10: HYPVISBND72X54X04 | L10: SKSGFM72X54X06 | N10: 25D-HELIXA-FOAM-72X54X119MM | O10: 40D-MDI-MEM-FOAM-72X54X25MM
A11: HYPINSFMLTGRN72X57X05-90D | B11: HYPINSFMMFBL72X57X05-90D | C11: HYPINSFMMR72X57X05-90D | D11: HYPVISBND72X57X04 | L11: SKSGFM72X57X06 | N11: 25D-HELIXA-FOAM-72X57X119MM | O11: 40D-MDI-MEM-FOAM-72X57X25MM
A12: HYPINSFMLTGRN72X60X05-90D | B12: HYPINSFMMFBL72X60X05-90D | C12: HYPINSFMMR72X60X05-90D | D12: HYPVISBND72X60X04 | L12: SKSGFM72X60X06 | N12: 25D-HELIXA-FOAM-72X60X119MM | O12: 40D-MDI-MEM-FOAM-72X60X25MM
A13: HYPINSFMLTGRN72X63X05-90D | B13: HYPINSFMMFBL72X63X05-90D | C13: HYPINSFMMR72X63X05-90D | D13: HYPVISBND72X63X04 | L13: SKSGFM72X63X06 | N13: 25D-HELIXA-FOAM-72X63X119MM | O13: 40D-MDI-MEM-FOAM-72X63X25MM
A14: HYPINSFMLTGRN72X66X05-90D | B14: HYPINSFMMFBL72X66X05-90D | C14: HYPINSFMMR72X66X05-90D | D14: HYPVISBND72X66X04 | L14: SKSGFM72X66X06 | N14: 25D-HELIXA-FOAM-72X66X119MM | O14: 40D-MDI-MEM-FOAM-72X66X25MM
A15: HYPINSFMLTGRN72X69X05-90D | B15: HYPINSFMMFBL72X69X05-90D | C15: HYPINSFMMR72X69X05-90D | D15: HYPVISBND72X69X04 | L15: SKSGFM72X69X06 | N15: 25D-HELIXA-FOAM-72X69X119MM | O15: 40D-MDI-MEM-FOAM-72X69X25MM
A16: HYPINSFMLTGRN72X72X05-90D | B16: HYPINSFMMFBL72X72X05-90D | C16: HYPINSFMMR72X72X05-90D | D16: HYPVISBND72X72X04 | L16: SKSGFM72X72X06 | N16: 25D-HELIXA-FOAM-72X72X119MM | O16: 40D-MDI-MEM-FOAM-72X72X25MM
A17: HYPINSFMLTGRN75X30X05-90D | B17: HYPINSFMMFBL75X30X05-90D | C17: HYPINSFMMR75X30X05-90D | D17: HYPVISBND75X30X04 | L17: SKSGFM75X30X06 | N17: 25D-HELIXA-FOAM-75X30X119MM | O17: 40D-MDI-MEM-FOAM-75X30X25MM
... A151: HYPINSFMLTGRN84X72X06-90D | B151: HYPINSFMMFBL84X72X06-90D | C151: HYPINSFMMR84X72X06-90D | D151: HYPVISBND84X72X05 | L151: SKSGFM84X72X08 | N151: 25D-HELIXA-FOAM-84X72X170MM | O151: 40D-MDI-MEM-FOAM-84X72X25MM
A152: HYPINSFMLTGRN72X30X08-90D | B152: HYPINSFMMFBL72X30X08-90D | C152: HYPINSFMMR72X30X08-90D | D152: HYPVISBND72X30X06
A153: HYPINSFMLTGRN72X33X08-90D | B153: HYPINSFMMFBL72X33X08-90D | C153: HYPINSFMMR72X33X08-90D | D153: HYPVISBND72X33X06
A154: HYPINSFMLTGRN72X36X08-90D | B154: HYPINSFMMFBL72X36X08-90D | C154: HYPINSFMMR72X36X08-90D | D154: HYPVISBND72X36X06
A155: HYPINSFMLTGRN72X39X08-90D | B155: HYPINSFMMFBL72X39X08-90D | C155: HYPINSFMMR72X39X08-90D | D155: HYPVISBND72X39X06
A156: HYPINSFMLTGRN72X42X08-90D | B156: HYPINSFMMFBL72X42X08-90D | C156: HYPINSFMMR72X42X08-90D | D156: HYPVISBND72X42X06
A157: HYPINSFMLTGRN72X45X08-90D | B157: HYPINSFMMFBL72X45X08-90D | C157: HYPINSFMMR72X45X08-90D | D157: HYPVISBND72X45X06
A158: HYPINSFMLTGRN72X48X08-90D | B158: HYPINSFMMFBL72X48X08-90D | C158: HYPINSFMMR72X48X08-90D | D158: HYPVISBND72X48X06
A159: HYPINSFMLTGRN72X51X08-90D | B159: HYPINSFMMFBL72X51X08-90D | C159: HYPINSFMMR72X51X08-90D | D159: HYPVISBND72X51X06
A160: HYPINSFMLTGRN72X54X08-90D | B160: HYPINSFMMFBL72X54X08-90D | C160: HYPINSFMMR72X54X08-90D | D160: HYPVISBND72X54X06
A161: HYPINSFMLTGRN72X57X08-90D | B161: HYPINSFMMFBL72X57X08-90D | C161: HYPINSFMMR72X57X08-90D | D161: HYPVISBND72X57X06
A162: HYPINSFMLTGRN72X60X08-90D | B162: HYPINSFMMFBL72X60X08-90D | C162: HYPINSFMMR72X60X08-90D | D162: HYPVISBND72X60X06
A163: HYPINSFMLTGRN72X63X08-90D | B163: HYPINSFMMFBL72X63X08-90D | C163: HYPINSFMMR72X63X08-90D | D163: HYPVISBND72X63X06
... A226: HYPINSFMLTGRN84X72X08-90D | B226: HYPINSFMMFBL84X72X08-90D | C226: HYPINSFMMR84X72X08-90D | D226: HYPVISBND84X72X06
A227: HYPINSFMLTPNK72X30X05-90D | B227: HYPINSFMMFGR72X30X05-90D | C227: HYPINSFMETMR72X30X05-90D
A228: HYPINSFMLTPNK72X33X05-90D | B228: HYPINSFMMFGR72X33X05-90D | C228: HYPINSFMETMR72X33X05-90D
A229: HYPINSFMLTPNK72X36X05-90D | B229: HYPINSFMMFGR72X36X05-90D | C229: HYPINSFMETMR72X36X05-90D
A230: HYPINSFMLTPNK72X39X05-90D | B230: HYPINSFMMFGR72X39X05-90D | C230: HYPINSFMETMR72X39X05-90D
A231: HYPINSFMLTPNK72X42X05-90D | B231: HYPINSFMMFGR72X42X05-90D | C231: HYPINSFMETMR72X42X05-90D
A232: HYPINSFMLTPNK72X45X05-90D | B232: HYPINSFMMFGR72X45X05-90D | C232: HYPINSFMETMR72X45X05-90D
A233: HYPINSFMLTPNK72X48X05-90D | B233: HYPINSFMMFGR72X48X05-90D | C233: HYPINSFMETMR72X48X05-90D
A234: HYPINSFMLTPNK72X51X05-90D | B234: HYPINSFMMFGR72X51X05-90D | C234: HYPINSFMETMR72X51X05-90D
A235: HYPINSFMLTPNK72X54X05-90D | B235: HYPINSFMMFGR72X54X05-90D | C235: HYPINSFMETMR72X54X05-90D
...

Sheet Sheet3
A3: Row Labels | B3: Sum of 2
A4: 90D-HYP-INSPREE-BLOCK-72X30X05 | B4: 1
A5: 90D-HYP-INSPREE-BLOCK-72X30X06 | B5: 2
A6: 90D-HYP-INSPREE-BLOCK-72X36X05 | B6: 1
A7: 90D-HYP-INSPREE-BLOCK-72X36X06 | B7: 1
A8: 90D-HYP-INSPREE-BLOCK-72X42X05 | B8: 1
A9: 90D-HYP-INSPREE-BLOCK-72X48X05 | B9: 4
A10: 90D-HYP-INSPREE-BLOCK-72X48X06 | B10: 3
A11: 90D-HYP-INSPREE-BLOCK-72X60X06 | B11: 1
A12: 90D-HYP-INSPREE-BLOCK-72X72X05 | B12: 1
A13: 90D-HYP-INSPREE-BLOCK-75X36X06 | B13: 2
A14: 90D-HYP-INSPREE-BLOCK-75X48X05 | B14: 1
A15: 90D-HYP-INSPREE-BLOCK-75X48X06 | B15: 1
... A81: Grand Total | B81: 277

Sheet Sheet1
A1: 1 | B1: 2
A2: FOAMERA-FOAM-BLOCK-72X30X04 | B2: 1 | C2: 90D-HYP-INSPREE-BLOCK-72X30X05 | D2: 1
A3: 90D-HYP-INSPREE-BLOCK-72X60X06 | B3: 1 | C3: 90D-HYP-INSPREE-BLOCK-72X30X06 | D3: 2
A4: 90D-HYP-INSPREE-BLOCK-75X36X06 | B4: 2 | C4: 90D-HYP-INSPREE-BLOCK-72X36X05 | D4: 1
A5: 90D-HYP-INSPREE-BLOCK-75X60X05 | B5: 1 | C5: 90D-HYP-INSPREE-BLOCK-72X36X06 | D5: 1
A6: 90D-HYP-INSPREE-BLOCK-78X72X08 | B6: 1 | C6: 90D-HYP-INSPREE-BLOCK-72X42X05 | D6: 1
A7: 90D-HYP-INSPREE-BLOCK-75X66X05 | B7: 1 | C7: 90D-HYP-INSPREE-BLOCK-72X48X05 | D7: 4
A8: 90D-HYP-INSPREE-BLOCK-72X48X06 | B8: 1 | C8: 90D-HYP-INSPREE-BLOCK-72X48X06 | D8: 3
A9: 90D-HYP-INSPREE-BLOCK-75X72X06 | B9: 1 | C9: 90D-HYP-INSPREE-BLOCK-72X60X06 | D9: 1
A10: 90D-HYP-INSPREE-BLOCK-80X66X06 | B10: 2 | C10: 90D-HYP-INSPREE-BLOCK-72X72X05 | D10: 1
A11: 90D-HYP-INSPREE-BLOCK-72X48X06 | B11: 1 | C11: 90D-HYP-INSPREE-BLOCK-75X36X06 | D11: 2
A12: KOZY-BREEZE-FOAM-BLOCK-75X60X04 | B12: 1 | C12: 90D-HYP-INSPREE-BLOCK-75X48X05 | D12: 1
A13: KOZY-BREEZE-FOAM-BLOCK-78X72X04 | B13: 2 | C13: 90D-HYP-INSPREE-BLOCK-75X48X06 | D13: 1
... A78: KOZY-BREEZE-FOAM-BLOCK-75X48X04 | B78: 1 | C78: VISTA-BOND-FOAM-BLOCK-78X60X05 | D78: 8
A79: KOZY-BREEZE-FOAM-BLOCK-78X60X04 | B79: 1
A80: KOZY-BREEZE-FOAM-BLOCK-78X60X05 | B80: 1
A81: MEMORIO-FOAM-BLOCK-75X60X06 | B81: 1
A82: SPINE-SAFE-FOAM-BLOCK-78X57X08 | B82: 1
A83: SPINE-SAFE-FOAM-BLOCK-84X57X08 | B83: 2
A84: SPINE-SAFE-FOAM-BLOCK-84X69X08 | B84: 1
A85: VISTA-BOND-FOAM-BLOCK-72X30X04 | B85: 5
A86: VISTA-BOND-FOAM-BLOCK-72X36X04 | B86: 2
A87: VISTA-BOND-FOAM-BLOCK-72X36X05 | B87: 2
A88: VISTA-BOND-FOAM-BLOCK-72X45X04 | B88: 1
A89: VISTA-BOND-FOAM-BLOCK-72X45X05 | B89: 1
A90: VISTA-BOND-FOAM-BLOCK-75X36X04 | B90: 2
... A118: VISTA-BOND-FOAM-BLOCK-78X60X05 | B118: 2

Sheet MASTER
A1: SNO | B1: ITEM | C1: VARIETY | D1: BLOCK NAME | E1: UOM | F1: HEIGHT | G1: TOPLAYER FOAM | H1: HEIGHT
A2: 1 | B2: HYPFOMFMDB04 | C2: FOAMERA SOFT TOP | D2: FOAMERA-FOAM-BLOCK- | E2: NOS
A3: 2 | B3: HYPFOMFMDB05 | C3: FOAMERA SOFT TOP | D3: FOAMERA-FOAM-BLOCK- | E3: NOS
A4: 3 | B4: HYPFOMFMDB06 | C4: FOAMERA SOFT TOP | D4: FOAMERA-FOAM-BLOCK- | E4: NOS
A5: 4 | B5: HYPFOMFMMR04 | C5: FOAMERA SOFT TOP | D5: FOAMERA-FOAM-BLOCK- | E5: NOS
A6: 5 | B6: HYPFOMFMMR05 | C6: FOAMERA SOFT TOP | D6: FOAMERA-FOAM-BLOCK- | E6: NOS
A7: 6 | B7: HYPFOMFMMR06 | C7: FOAMERA SOFT TOP | D7: FOAMERA-FOAM-BLOCK- | E7: NOS
A8: 7 | B8: HYPINSFMMR04 | C8: INSPREE SOFT TOP | D8: 90D-HYP-INSPREE-BLOCK- | E8: NOS
A9: 8 | B9: HYPINSFMMR05 | C9: INSPREE SOFT TOP | D9: 90D-HYP-INSPREE-BLOCK- | E9: NOS
A10: 9 | B10: HYPINSFMMR06 | C10: INSPREE SOFT TOP | D10: 90D-HYP-INSPREE-BLOCK- | E10: NOS
A11: 10 | B11: HYPINSFMMR08 | C11: INSPREE SOFT TOP | D11: 90D-HYP-INSPREE-BLOCK- | E11: NOS
A12: 11 | B12: HYPINSFMDB04 | C12: INSPREE SOFT TOP | D12: 90D-HYP-INSPREE-BLOCK- | E12: NOS
A13: 12 | B13: HYPINSFMDB05 | C13: INSPREE SOFT TOP | D13: 90D-HYP-INSPREE-BLOCK- | E13: NOS
... A49: 48 | B49: HYPKBRZFMDB04 | C49: KOZY BREEZE | D49: KOZY-BREEZE-FOAM-BLOCK- | E49: NOS
A50: 49 | B50: HYPKBRZFMDB05 | C50: KOZY BREEZE | D50: KOZY-BREEZE-FOAM-BLOCK- | E50: NOS | G50: 15
A51: 50 | B51: HYPKBRZFMDB06 | C51: KOZY BREEZE | D51: KOZY-BREEZE-FOAM-BLOCK- | E51: NOS
A52: 51 | B52: HYPMEMFMOR05 | C52: MEMORIO SOFT | D52: MEMORIO-FOAM-BLOCK- | E52: NOS
A53: 52 | B53: HYPMEMFMOR06 | C53: MEMORIO SOFT | D53: MEMORIO-FOAM-BLOCK- | E53: NOS
A54: 53 | B54: HYPMEMFMOR08 | C54: MEMORIO SOFT | D54: MEMORIO-FOAM-BLOCK- | E54: NOS
A55: 54 | B55: HYPMEMFMVL05 | C55: MEMORIO SOFT | D55: MEMORIO-FOAM-BLOCK- | E55: NOS
A56: 55 | B56: HYPMEMFMVL06 | C56: MEMORIO SOFT | D56: MEMORIO-FOAM-BLOCK- | E56: NOS
A57: 56 | B57: HYPMEMFMVL08 | C57: MEMORIO SOFT | D57: MEMORIO-FOAM-BLOCK- | E57: NOS
A58: 57 | B58: HYPMULTFMGR05 | C58: MEMORIO ULTRA SOFT | D58: MEM-ULTRA-FOAM-BLOCK- | E58: NOS
A59: 58 | B59: HYPMULTFMGR06 | C59: MEMORIO ULTRA SOFT | D59: MEM-ULTRA-FOAM-BLOCK- | E59: NOS
A60: 59 | B60: HYPMULTFMGR08 | C60: MEMORIO ULTRA SOFT | D60: MEM-ULTRA-FOAM-BLOCK- | E60: NOS
A61: 60 | B61: HYPMULTFMDB05 | C61: MEMORIO ULTRA SOFT | D61: MEM-ULTRA-FOAM-BLOCK- | E61: NOS
A62: 61 | B62: HYPMULTFMDB06 | C62: MEMORIO ULTRA SOFT | D62: MEM-ULTRA-FOAM-BLOCK- | E62: NOS
... A78: 77 | B78: HYPSPSFMNB08 | C78: SPINE SAFE | D78: SPINE-SAFE-FOAM-BLOCK- | E78: NOS
B79: HYPSPSFMNB10 | C79: SPINE SAFE | D79: SPINE-SAFE-FOAM-BLOCK- | E79: NOS
A80: 78 | B80: HYPVISBND04 | C80: VISTA BOND | D80: VISTA-BOND-FOAM-BLOCK- | E80: NOS
A81: 79 | B81: HYPVISBND05 | C81: VISTA BOND | D81: VISTA-BOND-FOAM-BLOCK- | E81: NOS
A82: 80 | B82: HYPVISBND06 | C82: VISTA BOND | D82: VISTA-BOND-FOAM-BLOCK- | E82: NOS
A83: 81 | B83: HYPKOZBND04 | C83: KOZY BOND | D83: VISTA-BOND-FOAM-BLOCK- | E83: NOS
A84: 82 | B84: HYPKOZBND05 | C84: KOZY BOND | D84: VISTA-BOND-FOAM-BLOCK- | E84: NOS
A85: 83 | B85: HYPKOZBND06 | C85: KOZY BOND | D85: VISTA-BOND-FOAM-BLOCK- | E85: NOS
A86: 84 | B86: ORTHOBOND04 | C86: ORTHO BOND | D86: ORTHO-BOND-FOAM-BLOCK- | E86: NOS
A87: 85 | B87: ORTHOBOND05 | C87: ORTHO BOND | D87: ORTHO-BOND-FOAM-BLOCK- | E87: NOS
A88: 86 | B88: ORTHOBOND06 | C88: ORTHO BOND | D88: ORTHO-BOND-FOAM-BLOCK- | E88: NOS
A89: 87 | B89: CIRHVNMFCR05 | C89: HAVEN MEMORY FOAM | D89: HEAVEN-MEM-FOAM-BLOCK- | E89: NOS
A90: 88 | B90: CIRHVNMFCR06 | C90: HAVEN MEMORY FOAM | D90: HEAVEN-MEM-FOAM-BLOCK- | E90: NOS
...

Sheet FW
A1: S.No | B1: ITEM CODE | C1: UOM | D1: WEIGHT
A2: 1 | B2: 23D-ECO-FOAM-13X13X50MM | C2: KGS | D2: 0.125
A3: 2 | B3: 23D-ECO-FOAM-20X18X50MM | C3: KGS | D3: 0.267
A4: 3 | B4: 23D-ECO-FOAM-72X30X50MM | C4: KGS | D4: 1.603
A5: 4 | B5: 23D-ECO-FOAM-72X33X50MM | C5: KGS | D5: 1.763
A6: 5 | B6: 23D-ECO-FOAM-72X36X50MM | C6: KGS | D6: 1.923
A7: 6 | B7: 23D-ECO-FOAM-72X39X50MM | C7: KGS | D7: 2.083
A8: 7 | B8: 23D-ECO-FOAM-72X42X50MM | C8: KGS | D8: 2.244
A9: 8 | B9: 23D-ECO-FOAM-72X45X50MM | C9: KGS | D9: 2.404
A10: 9 | B10: 23D-ECO-FOAM-72X48X50MM | C10: KGS | D10: 2.564
A11: 10 | B11: 23D-ECO-FOAM-72X51X50MM | C11: KGS | D11: 2.724
A12: 11 | B12: 23D-ECO-FOAM-72X54X50MM | C12: KGS | D12: 2.885
A13: 12 | B13: 23D-ECO-FOAM-72X57X50MM | C13: KGS | D13: 3.045
... A1654: 1653 | B1654: 40D-MDI-MEM-FOAM-13X13X25MM | C1654: KGS | D1654: 0.109

Sheet INPUT
A1: SL.NO | B1: ITEM CODE | C1: QTY
A2: 1 | B2: HYPMIRFMDB72X36X04-ECOM | C2: 1
A3: 2 | B3: HYPMIRFMDB72X30X04-ECOM | C3: 1
A4: 3
A5: 4
A6: 5
A7: 6
A8: 7
A9: 8
A10: 9
A11: 10
A12: 11
A13: 12
A14: 13
A15: 14
... A22: 21
A23: 22 | B23: SKSGFM72X48X06
A24: 23
A25: 24
A26: 25
A27: 26
A28: 27
A29: 28
A30: 29
A31: 30
A32: 31
A33: 32
A34: 33
A35: 34
... A101: 100

Sheet Sheet4
A3: Row Labels | B3: Sum of QTY | G3: 90D-HYP-INS-ET-BLOCK-72X48X05 | H3: 2
B4: 2 | G4: 90D-HYP-INS-ET-BLOCK-75X60X06 | H4: 17
A5: (blank) | G5: 90D-HYP-INS-ET-BLOCK-78X72X05 | H5: 2
A6: 25D-HELIXA-FOAM-72X48X119MM | B6: 0 | G6: 90D-HYP-INS-ET-BLOCK-78X72X08 | H6: 5
A7: Grand Total | B7: 2 | G7: 90D-HYP-INSPREE-BLOCK-72X48X06 | H7: 5
G8: 90D-HYP-INSPREE-BLOCK-75X60X05 | H8: 4
G9: 90D-HYP-INSPREE-BLOCK-75X60X06 | H9: 11
G10: 90D-HYP-INSPREE-BLOCK-75X72X05 | H10: 4
G11: 90D-HYP-INSPREE-BLOCK-75X36X05 | H11: 3
G12: 90D-HYP-INSPREE-BLOCK-78X60X05 | H12: 7
G13: FURNO-FOAM-BLOCK-72X36X04 | H13: 4
G14: 90D-HYP-INSPREE-BLOCK-72X30X06 | H14: 1
G15: 90D-HYP-INSPREE-BLOCK-72X36X06 | H15: 1
G16: 90D-HYP-INSPREE-BLOCK-72X48X05 | H16: 1
G17: 90D-HYP-INSPREE-BLOCK-75X48X05 | H17: 1
G18: 90D-HYP-INSPREE-BLOCK-78X60X08 | H18: 2
G19: 90D-HYP-INSPREE-BLOCK-72X42X05 | H19: 1
... G162: VISTA-FOAM-FOAM-BLOCK-72X45X05 | H162: 1

Sheet STEP-1
A1: SNO | B1: 1 | C1: 2 | D1: 3 | E1: 4 | F1: 5 | G1: L | H1: W | I1: H | J1: L1 | K1: W1 | L1: STD-L | M1: STD-W | N1: UNIT SIZE | O1: STD ITEMCODE | P1: VARIETY | Q1: QTY | R1: Column1 | S1: VARIETY | T1: BLOCK NAME | U1: ITEM CODE | V1: FOAM WEIGHT | W1: QTY
A2: =ROW()-1 -> 1 | B2: =LEFT(Table13[[#This Row],[ITEM CODE]],MIN(FIND({0,1,2,3,4,5,6,7,8,9},Table13[[#This Row],[ITEM CODE]]&"0123456789"))-1) -> HYPMIRFMDB | C2: =SUBSTITUTE(Table13[[#This Row],[ITEM CODE]],B2,"") -> 72X36X04-ECOM | D2: =IFERROR(LEFT(C2,FIND("-",C2)-1),C2) -> 72X36X04 | E2: =IFERROR(SEARCH("X",D2),"") -> 3 | F2: =IFERROR(SEARCH("X",D2,E2+1),"") -> 6 | G2: =IFERROR(LEFT(C2,SEARCH("x",C2)-1),"") -> 72 | H2: =IFERROR(MID(D2,E2+1,F2-E2-1),"") -> 36 | I2: =IFERROR(MID(D2,F2+1,20),"") -> 04 | J2: =IFERROR(IF(Table2[[#This Row],[L]]<Table2[[#This Row],[W]],Table2[[#This Row],[W]],Table2[[#This Row],[L]]),"") -> 72 | K2: =IF(Table2[[#This Row],[L]]<Table2[[#This Row],[W]],Table2[[#This Row],[L]],Table2[[#This Row],[W]]) -> 36 | L2: =IFERROR(IF(J2="","",IF(VALUE(J2)>=VALUE(K2),IF(OR(VALUE(J2)=13,VALUE(J2)=20,VALUE(J2)=72,VALUE(J2)=75,VALUE(J2)=78,VALUE(J2)=80,VALUE(J2)=84),J2,IF(VALUE(J2)<72,72,IF(VALUE(J2)<75,75,IF(VALUE(J2)<78,78,IF(VALUE(J2)<80,80,IF(VALUE(J2)<84,84,IF(VALUE(J2)>84,84,""""))))))))),0) -> 72 | M2: =IF(H2="","",IF(VALUE(J2)>=VALUE(K2),IF(OR(VALUE(K2)=13,VALUE(K2)=18,VALUE(K2)=18,VALUE(K2)=30,VALUE(K2)=33,VALUE(K2)=36,VALUE(K2)=39,VALUE(K2)=42,VALUE(K2)=45,VALUE(K2)=48,VALUE(K2)=51,VALUE(K2)=54,VALUE(K2)=57,VALUE(K2)=60,VALUE(K2)=63,VALUE(K2)=66,VALUE(K2)=69,VALUE(K2)=72),K2,IF(VALUE(K2)<30,30,IF(VALUE(K2)<33,33,IF(VALUE(H2)<36,36,IF(VALUE(H2)<39,39,IF(VALUE(H2)<42,42,IF(VALUE(H2)<45,45,IF(VALUE(H2)<48,48,IF(VALUE(H2)<51,51,IF(VALUE(H2)<54,54,IF(VALUE(H2)<57,57,IF(VALUE(K2)<60,60,IF(VALUE(K2)<63,63,IF(VALUE(K2)<66,66,IF(VALUE(K2)<69,69,IF(VALUE(K2)<72,72,IF(VALUE(K2)>72,72,""""))))))))))))))))))) -> 36 | N2: =IFERROR(CONCATENATE(L2,"X",M2,"X",I2),"") -> 72X36X04 | O2: =IFERROR(CONCATENATE(B2,N2),"") -> HYPMIRFMDB72X36X04 | P2: =+CONCATENATE(Table2[[#This Row],[1]],Table2[[#This Row],[H]]) -> HYPMIRFMDB04 | Q2: =IFERROR(Table13[[#This Row],[QTY]],"") -> 1 | S2: =+Table2[[#This Row],[VARIETY]] -> HYPMIRFMDB04 | T2: =IFERROR(VLOOKUP(Table9[[#This Row],[VARIETY]],MASTER!B:D,3,0),"") | U2: =IFERROR(IF(OR(S2=MASTER!$B$95,S2=MASTER!$B$96,S2=MASTER!$B$97,S2=MASTER!$B$98,S2=MASTER!$B$102,S2=MASTER!$B$103,S2=MASTER!$B$99,S2=MASTER!$B$100,S2=MASTER!$B$101,S2=MASTER!$B$104,S2=MASTER!$B$105,S2=MASTER!$B$106,S2=MASTER!$B$107,S2=MASTER!$B$108,S2=MASTER!$B$109),(CONCATENATE(VLOOKUP(S2,MASTER!$B:$D,3,0),L2,"X",M2,"X",VLOOKUP(S2,MASTER!$B:$F,5,0))),(CONCATENATE(VLOOKUP(S2,MASTER!$B:$D,3,0),N2))),"") | V2: =IFERROR(VLOOKUP(Table9[[#This Row],[ITEM CODE]],FW!$B:$D,3,0),"") | W2: =IF(OR(S2=MASTER!$B$95,S2=MASTER!$B$96,S2=MASTER!$B$97,S2=MASTER!$B$98,S2=MASTER!$B$102,S2=MASTER!$B$103,S2=MASTER!$B$99,S2=MASTER!$B$100,S2=MASTER!$B$101,S2=MASTER!$B$104,S2=MASTER!$B$105,S2=MASTER!$B$106,S2=MASTER!$B$107,S2=MASTER!$B$108,S2=MASTER!$B$109),(Q2*V2),Q2) -> 1
A3: =ROW()-1 -> 2 | B3: =LEFT(Table13[[#This Row],[ITEM CODE]],MIN(FIND({0,1,2,3,4,5,6,7,8,9},Table13[[#This Row],[ITEM CODE]]&"0123456789"))-1) -> HYPMIRFMDB | C3: =SUBSTITUTE(Table13[[#This Row],[ITEM CODE]],B3,"") -> 72X30X04-ECOM | D3: =IFERROR(LEFT(C3,FIND("-",C3)-1),C3) -> 72X30X04 | E3: =IFERROR(SEARCH("X",D3),"") -> 3 | F3: =IFERROR(SEARCH("X",D3,E3+1),"") -> 6 | G3: =IFERROR(LEFT(C3,SEARCH("x",C3)-1),"") -> 72 | H3: =IFERROR(MID(D3,E3+1,F3-E3-1),"") -> 30 | I3: =IFERROR(MID(D3,F3+1,20),"") -> 04 | J3: =IFERROR(IF(Table2[[#This Row],[L]]<Table2[[#This Row],[W]],Table2[[#This Row],[W]],Table2[[#This Row],[L]]),"") -> 72 | K3: =IF(Table2[[#This Row],[L]]<Table2[[#This Row],[W]],Table2[[#This Row],[L]],Table2[[#This Row],[W]]) -> 30 | L3: =IFERROR(IF(J3="","",IF(VALUE(J3)>=VALUE(K3),IF(OR(VALUE(J3)=13,VALUE(J3)=20,VALUE(J3)=72,VALUE(J3)=75,VALUE(J3)=78,VALUE(J3)=80,VALUE(J3)=84),J3,IF(VALUE(J3)<72,72,IF(VALUE(J3)<75,75,IF(VALUE(J3)<78,78,IF(VALUE(J3)<80,80,IF(VALUE(J3)<84,84,IF(VALUE(J3)>84,84,""""))))))))),0) -> 72 | M3: =IF(H3="","",IF(VALUE(J3)>=VALUE(K3),IF(OR(VALUE(K3)=13,VALUE(K3)=18,VALUE(K3)=18,VALUE(K3)=30,VALUE(K3)=33,VALUE(K3)=36,VALUE(K3)=39,VALUE(K3)=42,VALUE(K3)=45,VALUE(K3)=48,VALUE(K3)=51,VALUE(K3)=54,VALUE(K3)=57,VALUE(K3)=60,VALUE(K3)=63,VALUE(K3)=66,VALUE(K3)=69,VALUE(K3)=72),K3,IF(VALUE(K3)<30,30,IF(VALUE(K3)<33,33,IF(VALUE(H3)<36,36,IF(VALUE(H3)<39,39,IF(VALUE(H3)<42,42,IF(VALUE(H3)<45,45,IF(VALUE(H3)<48,48,IF(VALUE(H3)<51,51,IF(VALUE(H3)<54,54,IF(VALUE(H3)<57,57,IF(VALUE(K3)<60,60,IF(VALUE(K3)<63,63,IF(VALUE(K3)<66,66,IF(VALUE(K3)<69,69,IF(VALUE(K3)<72,72,IF(VALUE(K3)>72,72,""""))))))))))))))))))) -> 30 | N3: =IFERROR(CONCATENATE(L3,"X",M3,"X",I3),"") -> 72X30X04 | O3: =IFERROR(CONCATENATE(B3,N3),"") -> HYPMIRFMDB72X30X04 | P3: =+CONCATENATE(Table2[[#This Row],[1]],Table2[[#This Row],[H]]) -> HYPMIRFMDB04 | Q3: =IFERROR(Table13[[#This Row],[QTY]],"") -> 1 | S3: =+Table2[[#This Row],[VARIETY]] -> HYPMIRFMDB04 | T3: =IFERROR(VLOOKUP(Table9[[#This Row],[VARIETY]],MASTER!B:D,3,0),"") | U3: =IFERROR(IF(OR(S3=MASTER!$B$95,S3=MASTER!$B$96,S3=MASTER!$B$97,S3=MASTER!$B$98,S3=MASTER!$B$102,S3=MASTER!$B$103,S3=MASTER!$B$99,S3=MASTER!$B$100,S3=MASTER!$B$101,S3=MASTER!$B$104,S3=MASTER!$B$105,S3=MASTER!$B$106,S3=MASTER!$B$107,S3=MASTER!$B$108,S3=MASTER!$B$109),(CONCATENATE(VLOOKUP(S3,MASTER!$B:$D,3,0),L3,"X",M3,"X",VLOOKUP(S3,MASTER!$B:$F,5,0))),(CONCATENATE(VLOOKUP(S3,MASTER!$B:$D,3,0),N3))),"") | V3: =IFERROR(VLOOKUP(Table9[[#This Row],[ITEM CODE]],FW!$B:$D,3,0),"") | W3: =IF(OR(S3=MASTER!$B$95,S3=MASTER!$B$96,S3=MASTER!$B$97,S3=MASTER!$B$98,S3=MASTER!$B$102,S3=MASTER!$B$103,S3=MASTER!$B$99,S3=MASTER!$B$100,S3=MASTER!$B$101,S3=MASTER!$B$104,S3=MASTER!$B$105,S3=MASTER!$B$106,S3=MASTER!$B$107,S3=MASTER!$B$108,S3=MASTER!$B$109),(Q3*V3),Q3) -> 1
A4: =ROW()-1 -> 3 | B4: =LEFT(Table13[[#This Row],[ITEM CODE]],MIN(FIND({0,1,2,3,4,5,6,7,8,9},Table13[[#This Row],[ITEM CODE]]&"0123456789"))-1) | C4: =SUBSTITUTE(Table13[[#This Row],[ITEM CODE]],B4,"") | D4: =IFERROR(LEFT(C4,FIND("-",C4)-1),C4) | E4: =IFERROR(SEARCH("X",D4),"") | F4: =IFERROR(SEARCH("X",D4,E4+1),"") | G4: =IFERROR(LEFT(C4,SEARCH("x",C4)-1),"") | H4: =IFERROR(MID(D4,E4+1,F4-E4-1),"") | I4: =IFERROR(MID(D4,F4+1,20),"") | J4: =IFERROR(IF(Table2[[#This Row],[L]]<Table2[[#This Row],[W]],Table2[[#This Row],[W]],Table2[[#This Row],[L]]),"") | K4: =IF(Table2[[#This Row],[L]]<Table2[[#This Row],[W]],Table2[[#This Row],[L]],Table2[[#This Row],[W]]) | L4: =IFERROR(IF(J4="","",IF(VALUE(J4)>=VALUE(K4),IF(OR(VALUE(J4)=13,VALUE(J4)=20,VALUE(J4)=72,VALUE(J4)=75,VALUE(J4)=78,VALUE(J4)=80,VALUE(J4)=84),J4,IF(VALUE(J4)<72,72,IF(VALUE(J4)<75,75,IF(VALUE(J4)<78,78,IF(VALUE(J4)<80,80,IF(VALUE(J4)<84,84,IF(VALUE(J4)>84,84,""""))))))))),0) | M4: =IF(H4="","",IF(VALUE(J4)>=VALUE(K4),IF(OR(VALUE(K4)=13,VALUE(K4)=18,VALUE(K4)=18,VALUE(K4)=30,VALUE(K4)=33,VALUE(K4)=36,VALUE(K4)=39,VALUE(K4)=42,VALUE(K4)=45,VALUE(K4)=48,VALUE(K4)=51,VALUE(K4)=54,VALUE(K4)=57,VALUE(K4)=60,VALUE(K4)=63,VALUE(K4)=66,VALUE(K4)=69,VALUE(K4)=72),K4,IF(VALUE(K4)<30,30,IF(VALUE(K4)<33,33,IF(VALUE(H4)<36,36,IF(VALUE(H4)<39,39,IF(VALUE(H4)<42,42,IF(VALUE(H4)<45,45,IF(VALUE(H4)<48,48,IF(VALUE(H4)<51,51,IF(VALUE(H4)<54,54,IF(VALUE(H4)<57,57,IF(VALUE(K4)<60,60,IF(VALUE(K4)<63,63,IF(VALUE(K4)<66,66,IF(VALUE(K4)<69,69,IF(VALUE(K4)<72,72,IF(VALUE(K4)>72,72,""""))))))))))))))))))) | N4: =IFERROR(CONCATENATE(L4,"X",M4,"X",I4),"") -> XX | O4: =IFERROR(CONCATENATE(B4,N4),"") -> XX | P4: =+CONCATENATE(Table2[[#This Row],[1]],Table2[[#This Row],[H]]) | Q4: =IFERROR(Table13[[#This Row],[QTY]],"") -> 0 | S4: =+Table2[[#This Row],[VARIETY]] | T4: =IFERROR(VLOOKUP(Table9[[#This Row],[VARIETY]],MASTER!B:D,3,0),"") | U4: =IFERROR(IF(OR(S4=MASTER!$B$95,S4=MASTER!$B$96,S4=MASTER!$B$97,S4=MASTER!$B$98,S4=MASTER!$B$102,S4=MASTER!$B$103,S4=MASTER!$B$99,S4=MASTER!$B$100,S4=MASTER!$B$101,S4=MASTER!$B$104,S4=MASTER!$B$105,S4=MASTER!$B$106,S4=MASTER!$B$107,S4=MASTER!$B$108,S4=MASTER!$B$109),(CONCATENATE(VLOOKUP(S4,MASTER!$B:$D,3,0),L4,"X",M4,"X",VLOOKUP(S4,MASTER!$B:$F,5,0))),(CONCATENATE(VLOOKUP(S4,MASTER!$B:$D,3,0),N4))),"") | V4: =IFERROR(VLOOKUP(Table9[[#This Row],[ITEM CODE]],FW!$B:$D,3,0),"") | W4: =IF(OR(S4=MASTER!$B$95,S4=MASTER!$B$96,S4=MASTER!$B$97,S4=MASTER!$B$98,S4=MASTER!$B$102,S4=MASTER!$B$103,S4=MASTER!$B$99,S4=MASTER!$B$100,S4=MASTER!$B$101,S4=MASTER!$B$104,S4=MASTER!$B$105,S4=MASTER!$B$106,S4=MASTER!$B$107,S4=MASTER!$B$108,S4=MASTER!$B$109),(Q4*V4),Q4) -> 0
A5: =ROW()-1 -> 4 | B5: =LEFT(Table13[[#This Row],[ITEM CODE]],MIN(FIND({0,1,2,3,4,5,6,7,8,9},Table13[[#This Row],[ITEM CODE]]&"0123456789"))-1) | C5: =SUBSTITUTE(Table13[[#This Row],[ITEM CODE]],B5,"") | D5: =IFERROR(LEFT(C5,FIND("-",C5)-1),C5) | E5: =IFERROR(SEARCH("X",D5),"") | F5: =IFERROR(SEARCH("X",D5,E5+1),"") | G5: =IFERROR(LEFT(C5,SEARCH("x",C5)-1),"") | H5: =IFERROR(MID(D5,E5+1,F5-E5-1),"") | I5: =IFERROR(MID(D5,F5+1,20),"") | J5: =IFERROR(IF(Table2[[#This Row],[L]]<Table2[[#This Row],[W]],Table2[[#This Row],[W]],Table2[[#This Row],[L]]),"") | K5: =IF(Table2[[#This Row],[L]]<Table2[[#This Row],[W]],Table2[[#This Row],[L]],Table2[[#This Row],[W]]) | L5: =IFERROR(IF(J5="","",IF(VALUE(J5)>=VALUE(K5),IF(OR(VALUE(J5)=13,VALUE(J5)=20,VALUE(J5)=72,VALUE(J5)=75,VALUE(J5)=78,VALUE(J5)=80,VALUE(J5)=84),J5,IF(VALUE(J5)<72,72,IF(VALUE(J5)<75,75,IF(VALUE(J5)<78,78,IF(VALUE(J5)<80,80,IF(VALUE(J5)<84,84,IF(VALUE(J5)>84,84,""""))))))))),0) | M5: =IF(H5="","",IF(VALUE(J5)>=VALUE(K5),IF(OR(VALUE(K5)=13,VALUE(K5)=18,VALUE(K5)=18,VALUE(K5)=30,VALUE(K5)=33,VALUE(K5)=36,VALUE(K5)=39,VALUE(K5)=42,VALUE(K5)=45,VALUE(K5)=48,VALUE(K5)=51,VALUE(K5)=54,VALUE(K5)=57,VALUE(K5)=60,VALUE(K5)=63,VALUE(K5)=66,VALUE(K5)=69,VALUE(K5)=72),K5,IF(VALUE(K5)<30,30,IF(VALUE(K5)<33,33,IF(VALUE(H5)<36,36,IF(VALUE(H5)<39,39,IF(VALUE(H5)<42,42,IF(VALUE(H5)<45,45,IF(VALUE(H5)<48,48,IF(VALUE(H5)<51,51,IF(VALUE(H5)<54,54,IF(VALUE(H5)<57,57,IF(VALUE(K5)<60,60,IF(VALUE(K5)<63,63,IF(VALUE(K5)<66,66,IF(VALUE(K5)<69,69,IF(VALUE(K5)<72,72,IF(VALUE(K5)>72,72,""""))))))))))))))))))) | N5: =IFERROR(CONCATENATE(L5,"X",M5,"X",I5),"") -> XX | O5: =IFERROR(CONCATENATE(B5,N5),"") -> XX | P5: =+CONCATENATE(Table2[[#This Row],[1]],Table2[[#This Row],[H]]) | Q5: =IFERROR(Table13[[#This Row],[QTY]],"") -> 0 | S5: =+Table2[[#This Row],[VARIETY]] | T5: =IFERROR(VLOOKUP(Table9[[#This Row],[VARIETY]],MASTER!B:D,3,0),"") | U5: =IFERROR(IF(OR(S5=MASTER!$B$95,S5=MASTER!$B$96,S5=MASTER!$B$97,S5=MASTER!$B$98,S5=MASTER!$B$102,S5=MASTER!$B$103,S5=MASTER!$B$99,S5=MASTER!$B$100,S5=MASTER!$B$101,S5=MASTER!$B$104,S5=MASTER!$B$105,S5=MASTER!$B$106,S5=MASTER!$B$107,S5=MASTER!$B$108,S5=MASTER!$B$109),(CONCATENATE(VLOOKUP(S5,MASTER!$B:$D,3,0),L5,"X",M5,"X",VLOOKUP(S5,MASTER!$B:$F,5,0))),(CONCATENATE(VLOOKUP(S5,MASTER!$B:$D,3,0),N5))),"") | V5: =IFERROR(VLOOKUP(Table9[[#This Row],[ITEM CODE]],FW!$B:$D,3,0),"") | W5: =IF(OR(S5=MASTER!$B$95,S5=MASTER!$B$96,S5=MASTER!$B$97,S5=MASTER!$B$98,S5=MASTER!$B$102,S5=MASTER!$B$103,S5=MASTER!$B$99,S5=MASTER!$B$100,S5=MASTER!$B$101,S5=MASTER!$B$104,S5=MASTER!$B$105,S5=MASTER!$B$106,S5=MASTER!$B$107,S5=MASTER!$B$108,S5=MASTER!$B$109),(Q5*V5),Q5) -> 0
A6: =ROW()-1 -> 5 | B6: =LEFT(Table13[[#This Row],[ITEM CODE]],MIN(FIND({0,1,2,3,4,5,6,7,8,9},Table13[[#This Row],[ITEM CODE]]&"0123456789"))-1) | C6: =SUBSTITUTE(Table13[[#This Row],[ITEM CODE]],B6,"") | D6: =IFERROR(LEFT(C6,FIND("-",C6)-1),C6) | E6: =IFERROR(SEARCH("X",D6),"") | F6: =IFERROR(SEARCH("X",D6,E6+1),"") | G6: =IFERROR(LEFT(C6,SEARCH("x",C6)-1),"") | H6: =IFERROR(MID(D6,E6+1,F6-E6-1),"") | I6: =IFERROR(MID(D6,F6+1,20),"") | J6: =IFERROR(IF(Table2[[#This Row],[L]]<Table2[[#This Row],[W]],Table2[[#This Row],[W]],Table2[[#This Row],[L]]),"") | K6: =IF(Table2[[#This Row],[L]]<Table2[[#This Row],[W]],Table2[[#This Row],[L]],Table2[[#This Row],[W]]) | L6: =IFERROR(IF(J6="","",IF(VALUE(J6)>=VALUE(K6),IF(OR(VALUE(J6)=13,VALUE(J6)=20,VALUE(J6)=72,VALUE(J6)=75,VALUE(J6)=78,VALUE(J6)=80,VALUE(J6)=84),J6,IF(VALUE(J6)<72,72,IF(VALUE(J6)<75,75,IF(VALUE(J6)<78,78,IF(VALUE(J6)<80,80,IF(VALUE(J6)<84,84,IF(VALUE(J6)>84,84,""""))))))))),0) | M6: =IF(H6="","",IF(VALUE(J6)>=VALUE(K6),IF(OR(VALUE(K6)=13,VALUE(K6)=18,VALUE(K6)=18,VALUE(K6)=30,VALUE(K6)=33,VALUE(K6)=36,VALUE(K6)=39,VALUE(K6)=42,VALUE(K6)=45,VALUE(K6)=48,VALUE(K6)=51,VALUE(K6)=54,VALUE(K6)=57,VALUE(K6)=60,VALUE(K6)=63,VALUE(K6)=66,VALUE(K6)=69,VALUE(K6)=72),K6,IF(VALUE(K6)<30,30,IF(VALUE(K6)<33,33,IF(VALUE(H6)<36,36,IF(VALUE(H6)<39,39,IF(VALUE(H6)<42,42,IF(VALUE(H6)<45,45,IF(VALUE(H6)<48,48,IF(VALUE(H6)<51,51,IF(VALUE(H6)<54,54,IF(VALUE(H6)<57,57,IF(VALUE(K6)<60,60,IF(VALUE(K6)<63,63,IF(VALUE(K6)<66,66,IF(VALUE(K6)<69,69,IF(VALUE(K6)<72,72,IF(VALUE(K6)>72,72,""""))))))))))))))))))) | N6: =IFERROR(CONCATENATE(L6,"X",M6,"X",I6),"") -> XX | O6: =IFERROR(CONCATENATE(B6,N6),"") -> XX | P6: =+CONCATENATE(Table2[[#This Row],[1]],Table2[[#This Row],[H]]) | Q6: =IFERROR(Table13[[#This Row],[QTY]],"") -> 0 | S6: =+Table2[[#This Row],[VARIETY]] | T6: =IFERROR(VLOOKUP(Table9[[#This Row],[VARIETY]],MASTER!B:D,3,0),"") | U6: =IFERROR(IF(OR(S6=MASTER!$B$95,S6=MASTER!$B$96,S6=MASTER!$B$97,S6=MASTER!$B$98,S6=MASTER!$B$102,S6=MASTER!$B$103,S6=MASTER!$B$99,S6=MASTER!$B$100,S6=MASTER!$B$101,S6=MASTER!$B$104,S6=MASTER!$B$105,S6=MASTER!$B$106,S6=MASTER!$B$107,S6=MASTER!$B$108,S6=MASTER!$B$109),(CONCATENATE(VLOOKUP(S6,MASTER!$B:$D,3,0),L6,"X",M6,"X",VLOOKUP(S6,MASTER!$B:$F,5,0))),(CONCATENATE(VLOOKUP(S6,MASTER!$B:$D,3,0),N6))),"") | V6: =IFERROR(VLOOKUP(Table9[[#This Row],[ITEM CODE]],FW!$B:$D,3,0),"") | W6: =IF(OR(S6=MASTER!$B$95,S6=MASTER!$B$96,S6=MASTER!$B$97,S6=MASTER!$B$98,S6=MASTER!$B$102,S6=MASTER!$B$103,S6=MASTER!$B$99,S6=MASTER!$B$100,S6=MASTER!$B$101,S6=MASTER!$B$104,S6=MASTER!$B$105,S6=MASTER!$B$106,S6=MASTER!$B$107,S6=MASTER!$B$108,S6=MASTER!$B$109),(Q6*V6),Q6) -> 0
A7: =ROW()-1 -> 6 | B7: =LEFT(Table13[[#This Row],[ITEM CODE]],MIN(FIND({0,1,2,3,4,5,6,7,8,9},Table13[[#This Row],[ITEM CODE]]&"0123456789"))-1) | C7: =SUBSTITUTE(Table13[[#This Row],[ITEM CODE]],B7,"") | D7: =IFERROR(LEFT(C7,FIND("-",C7)-1),C7) | E7: =IFERROR(SEARCH("X",D7),"") | F7: =IFERROR(SEARCH("X",D7,E7+1),"") | G7: =IFERROR(LEFT(C7,SEARCH("x",C7)-1),"") | H7: =IFERROR(MID(D7,E7+1,F7-E7-1),"") | I7: =IFERROR(MID(D7,F7+1,20),"") | J7: =IFERROR(IF(Table2[[#This Row],[L]]<Table2[[#This Row],[W]],Table2[[#This Row],[W]],Table2[[#This Row],[L]]),"") | K7: =IF(Table2[[#This Row],[L]]<Table2[[#This Row],[W]],Table2[[#This Row],[L]],Table2[[#This Row],[W]]) | L7: =IFERROR(IF(J7="","",IF(VALUE(J7)>=VALUE(K7),IF(OR(VALUE(J7)=13,VALUE(J7)=20,VALUE(J7)=72,VALUE(J7)=75,VALUE(J7)=78,VALUE(J7)=80,VALUE(J7)=84),J7,IF(VALUE(J7)<72,72,IF(VALUE(J7)<75,75,IF(VALUE(J7)<78,78,IF(VALUE(J7)<80,80,IF(VALUE(J7)<84,84,IF(VALUE(J7)>84,84,""""))))))))),0) | M7: =IF(H7="","",IF(VALUE(J7)>=VALUE(K7),IF(OR(VALUE(K7)=13,VALUE(K7)=18,VALUE(K7)=18,VALUE(K7)=30,VALUE(K7)=33,VALUE(K7)=36,VALUE(K7)=39,VALUE(K7)=42,VALUE(K7)=45,VALUE(K7)=48,VALUE(K7)=51,VALUE(K7)=54,VALUE(K7)=57,VALUE(K7)=60,VALUE(K7)=63,VALUE(K7)=66,VALUE(K7)=69,VALUE(K7)=72),K7,IF(VALUE(K7)<30,30,IF(VALUE(K7)<33,33,IF(VALUE(H7)<36,36,IF(VALUE(H7)<39,39,IF(VALUE(H7)<42,42,IF(VALUE(H7)<45,45,IF(VALUE(H7)<48,48,IF(VALUE(H7)<51,51,IF(VALUE(H7)<54,54,IF(VALUE(H7)<57,57,IF(VALUE(K7)<60,60,IF(VALUE(K7)<63,63,IF(VALUE(K7)<66,66,IF(VALUE(K7)<69,69,IF(VALUE(K7)<72,72,IF(VALUE(K7)>72,72,""""))))))))))))))))))) | N7: =IFERROR(CONCATENATE(L7,"X",M7,"X",I7),"") -> XX | O7: =IFERROR(CONCATENATE(B7,N7),"") -> XX | P7: =+CONCATENATE(Table2[[#This Row],[1]],Table2[[#This Row],[H]]) | Q7: =IFERROR(Table13[[#This Row],[QTY]],"") -> 0 | S7: =+Table2[[#This Row],[VARIETY]] | T7: =IFERROR(VLOOKUP(Table9[[#This Row],[VARIETY]],MASTER!B:D,3,0),"") | U7: =IFERROR(IF(OR(S7=MASTER!$B$95,S7=MASTER!$B$96,S7=MASTER!$B$97,S7=MASTER!$B$98,S7=MASTER!$B$102,S7=MASTER!$B$103,S7=MASTER!$B$99,S7=MASTER!$B$100,S7=MASTER!$B$101,S7=MASTER!$B$104,S7=MASTER!$B$105,S7=MASTER!$B$106,S7=MASTER!$B$107,S7=MASTER!$B$108,S7=MASTER!$B$109),(CONCATENATE(VLOOKUP(S7,MASTER!$B:$D,3,0),L7,"X",M7,"X",VLOOKUP(S7,MASTER!$B:$F,5,0))),(CONCATENATE(VLOOKUP(S7,MASTER!$B:$D,3,0),N7))),"") | V7: =IFERROR(VLOOKUP(Table9[[#This Row],[ITEM CODE]],FW!$B:$D,3,0),"") | W7: =IF(OR(S7=MASTER!$B$95,S7=MASTER!$B$96,S7=MASTER!$B$97,S7=MASTER!$B$98,S7=MASTER!$B$102,S7=MASTER!$B$103,S7=MASTER!$B$99,S7=MASTER!$B$100,S7=MASTER!$B$101,S7=MASTER!$B$104,S7=MASTER!$B$105,S7=MASTER!$B$106,S7=MASTER!$B$107,S7=MASTER!$B$108,S7=MASTER!$B$109),(Q7*V7),Q7) -> 0
A8: =ROW()-1 -> 7 | B8: =LEFT(Table13[[#This Row],[ITEM CODE]],MIN(FIND({0,1,2,3,4,5,6,7,8,9},Table13[[#This Row],[ITEM CODE]]&"0123456789"))-1) | C8: =SUBSTITUTE(Table13[[#This Row],[ITEM CODE]],B8,"") | D8: =IFERROR(LEFT(C8,FIND("-",C8)-1),C8) | E8: =IFERROR(SEARCH("X",D8),"") | F8: =IFERROR(SEARCH("X",D8,E8+1),"") | G8: =IFERROR(LEFT(C8,SEARCH("x",C8)-1),"") | H8: =IFERROR(MID(D8,E8+1,F8-E8-1),"") | I8: =IFERROR(MID(D8,F8+1,20),"") | J8: =IFERROR(IF(Table2[[#This Row],[L]]<Table2[[#This Row],[W]],Table2[[#This Row],[W]],Table2[[#This Row],[L]]),"") | K8: =IF(Table2[[#This Row],[L]]<Table2[[#This Row],[W]],Table2[[#This Row],[L]],Table2[[#This Row],[W]]) | L8: =IFERROR(IF(J8="","",IF(VALUE(J8)>=VALUE(K8),IF(OR(VALUE(J8)=13,VALUE(J8)=20,VALUE(J8)=72,VALUE(J8)=75,VALUE(J8)=78,VALUE(J8)=80,VALUE(J8)=84),J8,IF(VALUE(J8)<72,72,IF(VALUE(J8)<75,75,IF(VALUE(J8)<78,78,IF(VALUE(J8)<80,80,IF(VALUE(J8)<84,84,IF(VALUE(J8)>84,84,""""))))))))),0) | M8: =IF(H8="","",IF(VALUE(J8)>=VALUE(K8),IF(OR(VALUE(K8)=13,VALUE(K8)=18,VALUE(K8)=18,VALUE(K8)=30,VALUE(K8)=33,VALUE(K8)=36,VALUE(K8)=39,VALUE(K8)=42,VALUE(K8)=45,VALUE(K8)=48,VALUE(K8)=51,VALUE(K8)=54,VALUE(K8)=57,VALUE(K8)=60,VALUE(K8)=63,VALUE(K8)=66,VALUE(K8)=69,VALUE(K8)=72),K8,IF(VALUE(K8)<30,30,IF(VALUE(K8)<33,33,IF(VALUE(H8)<36,36,IF(VALUE(H8)<39,39,IF(VALUE(H8)<42,42,IF(VALUE(H8)<45,45,IF(VALUE(H8)<48,48,IF(VALUE(H8)<51,51,IF(VALUE(H8)<54,54,IF(VALUE(H8)<57,57,IF(VALUE(K8)<60,60,IF(VALUE(K8)<63,63,IF(VALUE(K8)<66,66,IF(VALUE(K8)<69,69,IF(VALUE(K8)<72,72,IF(VALUE(K8)>72,72,""""))))))))))))))))))) | N8: =IFERROR(CONCATENATE(L8,"X",M8,"X",I8),"") -> XX | O8: =IFERROR(CONCATENATE(B8,N8),"") -> XX | P8: =+CONCATENATE(Table2[[#This Row],[1]],Table2[[#This Row],[H]]) | Q8: =IFERROR(Table13[[#This Row],[QTY]],"") -> 0 | S8: =+Table2[[#This Row],[VARIETY]] | T8: =IFERROR(VLOOKUP(Table9[[#This Row],[VARIETY]],MASTER!B:D,3,0),"") | U8: =IFERROR(IF(OR(S8=MASTER!$B$95,S8=MASTER!$B$96,S8=MASTER!$B$97,S8=MASTER!$B$98,S8=MASTER!$B$102,S8=MASTER!$B$103,S8=MASTER!$B$99,S8=MASTER!$B$100,S8=MASTER!$B$101,S8=MASTER!$B$104,S8=MASTER!$B$105,S8=MASTER!$B$106,S8=MASTER!$B$107,S8=MASTER!$B$108,S8=MASTER!$B$109),(CONCATENATE(VLOOKUP(S8,MASTER!$B:$D,3,0),L8,"X",M8,"X",VLOOKUP(S8,MASTER!$B:$F,5,0))),(CONCATENATE(VLOOKUP(S8,MASTER!$B:$D,3,0),N8))),"") | V8: =IFERROR(VLOOKUP(Table9[[#This Row],[ITEM CODE]],FW!$B:$D,3,0),"") | W8: =IF(OR(S8=MASTER!$B$95,S8=MASTER!$B$96,S8=MASTER!$B$97,S8=MASTER!$B$98,S8=MASTER!$B$102,S8=MASTER!$B$103,S8=MASTER!$B$99,S8=MASTER!$B$100,S8=MASTER!$B$101,S8=MASTER!$B$104,S8=MASTER!$B$105,S8=MASTER!$B$106,S8=MASTER!$B$107,S8=MASTER!$B$108,S8=MASTER!$B$109),(Q8*V8),Q8) -> 0
A9: =ROW()-1 -> 8 | B9: =LEFT(Table13[[#This Row],[ITEM CODE]],MIN(FIND({0,1,2,3,4,5,6,7,8,9},Table13[[#This Row],[ITEM CODE]]&"0123456789"))-1) | C9: =SUBSTITUTE(Table13[[#This Row],[ITEM CODE]],B9,"") | D9: =IFERROR(LEFT(C9,FIND("-",C9)-1),C9) | E9: =IFERROR(SEARCH("X",D9),"") | F9: =IFERROR(SEARCH("X",D9,E9+1),"") | G9: =IFERROR(LEFT(C9,SEARCH("x",C9)-1),"") | H9: =IFERROR(MID(D9,E9+1,F9-E9-1),"") | I9: =IFERROR(MID(D9,F9+1,20),"") | J9: =IFERROR(IF(Table2[[#This Row],[L]]<Table2[[#This Row],[W]],Table2[[#This Row],[W]],Table2[[#This Row],[L]]),"") | K9: =IF(Table2[[#This Row],[L]]<Table2[[#This Row],[W]],Table2[[#This Row],[L]],Table2[[#This Row],[W]]) | L9: =IFERROR(IF(J9="","",IF(VALUE(J9)>=VALUE(K9),IF(OR(VALUE(J9)=13,VALUE(J9)=20,VALUE(J9)=72,VALUE(J9)=75,VALUE(J9)=78,VALUE(J9)=80,VALUE(J9)=84),J9,IF(VALUE(J9)<72,72,IF(VALUE(J9)<75,75,IF(VALUE(J9)<78,78,IF(VALUE(J9)<80,80,IF(VALUE(J9)<84,84,IF(VALUE(J9)>84,84,""""))))))))),0) | M9: =IF(H9="","",IF(VALUE(J9)>=VALUE(K9),IF(OR(VALUE(K9)=13,VALUE(K9)=18,VALUE(K9)=18,VALUE(K9)=30,VALUE(K9)=33,VALUE(K9)=36,VALUE(K9)=39,VALUE(K9)=42,VALUE(K9)=45,VALUE(K9)=48,VALUE(K9)=51,VALUE(K9)=54,VALUE(K9)=57,VALUE(K9)=60,VALUE(K9)=63,VALUE(K9)=66,VALUE(K9)=69,VALUE(K9)=72),K9,IF(VALUE(K9)<30,30,IF(VALUE(K9)<33,33,IF(VALUE(H9)<36,36,IF(VALUE(H9)<39,39,IF(VALUE(H9)<42,42,IF(VALUE(H9)<45,45,IF(VALUE(H9)<48,48,IF(VALUE(H9)<51,51,IF(VALUE(H9)<54,54,IF(VALUE(H9)<57,57,IF(VALUE(K9)<60,60,IF(VALUE(K9)<63,63,IF(VALUE(K9)<66,66,IF(VALUE(K9)<69,69,IF(VALUE(K9)<72,72,IF(VALUE(K9)>72,72,""""))))))))))))))))))) | N9: =IFERROR(CONCATENATE(L9,"X",M9,"X",I9),"") -> XX | O9: =IFERROR(CONCATENATE(B9,N9),"") -> XX | P9: =+CONCATENATE(Table2[[#This Row],[1]],Table2[[#This Row],[H]]) | Q9: =IFERROR(Table13[[#This Row],[QTY]],"") -> 0 | S9: =+Table2[[#This Row],[VARIETY]] | T9: =IFERROR(VLOOKUP(Table9[[#This Row],[VARIETY]],MASTER!B:D,3,0),"") | U9: =IFERROR(IF(OR(S9=MASTER!$B$95,S9=MASTER!$B$96,S9=MASTER!$B$97,S9=MASTER!$B$98,S9=MASTER!$B$102,S9=MASTER!$B$103,S9=MASTER!$B$99,S9=MASTER!$B$100,S9=MASTER!$B$101,S9=MASTER!$B$104,S9=MASTER!$B$105,S9=MASTER!$B$106,S9=MASTER!$B$107,S9=MASTER!$B$108,S9=MASTER!$B$109),(CONCATENATE(VLOOKUP(S9,MASTER!$B:$D,3,0),L9,"X",M9,"X",VLOOKUP(S9,MASTER!$B:$F,5,0))),(CONCATENATE(VLOOKUP(S9,MASTER!$B:$D,3,0),N9))),"") | V9: =IFERROR(VLOOKUP(Table9[[#This Row],[ITEM CODE]],FW!$B:$D,3,0),"") | W9: =IF(OR(S9=MASTER!$B$95,S9=MASTER!$B$96,S9=MASTER!$B$97,S9=MASTER!$B$98,S9=MASTER!$B$102,S9=MASTER!$B$103,S9=MASTER!$B$99,S9=MASTER!$B$100,S9=MASTER!$B$101,S9=MASTER!$B$104,S9=MASTER!$B$105,S9=MASTER!$B$106,S9=MASTER!$B$107,S9=MASTER!$B$108,S9=MASTER!$B$109),(Q9*V9),Q9) -> 0
A10: =ROW()-1 -> 9 | B10: =LEFT(Table13[[#This Row],[ITEM CODE]],MIN(FIND({0,1,2,3,4,5,6,7,8,9},Table13[[#This Row],[ITEM CODE]]&"0123456789"))-1) | C10: =SUBSTITUTE(Table13[[#This Row],[ITEM CODE]],B10,"") | D10: =IFERROR(LEFT(C10,FIND("-",C10)-1),C10) | E10: =IFERROR(SEARCH("X",D10),"") | F10: =IFERROR(SEARCH("X",D10,E10+1),"") | G10: =IFERROR(LEFT(C10,SEARCH("x",C10)-1),"") | H10: =IFERROR(MID(D10,E10+1,F10-E10-1),"") | I10: =IFERROR(MID(D10,F10+1,20),"") | J10: =IFERROR(IF(Table2[[#This Row],[L]]<Table2[[#This Row],[W]],Table2[[#This Row],[W]],Table2[[#This Row],[L]]),"") | K10: =IF(Table2[[#This Row],[L]]<Table2[[#This Row],[W]],Table2[[#This Row],[L]],Table2[[#This Row],[W]]) | L10: =IFERROR(IF(J10="","",IF(VALUE(J10)>=VALUE(K10),IF(OR(VALUE(J10)=13,VALUE(J10)=20,VALUE(J10)=72,VALUE(J10)=75,VALUE(J10)=78,VALUE(J10)=80,VALUE(J10)=84),J10,IF(VALUE(J10)<72,72,IF(VALUE(J10)<75,75,IF(VALUE(J10)<78,78,IF(VALUE(J10)<80,80,IF(VALUE(J10)<84,84,IF(VALUE(J10)>84,84,""""))))))))),0) | M10: =IF(H10="","",IF(VALUE(J10)>=VALUE(K10),IF(OR(VALUE(K10)=13,VALUE(K10)=18,VALUE(K10)=18,VALUE(K10)=30,VALUE(K10)=33,VALUE(K10)=36,VALUE(K10)=39,VALUE(K10)=42,VALUE(K10)=45,VALUE(K10)=48,VALUE(K10)=51,VALUE(K10)=54,VALUE(K10)=57,VALUE(K10)=60,VALUE(K10)=63,VALUE(K10)=66,VALUE(K10)=69,VALUE(K10)=72),K10,IF(VALUE(K10)<30,30,IF(VALUE(K10)<33,33,IF(VALUE(H10)<36,36,IF(VALUE(H10)<39,39,IF(VALUE(H10)<42,42,IF(VALUE(H10)<45,45,IF(VALUE(H10)<48,48,IF(VALUE(H10)<51,51,IF(VALUE(H10)<54,54,IF(VALUE(H10)<57,57,IF(VALUE(K10)<60,60,IF(VALUE(K10)<63,63,IF(VALUE(K10)<66,66,IF(VALUE(K10)<69,69,IF(VALUE(K10)<72,72,IF(VALUE(K10)>72,72,""""))))))))))))))))))) | N10: =IFERROR(CONCATENATE(L10,"X",M10,"X",I10),"") -> XX | O10: =IFERROR(CONCATENATE(B10,N10),"") -> XX | P10: =+CONCATENATE(Table2[[#This Row],[1]],Table2[[#This Row],[H]]) | Q10: =IFERROR(Table13[[#This Row],[QTY]],"") -> 0 | S10: =+Table2[[#This Row],[VARIETY]] | T10: =IFERROR(VLOOKUP(Table9[[#This Row],[VARIETY]],MASTER!B:D,3,0),"") | U10: =IFERROR(IF(OR(S10=MASTER!$B$95,S10=MASTER!$B$96,S10=MASTER!$B$97,S10=MASTER!$B$98,S10=MASTER!$B$102,S10=MASTER!$B$103,S10=MASTER!$B$99,S10=MASTER!$B$100,S10=MASTER!$B$101,S10=MASTER!$B$104,S10=MASTER!$B$105,S10=MASTER!$B$106,S10=MASTER!$B$107,S10=MASTER!$B$108,S10=MASTER!$B$109),(CONCATENATE(VLOOKUP(S10,MASTER!$B:$D,3,0),L10,"X",M10,"X",VLOOKUP(S10,MASTER!$B:$F,5,0))),(CONCATENATE(VLOOKUP(S10,MASTER!$B:$D,3,0),N10))),"") | V10: =IFERROR(VLOOKUP(Table9[[#This Row],[ITEM CODE]],FW!$B:$D,3,0),"") | W10: =IF(OR(S10=MASTER!$B$95,S10=MASTER!$B$96,S10=MASTER!$B$97,S10=MASTER!$B$98,S10=MASTER!$B$102,S10=MASTER!$B$103,S10=MASTER!$B$99,S10=MASTER!$B$100,S10=MASTER!$B$101,S10=MASTER!$B$104,S10=MASTER!$B$105,S10=MASTER!$B$106,S10=MASTER!$B$107,S10=MASTER!$B$108,S10=MASTER!$B$109),(Q10*V10),Q10) -> 0
A11: =ROW()-1 -> 10 | B11: =LEFT(Table13[[#This Row],[ITEM CODE]],MIN(FIND({0,1,2,3,4,5,6,7,8,9},Table13[[#This Row],[ITEM CODE]]&"0123456789"))-1) | C11: =SUBSTITUTE(Table13[[#This Row],[ITEM CODE]],B11,"") | D11: =IFERROR(LEFT(C11,FIND("-",C11)-1),C11) | E11: =IFERROR(SEARCH("X",D11),"") | F11: =IFERROR(SEARCH("X",D11,E11+1),"") | G11: =IFERROR(LEFT(C11,SEARCH("x",C11)-1),"") | H11: =IFERROR(MID(D11,E11+1,F11-E11-1),"") | I11: =IFERROR(MID(D11,F11+1,20),"") | J11: =IFERROR(IF(Table2[[#This Row],[L]]<Table2[[#This Row],[W]],Table2[[#This Row],[W]],Table2[[#This Row],[L]]),"") | K11: =IF(Table2[[#This Row],[L]]<Table2[[#This Row],[W]],Table2[[#This Row],[L]],Table2[[#This Row],[W]]) | L11: =IFERROR(IF(J11="","",IF(VALUE(J11)>=VALUE(K11),IF(OR(VALUE(J11)=13,VALUE(J11)=20,VALUE(J11)=72,VALUE(J11)=75,VALUE(J11)=78,VALUE(J11)=80,VALUE(J11)=84),J11,IF(VALUE(J11)<72,72,IF(VALUE(J11)<75,75,IF(VALUE(J11)<78,78,IF(VALUE(J11)<80,80,IF(VALUE(J11)<84,84,IF(VALUE(J11)>84,84,""""))))))))),0) | M11: =IF(H11="","",IF(VALUE(J11)>=VALUE(K11),IF(OR(VALUE(K11)=13,VALUE(K11)=18,VALUE(K11)=18,VALUE(K11)=30,VALUE(K11)=33,VALUE(K11)=36,VALUE(K11)=39,VALUE(K11)=42,VALUE(K11)=45,VALUE(K11)=48,VALUE(K11)=51,VALUE(K11)=54,VALUE(K11)=57,VALUE(K11)=60,VALUE(K11)=63,VALUE(K11)=66,VALUE(K11)=69,VALUE(K11)=72),K11,IF(VALUE(K11)<30,30,IF(VALUE(K11)<33,33,IF(VALUE(H11)<36,36,IF(VALUE(H11)<39,39,IF(VALUE(H11)<42,42,IF(VALUE(H11)<45,45,IF(VALUE(H11)<48,48,IF(VALUE(H11)<51,51,IF(VALUE(H11)<54,54,IF(VALUE(H11)<57,57,IF(VALUE(K11)<60,60,IF(VALUE(K11)<63,63,IF(VALUE(K11)<66,66,IF(VALUE(K11)<69,69,IF(VALUE(K11)<72,72,IF(VALUE(K11)>72,72,""""))))))))))))))))))) | N11: =IFERROR(CONCATENATE(L11,"X",M11,"X",I11),"") -> XX | O11: =IFERROR(CONCATENATE(B11,N11),"") -> XX | P11: =+CONCATENATE(Table2[[#This Row],[1]],Table2[[#This Row],[H]]) | Q11: =IFERROR(Table13[[#This Row],[QTY]],"") -> 0 | S11: =+Table2[[#This Row],[VARIETY]] | T11: =IFERROR(VLOOKUP(Table9[[#This Row],[VARIETY]],MASTER!B:D,3,0),"") | U11: =IFERROR(IF(OR(S11=MASTER!$B$95,S11=MASTER!$B$96,S11=MASTER!$B$97,S11=MASTER!$B$98,S11=MASTER!$B$102,S11=MASTER!$B$103,S11=MASTER!$B$99,S11=MASTER!$B$100,S11=MASTER!$B$101,S11=MASTER!$B$104,S11=MASTER!$B$105,S11=MASTER!$B$106,S11=MASTER!$B$107,S11=MASTER!$B$108,S11=MASTER!$B$109),(CONCATENATE(VLOOKUP(S11,MASTER!$B:$D,3,0),L11,"X",M11,"X",VLOOKUP(S11,MASTER!$B:$F,5,0))),(CONCATENATE(VLOOKUP(S11,MASTER!$B:$D,3,0),N11))),"") | V11: =IFERROR(VLOOKUP(Table9[[#This Row],[ITEM CODE]],FW!$B:$D,3,0),"") | W11: =IF(OR(S11=MASTER!$B$95,S11=MASTER!$B$96,S11=MASTER!$B$97,S11=MASTER!$B$98,S11=MASTER!$B$102,S11=MASTER!$B$103,S11=MASTER!$B$99,S11=MASTER!$B$100,S11=MASTER!$B$101,S11=MASTER!$B$104,S11=MASTER!$B$105,S11=MASTER!$B$106,S11=MASTER!$B$107,S11=MASTER!$B$108,S11=MASTER!$B$109),(Q11*V11),Q11) -> 0
A12: =ROW()-1 -> 11 | B12: =LEFT(Table13[[#This Row],[ITEM CODE]],MIN(FIND({0,1,2,3,4,5,6,7,8,9},Table13[[#This Row],[ITEM CODE]]&"0123456789"))-1) | C12: =SUBSTITUTE(Table13[[#This Row],[ITEM CODE]],B12,"") | D12: =IFERROR(LEFT(C12,FIND("-",C12)-1),C12) | E12: =IFERROR(SEARCH("X",D12),"") | F12: =IFERROR(SEARCH("X",D12,E12+1),"") | G12: =IFERROR(LEFT(C12,SEARCH("x",C12)-1),"") | H12: =IFERROR(MID(D12,E12+1,F12-E12-1),"") | I12: =IFERROR(MID(D12,F12+1,20),"") | J12: =IFERROR(IF(Table2[[#This Row],[L]]<Table2[[#This Row],[W]],Table2[[#This Row],[W]],Table2[[#This Row],[L]]),"") | K12: =IF(Table2[[#This Row],[L]]<Table2[[#This Row],[W]],Table2[[#This Row],[L]],Table2[[#This Row],[W]]) | L12: =IFERROR(IF(J12="","",IF(VALUE(J12)>=VALUE(K12),IF(OR(VALUE(J12)=13,VALUE(J12)=20,VALUE(J12)=72,VALUE(J12)=75,VALUE(J12)=78,VALUE(J12)=80,VALUE(J12)=84),J12,IF(VALUE(J12)<72,72,IF(VALUE(J12)<75,75,IF(VALUE(J12)<78,78,IF(VALUE(J12)<80,80,IF(VALUE(J12)<84,84,IF(VALUE(J12)>84,84,""""))))))))),0) | M12: =IF(H12="","",IF(VALUE(J12)>=VALUE(K12),IF(OR(VALUE(K12)=13,VALUE(K12)=18,VALUE(K12)=18,VALUE(K12)=30,VALUE(K12)=33,VALUE(K12)=36,VALUE(K12)=39,VALUE(K12)=42,VALUE(K12)=45,VALUE(K12)=48,VALUE(K12)=51,VALUE(K12)=54,VALUE(K12)=57,VALUE(K12)=60,VALUE(K12)=63,VALUE(K12)=66,VALUE(K12)=69,VALUE(K12)=72),K12,IF(VALUE(K12)<30,30,IF(VALUE(K12)<33,33,IF(VALUE(H12)<36,36,IF(VALUE(H12)<39,39,IF(VALUE(H12)<42,42,IF(VALUE(H12)<45,45,IF(VALUE(H12)<48,48,IF(VALUE(H12)<51,51,IF(VALUE(H12)<54,54,IF(VALUE(H12)<57,57,IF(VALUE(K12)<60,60,IF(VALUE(K12)<63,63,IF(VALUE(K12)<66,66,IF(VALUE(K12)<69,69,IF(VALUE(K12)<72,72,IF(VALUE(K12)>72,72,""""))))))))))))))))))) | N12: =IFERROR(CONCATENATE(L12,"X",M12,"X",I12),"") -> XX | O12: =IFERROR(CONCATENATE(B12,N12),"") -> XX | P12: =+CONCATENATE(Table2[[#This Row],[1]],Table2[[#This Row],[H]]) | Q12: =IFERROR(Table13[[#This Row],[QTY]],"") -> 0 | S12: =+Table2[[#This Row],[VARIETY]] | T12: =IFERROR(VLOOKUP(Table9[[#This Row],[VARIETY]],MASTER!B:D,3,0),"") | U12: =IFERROR(IF(OR(S12=MASTER!$B$95,S12=MASTER!$B$96,S12=MASTER!$B$97,S12=MASTER!$B$98,S12=MASTER!$B$102,S12=MASTER!$B$103,S12=MASTER!$B$99,S12=MASTER!$B$100,S12=MASTER!$B$101,S12=MASTER!$B$104,S12=MASTER!$B$105,S12=MASTER!$B$106,S12=MASTER!$B$107,S12=MASTER!$B$108,S12=MASTER!$B$109),(CONCATENATE(VLOOKUP(S12,MASTER!$B:$D,3,0),L12,"X",M12,"X",VLOOKUP(S12,MASTER!$B:$F,5,0))),(CONCATENATE(VLOOKUP(S12,MASTER!$B:$D,3,0),N12))),"") | V12: =IFERROR(VLOOKUP(Table9[[#This Row],[ITEM CODE]],FW!$B:$D,3,0),"") | W12: =IF(OR(S12=MASTER!$B$95,S12=MASTER!$B$96,S12=MASTER!$B$97,S12=MASTER!$B$98,S12=MASTER!$B$102,S12=MASTER!$B$103,S12=MASTER!$B$99,S12=MASTER!$B$100,S12=MASTER!$B$101,S12=MASTER!$B$104,S12=MASTER!$B$105,S12=MASTER!$B$106,S12=MASTER!$B$107,S12=MASTER!$B$108,S12=MASTER!$B$109),(Q12*V12),Q12) -> 0
A13: =ROW()-1 -> 12 | B13: =LEFT(Table13[[#This Row],[ITEM CODE]],MIN(FIND({0,1,2,3,4,5,6,7,8,9},Table13[[#This Row],[ITEM CODE]]&"0123456789"))-1) | C13: =SUBSTITUTE(Table13[[#This Row],[ITEM CODE]],B13,"") | D13: =IFERROR(LEFT(C13,FIND("-",C13)-1),C13) | E13: =IFERROR(SEARCH("X",D13),"") | F13: =IFERROR(SEARCH("X",D13,E13+1),"") | G13: =IFERROR(LEFT(C13,SEARCH("x",C13)-1),"") | H13: =IFERROR(MID(D13,E13+1,F13-E13-1),"") | I13: =IFERROR(MID(D13,F13+1,20),"") | J13: =IFERROR(IF(Table2[[#This Row],[L]]<Table2[[#This Row],[W]],Table2[[#This Row],[W]],Table2[[#This Row],[L]]),"") | K13: =IF(Table2[[#This Row],[L]]<Table2[[#This Row],[W]],Table2[[#This Row],[L]],Table2[[#This Row],[W]]) | L13: =IFERROR(IF(J13="","",IF(VALUE(J13)>=VALUE(K13),IF(OR(VALUE(J13)=13,VALUE(J13)=20,VALUE(J13)=72,VALUE(J13)=75,VALUE(J13)=78,VALUE(J13)=80,VALUE(J13)=84),J13,IF(VALUE(J13)<72,72,IF(VALUE(J13)<75,75,IF(VALUE(J13)<78,78,IF(VALUE(J13)<80,80,IF(VALUE(J13)<84,84,IF(VALUE(J13)>84,84,""""))))))))),0) | M13: =IF(H13="","",IF(VALUE(J13)>=VALUE(K13),IF(OR(VALUE(K13)=13,VALUE(K13)=18,VALUE(K13)=18,VALUE(K13)=30,VALUE(K13)=33,VALUE(K13)=36,VALUE(K13)=39,VALUE(K13)=42,VALUE(K13)=45,VALUE(K13)=48,VALUE(K13)=51,VALUE(K13)=54,VALUE(K13)=57,VALUE(K13)=60,VALUE(K13)=63,VALUE(K13)=66,VALUE(K13)=69,VALUE(K13)=72),K13,IF(VALUE(K13)<30,30,IF(VALUE(K13)<33,33,IF(VALUE(H13)<36,36,IF(VALUE(H13)<39,39,IF(VALUE(H13)<42,42,IF(VALUE(H13)<45,45,IF(VALUE(H13)<48,48,IF(VALUE(H13)<51,51,IF(VALUE(H13)<54,54,IF(VALUE(H13)<57,57,IF(VALUE(K13)<60,60,IF(VALUE(K13)<63,63,IF(VALUE(K13)<66,66,IF(VALUE(K13)<69,69,IF(VALUE(K13)<72,72,IF(VALUE(K13)>72,72,""""))))))))))))))))))) | N13: =IFERROR(CONCATENATE(L13,"X",M13,"X",I13),"") -> XX | O13: =IFERROR(CONCATENATE(B13,N13),"") -> XX | P13: =+CONCATENATE(Table2[[#This Row],[1]],Table2[[#This Row],[H]]) | Q13: =IFERROR(Table13[[#This Row],[QTY]],"") -> 0 | S13: =+Table2[[#This Row],[VARIETY]] | T13: =IFERROR(VLOOKUP(Table9[[#This Row],[VARIETY]],MASTER!B:D,3,0),"") | U13: =IFERROR(IF(OR(S13=MASTER!$B$95,S13=MASTER!$B$96,S13=MASTER!$B$97,S13=MASTER!$B$98,S13=MASTER!$B$102,S13=MASTER!$B$103,S13=MASTER!$B$99,S13=MASTER!$B$100,S13=MASTER!$B$101,S13=MASTER!$B$104,S13=MASTER!$B$105,S13=MASTER!$B$106,S13=MASTER!$B$107,S13=MASTER!$B$108,S13=MASTER!$B$109),(CONCATENATE(VLOOKUP(S13,MASTER!$B:$D,3,0),L13,"X",M13,"X",VLOOKUP(S13,MASTER!$B:$F,5,0))),(CONCATENATE(VLOOKUP(S13,MASTER!$B:$D,3,0),N13))),"") | V13: =IFERROR(VLOOKUP(Table9[[#This Row],[ITEM CODE]],FW!$B:$D,3,0),"") | W13: =IF(OR(S13=MASTER!$B$95,S13=MASTER!$B$96,S13=MASTER!$B$97,S13=MASTER!$B$98,S13=MASTER!$B$102,S13=MASTER!$B$103,S13=MASTER!$B$99,S13=MASTER!$B$100,S13=MASTER!$B$101,S13=MASTER!$B$104,S13=MASTER!$B$105,S13=MASTER!$B$106,S13=MASTER!$B$107,S13=MASTER!$B$108,S13=MASTER!$B$109),(Q13*V13),Q13) -> 0
... A101: =ROW()-1 -> 100 | B101: =LEFT(Table13[[#This Row],[ITEM CODE]],MIN(FIND({0,1,2,3,4,5,6,7,8,9},Table13[[#This Row],[ITEM CODE]]&"0123456789"))-1) | C101: =SUBSTITUTE(Table13[[#This Row],[ITEM CODE]],B101,"") | D101: =IFERROR(LEFT(C101,FIND("-",C101)-1),C101) | E101: =IFERROR(SEARCH("X",D101),"") | F101: =IFERROR(SEARCH("X",D101,E101+1),"") | G101: =IFERROR(LEFT(C101,SEARCH("x",C101)-1),"") | H101: =IFERROR(MID(D101,E101+1,F101-E101-1),"") | I101: =IFERROR(MID(D101,F101+1,20),"") | J101: =IFERROR(IF(Table2[[#This Row],[L]]<Table2[[#This Row],[W]],Table2[[#This Row],[W]],Table2[[#This Row],[L]]),"") | K101: =IF(Table2[[#This Row],[L]]<Table2[[#This Row],[W]],Table2[[#This Row],[L]],Table2[[#This Row],[W]]) | L101: =IFERROR(IF(J101="","",IF(VALUE(J101)>=VALUE(K101),IF(OR(VALUE(J101)=13,VALUE(J101)=20,VALUE(J101)=72,VALUE(J101)=75,VALUE(J101)=78,VALUE(J101)=80,VALUE(J101)=84),J101,IF(VALUE(J101)<72,72,IF(VALUE(J101)<75,75,IF(VALUE(J101)<78,78,IF(VALUE(J101)<80,80,IF(VALUE(J101)<84,84,IF(VALUE(J101)>84,84,""""))))))))),0) | M101: =IF(H101="","",IF(VALUE(J101)>=VALUE(K101),IF(OR(VALUE(K101)=13,VALUE(K101)=18,VALUE(K101)=18,VALUE(K101)=30,VALUE(K101)=33,VALUE(K101)=36,VALUE(K101)=39,VALUE(K101)=42,VALUE(K101)=45,VALUE(K101)=48,VALUE(K101)=51,VALUE(K101)=54,VALUE(K101)=57,VALUE(K101)=60,VALUE(K101)=63,VALUE(K101)=66,VALUE(K101)=69,VALUE(K101)=72),K101,IF(VALUE(K101)<30,30,IF(VALUE(K101)<33,33,IF(VALUE(H101)<36,36,IF(VALUE(H101)<39,39,IF(VALUE(H101)<42,42,IF(VALUE(H101)<45,45,IF(VALUE(H101)<48,48,IF(VALUE(H101)<51,51,IF(VALUE(H101)<54,54,IF(VALUE(H101)<57,57,IF(VALUE(K101)<60,60,IF(VALUE(K101)<63,63,IF(VALUE(K101)<66,66,IF(VALUE(K101)<69,69,IF(VALUE(K101)<72,72,IF(VALUE(K101)>72,72,""""))))))))))))))))))) | N101: =IFERROR(CONCATENATE(L101,"X",M101,"X",I101),"") -> XX | O101: =IFERROR(CONCATENATE(B101,N101),"") -> XX | P101: =+CONCATENATE(Table2[[#This Row],[1]],Table2[[#This Row],[H]]) | Q101: =IFERROR(Table13[[#This Row],[QTY]],"") -> 0 | S101: =+Table2[[#This Row],[VARIETY]] | T101: =IFERROR(VLOOKUP(Table9[[#This Row],[VARIETY]],MASTER!B:D,3,0),"") | U101: =IFERROR(IF(OR(S101=MASTER!$B$95,S101=MASTER!$B$96,S101=MASTER!$B$97,S101=MASTER!$B$98,S101=MASTER!$B$102,S101=MASTER!$B$103,S101=MASTER!$B$99,S101=MASTER!$B$100,S101=MASTER!$B$101,S101=MASTER!$B$104,S101=MASTER!$B$105,S101=MASTER!$B$106,S101=MASTER!$B$107,S101=MASTER!$B$108,S101=MASTER!$B$109),(CONCATENATE(VLOOKUP(S101,MASTER!$B:$D,3,0),L101,"X",M101,"X",VLOOKUP(S101,MASTER!$B:$F,5,0))),(CONCATENATE(VLOOKUP(S101,MASTER!$B:$D,3,0),N101))),"") | V101: =IFERROR(VLOOKUP(Table9[[#This Row],[ITEM CODE]],FW!$B:$D,3,0),"") | W101: =IF(OR(S101=MASTER!$B$95,S101=MASTER!$B$96,S101=MASTER!$B$97,S101=MASTER!$B$98,S101=MASTER!$B$102,S101=MASTER!$B$103,S101=MASTER!$B$99,S101=MASTER!$B$100,S101=MASTER!$B$101,S101=MASTER!$B$104,S101=MASTER!$B$105,S101=MASTER!$B$106,S101=MASTER!$B$107,S101=MASTER!$B$108,S101=MASTER!$B$109),(Q101*V101),Q101) -> 0

Sheet Sheet5
A1: HYPNOS MR
A2: DATE | B2: ORDER NO | C2: SESSION | D2: MR NO | E2: TIME | F2: STATUS | G2: REMARKS
A3: 46055 | D3: INVST/13838/25-26
A4: 46056 | D4: INVST/13839/25-26
A5: 46057 | D5: INVST/13840/25-26
