Workbook

Sheet BORDER ITEM CODE
A1: S.NO | B1: CODE | C1: ITEM CODE
A2: 1 | B2: SPK-NL-MRN | C2: SFG-SPKNLMR-BOR-
A3: 2 | B3: SPK-PT-MRN | C3: SFG-SPKPTMR-BOR-
A4: 3 | B4: SPG- | C4: SFG-SPGSR-BOR-
A5: 4 | B5: ALR-OR | C5: SFG-ALRNLOR-BOR-
A6: 5 | B6: ALR-GR | C6: SFG-ALRNLGR-BOR-
A7: 6 | B7: CAS-MRN | C7: SFG-CASNLMR-BOR-
A8: 7 | B8: CAS-NB | C8: SFG-CASNLNB-BOR-
A9: 8 | B9: INS-MEM-ET-MRN | C9: SFG-INSRBMR-ST-ETBOR-
A10: 9 | B10: INS-LAT-ET-GRN | C10: SFG-INSRBGRN-LTX-ETBOR-
A11: 10 | B11: INS-LAT-ET-PNK | C11: SFG-INSRBPNK-LTX-ETBOR-
A12: 11 | B12: INS-LAT-GRN | C12: SFG-INSRBGRN-LTX-BOR-
A13: 12 | B13: INS-LAT-PNK | C13: SFG-INSRBPNK-LTX-BOR-
... A19: 18 | B19: KOZ-DB | C19: SFG-KBZDB-BOR-
A20: 19 | C20: SFG-MULTDB-BOR-
A21: 20 | C21: SFG-MULTGR-BOR-
A22: 21 | B22: SS-BG | C22: SFG-SSFBG-BOR-
A23: 22 | B23: VB-BRN | C23: SFG-VISBONBW-BOR-
A24: 23 | B24: COM-BG | C24: SFG-COMNLBG-BOR-
A25: 24 | B25: COM-GR | C25: SFG-COMNLGR-BOR-
A26: 25 | B26: COM-PNK | C26: SFG-COMNLPNK-BOR-
A27: 26 | C27: SFG-MER-GRCY-BOR-QUILT-
A28: 27 | B28: ORG-BRN | C28: SFG-ORGBW-BOR-
A29: 28 | B29: SUP-BG | C29: SFG-SUPNLBG-BOR-
A30: 29 | B30: SUP-GR | C30: SFG-SUPNLGR-BOR-
A31: 30 | B31: TAT-DB | C31: SFG-TRTPKDB-BOR-
A32: 31 | B32: TAT-GR | C32: SFG-TRTPKGR-BOR-
A33: 32 | B33: TAT-MRN | C33: SFG-TRTPKMR-BOR-
A34: 33 | B34: ZEN-FT-DB | C34: SFG-ZENFTDB-BOR-
A35: 34 | B35: ZEN-NL-DB | C35: SFG-ZENNLDB-BOR-
A36: 35 | B36: ZEN-PT-DB | C36: SFG-ZENPTDB-BOR-
A37: 36 | B37: GEN-NL-BG | C37: SFG-GVNLBG-BOR-
A38: 37 | B38: GEN-ET-BG | C38: SFG-GVETBG-BOR-
A39: 38 | B39: GEN-ET-LB | C39: SFG-GVETLB-BOR-
... A127: 126 | B127: SPN-FM | C127: SFG-SPGFM-BOR-

Sheet MASTER
B1: S.NO | C1: COLOUR | D1: ITEM CODE | F1: CODE | G1: ITEM CODE | H1: DESCRIPTION | I1: UOM | K1: CODE | L1: ITEMCODE
B2: 1 | C2: VB-BR | D2: SFG-VISBONBW-BOR- | F2: TC | G2: HW-CTON-THREAD | H2: COTTON THREAD WHITE 3PLY | I2: NOS | K2: VB-BR-15 | L2: SFG-VISBONBW-BOR-15CM | T2: VISTA BOND
B3: 2 | C3: KOZ-MR | D3: SFG-KBZMR-BOR- | F3: L-VB-F | G3: RML-CIR-VIS-BON-SDE-LBL-FUS | H3: CIRRUS VISTA BOND SIDE LABEL (FUSING TYPE) | I3: NOS | K3: VB-BR-18 | L3: SFG-VISBONBW-BOR-18CM | T3: S.NO | U3: COLOUR | V3: ITEM CODE | W3: HEIGHT | X3: EXAMBLE | Y3: BORDER
B4: 3 | C4: KOZ-DB | D4: SFG-KBZDB-BOR- | F4: MRP | G4: RML-MRP-BACK-LBL-260-92-FUS | H4: MRP BACK LABEL 260MMX92MM FUSING TYPE | I4: NOS | K4: VB-BR-20 | L4: SFG-VISBONBW-BOR-20CM | T4: 1 | U4: VISTA BOND | V4: SFG-VISBONBW-BOR- | W4: 4" | X4: SFG-VISBONBW-BOR-72X30X04 | Y4: SFG-VISBONBW-BOR-15CM
B5: 4 | C5: MEM-OR | D5: SFG-MEMOR-BOR- | F5: TW | G5: RM-THRD-QS-TKT40 | H5: THREAD TKT40 210D/3 PLY 10000MTS ( WHITE ) | I5: NOS | K5: KOZ-MR-15 | L5: SFG-KBZMR-BOR-15CM | W5: 5" | X5: SFG-VISBONBW-BOR-72X30X05 | Y5: SFG-VISBONBW-BOR-18CM
B6: 5 | C6: MEM-VL | D6: SFG-MEMVL-BOR- | F6: B-VB | G6: FBR-SPK-BR-BRN-KF | H6: SPRINGKOIL KNITTED BROWN BORDER FABRIC | I6: MTR | K6: KOZ-MR-18 | L6: SFG-KBZMR-BOR-18CM | W6: 6" | X6: SFG-VISBONBW-BOR-72X30X06 | Y6: SFG-VISBONBW-BOR-20CM
B7: 6 | C7: INS-GRN | D7: SFG-INSRBGRN-LTX-BOR- | F7: N-8.5 | G7: RM-NWN-BS-8.5"X30GSM | H7: NON WOVEN FABRIC 30 GSM x 8.5 INCH - WHITE | I7: KGS | K7: KOZ-MR-20 | L7: SFG-KBZMR-BOR-20CM | T7: KOZYBREEZE
B8: 7 | C8: INS-PNK | D8: SFG-INSRBPNK-LTX-BOR- | F8: L-KOZ | G8: RML-CIR-KOZBRE-SDE-LBL-FUS | H8: CIRRUS KOZYBREEZ SIDE LABEL (FUSING TYPE) | I8: NOS | K8: KOZ-DB-15 | L8: SFG-KBZDB-BOR-15CM | T8: 2 | U8: MAROON | V8: SFG-KBZMR-BOR- | W8: 4" | X8: SFG-KBZMR-BOR-72X30X04 | Y8: SFG-KBZMR-BOR-15CM
B9: 8 | C9: INS-ET-GRN | D9: SFG-INSRBGRN-LTX-ETBOR- | F9: B-KOZ-DB | G9: FBR-KOZBRE-PNL-BLUE | H9: KOZYBREEZ PANEL FABRIC DARK BLUE | I9: MTR | K9: KOZ-DB-18 | L9: SFG-KBZDB-BOR-18CM | W9: 5" | X9: SFG-KBZMR-BOR-72X30X05 | Y9: SFG-KBZMR-BOR-18CM
B10: 9 | C10: INS-ET-PNK | D10: SFG-INSRBPNK-LTX-ETBOR- | F10: B-KOZ-MR | G10: FBR-CASPIA-BR-MRN | H10: CASPIA MAROON BORDER FABRIC | I10: MTR | K10: KOZ-DB-20 | L10: SFG-KBZDB-BOR-20CM | W10: 6" | X10: SFG-KBZMR-BOR-72X30X06 | Y10: SFG-KBZMR-BOR-20CM
B11: 10 | C11: INS-BL | D11: SFG-INSRBBL-MEM-BOR- | F11: L-MEM-F | G11: RML-CIR-MEM-SDE-LBL-FUS | H11: CIRRUS MEMORIO SIDE LABEL (FUSING TYPE) | I11: NOS | K11: MEM-OR-18 | L11: SFG-MEMOR-BOR-18CM
B12: 11 | C12: INS-GR | D12: SFG-INSRBGR-MEM-BOR- | F12: B-MEM-OR | G12: FBR-INS-REB-LTX-BR-PINK | H12: INSPREE REBONDED LATEX PINK BORDER FABRIC | I12: MTR | K12: MEM-OR-20 | L12: SFG-MEMOR-BOR-20CM | T12: 3 | U12: DARK BLUE | V12: SFG-KBZDB-BOR- | W12: 4" | X12: SFG-KBZDB-BOR-72X30X04 | Y12: SFG-KBZDB-BOR-15CM
B13: 12 | C13: INS-MR | D13: SFG-INSRBMR-ST-BOR- | F13: B-MEM-VL | G13: FBR-INS-REB-MEM-BR-BLUE | H13: INSPREE REBONDED MEMORY BLUE BORDER FABRIC | I13: MTR | K13: MEM-OR-24 | L13: SFG-MEMOR-BOR-24CM | W13: 5" | X13: SFG-KBZDB-BOR-72X30X05 | Y13: SFG-KBZDB-BOR-18CM
B14: 13 | C14: INS-ET-BL | D14: SFG-INSRBBL-MEM-ETBOR- | F14: L-INS-LAT-F | G14: RML-CIR-INS-LAT-SDE-LBL-FUS | H14: CIRRUS INSPREE LATEX SIDE LABEL (FUSING TYPE) | I14: NOS | K14: MEM-VL-18 | L14: SFG-MEMVL-BOR-18CM | W14: 6" | X14: SFG-KBZDB-BOR-72X30X06 | Y14: SFG-KBZDB-BOR-20CM
B15: 14 | C15: INS-ET-GR | D15: SFG-INSRBGR-MEM-ETBOR- | F15: B-INS-PNK | G15: FBR-INS-REB-LTX-BR-PINK | H15: INSPREE REBONDED LATEX PINK BORDER FABRIC | I15: MTR | K15: MEM-VL-20 | L15: SFG-MEMVL-BOR-20CM | T15: MEMORIO
B16: 15 | C16: INS-ET-MR | D16: SFG-INSRBMR-ST-ETBOR- | F16: N-11.5 | G16: RM-NWN-BS-11.50"X30GSM | H16: NON WOVEN FABRIC 30 GSM x 11.5 INCH - WHITE | I16: KGS | K16: MEM-VL-24 | L16: SFG-MEMVL-BOR-24CM | T16: 4 | U16: ORANGE | V16: SFG-MEMOR-BOR- | W16: 5" | X16: SFG-MEMOR-BOR-72X30X05 | Y16: SFG-MEMOR-BOR-18CM
B17: 16 | C17: MEM-DB | D17: SFG-MULTDB-BOR- | F17: B-INS-GRN | G17: FBR-INS-REB-LTX-BR-GRN | H17: INSPREE REBONDED LATEX GREEN BORDER FABRIC | I17: MTR | K17: INS-GRN-18 | L17: SFG-INSRBGRN-LTX-BOR-18CM | W17: 6" | X17: SFG-MEMOR-BOR-72X30X06 | Y17: SFG-MEMOR-BOR-20CM
B18: 17 | C18: MEM-GR | D18: SFG-MULTDB-BOR- | F18: L-INS-LAT-4 | G18: RML-CIR-INS-LAT-SDE-LBL-4INC-FUS | H18: CIRRUS INSPREE LATEX SIDE LABEL 4 INCH MATTRESS (FUSING TYPE) | I18: NOS | K18: INS-GRN-20 | L18: SFG-INSRBGRN-LTX-BOR-20CM | W18: 8" | X18: SFG-MEMOR-BOR-72X30X08 | Y18: SFG-MEMOR-BOR-24CM
B19: 18 | C19: VS-FM | D19: SFG-VISTAFM-BOR- | F19: N-76 | G19: RML-NWN-70GSMX76" | H19: NON WOVEN FABRIC 70 GSM x 76 INCH - WHITE | I19: KGS | K19: INS-GRN-25 | L19: SFG-INSRBGRN-LTX-BOR-25CM
B20: 19 | C20: VS-SF | D20: SFG-VISTAST-BOR- | F20: N-6 | G20: RM-NWN-70GSMX6INCH | H20: NON WOVEN FABRIC 70 GSM x 6 INCH - WHITE | I20: KGS | K20: INS-PNK-18 | L20: SFG-INSRBPNK-LTX-BOR-18CM | T20: 5 | U20: VILOT | V20: SFG-MEMVL-BOR- | W20: 5" | X20: SFG-MEMVL-BOR-72X30X05 | Y20: SFG-MEMVL-BOR-18CM
B21: 20 | C21: RL-WAY | D21: SFG-ROLLAWAY-BOR- | F21: ET-WH | G21: RML-EDTAPE-WHT-KNIT | H21: EDGE TAPE. WHITE (42MM ,12.5GRM/PER MTR KNITTED) | I21: MTR | K21: INS-PNK-20 | L21: SFG-INSRBGRN-LTX-BOR-20CM | W21: 6" | X21: SFG-MEMVL-BOR-72X30X06 | Y21: SFG-MEMVL-BOR-20CM
B22: 21 | C22: CAP-LAT | D22: SFG-CAP-LTX-BOR- | F22: GUM | G22: RML-POLY-GUM | H22: SOLVENT BASED RUBBER ADHESIVE (SPRAY GLUE) | I22: LTR | K22: INS-PNK-25 | L22: SFG-INSRBPNK-LTX-BOR-25CM | W22: 8" | X22: SFG-MEMVL-BOR-72X30X08 | Y22: SFG-MEMVL-BOR-24CM
B23: 22 | C23: CAP-MEM | D23: SFG-CAP-MEM-BOR- | F23: INS-BL | G23: FBR-INS-REB-MEM-BR-BLUE | H23: INSPREE REBONDED MEMORY BLUE BORDER FABRIC | I23: MTR | K23: INS-GRN-13 | L23: SFG-INSRBGRN-LTX-BOR-13CM | T23: INSPREE LATEX
F24: L-INS-MEM-F | G24: RML-CIR-INS-MEM-SDE-LBL-FUS | H24: CIRRUS INSPREE MEMORY SIDE LABEL (FUSING TYPE) | I24: NOS | K24: INS-GRN-8 | L24: SFG-INSRBGRN-LTX-ETBOR-08CM | T24: 6 | U24: GREEN | V24: SFG-INSRBGRN-LTX-BOR- | W24: 5" | X24: SFG-INSRBGRN-LTX-BOR-72X30X05 | Y24: SFG-INSRBGRN-LTX-BOR-18CM
C25: CODE | D25: ITEMCODE | F25: B-INS-GR | G25: FBR-INS-REB-MEM-BR-GRY | H25: INSPREE REBONDED MEMORY GREY BORDER FABRIC | I25: MTR | K25: INS-GRN-15 | L25: SFG-INSRBGRN-LTX-BOR-15CM | W25: 6" | X25: SFG-INSRBGRN-LTX-BOR-72X30X06 | Y25: SFG-INSRBGRN-LTX-BOR-20CM
B26: 1 | C26: INS-GRN | D26: SFG-INSRBGRN-LTX-ETCVR- | F26: L-INS-MEM-4 | G26: RML-CIR-INS-MEM-SDE-LBL-4INC-FUS | H26: CIRRUS INSPREE MEMORY SIDE LABEL 4 INCH MATTRESS (FUSING TYPE) | I26: NOS | K26: INS-GRN-8 | L26: SFG-INSRBGRN-LTX-ETBOR-08CM | W26: 8" | X26: SFG-INSRBGRN-LTX-BOR-72X30X08 | Y26: SFG-INSRBGRN-LTX-BOR-25CM
B27: 2 | C27: INS-PNK | D27: SFG-INSRBPNK-LTX-ETCVR- | F27: B-INS-MR | G27: FBR-SPK-BR-MRN-KF | H27: SPRINGKOIL KNITTED MAROON BORDER FABRIC | I27: MTR | K27: INS-GRN-18 | L27: SFG-INSRBGRN-LTX-BOR-18CM
B28: 3 | C28: INS-BL | D28: SFG-INSRBBL-MEM-ETCVR- | F28: L-INS-4 | G28: RML-CIR-INS-SDE-LBL-4INC-FUS | H28: CIRRUS INSPREE SIDE LABEL 4 INCH MATTRESS (FUSING TYPE) | I28: NOS | K28: INS-GRN-10 | L28: SFG-INSRBGRN-LTX-ETBOR-10CM | T28: 7 | U28: PINK | V28: SFG-INSRBPNK-LTX-BOR- | W28: 5" | X28: SFG-INSRBPNK-LTX-BOR-72X30X05 | Y28: SFG-INSRBPNK-LTX-BOR-18CM
B29: 4 | C29: INS-GR | D29: SFG-INSRBGR-MEM-ETCVR- | F29: L-INS-F | G29: RML-CIR-INS-SDE-LBL-FUS | H29: CIRRUS INSPREE SIDE LABEL (FUSING TYPE) | I29: NOS | K29: INS-PNK-13 | L29: SFG-INSRBPNK-LTX-BOR-13CM | W29: 6" | X29: SFG-INSRBPNK-LTX-BOR-72X30X06 | Y29: SFG-INSRBGRN-LTX-BOR-20CM
B30: 5 | C30: INS-MR | D30: SFG-INSRBMR-ST-ETCVR- | F30: ET-BR | G30: RML-EDTAPE-BRN | H30: EDGE TAPE.BROWN (42MM ,12.5GRM/PER MTR KNITTED) | I30: MTR | K30: INS-PNK-8 | L30: SFG-INSRBPNK-LTX-ETBOR-08CM | W30: 8" | X30: SFG-INSRBPNK-LTX-BOR-72X30X08 | Y30: SFG-INSRBPNK-LTX-BOR-25CM
F31: TB | G31: RM-THRD-TKT40-BLACK | H31: 3 PLY POLYESTER THREAD 702/ TKT 40 BLACK 10000 MTR | I31: NOS | K31: INS-PNK-15 | L31: SFG-INSRBPNK-LTX-BOR-15CM | T31: INSPREE LATEX- EURO TOP
F32: B-DIV-BLK | G32: FBR-CRY-BAHB-REXIN-BLK | H32: CRYSTAL BASE & HEAD BOARD BLACK REXIN | I32: MTR | K32: INS-PNK-8 | L32: SFG-INSRBPNK-LTX-ETBOR-08CM | T32: 8 | U32: GREEN | V32: SFG-INSRBGRN-LTX-ETBOR- SFG-INSRBGRN-LTX-ETCVR- | W32: 5" | X32: SFG-INSRBGRN-LTX-ETBOR-72X30X05 | Y32: SFG-INSRBGRN-LTX-BOR-13CM
F33: ZIP | G33: RM-GREY-ZIP | H33: GREY ZIPPER NO -8 | I33: MTR | K33: INS-PNK-18 | L33: SFG-INSRBPNK-LTX-BOR-18CM | X33: SFG-INSRBGRN-LTX-ETCVR-72X30 | Y33: SFG-INSRBGRN-LTX-ETBOR-08CM
F34: RUN | G34: RML-RUNNER-SLVR | H34: Zipper Runner Silver No-8 | I34: NOS | K34: INS-PNK-10 | L34: SFG-INSRBPNK-LTX-ETBOR-10CM | W34: 6" | X34: SFG-INSRBGRN-LTX-ETBOR-72X30X06 | Y34: SFG-INSRBGRN-LTX-BOR-15CM
F35: N-BOT | G35: RML-FBR-BT-WHT | H35: BOTTLE FABRIC-WHITE | I35: KGS | K35: INS-BL-18 | L35: SFG-INSRBBL-MEM-BOR-18CM | X35: SFG-INSRBGRN-LTX-ETCVR-72X30 | Y35: SFG-INSRBGRN-LTX-ETBOR-08CM
F36: ET-MR | G36: RML-EDTAPE-MER-KNIT | H36: EDGE TAPE.MAROON(42MM ,12.5GRM/PER MTR KNITTED) | I36: MTR | K36: INS-BL-20 | L36: SFG-INSRBBL-MEM-BOR-20CM | W36: 8" | X36: SFG-INSRBGRN-LTX-ETBOR-72X30X08 | Y36: SFG-INSRBGRN-LTX-BOR-18CM
F37: ET-BL | G37: RML-EDTAPE-BLUE | H37: EDGE TAPE.D BLUE(42MM ,12.5GRM/PER MTR KNITTED) | I37: MTR | K37: INS-BL-25 | L37: SFG-INSRBBL-MEM-BOR-25CM | X37: SFG-INSRBGRN-LTX-ETCVR-72X30X08 | Y37: SFG-INSRBGRN-LTX-ETBOR-10CM
F38: L-MEM-ULT | G38: RML-CIR-MEM-ULT-SDE-LBL | H38: CIRRUS MEMORIO ULTRA SIDE LABEL | I38: NOS | K38: INS-GR-18 | L38: SFG-INSRBGR-MEM-BOR-18CM | T38: 9 | U38: PINK | V38: SFG-INSRBPNK-LTX-ETBOR- SFG-INSRBPNK-LTX-ETCVR- | W38: 5" | X38: SFG-INSRBPNK-LTX-ETBOR-72X30X05 | Y38: SFG-INSRBPNK-LTX-BOR-13CM
F39: B-MEM-GR | G39: FBR-MEM-UL-BR-GREY | H39: HYPNOS MEMORIO ULTRA GREY BORDER FABRIC | I39: MTR | K39: INS-GR-20 | L39: SFG-INSRBGR-MEM-BOR-20CM | X39: SFG-INSRBPNK-LTX-ETCVR-72X30 | Y39: SFG-INSRBPNK-LTX-ETBOR-08CM
F40: B-MEM-DB | G40: FBR-MEM-UL-BR-BLUE | H40: HYPNOS MEMORIO ULTRA BLUE BORDER FABRIC | I40: MTR | K40: INS-GR-25 | L40: SFG-INSRBGR-MEM-BOR-25CM | W40: 6" | X40: SFG-INSRBPNK-LTX-ETBOR-72X30X06 | Y40: SFG-INSRBPNK-LTX-BOR-15CM
...

Sheet ENTRY INSTRUCTIONS
B2: BORDER
B3: MATTRESS NAME | C3: VARIETY | D3: COLOUR
B4: VISTA BOND | C4: VB | D4: BR
B5: KOZY BREEZE DARK BLUE | C5: KOZ | D5: DB
B6: KOZY BREEZE MAROON | C6: KOZ | D6: MR
B7: MEMERIO ORANGE | C7: MEM | D7: OR
B8: MEMERIO VILOT | C8: MEM | D8: VL
B9: INSPREE LATEX GREEN | C9: INS | D9: GRN
B10: INSPREE LATEX PINK | C10: INS | D10: PNK
B11: INSPREE MEMORY BLUE | C11: INS | D11: BL
B12: INSPREE MEMORY GREY | C12: INS | D12: GR
B13: INSPREE PU MAROON | C13: INS | D13: MR
B14: INSPREE LATEX EURO TOP GREEN | C14: INS-ET | D14: GRN
... B18: INSPREE PU EURO TOP MAROON | C18: INS-ET | D18: MR
B20: COVER
B21: MATTRESS NAME | C21: VARIETY | D21: COLOUR
B22: INSPREE EURO TOP LATEX GREEN | C22: INS | D22: GRN
B23: INSPREE EURO TOP LATEX PINK | C23: INS | D23: PNK
B24: INSPREE MEMORY EURO TOP BLUE | C24: INS | D24: BL
B25: INSPREE MEMORY EURO TOP GREY | C25: INS | D25: GR
B26: INSPREE PU EURO TOP MAROON | C26: INS | D26: MR

Sheet WIP
A1: SNO | B1: VARIETY | C1: QTY | D1: ITEMCODE | E1: UOM | F1: QTY
A2: 1 | B2: TC | C2: 20 | D2: =IFERROR(INDEX(MASTER!G:G,MATCH(B2,MASTER!F:F,0)),"") -> HW-CTON-THREAD | E2: =IFERROR(INDEX(MASTER!I:I,MATCH(D2,MASTER!G:G,0)),"") -> NOS | F2: =+C2 -> 20
A3: 2 | B3: B-VB | C3: 100 | D3: =IFERROR(INDEX(MASTER!G:G,MATCH(B3,MASTER!F:F,0)),"") -> FBR-SPK-BR-BRN-KF | E3: =IFERROR(INDEX(MASTER!I:I,MATCH(D3,MASTER!G:G,0)),"") -> MTR | F3: =+C3 -> 100
A4: 3 | B4: TB | D4: =IFERROR(INDEX(MASTER!G:G,MATCH(B4,MASTER!F:F,0)),"") -> RM-THRD-TKT40-BLACK | E4: =IFERROR(INDEX(MASTER!I:I,MATCH(D4,MASTER!G:G,0)),"") -> NOS | F4: =+C4 -> 0
A5: 4 | B5: ET-WH | D5: =IFERROR(INDEX(MASTER!G:G,MATCH(B5,MASTER!F:F,0)),"") -> RML-EDTAPE-WHT-KNIT | E5: =IFERROR(INDEX(MASTER!I:I,MATCH(D5,MASTER!G:G,0)),"") -> MTR | F5: =+C5 -> 0
A6: 5 | D6: =IFERROR(INDEX(MASTER!G:G,MATCH(B6,MASTER!F:F,0)),"") | E6: =IFERROR(INDEX(MASTER!I:I,MATCH(D6,MASTER!G:G,0)),"") | F6: =+C6 -> 0
A7: 6 | D7: =IFERROR(INDEX(MASTER!G:G,MATCH(B7,MASTER!F:F,0)),"") | E7: =IFERROR(INDEX(MASTER!I:I,MATCH(D7,MASTER!G:G,0)),"") | F7: =+C7 -> 0
A8: 7 | D8: =IFERROR(INDEX(MASTER!G:G,MATCH(B8,MASTER!F:F,0)),"") | E8: =IFERROR(INDEX(MASTER!I:I,MATCH(D8,MASTER!G:G,0)),"") | F8: =+C8 -> 0
A9: 8 | D9: =IFERROR(INDEX(MASTER!G:G,MATCH(B9,MASTER!F:F,0)),"") | E9: =IFERROR(INDEX(MASTER!I:I,MATCH(D9,MASTER!G:G,0)),"") | F9: =+C9 -> 0
A10: 9 | D10: =IFERROR(INDEX(MASTER!G:G,MATCH(B10,MASTER!F:F,0)),"") | E10: =IFERROR(INDEX(MASTER!I:I,MATCH(D10,MASTER!G:G,0)),"") | F10: =+C10 -> 0
A11: 10 | D11: =IFERROR(INDEX(MASTER!G:G,MATCH(B11,MASTER!F:F,0)),"") | E11: =IFERROR(INDEX(MASTER!I:I,MATCH(D11,MASTER!G:G,0)),"") | F11: =+C11 -> 0
A12: 11 | D12: =IFERROR(INDEX(MASTER!G:G,MATCH(B12,MASTER!F:F,0)),"") | E12: =IFERROR(INDEX(MASTER!I:I,MATCH(D12,MASTER!G:G,0)),"") | F12: =+C12 -> 0
A13: 12 | D13: =IFERROR(INDEX(MASTER!G:G,MATCH(B13,MASTER!F:F,0)),"") | E13: =IFERROR(INDEX(MASTER!I:I,MATCH(D13,MASTER!G:G,0)),"") | F13: =+C13 -> 0
A14: 13 | D14: =IFERROR(INDEX(MASTER!G:G,MATCH(B14,MASTER!F:F,0)),"") | E14: =IFERROR(INDEX(MASTER!I:I,MATCH(D14,MASTER!G:G,0)),"") | F14: =+C14 -> 0
A15: 14 | D15: =IFERROR(INDEX(MASTER!G:G,MATCH(B15,MASTER!F:F,0)),"") | E15: =IFERROR(INDEX(MASTER!I:I,MATCH(D15,MASTER!G:G,0)),"") | F15: =+C15 -> 0
A16: 15 | D16: =IFERROR(INDEX(MASTER!G:G,MATCH(B16,MASTER!F:F,0)),"") | E16: =IFERROR(INDEX(MASTER!I:I,MATCH(D16,MASTER!G:G,0)),"") | F16: =+C16 -> 0
A17: 16 | D17: =IFERROR(INDEX(MASTER!G:G,MATCH(B17,MASTER!F:F,0)),"") | E17: =IFERROR(INDEX(MASTER!I:I,MATCH(D17,MASTER!G:G,0)),"") | F17: =+C17 -> 0
... A201: 200 | D201: =IFERROR(INDEX(MASTER!G:G,MATCH(B201,MASTER!F:F,0)),"") | E201: =IFERROR(INDEX(MASTER!I:I,MATCH(D201,MASTER!G:G,0)),"") | F201: =+C201 -> 0
B202: TOTAL | C202: =SUM(C2:C201) -> 120 | F202: =SUM(F2:F201) -> 120

Sheet SERGER
A1: SNO | B1: VARIETY | C1: COLOUR | D1: HEIGHT | E1: QTY | F1: CODE | G1: ITEM CODE | H1: QTY
A2: 1 | B2: INS | C2: GRN | D2: 18 | E2: 20 | F2: =B2&"-"&C2&"-"&D2 -> INS-GRN-18 | G2: =IFERROR(INDEX(MASTER!L:L,MATCH(F2,MASTER!K:K,0)),"") -> SFG-INSRBGRN-LTX-BOR-18CM | H2: =+E2 -> 20
A3: 2 | G3: =IFERROR(INDEX(MASTER!L:L,MATCH(E3,MASTER!K:K,0)),"")
A4: 3 | G4: =IFERROR(INDEX(MASTER!L:L,MATCH(E4,MASTER!K:K,0)),"")
A5: 4 | G5: =IFERROR(INDEX(MASTER!L:L,MATCH(E5,MASTER!K:K,0)),"")
A6: 5 | G6: =IFERROR(INDEX(MASTER!L:L,MATCH(E6,MASTER!K:K,0)),"")
A7: 6 | G7: =IFERROR(INDEX(MASTER!L:L,MATCH(E7,MASTER!K:K,0)),"")
A8: 7 | G8: =IFERROR(INDEX(MASTER!L:L,MATCH(E8,MASTER!K:K,0)),"")
A9: 8 | G9: =IFERROR(INDEX(MASTER!L:L,MATCH(E9,MASTER!K:K,0)),"")
A10: 9 | G10: =IFERROR(INDEX(MASTER!L:L,MATCH(E10,MASTER!K:K,0)),"")
A11: 10 | G11: =IFERROR(INDEX(MASTER!L:L,MATCH(E11,MASTER!K:K,0)),"")
A12: 11 | G12: =IFERROR(INDEX(MASTER!L:L,MATCH(E12,MASTER!K:K,0)),"")
A13: 12 | G13: =IFERROR(INDEX(MASTER!L:L,MATCH(E13,MASTER!K:K,0)),"")
A14: 13 | G14: =IFERROR(INDEX(MASTER!L:L,MATCH(E14,MASTER!K:K,0)),"")
... A201: 200 | G201: =IFERROR(INDEX(MASTER!L:L,MATCH(E201,MASTER!K:K,0)),"")
B202: TOTAL | D202: =SUM(D2:D201) -> 18 | E202: TOTAL | H202: =SUM(H2:H201) -> 20

Sheet BORDER
O1: =TODAY() -> 46084 | Q1: =TODAY() -> 46084
O2: SHIFT:
O3: ERP PERSON:
A4: TIME | B4: VARIETY | C4: COLOUR | D4: L | E4: W | F4: H | G4: QTY | H4: L1 | I4: W2 | J4: CODE | K4: ITEM CODE | L4: 1 | N4: ITEM-CODE | O4: QUANTITY | P4: WORKORDER | Q4: RECIEPT | R4: C.TIME | S4: W.TIME | T4: B.TIME | U4: REMARKS
H5: =IF(D5="",0,IF(VALUE(D5)>VALUE(E5),IF(OR(VALUE(D5)=13,VALUE(D5)=20,VALUE(D5)=72,VALUE(D5)=75,VALUE(D5)=78,VALUE(D5)=80,VALUE(D5)=84),D5,IF(VALUE(D5)<72,72,IF(VALUE(D5)<75,75,IF(VALUE(D5)<78,78,IF(VALUE(D5)<80,80,IF(VALUE(D5)<84,84,IF(VALUE(D5)>84,84,""""))))))),IF(OR(VALUE(D5)=13,VALUE(D5)=20,VALUE(D5)=30,VALUE(D5)=33,VALUE(D5)=36,VALUE(D5)=39,VALUE(D5)=42,VALUE(D5)=45,VALUE(D5)=48,VALUE(D5)=51,VALUE(D5)=54,VALUE(D5)=57,VALUE(D5)=60,VALUE(D5)=63,VALUE(D5)=66,VALUE(D5)=69,VALUE(D5)=72),D5,IF(VALUE(D5)<30,30,IF(VALUE(D5)<33,33,IF(VALUE(D5)<36,36,IF(VALUE(D5)<39,39,IF(VALUE(D5)<42,42,IF(VALUE(D5)<45,45,IF(VALUE(D5)<48,48,IF(VALUE(D5)<51,51,IF(VALUE(D5)<54,54,IF(VALUE(D5)<57,57,IF(VALUE(D5)<60,60,IF(VALUE(D5)<63,63,IF(VALUE(D5)<66,66,IF(VALUE(D5)<69,69,IF(VALUE(D5)<72,72,IF(VALUE(D5)>72,72,""""))))))))))))))))))) -> 0 | I5: =IF(E5="",0,IF(VALUE(D5)>VALUE(E5),IF(OR(VALUE(E5)=13,VALUE(E5)=18,VALUE(E5)=30,VALUE(E5)=33,VALUE(E5)=36,VALUE(E5)=39,VALUE(E5)=42,VALUE(E5)=45,VALUE(E5)=48,VALUE(E5)=51,VALUE(E5)=54,VALUE(E5)=57,VALUE(E5)=60,VALUE(E5)=63,VALUE(E5)=66,VALUE(E5)=69,VALUE(E5)=72),E5,IF(VALUE(E5)<30,30,IF(VALUE(E5)<33,33,IF(VALUE(E5)<36,36,IF(VALUE(E5)<39,39,IF(VALUE(E5)<42,42,IF(VALUE(E5)<45,45,IF(VALUE(E5)<48,48,IF(VALUE(E5)<51,51,IF(VALUE(E5)<54,54,IF(VALUE(E5)<57,57,IF(VALUE(E5)<60,60,IF(VALUE(E5)<63,63,IF(VALUE(E5)<66,66,IF(VALUE(E5)<69,69,IF(VALUE(E5)<72,72,IF(VALUE(E5)>72,72,""""))))))))))))))))),IF(OR(VALUE(E5)=13,VALUE(E5)=18,VALUE(E5)=72,VALUE(E5)=75,VALUE(E5)=78,VALUE(E5)=80,VALUE(E5)=84),E5,IF(VALUE(E5)<72,72,IF(VALUE(E5)<75,75,IF(VALUE(E5)<78,78,IF(VALUE(E5)<80,80,IF(VALUE(E5)<84,84,IF(VALUE(E5)>84,84,""""))))))))) -> 0 | J5: =B5&"-"&C5 -> - | K5: =IFERROR(VLOOKUP(J5,MASTER!C:D,2,0),"") | L5: =IFERROR((H5&"X"&I5&"X"&"0"&F5),"") -> 0X0X0 | M5: =CONCATENATE(K5,L5) -> 0X0X0 | N5: =M5 -> 0X0X0 | O5: =+G5 -> 0
H6: =IF(D6="",0,IF(VALUE(D6)>VALUE(E6),IF(OR(VALUE(D6)=13,VALUE(D6)=20,VALUE(D6)=72,VALUE(D6)=75,VALUE(D6)=78,VALUE(D6)=80,VALUE(D6)=84),D6,IF(VALUE(D6)<72,72,IF(VALUE(D6)<75,75,IF(VALUE(D6)<78,78,IF(VALUE(D6)<80,80,IF(VALUE(D6)<84,84,IF(VALUE(D6)>84,84,""""))))))),IF(OR(VALUE(D6)=13,VALUE(D6)=20,VALUE(D6)=30,VALUE(D6)=33,VALUE(D6)=36,VALUE(D6)=39,VALUE(D6)=42,VALUE(D6)=45,VALUE(D6)=48,VALUE(D6)=51,VALUE(D6)=54,VALUE(D6)=57,VALUE(D6)=60,VALUE(D6)=63,VALUE(D6)=66,VALUE(D6)=69,VALUE(D6)=72),D6,IF(VALUE(D6)<30,30,IF(VALUE(D6)<33,33,IF(VALUE(D6)<36,36,IF(VALUE(D6)<39,39,IF(VALUE(D6)<42,42,IF(VALUE(D6)<45,45,IF(VALUE(D6)<48,48,IF(VALUE(D6)<51,51,IF(VALUE(D6)<54,54,IF(VALUE(D6)<57,57,IF(VALUE(D6)<60,60,IF(VALUE(D6)<63,63,IF(VALUE(D6)<66,66,IF(VALUE(D6)<69,69,IF(VALUE(D6)<72,72,IF(VALUE(D6)>72,72,""""))))))))))))))))))) -> 0 | I6: =IF(E6="",0,IF(VALUE(D6)>VALUE(E6),IF(OR(VALUE(E6)=13,VALUE(E6)=18,VALUE(E6)=30,VALUE(E6)=33,VALUE(E6)=36,VALUE(E6)=39,VALUE(E6)=42,VALUE(E6)=45,VALUE(E6)=48,VALUE(E6)=51,VALUE(E6)=54,VALUE(E6)=57,VALUE(E6)=60,VALUE(E6)=63,VALUE(E6)=66,VALUE(E6)=69,VALUE(E6)=72),E6,IF(VALUE(E6)<30,30,IF(VALUE(E6)<33,33,IF(VALUE(E6)<36,36,IF(VALUE(E6)<39,39,IF(VALUE(E6)<42,42,IF(VALUE(E6)<45,45,IF(VALUE(E6)<48,48,IF(VALUE(E6)<51,51,IF(VALUE(E6)<54,54,IF(VALUE(E6)<57,57,IF(VALUE(E6)<60,60,IF(VALUE(E6)<63,63,IF(VALUE(E6)<66,66,IF(VALUE(E6)<69,69,IF(VALUE(E6)<72,72,IF(VALUE(E6)>72,72,""""))))))))))))))))),IF(OR(VALUE(E6)=13,VALUE(E6)=18,VALUE(E6)=72,VALUE(E6)=75,VALUE(E6)=78,VALUE(E6)=80,VALUE(E6)=84),E6,IF(VALUE(E6)<72,72,IF(VALUE(E6)<75,75,IF(VALUE(E6)<78,78,IF(VALUE(E6)<80,80,IF(VALUE(E6)<84,84,IF(VALUE(E6)>84,84,""""))))))))) -> 0 | J6: =B6&"-"&C6 -> - | K6: =IFERROR(VLOOKUP(J6,MASTER!C:D,2,0),"") | L6: =IFERROR((H6&"X"&I6&"X"&"0"&F6),"") -> 0X0X0 | M6: =CONCATENATE(K6,L6) -> 0X0X0 | N6: =M6 -> 0X0X0 | O6: =+G6 -> 0
H7: =IF(D7="",0,IF(VALUE(D7)>VALUE(E7),IF(OR(VALUE(D7)=13,VALUE(D7)=20,VALUE(D7)=72,VALUE(D7)=75,VALUE(D7)=78,VALUE(D7)=80,VALUE(D7)=84),D7,IF(VALUE(D7)<72,72,IF(VALUE(D7)<75,75,IF(VALUE(D7)<78,78,IF(VALUE(D7)<80,80,IF(VALUE(D7)<84,84,IF(VALUE(D7)>84,84,""""))))))),IF(OR(VALUE(D7)=13,VALUE(D7)=20,VALUE(D7)=30,VALUE(D7)=33,VALUE(D7)=36,VALUE(D7)=39,VALUE(D7)=42,VALUE(D7)=45,VALUE(D7)=48,VALUE(D7)=51,VALUE(D7)=54,VALUE(D7)=57,VALUE(D7)=60,VALUE(D7)=63,VALUE(D7)=66,VALUE(D7)=69,VALUE(D7)=72),D7,IF(VALUE(D7)<30,30,IF(VALUE(D7)<33,33,IF(VALUE(D7)<36,36,IF(VALUE(D7)<39,39,IF(VALUE(D7)<42,42,IF(VALUE(D7)<45,45,IF(VALUE(D7)<48,48,IF(VALUE(D7)<51,51,IF(VALUE(D7)<54,54,IF(VALUE(D7)<57,57,IF(VALUE(D7)<60,60,IF(VALUE(D7)<63,63,IF(VALUE(D7)<66,66,IF(VALUE(D7)<69,69,IF(VALUE(D7)<72,72,IF(VALUE(D7)>72,72,""""))))))))))))))))))) -> 0 | I7: =IF(E7="",0,IF(VALUE(D7)>VALUE(E7),IF(OR(VALUE(E7)=13,VALUE(E7)=18,VALUE(E7)=30,VALUE(E7)=33,VALUE(E7)=36,VALUE(E7)=39,VALUE(E7)=42,VALUE(E7)=45,VALUE(E7)=48,VALUE(E7)=51,VALUE(E7)=54,VALUE(E7)=57,VALUE(E7)=60,VALUE(E7)=63,VALUE(E7)=66,VALUE(E7)=69,VALUE(E7)=72),E7,IF(VALUE(E7)<30,30,IF(VALUE(E7)<33,33,IF(VALUE(E7)<36,36,IF(VALUE(E7)<39,39,IF(VALUE(E7)<42,42,IF(VALUE(E7)<45,45,IF(VALUE(E7)<48,48,IF(VALUE(E7)<51,51,IF(VALUE(E7)<54,54,IF(VALUE(E7)<57,57,IF(VALUE(E7)<60,60,IF(VALUE(E7)<63,63,IF(VALUE(E7)<66,66,IF(VALUE(E7)<69,69,IF(VALUE(E7)<72,72,IF(VALUE(E7)>72,72,""""))))))))))))))))),IF(OR(VALUE(E7)=13,VALUE(E7)=18,VALUE(E7)=72,VALUE(E7)=75,VALUE(E7)=78,VALUE(E7)=80,VALUE(E7)=84),E7,IF(VALUE(E7)<72,72,IF(VALUE(E7)<75,75,IF(VALUE(E7)<78,78,IF(VALUE(E7)<80,80,IF(VALUE(E7)<84,84,IF(VALUE(E7)>84,84,""""))))))))) -> 0 | J7: =B7&"-"&C7 -> - | K7: =IFERROR(VLOOKUP(J7,MASTER!C:D,2,0),"") | L7: =IFERROR((H7&"X"&I7&"X"&"0"&F7),"") -> 0X0X0 | M7: =CONCATENATE(K7,L7) -> 0X0X0 | N7: =M7 -> 0X0X0 | O7: =+G7 -> 0
H8: =IF(D8="",0,IF(VALUE(D8)>VALUE(E8),IF(OR(VALUE(D8)=13,VALUE(D8)=20,VALUE(D8)=72,VALUE(D8)=75,VALUE(D8)=78,VALUE(D8)=80,VALUE(D8)=84),D8,IF(VALUE(D8)<72,72,IF(VALUE(D8)<75,75,IF(VALUE(D8)<78,78,IF(VALUE(D8)<80,80,IF(VALUE(D8)<84,84,IF(VALUE(D8)>84,84,""""))))))),IF(OR(VALUE(D8)=13,VALUE(D8)=20,VALUE(D8)=30,VALUE(D8)=33,VALUE(D8)=36,VALUE(D8)=39,VALUE(D8)=42,VALUE(D8)=45,VALUE(D8)=48,VALUE(D8)=51,VALUE(D8)=54,VALUE(D8)=57,VALUE(D8)=60,VALUE(D8)=63,VALUE(D8)=66,VALUE(D8)=69,VALUE(D8)=72),D8,IF(VALUE(D8)<30,30,IF(VALUE(D8)<33,33,IF(VALUE(D8)<36,36,IF(VALUE(D8)<39,39,IF(VALUE(D8)<42,42,IF(VALUE(D8)<45,45,IF(VALUE(D8)<48,48,IF(VALUE(D8)<51,51,IF(VALUE(D8)<54,54,IF(VALUE(D8)<57,57,IF(VALUE(D8)<60,60,IF(VALUE(D8)<63,63,IF(VALUE(D8)<66,66,IF(VALUE(D8)<69,69,IF(VALUE(D8)<72,72,IF(VALUE(D8)>72,72,""""))))))))))))))))))) -> 0 | I8: =IF(E8="",0,IF(VALUE(D8)>VALUE(E8),IF(OR(VALUE(E8)=13,VALUE(E8)=18,VALUE(E8)=30,VALUE(E8)=33,VALUE(E8)=36,VALUE(E8)=39,VALUE(E8)=42,VALUE(E8)=45,VALUE(E8)=48,VALUE(E8)=51,VALUE(E8)=54,VALUE(E8)=57,VALUE(E8)=60,VALUE(E8)=63,VALUE(E8)=66,VALUE(E8)=69,VALUE(E8)=72),E8,IF(VALUE(E8)<30,30,IF(VALUE(E8)<33,33,IF(VALUE(E8)<36,36,IF(VALUE(E8)<39,39,IF(VALUE(E8)<42,42,IF(VALUE(E8)<45,45,IF(VALUE(E8)<48,48,IF(VALUE(E8)<51,51,IF(VALUE(E8)<54,54,IF(VALUE(E8)<57,57,IF(VALUE(E8)<60,60,IF(VALUE(E8)<63,63,IF(VALUE(E8)<66,66,IF(VALUE(E8)<69,69,IF(VALUE(E8)<72,72,IF(VALUE(E8)>72,72,""""))))))))))))))))),IF(OR(VALUE(E8)=13,VALUE(E8)=18,VALUE(E8)=72,VALUE(E8)=75,VALUE(E8)=78,VALUE(E8)=80,VALUE(E8)=84),E8,IF(VALUE(E8)<72,72,IF(VALUE(E8)<75,75,IF(VALUE(E8)<78,78,IF(VALUE(E8)<80,80,IF(VALUE(E8)<84,84,IF(VALUE(E8)>84,84,""""))))))))) -> 0 | J8: =B8&"-"&C8 -> - | K8: =IFERROR(VLOOKUP(J8,MASTER!C:D,2,0),"") | L8: =IFERROR((H8&"X"&I8&"X"&"0"&F8),"") -> 0X0X0 | M8: =CONCATENATE(K8,L8) -> 0X0X0 | N8: =M8 -> 0X0X0 | O8: =+G8 -> 0
H9: =IF(D9="",0,IF(VALUE(D9)>VALUE(E9),IF(OR(VALUE(D9)=13,VALUE(D9)=20,VALUE(D9)=72,VALUE(D9)=75,VALUE(D9)=78,VALUE(D9)=80,VALUE(D9)=84),D9,IF(VALUE(D9)<72,72,IF(VALUE(D9)<75,75,IF(VALUE(D9)<78,78,IF(VALUE(D9)<80,80,IF(VALUE(D9)<84,84,IF(VALUE(D9)>84,84,""""))))))),IF(OR(VALUE(D9)=13,VALUE(D9)=20,VALUE(D9)=30,VALUE(D9)=33,VALUE(D9)=36,VALUE(D9)=39,VALUE(D9)=42,VALUE(D9)=45,VALUE(D9)=48,VALUE(D9)=51,VALUE(D9)=54,VALUE(D9)=57,VALUE(D9)=60,VALUE(D9)=63,VALUE(D9)=66,VALUE(D9)=69,VALUE(D9)=72),D9,IF(VALUE(D9)<30,30,IF(VALUE(D9)<33,33,IF(VALUE(D9)<36,36,IF(VALUE(D9)<39,39,IF(VALUE(D9)<42,42,IF(VALUE(D9)<45,45,IF(VALUE(D9)<48,48,IF(VALUE(D9)<51,51,IF(VALUE(D9)<54,54,IF(VALUE(D9)<57,57,IF(VALUE(D9)<60,60,IF(VALUE(D9)<63,63,IF(VALUE(D9)<66,66,IF(VALUE(D9)<69,69,IF(VALUE(D9)<72,72,IF(VALUE(D9)>72,72,""""))))))))))))))))))) -> 0 | I9: =IF(E9="",0,IF(VALUE(D9)>VALUE(E9),IF(OR(VALUE(E9)=13,VALUE(E9)=18,VALUE(E9)=30,VALUE(E9)=33,VALUE(E9)=36,VALUE(E9)=39,VALUE(E9)=42,VALUE(E9)=45,VALUE(E9)=48,VALUE(E9)=51,VALUE(E9)=54,VALUE(E9)=57,VALUE(E9)=60,VALUE(E9)=63,VALUE(E9)=66,VALUE(E9)=69,VALUE(E9)=72),E9,IF(VALUE(E9)<30,30,IF(VALUE(E9)<33,33,IF(VALUE(E9)<36,36,IF(VALUE(E9)<39,39,IF(VALUE(E9)<42,42,IF(VALUE(E9)<45,45,IF(VALUE(E9)<48,48,IF(VALUE(E9)<51,51,IF(VALUE(E9)<54,54,IF(VALUE(E9)<57,57,IF(VALUE(E9)<60,60,IF(VALUE(E9)<63,63,IF(VALUE(E9)<66,66,IF(VALUE(E9)<69,69,IF(VALUE(E9)<72,72,IF(VALUE(E9)>72,72,""""))))))))))))))))),IF(OR(VALUE(E9)=13,VALUE(E9)=18,VALUE(E9)=72,VALUE(E9)=75,VALUE(E9)=78,VALUE(E9)=80,VALUE(E9)=84),E9,IF(VALUE(E9)<72,72,IF(VALUE(E9)<75,75,IF(VALUE(E9)<78,78,IF(VALUE(E9)<80,80,IF(VALUE(E9)<84,84,IF(VALUE(E9)>84,84,""""))))))))) -> 0 | J9: =B9&"-"&C9 -> - | K9: =IFERROR(VLOOKUP(J9,MASTER!C:D,2,0),"") | L9: =IFERROR((H9&"X"&I9&"X"&"0"&F9),"") -> 0X0X0 | M9: =CONCATENATE(K9,L9) -> 0X0X0 | N9: =M9 -> 0X0X0 | O9: =+G9 -> 0
H10: =IF(D10="",0,IF(VALUE(D10)>VALUE(E10),IF(OR(VALUE(D10)=13,VALUE(D10)=20,VALUE(D10)=72,VALUE(D10)=75,VALUE(D10)=78,VALUE(D10)=80,VALUE(D10)=84),D10,IF(VALUE(D10)<72,72,IF(VALUE(D10)<75,75,IF(VALUE(D10)<78,78,IF(VALUE(D10)<80,80,IF(VALUE(D10)<84,84,IF(VALUE(D10)>84,84,""""))))))),IF(OR(VALUE(D10)=13,VALUE(D10)=20,VALUE(D10)=30,VALUE(D10)=33,VALUE(D10)=36,VALUE(D10)=39,VALUE(D10)=42,VALUE(D10)=45,VALUE(D10)=48,VALUE(D10)=51,VALUE(D10)=54,VALUE(D10)=57,VALUE(D10)=60,VALUE(D10)=63,VALUE(D10)=66,VALUE(D10)=69,VALUE(D10)=72),D10,IF(VALUE(D10)<30,30,IF(VALUE(D10)<33,33,IF(VALUE(D10)<36,36,IF(VALUE(D10)<39,39,IF(VALUE(D10)<42,42,IF(VALUE(D10)<45,45,IF(VALUE(D10)<48,48,IF(VALUE(D10)<51,51,IF(VALUE(D10)<54,54,IF(VALUE(D10)<57,57,IF(VALUE(D10)<60,60,IF(VALUE(D10)<63,63,IF(VALUE(D10)<66,66,IF(VALUE(D10)<69,69,IF(VALUE(D10)<72,72,IF(VALUE(D10)>72,72,""""))))))))))))))))))) -> 0 | I10: =IF(E10="",0,IF(VALUE(D10)>VALUE(E10),IF(OR(VALUE(E10)=13,VALUE(E10)=18,VALUE(E10)=30,VALUE(E10)=33,VALUE(E10)=36,VALUE(E10)=39,VALUE(E10)=42,VALUE(E10)=45,VALUE(E10)=48,VALUE(E10)=51,VALUE(E10)=54,VALUE(E10)=57,VALUE(E10)=60,VALUE(E10)=63,VALUE(E10)=66,VALUE(E10)=69,VALUE(E10)=72),E10,IF(VALUE(E10)<30,30,IF(VALUE(E10)<33,33,IF(VALUE(E10)<36,36,IF(VALUE(E10)<39,39,IF(VALUE(E10)<42,42,IF(VALUE(E10)<45,45,IF(VALUE(E10)<48,48,IF(VALUE(E10)<51,51,IF(VALUE(E10)<54,54,IF(VALUE(E10)<57,57,IF(VALUE(E10)<60,60,IF(VALUE(E10)<63,63,IF(VALUE(E10)<66,66,IF(VALUE(E10)<69,69,IF(VALUE(E10)<72,72,IF(VALUE(E10)>72,72,""""))))))))))))))))),IF(OR(VALUE(E10)=13,VALUE(E10)=18,VALUE(E10)=72,VALUE(E10)=75,VALUE(E10)=78,VALUE(E10)=80,VALUE(E10)=84),E10,IF(VALUE(E10)<72,72,IF(VALUE(E10)<75,75,IF(VALUE(E10)<78,78,IF(VALUE(E10)<80,80,IF(VALUE(E10)<84,84,IF(VALUE(E10)>84,84,""""))))))))) -> 0 | J10: =B10&"-"&C10 -> - | K10: =IFERROR(VLOOKUP(J10,MASTER!C:D,2,0),"") | L10: =IFERROR((H10&"X"&I10&"X"&"0"&F10),"") -> 0X0X0 | M10: =CONCATENATE(K10,L10) -> 0X0X0 | N10: =M10 -> 0X0X0 | O10: =+G10 -> 0
H11: =IF(D11="",0,IF(VALUE(D11)>VALUE(E11),IF(OR(VALUE(D11)=13,VALUE(D11)=20,VALUE(D11)=72,VALUE(D11)=75,VALUE(D11)=78,VALUE(D11)=80,VALUE(D11)=84),D11,IF(VALUE(D11)<72,72,IF(VALUE(D11)<75,75,IF(VALUE(D11)<78,78,IF(VALUE(D11)<80,80,IF(VALUE(D11)<84,84,IF(VALUE(D11)>84,84,""""))))))),IF(OR(VALUE(D11)=13,VALUE(D11)=20,VALUE(D11)=30,VALUE(D11)=33,VALUE(D11)=36,VALUE(D11)=39,VALUE(D11)=42,VALUE(D11)=45,VALUE(D11)=48,VALUE(D11)=51,VALUE(D11)=54,VALUE(D11)=57,VALUE(D11)=60,VALUE(D11)=63,VALUE(D11)=66,VALUE(D11)=69,VALUE(D11)=72),D11,IF(VALUE(D11)<30,30,IF(VALUE(D11)<33,33,IF(VALUE(D11)<36,36,IF(VALUE(D11)<39,39,IF(VALUE(D11)<42,42,IF(VALUE(D11)<45,45,IF(VALUE(D11)<48,48,IF(VALUE(D11)<51,51,IF(VALUE(D11)<54,54,IF(VALUE(D11)<57,57,IF(VALUE(D11)<60,60,IF(VALUE(D11)<63,63,IF(VALUE(D11)<66,66,IF(VALUE(D11)<69,69,IF(VALUE(D11)<72,72,IF(VALUE(D11)>72,72,""""))))))))))))))))))) -> 0 | I11: =IF(E11="",0,IF(VALUE(D11)>VALUE(E11),IF(OR(VALUE(E11)=13,VALUE(E11)=18,VALUE(E11)=30,VALUE(E11)=33,VALUE(E11)=36,VALUE(E11)=39,VALUE(E11)=42,VALUE(E11)=45,VALUE(E11)=48,VALUE(E11)=51,VALUE(E11)=54,VALUE(E11)=57,VALUE(E11)=60,VALUE(E11)=63,VALUE(E11)=66,VALUE(E11)=69,VALUE(E11)=72),E11,IF(VALUE(E11)<30,30,IF(VALUE(E11)<33,33,IF(VALUE(E11)<36,36,IF(VALUE(E11)<39,39,IF(VALUE(E11)<42,42,IF(VALUE(E11)<45,45,IF(VALUE(E11)<48,48,IF(VALUE(E11)<51,51,IF(VALUE(E11)<54,54,IF(VALUE(E11)<57,57,IF(VALUE(E11)<60,60,IF(VALUE(E11)<63,63,IF(VALUE(E11)<66,66,IF(VALUE(E11)<69,69,IF(VALUE(E11)<72,72,IF(VALUE(E11)>72,72,""""))))))))))))))))),IF(OR(VALUE(E11)=13,VALUE(E11)=18,VALUE(E11)=72,VALUE(E11)=75,VALUE(E11)=78,VALUE(E11)=80,VALUE(E11)=84),E11,IF(VALUE(E11)<72,72,IF(VALUE(E11)<75,75,IF(VALUE(E11)<78,78,IF(VALUE(E11)<80,80,IF(VALUE(E11)<84,84,IF(VALUE(E11)>84,84,""""))))))))) -> 0 | J11: =B11&"-"&C11 -> - | K11: =IFERROR(VLOOKUP(J11,MASTER!C:D,2,0),"") | L11: =IFERROR((H11&"X"&I11&"X"&"0"&F11),"") -> 0X0X0 | M11: =CONCATENATE(K11,L11) -> 0X0X0 | N11: =M11 -> 0X0X0 | O11: =+G11 -> 0
H12: =IF(D12="",0,IF(VALUE(D12)>VALUE(E12),IF(OR(VALUE(D12)=13,VALUE(D12)=20,VALUE(D12)=72,VALUE(D12)=75,VALUE(D12)=78,VALUE(D12)=80,VALUE(D12)=84),D12,IF(VALUE(D12)<72,72,IF(VALUE(D12)<75,75,IF(VALUE(D12)<78,78,IF(VALUE(D12)<80,80,IF(VALUE(D12)<84,84,IF(VALUE(D12)>84,84,""""))))))),IF(OR(VALUE(D12)=13,VALUE(D12)=20,VALUE(D12)=30,VALUE(D12)=33,VALUE(D12)=36,VALUE(D12)=39,VALUE(D12)=42,VALUE(D12)=45,VALUE(D12)=48,VALUE(D12)=51,VALUE(D12)=54,VALUE(D12)=57,VALUE(D12)=60,VALUE(D12)=63,VALUE(D12)=66,VALUE(D12)=69,VALUE(D12)=72),D12,IF(VALUE(D12)<30,30,IF(VALUE(D12)<33,33,IF(VALUE(D12)<36,36,IF(VALUE(D12)<39,39,IF(VALUE(D12)<42,42,IF(VALUE(D12)<45,45,IF(VALUE(D12)<48,48,IF(VALUE(D12)<51,51,IF(VALUE(D12)<54,54,IF(VALUE(D12)<57,57,IF(VALUE(D12)<60,60,IF(VALUE(D12)<63,63,IF(VALUE(D12)<66,66,IF(VALUE(D12)<69,69,IF(VALUE(D12)<72,72,IF(VALUE(D12)>72,72,""""))))))))))))))))))) -> 0 | I12: =IF(E12="",0,IF(VALUE(D12)>VALUE(E12),IF(OR(VALUE(E12)=13,VALUE(E12)=18,VALUE(E12)=30,VALUE(E12)=33,VALUE(E12)=36,VALUE(E12)=39,VALUE(E12)=42,VALUE(E12)=45,VALUE(E12)=48,VALUE(E12)=51,VALUE(E12)=54,VALUE(E12)=57,VALUE(E12)=60,VALUE(E12)=63,VALUE(E12)=66,VALUE(E12)=69,VALUE(E12)=72),E12,IF(VALUE(E12)<30,30,IF(VALUE(E12)<33,33,IF(VALUE(E12)<36,36,IF(VALUE(E12)<39,39,IF(VALUE(E12)<42,42,IF(VALUE(E12)<45,45,IF(VALUE(E12)<48,48,IF(VALUE(E12)<51,51,IF(VALUE(E12)<54,54,IF(VALUE(E12)<57,57,IF(VALUE(E12)<60,60,IF(VALUE(E12)<63,63,IF(VALUE(E12)<66,66,IF(VALUE(E12)<69,69,IF(VALUE(E12)<72,72,IF(VALUE(E12)>72,72,""""))))))))))))))))),IF(OR(VALUE(E12)=13,VALUE(E12)=18,VALUE(E12)=72,VALUE(E12)=75,VALUE(E12)=78,VALUE(E12)=80,VALUE(E12)=84),E12,IF(VALUE(E12)<72,72,IF(VALUE(E12)<75,75,IF(VALUE(E12)<78,78,IF(VALUE(E12)<80,80,IF(VALUE(E12)<84,84,IF(VALUE(E12)>84,84,""""))))))))) -> 0 | J12: =B12&"-"&C12 -> - | K12: =IFERROR(VLOOKUP(J12,MASTER!C:D,2,0),"") | L12: =IFERROR((H12&"X"&I12&"X"&"0"&F12),"") -> 0X0X0 | M12: =CONCATENATE(K12,L12) -> 0X0X0 | N12: =M12 -> 0X0X0 | O12: =+G12 -> 0
H13: =IF(D13="",0,IF(VALUE(D13)>VALUE(E13),IF(OR(VALUE(D13)=13,VALUE(D13)=20,VALUE(D13)=72,VALUE(D13)=75,VALUE(D13)=78,VALUE(D13)=80,VALUE(D13)=84),D13,IF(VALUE(D13)<72,72,IF(VALUE(D13)<75,75,IF(VALUE(D13)<78,78,IF(VALUE(D13)<80,80,IF(VALUE(D13)<84,84,IF(VALUE(D13)>84,84,""""))))))),IF(OR(VALUE(D13)=13,VALUE(D13)=20,VALUE(D13)=30,VALUE(D13)=33,VALUE(D13)=36,VALUE(D13)=39,VALUE(D13)=42,VALUE(D13)=45,VALUE(D13)=48,VALUE(D13)=51,VALUE(D13)=54,VALUE(D13)=57,VALUE(D13)=60,VALUE(D13)=63,VALUE(D13)=66,VALUE(D13)=69,VALUE(D13)=72),D13,IF(VALUE(D13)<30,30,IF(VALUE(D13)<33,33,IF(VALUE(D13)<36,36,IF(VALUE(D13)<39,39,IF(VALUE(D13)<42,42,IF(VALUE(D13)<45,45,IF(VALUE(D13)<48,48,IF(VALUE(D13)<51,51,IF(VALUE(D13)<54,54,IF(VALUE(D13)<57,57,IF(VALUE(D13)<60,60,IF(VALUE(D13)<63,63,IF(VALUE(D13)<66,66,IF(VALUE(D13)<69,69,IF(VALUE(D13)<72,72,IF(VALUE(D13)>72,72,""""))))))))))))))))))) -> 0 | I13: =IF(E13="",0,IF(VALUE(D13)>VALUE(E13),IF(OR(VALUE(E13)=13,VALUE(E13)=18,VALUE(E13)=30,VALUE(E13)=33,VALUE(E13)=36,VALUE(E13)=39,VALUE(E13)=42,VALUE(E13)=45,VALUE(E13)=48,VALUE(E13)=51,VALUE(E13)=54,VALUE(E13)=57,VALUE(E13)=60,VALUE(E13)=63,VALUE(E13)=66,VALUE(E13)=69,VALUE(E13)=72),E13,IF(VALUE(E13)<30,30,IF(VALUE(E13)<33,33,IF(VALUE(E13)<36,36,IF(VALUE(E13)<39,39,IF(VALUE(E13)<42,42,IF(VALUE(E13)<45,45,IF(VALUE(E13)<48,48,IF(VALUE(E13)<51,51,IF(VALUE(E13)<54,54,IF(VALUE(E13)<57,57,IF(VALUE(E13)<60,60,IF(VALUE(E13)<63,63,IF(VALUE(E13)<66,66,IF(VALUE(E13)<69,69,IF(VALUE(E13)<72,72,IF(VALUE(E13)>72,72,""""))))))))))))))))),IF(OR(VALUE(E13)=13,VALUE(E13)=18,VALUE(E13)=72,VALUE(E13)=75,VALUE(E13)=78,VALUE(E13)=80,VALUE(E13)=84),E13,IF(VALUE(E13)<72,72,IF(VALUE(E13)<75,75,IF(VALUE(E13)<78,78,IF(VALUE(E13)<80,80,IF(VALUE(E13)<84,84,IF(VALUE(E13)>84,84,""""))))))))) -> 0 | J13: =B13&"-"&C13 -> - | K13: =IFERROR(VLOOKUP(J13,MASTER!C:D,2,0),"") | L13: =IFERROR((H13&"X"&I13&"X"&"0"&F13),"") -> 0X0X0 | M13: =CONCATENATE(K13,L13) -> 0X0X0 | N13: =M13 -> 0X0X0 | O13: =+G13 -> 0
H14: =IF(D14="",0,IF(VALUE(D14)>VALUE(E14),IF(OR(VALUE(D14)=13,VALUE(D14)=20,VALUE(D14)=72,VALUE(D14)=75,VALUE(D14)=78,VALUE(D14)=80,VALUE(D14)=84),D14,IF(VALUE(D14)<72,72,IF(VALUE(D14)<75,75,IF(VALUE(D14)<78,78,IF(VALUE(D14)<80,80,IF(VALUE(D14)<84,84,IF(VALUE(D14)>84,84,""""))))))),IF(OR(VALUE(D14)=13,VALUE(D14)=20,VALUE(D14)=30,VALUE(D14)=33,VALUE(D14)=36,VALUE(D14)=39,VALUE(D14)=42,VALUE(D14)=45,VALUE(D14)=48,VALUE(D14)=51,VALUE(D14)=54,VALUE(D14)=57,VALUE(D14)=60,VALUE(D14)=63,VALUE(D14)=66,VALUE(D14)=69,VALUE(D14)=72),D14,IF(VALUE(D14)<30,30,IF(VALUE(D14)<33,33,IF(VALUE(D14)<36,36,IF(VALUE(D14)<39,39,IF(VALUE(D14)<42,42,IF(VALUE(D14)<45,45,IF(VALUE(D14)<48,48,IF(VALUE(D14)<51,51,IF(VALUE(D14)<54,54,IF(VALUE(D14)<57,57,IF(VALUE(D14)<60,60,IF(VALUE(D14)<63,63,IF(VALUE(D14)<66,66,IF(VALUE(D14)<69,69,IF(VALUE(D14)<72,72,IF(VALUE(D14)>72,72,""""))))))))))))))))))) -> 0 | I14: =IF(E14="",0,IF(VALUE(D14)>VALUE(E14),IF(OR(VALUE(E14)=13,VALUE(E14)=18,VALUE(E14)=30,VALUE(E14)=33,VALUE(E14)=36,VALUE(E14)=39,VALUE(E14)=42,VALUE(E14)=45,VALUE(E14)=48,VALUE(E14)=51,VALUE(E14)=54,VALUE(E14)=57,VALUE(E14)=60,VALUE(E14)=63,VALUE(E14)=66,VALUE(E14)=69,VALUE(E14)=72),E14,IF(VALUE(E14)<30,30,IF(VALUE(E14)<33,33,IF(VALUE(E14)<36,36,IF(VALUE(E14)<39,39,IF(VALUE(E14)<42,42,IF(VALUE(E14)<45,45,IF(VALUE(E14)<48,48,IF(VALUE(E14)<51,51,IF(VALUE(E14)<54,54,IF(VALUE(E14)<57,57,IF(VALUE(E14)<60,60,IF(VALUE(E14)<63,63,IF(VALUE(E14)<66,66,IF(VALUE(E14)<69,69,IF(VALUE(E14)<72,72,IF(VALUE(E14)>72,72,""""))))))))))))))))),IF(OR(VALUE(E14)=13,VALUE(E14)=18,VALUE(E14)=72,VALUE(E14)=75,VALUE(E14)=78,VALUE(E14)=80,VALUE(E14)=84),E14,IF(VALUE(E14)<72,72,IF(VALUE(E14)<75,75,IF(VALUE(E14)<78,78,IF(VALUE(E14)<80,80,IF(VALUE(E14)<84,84,IF(VALUE(E14)>84,84,""""))))))))) -> 0 | J14: =B14&"-"&C14 -> - | K14: =IFERROR(VLOOKUP(J14,MASTER!C:D,2,0),"") | L14: =IFERROR((H14&"X"&I14&"X"&"0"&F14),"") -> 0X0X0 | M14: =CONCATENATE(K14,L14) -> 0X0X0 | N14: =M14 -> 0X0X0 | O14: =+G14 -> 0
H15: =IF(D15="",0,IF(VALUE(D15)>VALUE(E15),IF(OR(VALUE(D15)=13,VALUE(D15)=20,VALUE(D15)=72,VALUE(D15)=75,VALUE(D15)=78,VALUE(D15)=80,VALUE(D15)=84),D15,IF(VALUE(D15)<72,72,IF(VALUE(D15)<75,75,IF(VALUE(D15)<78,78,IF(VALUE(D15)<80,80,IF(VALUE(D15)<84,84,IF(VALUE(D15)>84,84,""""))))))),IF(OR(VALUE(D15)=13,VALUE(D15)=20,VALUE(D15)=30,VALUE(D15)=33,VALUE(D15)=36,VALUE(D15)=39,VALUE(D15)=42,VALUE(D15)=45,VALUE(D15)=48,VALUE(D15)=51,VALUE(D15)=54,VALUE(D15)=57,VALUE(D15)=60,VALUE(D15)=63,VALUE(D15)=66,VALUE(D15)=69,VALUE(D15)=72),D15,IF(VALUE(D15)<30,30,IF(VALUE(D15)<33,33,IF(VALUE(D15)<36,36,IF(VALUE(D15)<39,39,IF(VALUE(D15)<42,42,IF(VALUE(D15)<45,45,IF(VALUE(D15)<48,48,IF(VALUE(D15)<51,51,IF(VALUE(D15)<54,54,IF(VALUE(D15)<57,57,IF(VALUE(D15)<60,60,IF(VALUE(D15)<63,63,IF(VALUE(D15)<66,66,IF(VALUE(D15)<69,69,IF(VALUE(D15)<72,72,IF(VALUE(D15)>72,72,""""))))))))))))))))))) -> 0 | I15: =IF(E15="",0,IF(VALUE(D15)>VALUE(E15),IF(OR(VALUE(E15)=13,VALUE(E15)=18,VALUE(E15)=30,VALUE(E15)=33,VALUE(E15)=36,VALUE(E15)=39,VALUE(E15)=42,VALUE(E15)=45,VALUE(E15)=48,VALUE(E15)=51,VALUE(E15)=54,VALUE(E15)=57,VALUE(E15)=60,VALUE(E15)=63,VALUE(E15)=66,VALUE(E15)=69,VALUE(E15)=72),E15,IF(VALUE(E15)<30,30,IF(VALUE(E15)<33,33,IF(VALUE(E15)<36,36,IF(VALUE(E15)<39,39,IF(VALUE(E15)<42,42,IF(VALUE(E15)<45,45,IF(VALUE(E15)<48,48,IF(VALUE(E15)<51,51,IF(VALUE(E15)<54,54,IF(VALUE(E15)<57,57,IF(VALUE(E15)<60,60,IF(VALUE(E15)<63,63,IF(VALUE(E15)<66,66,IF(VALUE(E15)<69,69,IF(VALUE(E15)<72,72,IF(VALUE(E15)>72,72,""""))))))))))))))))),IF(OR(VALUE(E15)=13,VALUE(E15)=18,VALUE(E15)=72,VALUE(E15)=75,VALUE(E15)=78,VALUE(E15)=80,VALUE(E15)=84),E15,IF(VALUE(E15)<72,72,IF(VALUE(E15)<75,75,IF(VALUE(E15)<78,78,IF(VALUE(E15)<80,80,IF(VALUE(E15)<84,84,IF(VALUE(E15)>84,84,""""))))))))) -> 0 | J15: =B15&"-"&C15 -> - | K15: =IFERROR(VLOOKUP(J15,MASTER!C:D,2,0),"") | L15: =IFERROR((H15&"X"&I15&"X"&"0"&F15),"") -> 0X0X0 | M15: =CONCATENATE(K15,L15) -> 0X0X0 | N15: =M15 -> 0X0X0 | O15: =+G15 -> 0
H16: =IF(D16="",0,IF(VALUE(D16)>VALUE(E16),IF(OR(VALUE(D16)=13,VALUE(D16)=20,VALUE(D16)=72,VALUE(D16)=75,VALUE(D16)=78,VALUE(D16)=80,VALUE(D16)=84),D16,IF(VALUE(D16)<72,72,IF(VALUE(D16)<75,75,IF(VALUE(D16)<78,78,IF(VALUE(D16)<80,80,IF(VALUE(D16)<84,84,IF(VALUE(D16)>84,84,""""))))))),IF(OR(VALUE(D16)=13,VALUE(D16)=20,VALUE(D16)=30,VALUE(D16)=33,VALUE(D16)=36,VALUE(D16)=39,VALUE(D16)=42,VALUE(D16)=45,VALUE(D16)=48,VALUE(D16)=51,VALUE(D16)=54,VALUE(D16)=57,VALUE(D16)=60,VALUE(D16)=63,VALUE(D16)=66,VALUE(D16)=69,VALUE(D16)=72),D16,IF(VALUE(D16)<30,30,IF(VALUE(D16)<33,33,IF(VALUE(D16)<36,36,IF(VALUE(D16)<39,39,IF(VALUE(D16)<42,42,IF(VALUE(D16)<45,45,IF(VALUE(D16)<48,48,IF(VALUE(D16)<51,51,IF(VALUE(D16)<54,54,IF(VALUE(D16)<57,57,IF(VALUE(D16)<60,60,IF(VALUE(D16)<63,63,IF(VALUE(D16)<66,66,IF(VALUE(D16)<69,69,IF(VALUE(D16)<72,72,IF(VALUE(D16)>72,72,""""))))))))))))))))))) -> 0 | I16: =IF(E16="",0,IF(VALUE(D16)>VALUE(E16),IF(OR(VALUE(E16)=13,VALUE(E16)=18,VALUE(E16)=30,VALUE(E16)=33,VALUE(E16)=36,VALUE(E16)=39,VALUE(E16)=42,VALUE(E16)=45,VALUE(E16)=48,VALUE(E16)=51,VALUE(E16)=54,VALUE(E16)=57,VALUE(E16)=60,VALUE(E16)=63,VALUE(E16)=66,VALUE(E16)=69,VALUE(E16)=72),E16,IF(VALUE(E16)<30,30,IF(VALUE(E16)<33,33,IF(VALUE(E16)<36,36,IF(VALUE(E16)<39,39,IF(VALUE(E16)<42,42,IF(VALUE(E16)<45,45,IF(VALUE(E16)<48,48,IF(VALUE(E16)<51,51,IF(VALUE(E16)<54,54,IF(VALUE(E16)<57,57,IF(VALUE(E16)<60,60,IF(VALUE(E16)<63,63,IF(VALUE(E16)<66,66,IF(VALUE(E16)<69,69,IF(VALUE(E16)<72,72,IF(VALUE(E16)>72,72,""""))))))))))))))))),IF(OR(VALUE(E16)=13,VALUE(E16)=18,VALUE(E16)=72,VALUE(E16)=75,VALUE(E16)=78,VALUE(E16)=80,VALUE(E16)=84),E16,IF(VALUE(E16)<72,72,IF(VALUE(E16)<75,75,IF(VALUE(E16)<78,78,IF(VALUE(E16)<80,80,IF(VALUE(E16)<84,84,IF(VALUE(E16)>84,84,""""))))))))) -> 0 | J16: =B16&"-"&C16 -> - | K16: =IFERROR(VLOOKUP(J16,MASTER!C:D,2,0),"") | L16: =IFERROR((H16&"X"&I16&"X"&"0"&F16),"") -> 0X0X0 | M16: =CONCATENATE(K16,L16) -> 0X0X0 | N16: =M16 -> 0X0X0 | O16: =+G16 -> 0
... H35: =IF(D35="",0,IF(VALUE(D35)>VALUE(E35),IF(OR(VALUE(D35)=13,VALUE(D35)=20,VALUE(D35)=72,VALUE(D35)=75,VALUE(D35)=78,VALUE(D35)=80,VALUE(D35)=84),D35,IF(VALUE(D35)<72,72,IF(VALUE(D35)<75,75,IF(VALUE(D35)<78,78,IF(VALUE(D35)<80,80,IF(VALUE(D35)<84,84,IF(VALUE(D35)>84,84,""""))))))),IF(OR(VALUE(D35)=13,VALUE(D35)=20,VALUE(D35)=30,VALUE(D35)=33,VALUE(D35)=36,VALUE(D35)=39,VALUE(D35)=42,VALUE(D35)=45,VALUE(D35)=48,VALUE(D35)=51,VALUE(D35)=54,VALUE(D35)=57,VALUE(D35)=60,VALUE(D35)=63,VALUE(D35)=66,VALUE(D35)=69,VALUE(D35)=72),D35,IF(VALUE(D35)<30,30,IF(VALUE(D35)<33,33,IF(VALUE(D35)<36,36,IF(VALUE(D35)<39,39,IF(VALUE(D35)<42,42,IF(VALUE(D35)<45,45,IF(VALUE(D35)<48,48,IF(VALUE(D35)<51,51,IF(VALUE(D35)<54,54,IF(VALUE(D35)<57,57,IF(VALUE(D35)<60,60,IF(VALUE(D35)<63,63,IF(VALUE(D35)<66,66,IF(VALUE(D35)<69,69,IF(VALUE(D35)<72,72,IF(VALUE(D35)>72,72,""""))))))))))))))))))) -> 0 | I35: =IF(E35="",0,IF(VALUE(D35)>VALUE(E35),IF(OR(VALUE(E35)=13,VALUE(E35)=18,VALUE(E35)=30,VALUE(E35)=33,VALUE(E35)=36,VALUE(E35)=39,VALUE(E35)=42,VALUE(E35)=45,VALUE(E35)=48,VALUE(E35)=51,VALUE(E35)=54,VALUE(E35)=57,VALUE(E35)=60,VALUE(E35)=63,VALUE(E35)=66,VALUE(E35)=69,VALUE(E35)=72),E35,IF(VALUE(E35)<30,30,IF(VALUE(E35)<33,33,IF(VALUE(E35)<36,36,IF(VALUE(E35)<39,39,IF(VALUE(E35)<42,42,IF(VALUE(E35)<45,45,IF(VALUE(E35)<48,48,IF(VALUE(E35)<51,51,IF(VALUE(E35)<54,54,IF(VALUE(E35)<57,57,IF(VALUE(E35)<60,60,IF(VALUE(E35)<63,63,IF(VALUE(E35)<66,66,IF(VALUE(E35)<69,69,IF(VALUE(E35)<72,72,IF(VALUE(E35)>72,72,""""))))))))))))))))),IF(OR(VALUE(E35)=13,VALUE(E35)=18,VALUE(E35)=72,VALUE(E35)=75,VALUE(E35)=78,VALUE(E35)=80,VALUE(E35)=84),E35,IF(VALUE(E35)<72,72,IF(VALUE(E35)<75,75,IF(VALUE(E35)<78,78,IF(VALUE(E35)<80,80,IF(VALUE(E35)<84,84,IF(VALUE(E35)>84,84,""""))))))))) -> 0 | J35: =B35&"-"&C35 -> - | K35: =IFERROR(VLOOKUP(J35,MASTER!C:D,2,0),"") | L35: =IFERROR((H35&"X"&I35&"X"&"0"&F35),"") -> 0X0X0 | M35: =CONCATENATE(K35,L35) -> 0X0X0 | N35: =M35 -> 0X0X0 | O35: =+G35 -> 0
H36: =IF(D36="",0,IF(VALUE(D36)>VALUE(E36),IF(OR(VALUE(D36)=13,VALUE(D36)=20,VALUE(D36)=72,VALUE(D36)=75,VALUE(D36)=78,VALUE(D36)=80,VALUE(D36)=84),D36,IF(VALUE(D36)<72,72,IF(VALUE(D36)<75,75,IF(VALUE(D36)<78,78,IF(VALUE(D36)<80,80,IF(VALUE(D36)<84,84,IF(VALUE(D36)>84,84,""""))))))),IF(OR(VALUE(D36)=13,VALUE(D36)=20,VALUE(D36)=30,VALUE(D36)=33,VALUE(D36)=36,VALUE(D36)=39,VALUE(D36)=42,VALUE(D36)=45,VALUE(D36)=48,VALUE(D36)=51,VALUE(D36)=54,VALUE(D36)=57,VALUE(D36)=60,VALUE(D36)=63,VALUE(D36)=66,VALUE(D36)=69,VALUE(D36)=72),D36,IF(VALUE(D36)<30,30,IF(VALUE(D36)<33,33,IF(VALUE(D36)<36,36,IF(VALUE(D36)<39,39,IF(VALUE(D36)<42,42,IF(VALUE(D36)<45,45,IF(VALUE(D36)<48,48,IF(VALUE(D36)<51,51,IF(VALUE(D36)<54,54,IF(VALUE(D36)<57,57,IF(VALUE(D36)<60,60,IF(VALUE(D36)<63,63,IF(VALUE(D36)<66,66,IF(VALUE(D36)<69,69,IF(VALUE(D36)<72,72,IF(VALUE(D36)>72,72,""""))))))))))))))))))) -> 0 | I36: =IF(E36="",0,IF(VALUE(D36)>VALUE(E36),IF(OR(VALUE(E36)=13,VALUE(E36)=18,VALUE(E36)=30,VALUE(E36)=33,VALUE(E36)=36,VALUE(E36)=39,VALUE(E36)=42,VALUE(E36)=45,VALUE(E36)=48,VALUE(E36)=51,VALUE(E36)=54,VALUE(E36)=57,VALUE(E36)=60,VALUE(E36)=63,VALUE(E36)=66,VALUE(E36)=69,VALUE(E36)=72),E36,IF(VALUE(E36)<30,30,IF(VALUE(E36)<33,33,IF(VALUE(E36)<36,36,IF(VALUE(E36)<39,39,IF(VALUE(E36)<42,42,IF(VALUE(E36)<45,45,IF(VALUE(E36)<48,48,IF(VALUE(E36)<51,51,IF(VALUE(E36)<54,54,IF(VALUE(E36)<57,57,IF(VALUE(E36)<60,60,IF(VALUE(E36)<63,63,IF(VALUE(E36)<66,66,IF(VALUE(E36)<69,69,IF(VALUE(E36)<72,72,IF(VALUE(E36)>72,72,""""))))))))))))))))),IF(OR(VALUE(E36)=13,VALUE(E36)=18,VALUE(E36)=72,VALUE(E36)=75,VALUE(E36)=78,VALUE(E36)=80,VALUE(E36)=84),E36,IF(VALUE(E36)<72,72,IF(VALUE(E36)<75,75,IF(VALUE(E36)<78,78,IF(VALUE(E36)<80,80,IF(VALUE(E36)<84,84,IF(VALUE(E36)>84,84,""""))))))))) -> 0 | J36: =B36&"-"&C36 -> - | K36: =IFERROR(VLOOKUP(J36,MASTER!C:D,2,0),"") | L36: =IFERROR((H36&"X"&I36&"X"&"0"&F36),"") -> 0X0X0 | M36: =K36&L36 -> 0X0X0 | N36: =M36 -> 0X0X0 | O36: =+G36 -> 0
H37: =IF(D37="",0,IF(VALUE(D37)>VALUE(E37),IF(OR(VALUE(D37)=13,VALUE(D37)=20,VALUE(D37)=72,VALUE(D37)=75,VALUE(D37)=78,VALUE(D37)=80,VALUE(D37)=84),D37,IF(VALUE(D37)<72,72,IF(VALUE(D37)<75,75,IF(VALUE(D37)<78,78,IF(VALUE(D37)<80,80,IF(VALUE(D37)<84,84,IF(VALUE(D37)>84,84,""""))))))),IF(OR(VALUE(D37)=13,VALUE(D37)=20,VALUE(D37)=30,VALUE(D37)=33,VALUE(D37)=36,VALUE(D37)=39,VALUE(D37)=42,VALUE(D37)=45,VALUE(D37)=48,VALUE(D37)=51,VALUE(D37)=54,VALUE(D37)=57,VALUE(D37)=60,VALUE(D37)=63,VALUE(D37)=66,VALUE(D37)=69,VALUE(D37)=72),D37,IF(VALUE(D37)<30,30,IF(VALUE(D37)<33,33,IF(VALUE(D37)<36,36,IF(VALUE(D37)<39,39,IF(VALUE(D37)<42,42,IF(VALUE(D37)<45,45,IF(VALUE(D37)<48,48,IF(VALUE(D37)<51,51,IF(VALUE(D37)<54,54,IF(VALUE(D37)<57,57,IF(VALUE(D37)<60,60,IF(VALUE(D37)<63,63,IF(VALUE(D37)<66,66,IF(VALUE(D37)<69,69,IF(VALUE(D37)<72,72,IF(VALUE(D37)>72,72,""""))))))))))))))))))) -> 0 | I37: =IF(E37="",0,IF(VALUE(D37)>VALUE(E37),IF(OR(VALUE(E37)=13,VALUE(E37)=18,VALUE(E37)=30,VALUE(E37)=33,VALUE(E37)=36,VALUE(E37)=39,VALUE(E37)=42,VALUE(E37)=45,VALUE(E37)=48,VALUE(E37)=51,VALUE(E37)=54,VALUE(E37)=57,VALUE(E37)=60,VALUE(E37)=63,VALUE(E37)=66,VALUE(E37)=69,VALUE(E37)=72),E37,IF(VALUE(E37)<30,30,IF(VALUE(E37)<33,33,IF(VALUE(E37)<36,36,IF(VALUE(E37)<39,39,IF(VALUE(E37)<42,42,IF(VALUE(E37)<45,45,IF(VALUE(E37)<48,48,IF(VALUE(E37)<51,51,IF(VALUE(E37)<54,54,IF(VALUE(E37)<57,57,IF(VALUE(E37)<60,60,IF(VALUE(E37)<63,63,IF(VALUE(E37)<66,66,IF(VALUE(E37)<69,69,IF(VALUE(E37)<72,72,IF(VALUE(E37)>72,72,""""))))))))))))))))),IF(OR(VALUE(E37)=13,VALUE(E37)=18,VALUE(E37)=72,VALUE(E37)=75,VALUE(E37)=78,VALUE(E37)=80,VALUE(E37)=84),E37,IF(VALUE(E37)<72,72,IF(VALUE(E37)<75,75,IF(VALUE(E37)<78,78,IF(VALUE(E37)<80,80,IF(VALUE(E37)<84,84,IF(VALUE(E37)>84,84,""""))))))))) -> 0 | J37: =B37&"-"&C37 -> - | K37: =IFERROR(VLOOKUP(J37,MASTER!C:D,2,0),"") | L37: =IFERROR((H37&"X"&I37&"X"&"0"&F37),"") -> 0X0X0 | M37: =CONCATENATE(K37,L37) -> 0X0X0 | N37: =M37 -> 0X0X0 | O37: =+G37 -> 0
H38: =IF(D38="",0,IF(VALUE(D38)>VALUE(E38),IF(OR(VALUE(D38)=13,VALUE(D38)=20,VALUE(D38)=72,VALUE(D38)=75,VALUE(D38)=78,VALUE(D38)=80,VALUE(D38)=84),D38,IF(VALUE(D38)<72,72,IF(VALUE(D38)<75,75,IF(VALUE(D38)<78,78,IF(VALUE(D38)<80,80,IF(VALUE(D38)<84,84,IF(VALUE(D38)>84,84,""""))))))),IF(OR(VALUE(D38)=13,VALUE(D38)=20,VALUE(D38)=30,VALUE(D38)=33,VALUE(D38)=36,VALUE(D38)=39,VALUE(D38)=42,VALUE(D38)=45,VALUE(D38)=48,VALUE(D38)=51,VALUE(D38)=54,VALUE(D38)=57,VALUE(D38)=60,VALUE(D38)=63,VALUE(D38)=66,VALUE(D38)=69,VALUE(D38)=72),D38,IF(VALUE(D38)<30,30,IF(VALUE(D38)<33,33,IF(VALUE(D38)<36,36,IF(VALUE(D38)<39,39,IF(VALUE(D38)<42,42,IF(VALUE(D38)<45,45,IF(VALUE(D38)<48,48,IF(VALUE(D38)<51,51,IF(VALUE(D38)<54,54,IF(VALUE(D38)<57,57,IF(VALUE(D38)<60,60,IF(VALUE(D38)<63,63,IF(VALUE(D38)<66,66,IF(VALUE(D38)<69,69,IF(VALUE(D38)<72,72,IF(VALUE(D38)>72,72,""""))))))))))))))))))) -> 0 | I38: =IF(E38="",0,IF(VALUE(D38)>VALUE(E38),IF(OR(VALUE(E38)=13,VALUE(E38)=18,VALUE(E38)=30,VALUE(E38)=33,VALUE(E38)=36,VALUE(E38)=39,VALUE(E38)=42,VALUE(E38)=45,VALUE(E38)=48,VALUE(E38)=51,VALUE(E38)=54,VALUE(E38)=57,VALUE(E38)=60,VALUE(E38)=63,VALUE(E38)=66,VALUE(E38)=69,VALUE(E38)=72),E38,IF(VALUE(E38)<30,30,IF(VALUE(E38)<33,33,IF(VALUE(E38)<36,36,IF(VALUE(E38)<39,39,IF(VALUE(E38)<42,42,IF(VALUE(E38)<45,45,IF(VALUE(E38)<48,48,IF(VALUE(E38)<51,51,IF(VALUE(E38)<54,54,IF(VALUE(E38)<57,57,IF(VALUE(E38)<60,60,IF(VALUE(E38)<63,63,IF(VALUE(E38)<66,66,IF(VALUE(E38)<69,69,IF(VALUE(E38)<72,72,IF(VALUE(E38)>72,72,""""))))))))))))))))),IF(OR(VALUE(E38)=13,VALUE(E38)=18,VALUE(E38)=72,VALUE(E38)=75,VALUE(E38)=78,VALUE(E38)=80,VALUE(E38)=84),E38,IF(VALUE(E38)<72,72,IF(VALUE(E38)<75,75,IF(VALUE(E38)<78,78,IF(VALUE(E38)<80,80,IF(VALUE(E38)<84,84,IF(VALUE(E38)>84,84,""""))))))))) -> 0 | J38: =B38&"-"&C38 -> - | K38: =IFERROR(VLOOKUP(J38,MASTER!C:D,2,0),"") | L38: =IFERROR((H38&"X"&I38&"X"&"0"&F38),"") -> 0X0X0 | M38: =CONCATENATE(K38,L38) -> 0X0X0 | N38: =M38 -> 0X0X0 | O38: =+G38 -> 0
H39: =IF(D39="",0,IF(VALUE(D39)>VALUE(E39),IF(OR(VALUE(D39)=13,VALUE(D39)=20,VALUE(D39)=72,VALUE(D39)=75,VALUE(D39)=78,VALUE(D39)=80,VALUE(D39)=84),D39,IF(VALUE(D39)<72,72,IF(VALUE(D39)<75,75,IF(VALUE(D39)<78,78,IF(VALUE(D39)<80,80,IF(VALUE(D39)<84,84,IF(VALUE(D39)>84,84,""""))))))),IF(OR(VALUE(D39)=13,VALUE(D39)=20,VALUE(D39)=30,VALUE(D39)=33,VALUE(D39)=36,VALUE(D39)=39,VALUE(D39)=42,VALUE(D39)=45,VALUE(D39)=48,VALUE(D39)=51,VALUE(D39)=54,VALUE(D39)=57,VALUE(D39)=60,VALUE(D39)=63,VALUE(D39)=66,VALUE(D39)=69,VALUE(D39)=72),D39,IF(VALUE(D39)<30,30,IF(VALUE(D39)<33,33,IF(VALUE(D39)<36,36,IF(VALUE(D39)<39,39,IF(VALUE(D39)<42,42,IF(VALUE(D39)<45,45,IF(VALUE(D39)<48,48,IF(VALUE(D39)<51,51,IF(VALUE(D39)<54,54,IF(VALUE(D39)<57,57,IF(VALUE(D39)<60,60,IF(VALUE(D39)<63,63,IF(VALUE(D39)<66,66,IF(VALUE(D39)<69,69,IF(VALUE(D39)<72,72,IF(VALUE(D39)>72,72,""""))))))))))))))))))) -> 0 | I39: =IF(E39="",0,IF(VALUE(D39)>VALUE(E39),IF(OR(VALUE(E39)=13,VALUE(E39)=18,VALUE(E39)=30,VALUE(E39)=33,VALUE(E39)=36,VALUE(E39)=39,VALUE(E39)=42,VALUE(E39)=45,VALUE(E39)=48,VALUE(E39)=51,VALUE(E39)=54,VALUE(E39)=57,VALUE(E39)=60,VALUE(E39)=63,VALUE(E39)=66,VALUE(E39)=69,VALUE(E39)=72),E39,IF(VALUE(E39)<30,30,IF(VALUE(E39)<33,33,IF(VALUE(E39)<36,36,IF(VALUE(E39)<39,39,IF(VALUE(E39)<42,42,IF(VALUE(E39)<45,45,IF(VALUE(E39)<48,48,IF(VALUE(E39)<51,51,IF(VALUE(E39)<54,54,IF(VALUE(E39)<57,57,IF(VALUE(E39)<60,60,IF(VALUE(E39)<63,63,IF(VALUE(E39)<66,66,IF(VALUE(E39)<69,69,IF(VALUE(E39)<72,72,IF(VALUE(E39)>72,72,""""))))))))))))))))),IF(OR(VALUE(E39)=13,VALUE(E39)=18,VALUE(E39)=72,VALUE(E39)=75,VALUE(E39)=78,VALUE(E39)=80,VALUE(E39)=84),E39,IF(VALUE(E39)<72,72,IF(VALUE(E39)<75,75,IF(VALUE(E39)<78,78,IF(VALUE(E39)<80,80,IF(VALUE(E39)<84,84,IF(VALUE(E39)>84,84,""""))))))))) -> 0 | J39: =B39&"-"&C39 -> - | K39: =IFERROR(VLOOKUP(J39,MASTER!C:D,2,0),"") | L39: =IFERROR((H39&"X"&I39&"X"&"0"&F39),"") -> 0X0X0 | M39: =IFERROR((K39&L39),"") -> 0X0X0 | N39: =M39 -> 0X0X0 | O39: =+G39 -> 0
H40: =IF(D40="",0,IF(VALUE(D40)>VALUE(E40),IF(OR(VALUE(D40)=13,VALUE(D40)=20,VALUE(D40)=72,VALUE(D40)=75,VALUE(D40)=78,VALUE(D40)=80,VALUE(D40)=84),D40,IF(VALUE(D40)<72,72,IF(VALUE(D40)<75,75,IF(VALUE(D40)<78,78,IF(VALUE(D40)<80,80,IF(VALUE(D40)<84,84,IF(VALUE(D40)>84,84,""""))))))),IF(OR(VALUE(D40)=13,VALUE(D40)=20,VALUE(D40)=30,VALUE(D40)=33,VALUE(D40)=36,VALUE(D40)=39,VALUE(D40)=42,VALUE(D40)=45,VALUE(D40)=48,VALUE(D40)=51,VALUE(D40)=54,VALUE(D40)=57,VALUE(D40)=60,VALUE(D40)=63,VALUE(D40)=66,VALUE(D40)=69,VALUE(D40)=72),D40,IF(VALUE(D40)<30,30,IF(VALUE(D40)<33,33,IF(VALUE(D40)<36,36,IF(VALUE(D40)<39,39,IF(VALUE(D40)<42,42,IF(VALUE(D40)<45,45,IF(VALUE(D40)<48,48,IF(VALUE(D40)<51,51,IF(VALUE(D40)<54,54,IF(VALUE(D40)<57,57,IF(VALUE(D40)<60,60,IF(VALUE(D40)<63,63,IF(VALUE(D40)<66,66,IF(VALUE(D40)<69,69,IF(VALUE(D40)<72,72,IF(VALUE(D40)>72,72,""""))))))))))))))))))) -> 0 | I40: =IF(E40="",0,IF(VALUE(D40)>VALUE(E40),IF(OR(VALUE(E40)=13,VALUE(E40)=18,VALUE(E40)=30,VALUE(E40)=33,VALUE(E40)=36,VALUE(E40)=39,VALUE(E40)=42,VALUE(E40)=45,VALUE(E40)=48,VALUE(E40)=51,VALUE(E40)=54,VALUE(E40)=57,VALUE(E40)=60,VALUE(E40)=63,VALUE(E40)=66,VALUE(E40)=69,VALUE(E40)=72),E40,IF(VALUE(E40)<30,30,IF(VALUE(E40)<33,33,IF(VALUE(E40)<36,36,IF(VALUE(E40)<39,39,IF(VALUE(E40)<42,42,IF(VALUE(E40)<45,45,IF(VALUE(E40)<48,48,IF(VALUE(E40)<51,51,IF(VALUE(E40)<54,54,IF(VALUE(E40)<57,57,IF(VALUE(E40)<60,60,IF(VALUE(E40)<63,63,IF(VALUE(E40)<66,66,IF(VALUE(E40)<69,69,IF(VALUE(E40)<72,72,IF(VALUE(E40)>72,72,""""))))))))))))))))),IF(OR(VALUE(E40)=13,VALUE(E40)=18,VALUE(E40)=72,VALUE(E40)=75,VALUE(E40)=78,VALUE(E40)=80,VALUE(E40)=84),E40,IF(VALUE(E40)<72,72,IF(VALUE(E40)<75,75,IF(VALUE(E40)<78,78,IF(VALUE(E40)<80,80,IF(VALUE(E40)<84,84,IF(VALUE(E40)>84,84,""""))))))))) -> 0 | J40: =B40&"-"&C40 -> - | K40: =IFERROR(VLOOKUP(J40,MASTER!C:D,2,0),"") | L40: =IFERROR((H40&"X"&I40&"X"&"0"&F40),"") -> 0X0X0 | M40: =IFERROR((K40&L40),"") -> 0X0X0 | N40: =M40 -> 0X0X0 | O40: =+G40 -> 0
H41: =IF(D41="",0,IF(VALUE(D41)>VALUE(E41),IF(OR(VALUE(D41)=13,VALUE(D41)=20,VALUE(D41)=72,VALUE(D41)=75,VALUE(D41)=78,VALUE(D41)=80,VALUE(D41)=84),D41,IF(VALUE(D41)<72,72,IF(VALUE(D41)<75,75,IF(VALUE(D41)<78,78,IF(VALUE(D41)<80,80,IF(VALUE(D41)<84,84,IF(VALUE(D41)>84,84,""""))))))),IF(OR(VALUE(D41)=13,VALUE(D41)=20,VALUE(D41)=30,VALUE(D41)=33,VALUE(D41)=36,VALUE(D41)=39,VALUE(D41)=42,VALUE(D41)=45,VALUE(D41)=48,VALUE(D41)=51,VALUE(D41)=54,VALUE(D41)=57,VALUE(D41)=60,VALUE(D41)=63,VALUE(D41)=66,VALUE(D41)=69,VALUE(D41)=72),D41,IF(VALUE(D41)<30,30,IF(VALUE(D41)<33,33,IF(VALUE(D41)<36,36,IF(VALUE(D41)<39,39,IF(VALUE(D41)<42,42,IF(VALUE(D41)<45,45,IF(VALUE(D41)<48,48,IF(VALUE(D41)<51,51,IF(VALUE(D41)<54,54,IF(VALUE(D41)<57,57,IF(VALUE(D41)<60,60,IF(VALUE(D41)<63,63,IF(VALUE(D41)<66,66,IF(VALUE(D41)<69,69,IF(VALUE(D41)<72,72,IF(VALUE(D41)>72,72,""""))))))))))))))))))) -> 0 | I41: =IF(E41="",0,IF(VALUE(D41)>VALUE(E41),IF(OR(VALUE(E41)=13,VALUE(E41)=18,VALUE(E41)=30,VALUE(E41)=33,VALUE(E41)=36,VALUE(E41)=39,VALUE(E41)=42,VALUE(E41)=45,VALUE(E41)=48,VALUE(E41)=51,VALUE(E41)=54,VALUE(E41)=57,VALUE(E41)=60,VALUE(E41)=63,VALUE(E41)=66,VALUE(E41)=69,VALUE(E41)=72),E41,IF(VALUE(E41)<30,30,IF(VALUE(E41)<33,33,IF(VALUE(E41)<36,36,IF(VALUE(E41)<39,39,IF(VALUE(E41)<42,42,IF(VALUE(E41)<45,45,IF(VALUE(E41)<48,48,IF(VALUE(E41)<51,51,IF(VALUE(E41)<54,54,IF(VALUE(E41)<57,57,IF(VALUE(E41)<60,60,IF(VALUE(E41)<63,63,IF(VALUE(E41)<66,66,IF(VALUE(E41)<69,69,IF(VALUE(E41)<72,72,IF(VALUE(E41)>72,72,""""))))))))))))))))),IF(OR(VALUE(E41)=13,VALUE(E41)=18,VALUE(E41)=72,VALUE(E41)=75,VALUE(E41)=78,VALUE(E41)=80,VALUE(E41)=84),E41,IF(VALUE(E41)<72,72,IF(VALUE(E41)<75,75,IF(VALUE(E41)<78,78,IF(VALUE(E41)<80,80,IF(VALUE(E41)<84,84,IF(VALUE(E41)>84,84,""""))))))))) -> 0 | J41: =B41&"-"&C41 -> - | K41: =IFERROR(VLOOKUP(J41,MASTER!C:D,2,0),"") | L41: =IFERROR((H41&"X"&I41&"X"&"0"&F41),"") -> 0X0X0 | M41: =IFERROR((K41&L41),"") -> 0X0X0 | N41: =M41 -> 0X0X0 | O41: =+G41 -> 0
H42: =IF(D42="",0,IF(VALUE(D42)>VALUE(E42),IF(OR(VALUE(D42)=13,VALUE(D42)=20,VALUE(D42)=72,VALUE(D42)=75,VALUE(D42)=78,VALUE(D42)=80,VALUE(D42)=84),D42,IF(VALUE(D42)<72,72,IF(VALUE(D42)<75,75,IF(VALUE(D42)<78,78,IF(VALUE(D42)<80,80,IF(VALUE(D42)<84,84,IF(VALUE(D42)>84,84,""""))))))),IF(OR(VALUE(D42)=13,VALUE(D42)=20,VALUE(D42)=30,VALUE(D42)=33,VALUE(D42)=36,VALUE(D42)=39,VALUE(D42)=42,VALUE(D42)=45,VALUE(D42)=48,VALUE(D42)=51,VALUE(D42)=54,VALUE(D42)=57,VALUE(D42)=60,VALUE(D42)=63,VALUE(D42)=66,VALUE(D42)=69,VALUE(D42)=72),D42,IF(VALUE(D42)<30,30,IF(VALUE(D42)<33,33,IF(VALUE(D42)<36,36,IF(VALUE(D42)<39,39,IF(VALUE(D42)<42,42,IF(VALUE(D42)<45,45,IF(VALUE(D42)<48,48,IF(VALUE(D42)<51,51,IF(VALUE(D42)<54,54,IF(VALUE(D42)<57,57,IF(VALUE(D42)<60,60,IF(VALUE(D42)<63,63,IF(VALUE(D42)<66,66,IF(VALUE(D42)<69,69,IF(VALUE(D42)<72,72,IF(VALUE(D42)>72,72,""""))))))))))))))))))) -> 0 | I42: =IF(E42="",0,IF(VALUE(D42)>VALUE(E42),IF(OR(VALUE(E42)=13,VALUE(E42)=18,VALUE(E42)=30,VALUE(E42)=33,VALUE(E42)=36,VALUE(E42)=39,VALUE(E42)=42,VALUE(E42)=45,VALUE(E42)=48,VALUE(E42)=51,VALUE(E42)=54,VALUE(E42)=57,VALUE(E42)=60,VALUE(E42)=63,VALUE(E42)=66,VALUE(E42)=69,VALUE(E42)=72),E42,IF(VALUE(E42)<30,30,IF(VALUE(E42)<33,33,IF(VALUE(E42)<36,36,IF(VALUE(E42)<39,39,IF(VALUE(E42)<42,42,IF(VALUE(E42)<45,45,IF(VALUE(E42)<48,48,IF(VALUE(E42)<51,51,IF(VALUE(E42)<54,54,IF(VALUE(E42)<57,57,IF(VALUE(E42)<60,60,IF(VALUE(E42)<63,63,IF(VALUE(E42)<66,66,IF(VALUE(E42)<69,69,IF(VALUE(E42)<72,72,IF(VALUE(E42)>72,72,""""))))))))))))))))),IF(OR(VALUE(E42)=13,VALUE(E42)=18,VALUE(E42)=72,VALUE(E42)=75,VALUE(E42)=78,VALUE(E42)=80,VALUE(E42)=84),E42,IF(VALUE(E42)<72,72,IF(VALUE(E42)<75,75,IF(VALUE(E42)<78,78,IF(VALUE(E42)<80,80,IF(VALUE(E42)<84,84,IF(VALUE(E42)>84,84,""""))))))))) -> 0 | J42: =B42&"-"&C42 -> - | K42: =IFERROR(VLOOKUP(J42,MASTER!C:D,2,0),"") | L42: =IFERROR((H42&"X"&I42&"X"&"0"&F42),"") -> 0X0X0 | M42: =IFERROR((K42&L42),"") -> 0X0X0 | N42: =M42 -> 0X0X0 | O42: =+G42 -> 0
H43: =IF(D43="",0,IF(VALUE(D43)>VALUE(E43),IF(OR(VALUE(D43)=13,VALUE(D43)=20,VALUE(D43)=72,VALUE(D43)=75,VALUE(D43)=78,VALUE(D43)=80,VALUE(D43)=84),D43,IF(VALUE(D43)<72,72,IF(VALUE(D43)<75,75,IF(VALUE(D43)<78,78,IF(VALUE(D43)<80,80,IF(VALUE(D43)<84,84,IF(VALUE(D43)>84,84,""""))))))),IF(OR(VALUE(D43)=13,VALUE(D43)=20,VALUE(D43)=30,VALUE(D43)=33,VALUE(D43)=36,VALUE(D43)=39,VALUE(D43)=42,VALUE(D43)=45,VALUE(D43)=48,VALUE(D43)=51,VALUE(D43)=54,VALUE(D43)=57,VALUE(D43)=60,VALUE(D43)=63,VALUE(D43)=66,VALUE(D43)=69,VALUE(D43)=72),D43,IF(VALUE(D43)<30,30,IF(VALUE(D43)<33,33,IF(VALUE(D43)<36,36,IF(VALUE(D43)<39,39,IF(VALUE(D43)<42,42,IF(VALUE(D43)<45,45,IF(VALUE(D43)<48,48,IF(VALUE(D43)<51,51,IF(VALUE(D43)<54,54,IF(VALUE(D43)<57,57,IF(VALUE(D43)<60,60,IF(VALUE(D43)<63,63,IF(VALUE(D43)<66,66,IF(VALUE(D43)<69,69,IF(VALUE(D43)<72,72,IF(VALUE(D43)>72,72,""""))))))))))))))))))) -> 0 | I43: =IF(E43="",0,IF(VALUE(D43)>VALUE(E43),IF(OR(VALUE(E43)=13,VALUE(E43)=18,VALUE(E43)=30,VALUE(E43)=33,VALUE(E43)=36,VALUE(E43)=39,VALUE(E43)=42,VALUE(E43)=45,VALUE(E43)=48,VALUE(E43)=51,VALUE(E43)=54,VALUE(E43)=57,VALUE(E43)=60,VALUE(E43)=63,VALUE(E43)=66,VALUE(E43)=69,VALUE(E43)=72),E43,IF(VALUE(E43)<30,30,IF(VALUE(E43)<33,33,IF(VALUE(E43)<36,36,IF(VALUE(E43)<39,39,IF(VALUE(E43)<42,42,IF(VALUE(E43)<45,45,IF(VALUE(E43)<48,48,IF(VALUE(E43)<51,51,IF(VALUE(E43)<54,54,IF(VALUE(E43)<57,57,IF(VALUE(E43)<60,60,IF(VALUE(E43)<63,63,IF(VALUE(E43)<66,66,IF(VALUE(E43)<69,69,IF(VALUE(E43)<72,72,IF(VALUE(E43)>72,72,""""))))))))))))))))),IF(OR(VALUE(E43)=13,VALUE(E43)=18,VALUE(E43)=72,VALUE(E43)=75,VALUE(E43)=78,VALUE(E43)=80,VALUE(E43)=84),E43,IF(VALUE(E43)<72,72,IF(VALUE(E43)<75,75,IF(VALUE(E43)<78,78,IF(VALUE(E43)<80,80,IF(VALUE(E43)<84,84,IF(VALUE(E43)>84,84,""""))))))))) -> 0 | J43: =B43&"-"&C43 -> - | K43: =IFERROR(VLOOKUP(J43,MASTER!C:D,2,0),"") | L43: =IFERROR((H43&"X"&I43&"X"&"0"&F43),"") -> 0X0X0 | M43: =IFERROR((K43&L43),"") -> 0X0X0 | N43: =M43 -> 0X0X0 | O43: =+G43 -> 0
H44: =IF(D44="",0,IF(VALUE(D44)>VALUE(E44),IF(OR(VALUE(D44)=13,VALUE(D44)=20,VALUE(D44)=72,VALUE(D44)=75,VALUE(D44)=78,VALUE(D44)=80,VALUE(D44)=84),D44,IF(VALUE(D44)<72,72,IF(VALUE(D44)<75,75,IF(VALUE(D44)<78,78,IF(VALUE(D44)<80,80,IF(VALUE(D44)<84,84,IF(VALUE(D44)>84,84,""""))))))),IF(OR(VALUE(D44)=13,VALUE(D44)=20,VALUE(D44)=30,VALUE(D44)=33,VALUE(D44)=36,VALUE(D44)=39,VALUE(D44)=42,VALUE(D44)=45,VALUE(D44)=48,VALUE(D44)=51,VALUE(D44)=54,VALUE(D44)=57,VALUE(D44)=60,VALUE(D44)=63,VALUE(D44)=66,VALUE(D44)=69,VALUE(D44)=72),D44,IF(VALUE(D44)<30,30,IF(VALUE(D44)<33,33,IF(VALUE(D44)<36,36,IF(VALUE(D44)<39,39,IF(VALUE(D44)<42,42,IF(VALUE(D44)<45,45,IF(VALUE(D44)<48,48,IF(VALUE(D44)<51,51,IF(VALUE(D44)<54,54,IF(VALUE(D44)<57,57,IF(VALUE(D44)<60,60,IF(VALUE(D44)<63,63,IF(VALUE(D44)<66,66,IF(VALUE(D44)<69,69,IF(VALUE(D44)<72,72,IF(VALUE(D44)>72,72,""""))))))))))))))))))) -> 0 | I44: =IF(E44="",0,IF(VALUE(D44)>VALUE(E44),IF(OR(VALUE(E44)=13,VALUE(E44)=18,VALUE(E44)=30,VALUE(E44)=33,VALUE(E44)=36,VALUE(E44)=39,VALUE(E44)=42,VALUE(E44)=45,VALUE(E44)=48,VALUE(E44)=51,VALUE(E44)=54,VALUE(E44)=57,VALUE(E44)=60,VALUE(E44)=63,VALUE(E44)=66,VALUE(E44)=69,VALUE(E44)=72),E44,IF(VALUE(E44)<30,30,IF(VALUE(E44)<33,33,IF(VALUE(E44)<36,36,IF(VALUE(E44)<39,39,IF(VALUE(E44)<42,42,IF(VALUE(E44)<45,45,IF(VALUE(E44)<48,48,IF(VALUE(E44)<51,51,IF(VALUE(E44)<54,54,IF(VALUE(E44)<57,57,IF(VALUE(E44)<60,60,IF(VALUE(E44)<63,63,IF(VALUE(E44)<66,66,IF(VALUE(E44)<69,69,IF(VALUE(E44)<72,72,IF(VALUE(E44)>72,72,""""))))))))))))))))),IF(OR(VALUE(E44)=13,VALUE(E44)=18,VALUE(E44)=72,VALUE(E44)=75,VALUE(E44)=78,VALUE(E44)=80,VALUE(E44)=84),E44,IF(VALUE(E44)<72,72,IF(VALUE(E44)<75,75,IF(VALUE(E44)<78,78,IF(VALUE(E44)<80,80,IF(VALUE(E44)<84,84,IF(VALUE(E44)>84,84,""""))))))))) -> 0 | J44: =B44&"-"&C44 -> - | K44: =IFERROR(VLOOKUP(J44,MASTER!C:D,2,0),"") | L44: =IFERROR((H44&"X"&I44&"X"&"0"&F44),"") -> 0X0X0 | M44: =IFERROR((K44&L44),"") -> 0X0X0 | N44: =M44 -> 0X0X0 | O44: =+G44 -> 0
