Workbook

Sheet BUNDLE STOCK 
A1: 1
A2: WIRE DIA=2.1 MM SPRING SIZE= 150MM MM RACK NO:1
A3: UPPER SIDE
A4: SNO | B4: WEIGHT | C4: SNO | D4: WEIGHT
A5: 1 | C5: 41
A6: 2 | C6: 42
A7: 3 | C7: 43
A8: 4 | C8: 44
A9: 5 | C9: 45
A10: 6 | C10: 46
A11: 7 | C11: 47
A12: 8 | C12: 48
A13: 9 | C13: 49
A14: 10 | C14: 50
A15: 11 | C15: 51
A16: 12 | C16: 52
... A44: 40 | C44: 80
A45: TOTAL | B45: =SUM(B5:B44) -> 0 | C45: TOTAL | D45: =SUM(D5:D44) -> 0
B46: TOTAL BUNDLES | D46: =COUNT(B5:B44)+COUNT(D5:D44) -> 0
B47: TOTAL WEIGHT | D47: =+D45+B45 -> 0
A48: 2
A49: WIRE DIA=2.2 MM SPRING SIZE= 160MM RACK NO:1
A50: LOWER SIDE
A51: SNO | B51: WEIGHT | C51: SNO | D51: WEIGHT
A52: 1 | C52: 41
A53: 2 | C53: 42
A54: 3 | C54: 43
A55: 4 | C55: 44
A56: 5 | C56: 45
A57: 6 | C57: 46
A58: 7 | C58: 47
A59: 8 | C59: 48
A60: 9 | C60: 49
A61: 10 | C61: 50
A62: 11 | C62: 51
A63: 12 | C63: 52
... A91: 40 | C91: 80
A92: TOTAL | B92: =SUM(B52:B91) -> 0 | C92: TOTAL | D92: =SUM(D52:D91) -> 0
B93: TOTAL BUNDLES | D93: =COUNT(B52:B91)+COUNT(D52:D91) -> 0
B94: TOTAL WEIGHT | D94: =+D92+B92 -> 0
...

Sheet ITEM CODE
A1: Item Code | B1: SPRING WEIGHT | C1: Item Variant Desc. | D1: Stock UOM | E1: STEEL | F1: TADE EDGE | G1: QUILTING | H1: HYPNOS | I1: TOTAL QTY
A2: PKSPR90-1.7MM | B2: 0.018 | C2: Semifinished Pocketed Springs 90 Steel Wire 1.7MM | D2: NOS
A3: PKSPR120-1.8MM-TNDR | C3: Semifinished Pocketed Springs 120 Steel Wire 1.8MM | D3: NOS
A4: PKSPR110-1.9MM | B4: 0.026 | C4: Semifinished Pocketed Springs 110 Steel Wire 1.9MM | D4: NOS
A5: PKSPR140-1.9MM | B5: 0.026 | C5: Semifinished Pocketed Springs 140 Steel Wire 1.9MM | D5: NOS
A6: PKSPR160-1.9MM | B6: 0.032 | C6: Semifinished Pocketed Springs 160 Steel Wire 1.9MM | D6: NOS
A7: PKSPR110-1.8MM | B7: 0.024 | C7: Semifinished Pocketed Springs 110 Steel Wire 1.8MM | D7: NOS
A8: PKSPR160-1.8MM | B8: 0.030 | C8: Semifinished Pocketed Springs 160 Steel Wire 1.8MM | D8: NOS
A9: PKSPR200-1.8MM | B9: 0.033 | C9: Semifinished Pocketed Springs 200 Steel Wire 1.8MM | D9: NOS
A10: BNSPR110 | B10: 0.029 | C10: Semi Finised Bonnel Springs 100 | D10: KGS
A11: BNSPR110-2.2MM | B11: 0.027 | C11: Semifinised Bonnell Springs 100 Steel wire 2.2mm | D11: KGS
A12: BNSPR130 | B12: 0.034 | C12: Semi Finised Bonnel Springs 130 | D12: KGS
A13: BNSPR130-2.2MM | B13: 0.033 | C13: Semifinised Bonnell Springs 130 Steel wire 2.2mm | D13: KGS
A14: BNSPR150 | B14: 0.0417 | C14: Semi Finised Bonnel Springs 150 | D14: KGS
A15: BNSPR150-2.2MM | B15: 0.038 | C15: Semifinised Bonnell Springs 150 Steel wire 2.2mm | D15: KGS
A16: BNSPR170 | B16: 0.038 | C16: Semifinised Bonnell Springs 160 Steel wire 2.2mm | D16: KGS
A17: BNSPR170-2.2MM | B17: 0.038 | C17: Semifinised Bonnell Springs 180 Steel wire 2.2mm | D17: KGS
A18: BNSPR90 | B18: 0.0294 | C18: Semi Finised Bonnel Springs 90 | D18: KGS

Sheet OVERALL
A1: BUNDLE CLOSING STOCK DEC-2025
A2: S.NO | B2: RACK.NO | C2: SIDE | D2: ITEM CODE | E2: NO.OF BUNDLE | F2: WEIGHT
A3: 1 | E3: =+'BUNDLE STOCK '!D46 -> 0 | F3: =+'BUNDLE STOCK '!D47 -> 0
A4: 2 | E4: =+'BUNDLE STOCK '!D93 -> 0 | F4: =+'BUNDLE STOCK '!D94 -> 0
A5: 3 | E5: =+'BUNDLE STOCK '!D140 -> 0 | F5: =+'BUNDLE STOCK '!D141 -> 0
A6: 4 | E6: =+'BUNDLE STOCK '!D187 -> 0 | F6: =+'BUNDLE STOCK '!D188 -> 0
A7: 5 | E7: =+'BUNDLE STOCK '!D234 -> 0 | F7: =+'BUNDLE STOCK '!D235 -> 0
A8: 6 | E8: =+'BUNDLE STOCK '!D281 -> 0 | F8: =+'BUNDLE STOCK '!D282 -> 0
A9: 7 | E9: =+'BUNDLE STOCK '!D328 -> 0 | F9: =+'BUNDLE STOCK '!D329 -> 0
A10: 8 | E10: =+'BUNDLE STOCK '!D375 -> 0 | F10: =+'BUNDLE STOCK '!D376 -> 0
A11: 9 | E11: =+'BUNDLE STOCK '!D422 -> 0 | F11: =+'BUNDLE STOCK '!D423 -> 0
A12: 10 | E12: =+'BUNDLE STOCK '!D469 -> 0 | F12: =+'BUNDLE STOCK '!D470 -> 0
A13: 11 | E13: =+'BUNDLE STOCK '!D516 -> 0 | F13: =+'BUNDLE STOCK '!D517 -> 0
A14: 12 | E14: =+'BUNDLE STOCK '!D563 -> 0 | F14: =+'BUNDLE STOCK '!D564 -> 0
A15: 13 | E15: =+'BUNDLE STOCK '!D610 -> 0 | F15: =+'BUNDLE STOCK '!D611 -> 0
A16: 14 | E16: =+'BUNDLE STOCK '!D657 -> 0 | F16: =+'BUNDLE STOCK '!D658 -> 0
A17: 15 | E17: =+'BUNDLE STOCK '!D703 -> 0 | F17: =+'BUNDLE STOCK '!D704 -> 0
A18: 16 | E18: =+'BUNDLE STOCK '!D749 -> 0 | F18: =+'BUNDLE STOCK '!D750 -> 0
A19: 17 | E19: =+'BUNDLE STOCK '!D795 -> 0 | F19: =+'BUNDLE STOCK '!D796 -> 0
A20: 18 | E20: =+'BUNDLE STOCK '!D841 -> 0 | F20: =+'BUNDLE STOCK '!D842 -> 0
A21: 19 | E21: =+'BUNDLE STOCK '!D895 -> 0 | F21: =+'BUNDLE STOCK '!D896 -> 0
A22: 20 | E22: =+'BUNDLE STOCK '!D949 -> 0 | F22: =+'BUNDLE STOCK '!D950 -> 0
D23: TOTAL | E23: =SUBTOTAL(109,E3:E22) -> 0 | F23: =SUBTOTAL(109,F3:F22) -> 0

Sheet SPRING
B2: PKSPR110-1.8MM | C2: PKSPR110-1.8MM-GRN | D2: PKSPR130-1.8MM | E2: PKSPR150-1.8MM-GRN | F2: PKSPR170-1.8MM | G2: PKSPR80-1.8MM
B44: =SUM(B3:B43) -> 0 | D44: =SUM(D3:D43) -> 0 | G44: =SUM(G3:G43) -> 0

Sheet SPRING COUNT
A1: Item Code | B1: SPRING WEIGHT | C1: TOTAL WEIGHT
A2: PKSPR110-1.8MM
A3: PKSPR110-1.8MM-GRN
A4: PKSPR130-1.8MM
A5: PKSPR150-1.8MM-GRN
A6: PKSPR170-1.8MM
A7: PKSPR80-1.8MM

Sheet SPRING WEIGHT
A1: PER SPRING WEIGHT (BONNELL) | E1: PER SPRING WEIGHT (POCKETED)
A2: SIZE OF SPRING | C2: WEIGHT OF SPRING | E2: SIZE OF SPRING | G2: WEIGHT OF SPRING+NON WOVEN | I2: spring weight | J2: total spring weight | K2: no.of spring | L2: spring size
A3: 2.3(THICK) | B3: 100 MM | C3: 0.029 GMS | E3: 1.9 MM(THICK) | F3: 110 MM | G3: 0.023 GMS | H3: 0.003 GMS(NWN) | I3: =0.023+0.003 -> 0.026 | K3: =+J3/I3 -> 0 | L3: 110
B4: 130 MM | C4: 0.036 GMS | F4: 140 MM | G4: 0.025 GMS | H4: 0.003 GMS(NWN) | I4: =0.025+0.003 -> 0.028 | K4: =+J4/I4 -> 0 | L4: 140
B5: 150 MM | C5: 0.042 GMS | F5: 160 MM | G5: 0.028 GMS | H5: 0.005 GMS(NWN) | I5: =0.028+0.005 -> 0.033 | K5: =+J5/I5 -> 0
A6: 2.2(THICK) | B6: 100 MM | C6: 0.027 GMS | E6: 1.8 MM(THICK) | F6: 110MM | G6: 0.021 GMS | H6: 0.003 GMS(NWN) | I6: =0.021+0.003 -> 0.024 | K6: =+J6/I6 -> 0
B7: 130 MM | C7: 0.033 GMS | F7: 160 MM | G7: 0.026 GMS | H7: 0.005 GMS(NWN) | I7: =0.026+0.005 -> 0.031 | K7: =+J7/I7 -> 0 | L7: 160
B8: 150 MM | C8: 0.038 GMS | F8: 200 MM | G8: 0.028 GMS | H8: 0.005 GMS(NWN) | I8: =0.028+0.005 -> 0.033 | K8: =+J8/I8 -> 0 | L8: 200
B9: 160 MM | C9: 0.038 GMS
G13: =298+150 -> 448
