Workbook

Sheet CBEWIP
A1: SI.No | B1: ITEM CODE | C1: ITEM DESCRIPTION | D1: UOM | E1: WAREHOUSE | F1: STEEL
A2: 1 | B2: =+OVERALL!C2 -> RML-STW-1.4MM | C2: 1.4 MM UPHOLSTRY STEEL WIRE | D2: =+OVERALL!D2 -> KGS | E2: CBEWIP | F2: =+OVERALL!F2 -> 0
A3: 2 | B3: =+OVERALL!C3 -> RML-STW-1.7MM | C3: STEEL WIRE 1.7 MMDIA. | D3: =+OVERALL!D3 -> KGS | E3: CBEWIP | F3: =+OVERALL!F3 -> 0
A4: 3 | B4: =+OVERALL!C4 -> RML-STW-1.8MM | C4: STEEL WIRE 1.8 MMDIA. | D4: =+OVERALL!D4 -> KGS | E4: CBEWIP | F4: =+OVERALL!F4 -> 0
A5: 4 | B5: =+OVERALL!C5 -> RML-STW-1.9MM | C5: #N/A | D5: =+OVERALL!D5 -> KGS | E5: CBEWIP | F5: =+OVERALL!F5 -> 0
A6: 5 | B6: =+OVERALL!C6 -> RML-STW-2.0MM | C6: #N/A | D6: =+OVERALL!D6 -> KGS | E6: CBEWIP | F6: =+OVERALL!F6 -> 0
A7: 6 | B7: =+OVERALL!C7 -> RML-STW-2.1MM | C7: #N/A | D7: =+OVERALL!D7 -> KGS | E7: CBEWIP | F7: =+OVERALL!F7 -> 0
A8: 7 | B8: =+OVERALL!C8 -> RML-STW-2.2MM | C8: STEEL WIRE 2.2 MM DIA. | D8: =+OVERALL!D8 -> KGS | E8: CBEWIP | F8: =+OVERALL!F8 -> 0
A9: 8 | B9: =+OVERALL!C9 -> RML-STW-2.3MM | C9: 2.3 MM SPRING STEEL WIRE-GRADE II | D9: =+OVERALL!D9 -> KGS | E9: CBEWIP | F9: =+OVERALL!F9 -> 0
A10: 9 | B10: =+OVERALL!C10 -> RML-STW-3.6MM | C10: STEEL WIRE 3.6 MM DIA | D10: =+OVERALL!D10 -> KGS | E10: CBEWIP | F10: =+OVERALL!F10 -> 0
A11: 10 | B11: =+OVERALL!C11 -> RML-STW-4.0MM | C11: STEEL WIRE 4.0 MM DIA | D11: =+OVERALL!D11 -> KGS | E11: CBEWIP | F11: =+OVERALL!F11 -> 0
A12: 11 | B12: =+OVERALL!C12 -> RML-CL85 | C12: CLIPS CL-85 (8000 PCS/BOX) | D12: =+OVERALL!D12 -> BOX | E12: CBEWIP | F12: =+OVERALL!F12 -> 0
A13: 12 | B13: =+OVERALL!C13 -> RML-CL12B | C13: CLIPS CL-12B (13025 PCS/BOX) | D13: =+OVERALL!D13 -> BOX | E13: CBEWIP | F13: =+OVERALL!F13 -> 0
A14: 13 | B14: =+OVERALL!C14 -> RML-HR24 | C14: C-RINGS HR24 (10000 PCS/CTN) | D14: =+OVERALL!D14 -> BOX | E14: CBEWIP | F14: =+OVERALL!F14 -> 0
A15: 14 | B15: =+OVERALL!C15 -> RML-POLY-GUM | C15: SOLVENT BASED RUBBER ADHESIVE (SPRAY GLUE) | D15: =+OVERALL!D15 -> LTRS | E15: CBEWIP | F15: =+OVERALL!F15 -> 0
A16: 15 | B16: =+OVERALL!C16 -> RML-STRAP-ROLL | C16: 12MM PACKING STRAP ROLL | D16: =+OVERALL!D16 -> NOS | E16: CBEWIP | F16: =+OVERALL!F16 -> 0
A17: 16 | B17: =+OVERALL!C17 -> RML-PAK-THRD | C17: Bag Stitching Thread | D17: =+OVERALL!D17 -> NOS | E17: CBEWIP | F17: =+OVERALL!F17 -> 0
A18: 17 | B18: =+OVERALL!C18 -> RML-TAG-WHIT | C18: WHITE COLOUR TAG | D18: =+OVERALL!D18 -> NOS | E18: CBEWIP | F18: =+OVERALL!F18 -> 0
A19: 18 | B19: =+OVERALL!C19 -> RML-TEX-CLEANER | C19: TEXTILE CLEANER -MC | D19: =+OVERALL!D19 -> LTRS | E19: CBEWIP | F19: =+OVERALL!F19 -> 0
... A24: 23 | B24: =+OVERALL!C24 -> RM-NWN-POS-45CMX70GSM | C24: NON WOVEN FABRIC 70 GSM x 45 CM - WHITE | D24: =+OVERALL!D24 -> KGS | E24: CBEWIP | F24: =+OVERALL!F24 -> 0
A25: 24 | B25: =+OVERALL!C25 -> RM-NWN-POS-50CMX70GSM | C25: #N/A | D25: =+OVERALL!D25 -> KGS | E25: CBEWIP | F25: =+OVERALL!F25 -> 0
A26: 25 | B26: =+OVERALL!C26 -> RM-NWN-POS-50CMX70GSM-GRN | C26: NON WOVEN FABRIC 70 GSM x 50 CM - GREEN | D26: =+OVERALL!D26 -> KGS | E26: CBEWIP | F26: =+OVERALL!F26 -> 0
A27: 26 | B27: =+OVERALL!C27 -> RM-NWN-POS-54CMX70GSM | C27: NON WOVEN FABRIC 70 GSM x 54 CM - WHITE | D27: =+OVERALL!D27 -> KGS | E27: CBEWIP | F27: =+OVERALL!F27 -> 0
A28: 27 | B28: =+OVERALL!C28 -> RM-NWN-POS-58CMX70GSM | C28: NON WOVEN FABRIC 70 GSM x 58 CM - GREEN | D28: =+OVERALL!D28 -> KGS | E28: CBEWIP | F28: =+OVERALL!F28 -> 0
A29: 28 | B29: =+OVERALL!C29 -> RML-NWN-70GSMX76" | C29: NON WOVEN FABRIC 70 GSM x 76 INCH - WHITE | D29: =+OVERALL!D29 -> KGS | E29: CBEWIP | F29: =+OVERALL!F29 -> 0
A30: 29 | B30: =+OVERALL!C30 -> RML-NWN-70GSMX79" | C30: NON WOVEN FABRIC 70 GSM x 79 INCH - WHITE | D30: =+OVERALL!D30 -> KGS | E30: CBEWIP | F30: =+OVERALL!F30 -> 0
A31: 30 | B31: =+OVERALL!C31 -> RM-NWN-POS-62CMX70GSM | C31: NON WOVEN FABRIC 70 GSM x 62 CM - WHITE | D31: =+OVERALL!D31 -> KGS | E31: CBEWIP | F31: =+OVERALL!F31 -> 0
A32: 31 | B32: =+OVERALL!C32 -> RML-NWN-80GSMX82BLK | C32: NON WOVEN FABRIC 80 GSM x 82 INCH - BLACK | D32: =+OVERALL!D32 -> KGS | E32: CBEWIP | F32: =+OVERALL!F32 -> 0
A33: 32 | B33: =+OVERALL!C33 -> RML-NWN-80GSMX8" | C33: NON WOVEN FABRIC 80 GSM x 8 INCH - WHITE | D33: =+OVERALL!D33 -> KGS | E33: CBEWIP | F33: =+OVERALL!F33 -> 0
A34: 33 | B34: =+OVERALL!C34 -> RML-EPE-1040MMX105MMX25MM | C34: #N/A | D34: =+OVERALL!D34 -> NOS | E34: CBEWIP | F34: =+OVERALL!F34 -> 0
A35: 34 | B35: =+OVERALL!C35 -> RML-EPE-1345MMX105MMX25MM | C35: #N/A | D35: =+OVERALL!D35 -> NOS | E35: CBEWIP | F35: =+OVERALL!F35 -> 0
A36: 35 | B36: =+OVERALL!C36 -> RML-EPE-1650MMX105MMX25MM | C36: #N/A | D36: =+OVERALL!D36 -> NOS | E36: CBEWIP | F36: =+OVERALL!F36 -> 0
A37: 36 | B37: =+OVERALL!C37 -> RML-EPE-1040MMX125MMX25MM | C37: #N/A | D37: =+OVERALL!D37 -> NOS | E37: CBEWIP | F37: =+OVERALL!F37 -> 0
A38: 37 | B38: =+OVERALL!C38 -> RML-EPE-1345MMX125MMX25MM | C38: #N/A | D38: =+OVERALL!D38 -> NOS | E38: CBEWIP | F38: =+OVERALL!F38 -> 0
A39: 38 | B39: =+OVERALL!C39 -> RML-EPE-1650MMX125MMX25MM | C39: #N/A | D39: =+OVERALL!D39 -> NOS | E39: CBEWIP | F39: =+OVERALL!F39 -> 0
A40: 39 | B40: =+OVERALL!C40 -> RML-EPE-1040MMX145MMX25MM | C40: #N/A | D40: =+OVERALL!D40 -> NOS | E40: CBEWIP | F40: =+OVERALL!F40 -> 0
A41: 40 | B41: =+OVERALL!C41 -> RML-EPE-1345MMX145MMX25MM | C41: #N/A | D41: =+OVERALL!D41 -> NOS | E41: CBEWIP | F41: =+OVERALL!F41 -> 0
A42: 41 | B42: =+OVERALL!C42 -> RML-EPE-1650MMX145MMX25MM | C42: #N/A | D42: =+OVERALL!D42 -> NOS | E42: CBEWIP | F42: =+OVERALL!F42 -> 0
A43: 42 | B43: =+OVERALL!C43 -> RML-EPE-1040MMX165MMX25MM | C43: #N/A | D43: =+OVERALL!D43 -> NOS | E43: CBEWIP | F43: =+OVERALL!F43 -> 0
A44: 43 | B44: =+OVERALL!C44 -> RML-EPE-1345MMX165MMX25MM | C44: #N/A | D44: =+OVERALL!D44 -> NOS | E44: CBEWIP | F44: =+OVERALL!F44 -> 0
...

Sheet WIP ENTRY
C2: 1.4 | D2: 1.7 | E2: 1.8 | F2: 1.9 | G2: 2 | H2: 2.1 | I2: 2.2 | J2: 2.3 | K2: 3.6 | L2: 4 | O2: 85 | P2: 12B | Q2: 24 | R2: GUM | S2: S | T2: T | U2: W | V2: MC | Y2: GLUE | Z2: 34 | AA2: 37 | AB2: 37G | AC2: 45 | AD2: 50 | AE2: 50G | AF2: 54 | AG2: 58 | AJ2: 76 | AK2: 79 | AL2: 82 | AM2: 82BLK | AN2: 8
B3: S.NO | C3: STEEL WIRE STOCK DETAILS | N3: S.NO | O3: PIN BOX & GUM ,TOKEN, STRAP ROLL , STOCK DETAILS | X3: S.NO | Z3: NON-WOVEN STOCK DETAILS | AI3: S.NO
C4: RML-STW-1.4MM | D4: RML-STW-1.7MM | E4: RML-STW-1.8MM | F4: RML-STW-1.9MM | G4: RML-STW-2.0MM | H4: RML-STW-2.1MM | I4: RML-STW-2.2MM | J4: RML-STW-2.3MM | K4: RML-STW-3.6MM | L4: RML-STW-4.0MM | O4: RML-CL85 | P4: RML-CL12B | Q4: RML-HR24 | R4: RML-POLY-GUM | S4: RML-STRAP-ROLL | T4: RML-PAK-THRD | U4: RML-TAG-WHIT | V4: RML-TEX-CLEANER | Y4: RMI-HGLUE | Z4: RM-NWN-POS-34CMX70GSM | AA4: RM-NWN-POS-37CMX70GSM | AB4: RM-NWN-POS-37CMX70GSM-GRN | AC4: RM-NWN-POS-45CMX70GSM | AD4: RM-NWN-POS-50CMX70GSM | AE4: RM-NWN-POS-50CMX70GSM-GRN | AF4: RM-NWN-POS-54CMX70GSM | AG4: RM-NWN-POS-58CMX70GSM | AJ4: RML-NWN-70GSMX76" | AK4: RML-NWN-70GSMX79" | AL4: RM-NWN-POS-62CMX70GSM | AM4: RML-NWN-80GSMX82BLK | AN4: RML-NWN-80GSMX8" | AQ4: EPE SHEET STOCK DETAILS
B5: UOM | C5: KGS | D5: KGS | E5: KGS | F5: KGS | G5: KGS | H5: KGS | I5: KGS | J5: KGS | K5: KGS | L5: KGS | N5: UOM | O5: BOX | P5: BOX | Q5: BOX | R5: LTRS | S5: NOS | T5: NOS | U5: NOS | V5: LTRS | X5: UOM | Y5: KGS | Z5: KGS | AA5: KGS | AB5: KGS | AC5: KGS | AD5: KGS | AE5: KGS | AF5: KGS | AG5: KGS | AI5: UOM | AJ5: KGS | AK5: KGS | AL5: KGS | AM5: KGS | AN5: KGS | AQ5: SIZE | AR5: ITEMCODE | AS5: UOM | AT5: QTY
B6: 1 | N6: 1 | X6: 1 | AI6: 1 | AQ6: 48X110 | AR6: RML-EPE-1040MMX105MMX25MM | AS6: NOS
B7: 2 | N7: 2 | X7: 2 | AI7: 2 | AQ7: 60X110 | AR7: RML-EPE-1345MMX105MMX25MM | AS7: NOS
B8: 3 | N8: 3 | X8: 3 | AI8: 3 | AQ8: 72X110 | AR8: RML-EPE-1650MMX105MMX25MM | AS8: NOS
B9: 4 | N9: 4 | X9: 4 | AI9: 4 | AQ9: 48X130 | AR9: RML-EPE-1040MMX125MMX25MM | AS9: NOS
B10: 5 | N10: 5 | X10: 5 | AI10: 5 | AQ10: 60X130 | AR10: RML-EPE-1345MMX125MMX25MM | AS10: NOS
B11: 6 | N11: 6 | X11: 6 | AI11: 6 | AQ11: 72X130 | AR11: RML-EPE-1650MMX125MMX25MM | AS11: NOS
B12: 7 | N12: 7 | X12: 7 | AI12: 7 | AQ12: 48X150 | AR12: RML-EPE-1040MMX145MMX25MM | AS12: NOS
B13: 8 | N13: 8 | X13: 8 | AI13: 8 | AQ13: 60X150 | AR13: RML-EPE-1345MMX145MMX25MM | AS13: NOS
B14: 9 | N14: 9 | X14: 9 | AI14: 9 | AQ14: 72X150 | AR14: RML-EPE-1650MMX145MMX25MM | AS14: NOS
B15: 10 | N15: 10 | X15: 10 | AI15: 10 | AQ15: 48X170 | AR15: RML-EPE-1040MMX165MMX25MM | AS15: NOS
B16: 11 | N16: 11 | X16: 11 | AI16: 11 | AQ16: 60X170 | AR16: RML-EPE-1345MMX165MMX25MM | AS16: NOS
B17: 12 | N17: 12 | X17: 12 | AI17: 12 | AQ17: 72X170 | AR17: RML-EPE-1650MMX165MMX25MM | AS17: NOS
B18: 13 | N18: 13 | X18: 13 | AI18: 13 | AQ18: 74.5X135 | AR18: RML-EPE-1893X135X40 | AS18: NOS
B19: 14 | N19: 14 | X19: 14 | AI19: 14 | AR19: TOTAL | AT19: =SUM(AT6:AT18) -> 0
B20: 15 | N20: 15 | X20: 15 | AI20: 15
B21: 16 | N21: 16 | X21: 16 | AI21: 16 | AQ21: EXACT COTTON FELT STOCK DETAILS
B22: 17 | N22: 17 | X22: 17 | AI22: 17 | AQ22: SIZE | AR22: ITEM CODE | AS22: UOM | AT22: KGS/NOS | AU22: QTY | AV22: TOTAL WEIGHT
B23: 18 | N23: 18 | X23: 18 | AI23: 18 | AQ23: 72X30 | AR23: RMI-HCTNF-71.50X29.50. | AS23: KGS | AT23: 0.95256261 | AV23: =+AU23*AT23 -> 0
B24: 19 | N24: 19 | X24: 19 | AI24: 19 | AQ24: 72X36 | AR24: RMI-HCTNF-71.50X35.50. | AS24: KGS | AT24: 1.1463042 | AV24: =+AU24*AT24 -> 0
B25: 20 | N25: 20 | X25: 20 | AI25: 20 | AQ25: 72X42 | AR25: RMI-HCTNF-71.50X41.50. | AS25: KGS | AT25: 1.3400457 | AV25: =+AU25*AT25 -> 0
B26: 21 | N26: 21 | X26: 21 | AI26: 21 | AQ26: 72X48 | AR26: RMI-HCTNF-71.50X47.50. | AS26: KGS | AT26: 1.5337873 | AV26: =+AU26*AT26 -> 0
B27: 22 | N27: 22 | X27: 22 | AI27: 22 | AQ27: 72X60 | AR27: RMI-HCTNF-71.50X59.50. | AS27: KGS | AT27: 1.9212704 | AV27: =+AU27*AT27 -> 0
B28: 23 | N28: 23 | X28: 23 | AI28: 23 | AQ28: 72X66 | AR28: RMI-HCTNF-71.50X65.50. | AS28: KGS | AT28: 2.1150119 | AV28: =+AU28*AT28 -> 0
B29: 24 | N29: 24 | X29: 24 | AI29: 24 | AQ29: 72X72 | AR29: RMI-HCTNF-71.50X71.50. | AS29: KGS | AT29: 2.3087534 | AV29: =+AU29*AT29 -> 0
B30: 25 | N30: 25 | X30: 25 | AI30: 25 | AQ30: 75X30 | AR30: RMI-HCTNF-74.50X29.50. | AS30: KGS | AT30: 0.99253027 | AV30: =+AU30*AT30 -> 0
B31: 26 | N31: 26 | X31: 26 | AI31: 26 | AQ31: 75X36 | AR31: RMI-HCTNF-74.50X35.50. | AS31: KGS | AT31: 1.1944008 | AV31: =+AU31*AT31 -> 0
B32: 27 | N32: 27 | X32: 27 | AI32: 27 | AQ32: 75X42 | AR32: RMI-HCTNF-74.50X41.50. | AS32: KGS | AT32: 1.3962714 | AV32: =+AU32*AT32 -> 0
B33: 28 | N33: 28 | X33: 28 | AI33: 28 | AQ33: 75X48 | AR33: RMI-HCTNF-74.50X47.50 | AS33: KGS | AT33: 1.598142 | AV33: =+AU33*AT33 -> 0
B34: 29 | N34: 29 | X34: 29 | AI34: 29 | AQ34: 75X60 | AR34: RMI-HCTNF-74.50x59.50. | AS34: KGS | AT34: 2.0018831 | AV34: =+AU34*AT34 -> 0
B35: 30 | N35: 30 | X35: 30 | AI35: 30 | AQ35: 75X66 | AR35: RMI-HCTNF-74.50X65.50. | AS35: KGS | AT35: 2.2037537 | AV35: =+AU35*AT35 -> 0
B36: NO.OF ROLLS | C36: =COUNT(C6:C35) -> 0 | D36: =COUNT(D6:D35) -> 0 | E36: =COUNT(E6:E35) -> 0 | F36: =COUNT(F6:F35) -> 0 | G36: =COUNT(G6:G35) -> 0 | H36: =COUNT(H6:H35) -> 0 | I36: =COUNT(I6:I35) -> 0 | J36: =COUNT(J6:J35) -> 0 | ... L36: =COUNT(L6:L35) -> 0 | N36: NO.OF BOX | O36: =COUNT(O6:O35) -> 0 | P36: =COUNT(P6:P35) -> 0 | Q36: =COUNT(Q6:Q35) -> 0 | R36: =COUNT(R6:R35) -> 0 | S36: =COUNT(S6:S35) -> 0 | T36: =COUNT(T6:T35) -> 0 | U36: =COUNT(U6:U35) -> 0 | V36: =COUNT(V6:V35) -> 0 | X36: NO.OF ROLLS | Y36: =COUNT(Y6:Y35) -> 0 | Z36: =COUNT(Z6:Z35) -> 0 | AA36: =COUNT(AA6:AA35) -> 0 | AB36: =COUNT(AB6:AB35) -> 0 | AC36: =COUNT(AC6:AC35) -> 0 | AD36: =COUNT(AD6:AD35) -> 0 | AE36: =COUNT(AE6:AE35) -> 0 | AF36: =COUNT(AF6:AF35) -> 0 | AG36: =COUNT(AG6:AG35) -> 0 | AI36: NO.OF ROLLS | AJ36: =COUNT(AJ6:AJ35) -> 0 | AK36: =COUNT(AK6:AK35) -> 0 | AL36: =COUNT(AL6:AL35) -> 0 | AM36: =COUNT(AM6:AM35) -> 0 | AN36: =COUNT(AN6:AN35) -> 0 | AQ36: 75X72 | AR36: RMI-HCTNF-74.50x71.50. | AS36: KGS | AT36: 2.4056242 | AV36: =+AU36*AT36 -> 0
B37: TOTAL WEIGHT | C37: =SUM(C6:C35) -> 0 | D37: =SUM(D6:D35) -> 0 | E37: =SUM(E6:E35) -> 0 | F37: =SUM(F6:F35) -> 0 | G37: =SUM(G6:G35) -> 0 | H37: =SUM(H6:H35) -> 0 | I37: =SUM(I6:I35) -> 0 | J37: =SUM(J6:J35) -> 0 | ... L37: =SUM(L6:L35) -> 0 | N37: TOTAL WEIGHT | O37: =+SUM(O6:O35) -> 0 | P37: =+SUM(P6:P35) -> 0 | Q37: =+SUM(Q6:Q35) -> 0 | R37: =+SUM(R6:R35) -> 0 | S37: =+SUM(S6:S35) -> 0 | T37: =+SUM(T6:T35) -> 0 | U37: =+SUM(U6:U35) -> 0 | V37: =+SUM(V6:V35) -> 0 | X37: TOTAL WEIGHT | Y37: =SUM(Y6:Y35) -> 0 | Z37: =SUM(Z6:Z35) -> 0 | AA37: =SUM(AA6:AA35) -> 0 | AB37: =SUM(AB6:AB35) -> 0 | AC37: =SUM(AC6:AC35) -> 0 | AD37: =SUM(AD6:AD35) -> 0 | AE37: =SUM(AE6:AE35) -> 0 | AF37: =SUM(AF6:AF35) -> 0 | AG37: =SUM(AG6:AG35) -> 0 | AI37: TOTAL WEIGHT | AJ37: =SUM(AJ6:AJ35) -> 0 | AK37: =SUM(AK6:AK35) -> 0 | AL37: =SUM(AL6:AL35) -> 0 | AM37: =SUM(AM6:AM35) -> 0 | AN37: =SUM(AN6:AN35) -> 0 | AQ37: 78X30 | AR37: RMI-HCTNF-77.50X29.50 | AS37: KGS | AT37: 1.0324979 | AV37: =+AU37*AT37 -> 0
AQ38: 78X36 | AR38: RMI-HCTNF-77.50X35.50. | AS38: KGS | AT38: 1.2424975 | AV38: =+AU38*AT38 -> 0
AQ39: 78X42 | AR39: RMI-HCTNF-77.50X41.50. | AS39: KGS | AT39: 1.4524971 | AV39: =+AU39*AT39 -> 0
AQ40: 78X48 | AR40: RMI-HCTNF-77.50X47.50. | AS40: KGS | AT40: 1.6624967 | AV40: =+AU40*AT40 -> 0
AQ41: 78X60 | AR41: RMI-HCTNF-77.50x59.50. | AS41: KGS | AT41: 2.0824958 | AV41: =+AU41*AT41 -> 0
...

Sheet OVERALL
B1: S.NO | C1: ITEM CODE | D1: UOM | E1: NO.0F ROLLS / BOX/CANE | F1: QTY
B2: 1 | C2: RML-STW-1.4MM | D2: =+HLOOKUP(C2,'WIP ENTRY'!$C$4:$L$5,2,0) -> KGS | E2: =+HLOOKUP(C2,'WIP ENTRY'!$C$4:$L$36,33,0) -> 0 | F2: =+HLOOKUP(C2,'WIP ENTRY'!$C$4:$L$37,34,0) -> 0
B3: 2 | C3: RML-STW-1.7MM | D3: =+HLOOKUP(C3,'WIP ENTRY'!$C$4:$L$5,2,0) -> KGS | E3: =+HLOOKUP(C3,'WIP ENTRY'!$C$4:$L$36,33,0) -> 0 | F3: =+HLOOKUP(C3,'WIP ENTRY'!$C$4:$L$37,34,0) -> 0
B4: 3 | C4: RML-STW-1.8MM | D4: =+HLOOKUP(C4,'WIP ENTRY'!$C$4:$L$5,2,0) -> KGS | E4: =+HLOOKUP(C4,'WIP ENTRY'!$C$4:$L$36,33,0) -> 0 | F4: =+HLOOKUP(C4,'WIP ENTRY'!$C$4:$L$37,34,0) -> 0
B5: 4 | C5: RML-STW-1.9MM | D5: =+HLOOKUP(C5,'WIP ENTRY'!$C$4:$L$5,2,0) -> KGS | E5: =+HLOOKUP(C5,'WIP ENTRY'!$C$4:$L$36,33,0) -> 0 | F5: =+HLOOKUP(C5,'WIP ENTRY'!$C$4:$L$37,34,0) -> 0
B6: 5 | C6: RML-STW-2.0MM | D6: =+HLOOKUP(C6,'WIP ENTRY'!$C$4:$L$5,2,0) -> KGS | E6: =+HLOOKUP(C6,'WIP ENTRY'!$C$4:$L$36,33,0) -> 0 | F6: =+HLOOKUP(C6,'WIP ENTRY'!$C$4:$L$37,34,0) -> 0
B7: 6 | C7: RML-STW-2.1MM | D7: =+HLOOKUP(C7,'WIP ENTRY'!$C$4:$L$5,2,0) -> KGS | E7: =+HLOOKUP(C7,'WIP ENTRY'!$C$4:$L$36,33,0) -> 0 | F7: =+HLOOKUP(C7,'WIP ENTRY'!$C$4:$L$37,34,0) -> 0
B8: 7 | C8: RML-STW-2.2MM | D8: =+HLOOKUP(C8,'WIP ENTRY'!$C$4:$L$5,2,0) -> KGS | E8: =+HLOOKUP(C8,'WIP ENTRY'!$C$4:$L$36,33,0) -> 0 | F8: =+HLOOKUP(C8,'WIP ENTRY'!$C$4:$L$37,34,0) -> 0
B9: 8 | C9: RML-STW-2.3MM | D9: =+HLOOKUP(C9,'WIP ENTRY'!$C$4:$L$5,2,0) -> KGS | E9: =+HLOOKUP(C9,'WIP ENTRY'!$C$4:$L$36,33,0) -> 0 | F9: =+HLOOKUP(C9,'WIP ENTRY'!$C$4:$L$37,34,0) -> 0
B10: 9 | C10: RML-STW-3.6MM | D10: =+HLOOKUP(C10,'WIP ENTRY'!$C$4:$L$5,2,0) -> KGS | E10: =+HLOOKUP(C10,'WIP ENTRY'!$C$4:$L$36,33,0) -> 0 | F10: =+HLOOKUP(C10,'WIP ENTRY'!$C$4:$L$37,34,0) -> 0
B11: 10 | C11: RML-STW-4.0MM | D11: =+HLOOKUP(C11,'WIP ENTRY'!$C$4:$L$5,2,0) -> KGS | E11: =+HLOOKUP(C11,'WIP ENTRY'!$C$4:$L$36,33,0) -> 0 | F11: =+HLOOKUP(C11,'WIP ENTRY'!$C$4:$L$37,34,0) -> 0
B12: 11 | C12: RML-CL85 | D12: =+HLOOKUP(C12,'WIP ENTRY'!$O$4:$V$5,2,0) -> BOX | E12: =+HLOOKUP(C12,'WIP ENTRY'!$O$4:$V$36,33,0) -> 0 | F12: =+HLOOKUP(C12,'WIP ENTRY'!$O$4:$V$37,34,0) -> 0
B13: 12 | C13: RML-CL12B | D13: =+HLOOKUP(C13,'WIP ENTRY'!$O$4:$V$5,2,0) -> BOX | E13: =+HLOOKUP(C13,'WIP ENTRY'!$O$4:$V$36,33,0) -> 0 | F13: =+HLOOKUP(C13,'WIP ENTRY'!$O$4:$V$37,34,0) -> 0
B14: 13 | C14: RML-HR24 | D14: =+HLOOKUP(C14,'WIP ENTRY'!$O$4:$V$5,2,0) -> BOX | E14: =+HLOOKUP(C14,'WIP ENTRY'!$O$4:$V$36,33,0) -> 0 | F14: =+HLOOKUP(C14,'WIP ENTRY'!$O$4:$V$37,34,0) -> 0
B15: 14 | C15: RML-POLY-GUM | D15: =+HLOOKUP(C15,'WIP ENTRY'!$O$4:$V$5,2,0) -> LTRS | E15: =+HLOOKUP(C15,'WIP ENTRY'!$O$4:$V$36,33,0) -> 0 | F15: =+HLOOKUP(C15,'WIP ENTRY'!$O$4:$V$37,34,0) -> 0
B16: 15 | C16: RML-STRAP-ROLL | D16: =+HLOOKUP(C16,'WIP ENTRY'!$O$4:$V$5,2,0) -> NOS | E16: =+HLOOKUP(C16,'WIP ENTRY'!$O$4:$V$36,33,0) -> 0 | F16: =+HLOOKUP(C16,'WIP ENTRY'!$O$4:$V$37,34,0) -> 0
B17: 16 | C17: RML-PAK-THRD | D17: =+HLOOKUP(C17,'WIP ENTRY'!$O$4:$V$5,2,0) -> NOS | E17: =+HLOOKUP(C17,'WIP ENTRY'!$O$4:$V$36,33,0) -> 0 | F17: =+HLOOKUP(C17,'WIP ENTRY'!$O$4:$V$37,34,0) -> 0
B18: 17 | C18: RML-TAG-WHIT | D18: =+HLOOKUP(C18,'WIP ENTRY'!$O$4:$V$5,2,0) -> NOS | E18: =+HLOOKUP(C18,'WIP ENTRY'!$O$4:$V$36,33,0) -> 0 | F18: =+HLOOKUP(C18,'WIP ENTRY'!$O$4:$V$37,34,0) -> 0
B19: 18 | C19: RML-TEX-CLEANER | D19: =+HLOOKUP(C19,'WIP ENTRY'!$O$4:$V$5,2,0) -> LTRS | E19: =+HLOOKUP(C19,'WIP ENTRY'!$O$4:$V$36,33,0) -> 0 | F19: =+HLOOKUP(C19,'WIP ENTRY'!$O$4:$V$37,34,0) -> 0
B20: 19 | C20: RMI-HGLUE | D20: =HLOOKUP(C20,'WIP ENTRY'!$Y$4:$AG$5,2,0) -> KGS | E20: =HLOOKUP(C20,'WIP ENTRY'!$Y$4:$AG$36,33,0) -> 0 | F20: =+HLOOKUP(C20,'WIP ENTRY'!$Y$4:$AG$37,34,0) -> 0
B21: 20 | C21: RM-NWN-POS-34CMX70GSM | D21: =HLOOKUP(C21,'WIP ENTRY'!$Y$4:$AG$5,2,0) -> KGS | E21: =HLOOKUP(C21,'WIP ENTRY'!$Y$4:$AG$36,33,0) -> 0 | F21: =+HLOOKUP(C21,'WIP ENTRY'!$Y$4:$AG$37,34,0) -> 0
B22: 21 | C22: RM-NWN-POS-37CMX70GSM | D22: =HLOOKUP(C22,'WIP ENTRY'!$Y$4:$AG$5,2,0) -> KGS | E22: =HLOOKUP(C22,'WIP ENTRY'!$Y$4:$AG$36,33,0) -> 0 | F22: =+HLOOKUP(C22,'WIP ENTRY'!$Y$4:$AG$37,34,0) -> 0
B23: 22 | C23: RM-NWN-POS-37CMX70GSM-GRN | D23: =HLOOKUP(C23,'WIP ENTRY'!$Y$4:$AG$5,2,0) -> KGS | E23: =HLOOKUP(C23,'WIP ENTRY'!$Y$4:$AG$36,33,0) -> 0 | F23: =+HLOOKUP(C23,'WIP ENTRY'!$Y$4:$AG$37,34,0) -> 0
B24: 23 | C24: RM-NWN-POS-45CMX70GSM | D24: =HLOOKUP(C24,'WIP ENTRY'!$Y$4:$AG$5,2,0) -> KGS | E24: =HLOOKUP(C24,'WIP ENTRY'!$Y$4:$AG$36,33,0) -> 0 | F24: =+HLOOKUP(C24,'WIP ENTRY'!$Y$4:$AG$37,34,0) -> 0
B25: 24 | C25: RM-NWN-POS-50CMX70GSM | D25: =HLOOKUP(C25,'WIP ENTRY'!$Y$4:$AG$5,2,0) -> KGS | E25: =HLOOKUP(C25,'WIP ENTRY'!$Y$4:$AG$36,33,0) -> 0 | F25: =+HLOOKUP(C25,'WIP ENTRY'!$Y$4:$AG$37,34,0) -> 0
B26: 25 | C26: RM-NWN-POS-50CMX70GSM-GRN | D26: =HLOOKUP(C26,'WIP ENTRY'!$Y$4:$AG$5,2,0) -> KGS | E26: =HLOOKUP(C26,'WIP ENTRY'!$Y$4:$AG$36,33,0) -> 0 | F26: =+HLOOKUP(C26,'WIP ENTRY'!$Y$4:$AG$37,34,0) -> 0
B27: 26 | C27: RM-NWN-POS-54CMX70GSM | D27: =HLOOKUP(C27,'WIP ENTRY'!$Y$4:$AG$5,2,0) -> KGS | E27: =HLOOKUP(C27,'WIP ENTRY'!$Y$4:$AG$36,33,0) -> 0 | F27: =+HLOOKUP(C27,'WIP ENTRY'!$Y$4:$AG$37,34,0) -> 0
B28: 27 | C28: RM-NWN-POS-58CMX70GSM | D28: =HLOOKUP(C28,'WIP ENTRY'!$Y$4:$AG$5,2,0) -> KGS | E28: =HLOOKUP(C28,'WIP ENTRY'!$Y$4:$AG$36,33,0) -> 0 | F28: =+HLOOKUP(C28,'WIP ENTRY'!$Y$4:$AG$37,34,0) -> 0
B29: 28 | C29: RML-NWN-70GSMX76" | D29: =+HLOOKUP(C29,'WIP ENTRY'!$AJ$4:$AN$5,2,0) -> KGS | E29: =HLOOKUP(C29,'WIP ENTRY'!$AJ$4:$AN$36,33,0) -> 0 | F29: =+HLOOKUP(C29,'WIP ENTRY'!$AJ$4:$AN$37,5,0) -> 0
B30: 29 | C30: RML-NWN-70GSMX79" | D30: =+HLOOKUP(C30,'WIP ENTRY'!$AJ$4:$AN$5,2,0) -> KGS | E30: =HLOOKUP(C30,'WIP ENTRY'!$AJ$4:$AN$36,33,0) -> 0 | F30: =+HLOOKUP(C30,'WIP ENTRY'!$AJ$4:$AN$37,5,0) -> 0
B31: 30 | C31: RM-NWN-POS-62CMX70GSM | D31: =+HLOOKUP(C31,'WIP ENTRY'!$AJ$4:$AN$5,2,0) -> KGS | E31: =HLOOKUP(C31,'WIP ENTRY'!$AJ$4:$AN$36,33,0) -> 0 | F31: =+HLOOKUP(C31,'WIP ENTRY'!$AJ$4:$AN$37,5,0) -> 0
B32: 31 | C32: RML-NWN-80GSMX82BLK | D32: =+HLOOKUP(C32,'WIP ENTRY'!$AJ$4:$AN$5,2,0) -> KGS | E32: =HLOOKUP(C32,'WIP ENTRY'!$AJ$4:$AN$36,33,0) -> 0 | F32: =+HLOOKUP(C32,'WIP ENTRY'!$AJ$4:$AN$37,5,0) -> 0
B33: 32 | C33: RML-NWN-80GSMX8" | D33: =+HLOOKUP(C33,'WIP ENTRY'!$AJ$4:$AN$5,2,0) -> KGS | E33: =HLOOKUP(C33,'WIP ENTRY'!$AJ$4:$AN$36,33,0) -> 0 | F33: =+HLOOKUP(C33,'WIP ENTRY'!$AJ$4:$AN$37,5,0) -> 0
B34: 33 | C34: RML-EPE-1040MMX105MMX25MM | D34: =VLOOKUP(C34,'WIP ENTRY'!AR6:AS17,2,0) -> NOS | F34: =+VLOOKUP(C34,'WIP ENTRY'!$AR$6:$AT$18,3,0) -> 0
B35: 34 | C35: RML-EPE-1345MMX105MMX25MM | D35: =VLOOKUP(C35,'WIP ENTRY'!AR7:AS18,2,0) -> NOS | F35: =+VLOOKUP(C35,'WIP ENTRY'!$AR$6:$AT$18,3,0) -> 0
B36: 35 | C36: RML-EPE-1650MMX105MMX25MM | D36: =VLOOKUP(C36,'WIP ENTRY'!AR8:AS19,2,0) -> NOS | F36: =+VLOOKUP(C36,'WIP ENTRY'!$AR$6:$AT$18,3,0) -> 0
B37: 36 | C37: RML-EPE-1040MMX125MMX25MM | D37: =VLOOKUP(C37,'WIP ENTRY'!AR9:AS20,2,0) -> NOS | F37: =+VLOOKUP(C37,'WIP ENTRY'!$AR$6:$AT$18,3,0) -> 0
B38: 37 | C38: RML-EPE-1345MMX125MMX25MM | D38: =VLOOKUP(C38,'WIP ENTRY'!AR10:AS21,2,0) -> NOS | F38: =+VLOOKUP(C38,'WIP ENTRY'!$AR$6:$AT$18,3,0) -> 0
B39: 38 | C39: RML-EPE-1650MMX125MMX25MM | D39: =VLOOKUP(C39,'WIP ENTRY'!AR11:AS22,2,0) -> NOS | F39: =+VLOOKUP(C39,'WIP ENTRY'!$AR$6:$AT$18,3,0) -> 0
B40: 39 | C40: RML-EPE-1040MMX145MMX25MM | D40: =VLOOKUP(C40,'WIP ENTRY'!AR12:AS23,2,0) -> NOS | F40: =+VLOOKUP(C40,'WIP ENTRY'!$AR$6:$AT$18,3,0) -> 0
...

Sheet COTTON FELT CALCULATION
E1: PER COTTON FELT WEIGHT | F1: REQUIRED QTY
A2: 72X30 | B2: 71.5 | C2: 29.5 | D2: RMI-HCTNF-71.50X29.50. | E2: =700*(B2)*(C2)*0.0254*0.0254/1000 -> 0.95256261 | G2: =F2*E2 -> 0
A3: 72X36 | B3: 71.5 | C3: 35.5 | D3: RMI-HCTNF-71.50X35.50. | E3: =700*(B3)*(C3)*0.0254*0.0254/1000 -> 1.1463042 | G3: =F3*E3 -> 0
A4: 72X42 | B4: 71.5 | C4: 41.5 | D4: RMI-HCTNF-71.50X41.50. | E4: =700*(B4)*(C4)*0.0254*0.0254/1000 -> 1.3400457 | G4: =F4*E4 -> 0
A5: 72X48 | B5: 71.5 | C5: 47.5 | D5: RMI-HCTNF-71.50X47.50. | E5: =700*(B5)*(C5)*0.0254*0.0254/1000 -> 1.5337873 | G5: =F5*E5 -> 0
A6: 72X60 | B6: 71.5 | C6: 59.5 | D6: RMI-HCTNF-71.50X59.50. | E6: =700*(B6)*(C6)*0.0254*0.0254/1000 -> 1.9212704 | G6: =F6*E6 -> 0
A7: 72X66 | B7: 71.5 | C7: 65.5 | D7: RMI-HCTNF-71.50X65.50. | E7: =700*(B7)*(C7)*0.0254*0.0254/1000 -> 2.1150119 | G7: =F7*E7 -> 0
A8: 72X72 | B8: 71.5 | C8: 71.5 | D8: RMI-HCTNF-71.50X71.50. | E8: =700*(B8)*(C8)*0.0254*0.0254/1000 -> 2.3087534 | G8: =F8*E8 -> 0
A9: 75X30 | B9: 74.5 | C9: 29.5 | D9: RMI-HCTNF-74.50X29.50. | E9: =700*(B9)*(C9)*0.0254*0.0254/1000 -> 0.99253027 | G9: =F9*E9 -> 0
A10: 75X36 | B10: 74.5 | C10: 35.5 | D10: RMI-HCTNF-74.50X35.50. | E10: =700*(B10)*(C10)*0.0254*0.0254/1000 -> 1.1944008 | G10: =F10*E10 -> 0
A11: 75X42 | B11: 74.5 | C11: 41.5 | D11: RMI-HCTNF-74.50X41.50. | E11: =700*(B11)*(C11)*0.0254*0.0254/1000 -> 1.3962714 | G11: =F11*E11 -> 0
A12: 75X48 | B12: 74.50 | C12: 47.5 | D12: RMI-HCTNF-74.50X47.50 | E12: =700*(B12)*(C12)*0.0254*0.0254/1000 -> 1.598142 | G12: =F12*E12 -> 0
A13: 75X60 | B13: 74.50 | C13: 59.5 | D13: RMI-HCTNF-74.50x59.50. | E13: =700*(B13)*(C13)*0.0254*0.0254/1000 -> 2.0018831 | G13: =F13*E13 -> 0
A14: 75X66 | B14: 74.5 | C14: 65.5 | D14: RMI-HCTNF-74.50x65.50. | E14: =700*(B14)*(C14)*0.0254*0.0254/1000 -> 2.2037537 | G14: =F14*E14 -> 0
A15: 75X72 | B15: 74.5 | C15: 71.5 | D15: RMI-HCTNF-74.50x71.50. | E15: =700*(B15)*(C15)*0.0254*0.0254/1000 -> 2.4056242 | G15: =F15*E15 -> 0
A16: 78X30 | B16: 77.5 | C16: 29.5 | D16: RMI-HCTNF-77.50X29.50 | E16: =700*(B16)*(C16)*0.0254*0.0254/1000 -> 1.0324979 | G16: =F16*E16 -> 0
A17: 78X36 | B17: 77.5 | C17: 35.5 | D17: RMI-HCTNF-77.50X35.50. | E17: =700*(B17)*(C17)*0.0254*0.0254/1000 -> 1.2424975 | G17: =F17*E17 -> 0
A18: 78X42 | B18: 77.5 | C18: 41.5 | D18: RMI-HCTNF-77.50X41.50. | E18: =700*(B18)*(C18)*0.0254*0.0254/1000 -> 1.4524971 | G18: =F18*E18 -> 0
A19: 78X48 | B19: 77.5 | C19: 47.5 | D19: RMI-HCTNF-77.50X47.50. | E19: =700*(B19)*(C19)*0.0254*0.0254/1000 -> 1.6624967 | G19: =F19*E19 -> 0
A20: 78X60 | B20: 77.50 | C20: 59.50 | D20: RMI-HCTNF-77.50x59.50. | E20: =700*(B20)*(C20)*0.0254*0.0254/1000 -> 2.0824958 | G20: =F20*E20 -> 0
A21: 78X66 | B21: 77.5 | C21: 65.5 | D21: RMI-HCTNF-77.50X65.50. | E21: =700*(B21)*(C21)*0.0254*0.0254/1000 -> 2.2924954 | G21: =F21*E21 -> 0
A22: 78X72 | B22: 77.50 | C22: 71.50 | D22: RMI-HCTNF-77.50x71.50. | E22: =700*(B22)*(C22)*0.0254*0.0254/1000 -> 2.502495 | G22: =F22*E22 -> 0
A23: 84X72 | B23: 83.5 | C23: 71.5 | D23: RMI-HCTNF-83.50X71.50. | E23: =700*(B23)*(C23)*0.0254*0.0254/1000 -> 2.6962365 | G23: =F23*E23 -> 0

Sheet STEEL WIRE PRINT
C1: 1
C2: ITEM CODE | D2: =+CBEWIP!B2 -> RML-STW-1.4MM
C3: DESCRIPTION | D3: =+CBEWIP!C2 -> 1.4 MM UPHOLSTRY STEEL WIRE
C4: UOM | D4: =+CBEWIP!D2 -> KGS
C5: SNO | D5: QTY
C6: 1 | D6: =+'WIP ENTRY'!C6 -> 0
C7: 2 | D7: =+'WIP ENTRY'!C7 -> 0
C8: 3 | D8: =+'WIP ENTRY'!C8 -> 0
C9: 4 | D9: =+'WIP ENTRY'!C9 -> 0
C10: 5 | D10: =+'WIP ENTRY'!C10 -> 0
C11: 6 | D11: =+'WIP ENTRY'!C11 -> 0
C12: 7 | D12: =+'WIP ENTRY'!C12 -> 0
C13: 8 | D13: =+'WIP ENTRY'!C13 -> 0
C14: 9 | D14: =+'WIP ENTRY'!C14 -> 0
C15: 10 | D15: =+'WIP ENTRY'!C15 -> 0
C16: 11 | D16: =+'WIP ENTRY'!C16 -> 0
C17: 12 | D17: =+'WIP ENTRY'!C17 -> 0
... C35: 30 | D35: =+'WIP ENTRY'!C35 -> 0
C36: TOTAL | D36: =SUM(D6:D35) -> 0
C38: 2
C39: ITEM CODE | D39: =+CBEWIP!#REF! -> #REF!
C40: DESCRIPTION | D40: =+CBEWIP!#REF! -> #REF!
C41: UOM | D41: =+CBEWIP!#REF! -> #REF!
C42: S.NO | D42: QTY
C43: 1 | D43: =+'WIP ENTRY'!D6 -> 0
C44: 2 | D44: =+'WIP ENTRY'!D7 -> 0
C45: 3 | D45: =+'WIP ENTRY'!D8 -> 0
C46: TOTAL | D46: =SUM(D43:D45) -> 0
C48: 3
C49: ITEM CODE | D49: =+CBEWIP!B3 -> RML-STW-1.7MM
C50: DESCRIPTION | D50: =+CBEWIP!C3 -> STEEL WIRE 1.7 MMDIA.
C51: UOM | D51: =+CBEWIP!D3 -> KGS
C52: SNO | D52: QTY
C53: 1 | D53: =+'WIP ENTRY'!E6 -> 0
C54: 2 | D54: =+'WIP ENTRY'!E7 -> 0
C55: 3 | D55: =+'WIP ENTRY'!E8 -> 0
C56: 4 | D56: =+'WIP ENTRY'!E9 -> 0
C57: 5 | D57: =+'WIP ENTRY'!E10 -> 0
C58: 6 | D58: =+'WIP ENTRY'!E11 -> 0
C59: 7 | D59: =+'WIP ENTRY'!E12 -> 0
...

Sheet NON-WOVEN
C1: 1
C2: ITEM CODE | D2: =+CBEWIP!B15 -> RML-POLY-GUM
C3: DESCRIPTION | D3: =+CBEWIP!C15 -> SOLVENT BASED RUBBER ADHESIVE (SPRAY GLUE)
C4: UOM | D4: =+CBEWIP!D15 -> LTRS
C5: SNO | D5: QTY
C6: 1 | D6: =+'WIP ENTRY'!Z6 -> 0
C7: 2 | D7: =+'WIP ENTRY'!Z7 -> 0
C8: 3 | D8: =+'WIP ENTRY'!Z8 -> 0
C9: 4 | D9: =+'WIP ENTRY'!Z9 -> 0
C10: 5 | D10: =+'WIP ENTRY'!Z10 -> 0
C11: TOTAL | D11: =SUM(D6:D10) -> 0
C14: 2
C15: ITEM CODE | D15: =+CBEWIP!B16 -> RML-STRAP-ROLL
C16: DESCRIPTION | D16: =+CBEWIP!C16 -> 12MM PACKING STRAP ROLL
C17: UOM | D17: =+CBEWIP!D16 -> NOS
C18: SNO | D18: QTY
C19: 1 | D19: =+'WIP ENTRY'!AA6 -> 0
C20: 2 | D20: =+'WIP ENTRY'!AA7 -> 0
C21: 3 | D21: =+'WIP ENTRY'!AA8 -> 0
C22: 4 | D22: =+'WIP ENTRY'!AA9 -> 0
C23: 5 | D23: =+'WIP ENTRY'!AA10 -> 0
C24: 6 | D24: =+'WIP ENTRY'!AA11 -> 0
C25: 7 | D25: =+'WIP ENTRY'!AA12 -> 0
C26: 8 | D26: =+'WIP ENTRY'!AA13 -> 0
C27: 9 | D27: =+'WIP ENTRY'!AA14 -> 0
C28: 10 | D28: =+'WIP ENTRY'!AA15 -> 0
C29: 11 | D29: =+'WIP ENTRY'!AA16 -> 0
C30: 12 | D30: =+'WIP ENTRY'!AA17 -> 0
... C33: 15 | D33: =+'WIP ENTRY'!AA20 -> 0
C34: TOTAL | D34: =SUM(D19:D33) -> 0
C36: 3
C37: ITEM CODE | D37: =+CBEWIP!B17 -> RML-PAK-THRD
C38: DESCRIPTION | D38: =+CBEWIP!C17 -> Bag Stitching Thread
C39: UOM | D39: =+CBEWIP!D17 -> NOS
C40: SNO | D40: QTY
C41: 1 | D41: =+'WIP ENTRY'!AB6 -> 0
C42: 2 | D42: =+'WIP ENTRY'!AB7 -> 0
C43: 3 | D43: =+'WIP ENTRY'!AB8 -> 0
C44: 4 | D44: =+'WIP ENTRY'!AB9 -> 0
C45: 5 | D45: =+'WIP ENTRY'!AB10 -> 0
...

Sheet PIN BOX
C3: ITEM CODE | D3: =+CBEWIP!B10 -> RML-STW-3.6MM
C4: DECRIPTION | D4: =+CBEWIP!C10 -> STEEL WIRE 3.6 MM DIA
C5: UOM | D5: =+CBEWIP!D10 -> KGS
C6: QTY | D6: =+'WIP ENTRY'!O37 -> 0
C13: ITEM CODE | D13: =+CBEWIP!B11 -> RML-STW-4.0MM
C14: DECRIPTION | D14: =+CBEWIP!C11 -> STEEL WIRE 4.0 MM DIA
C15: UOM | D15: =+CBEWIP!D11 -> KGS
C16: QTY | D16: =+'WIP ENTRY'!P37 -> 0
C21: ITEM CODE | D21: =+CBEWIP!B12 -> RML-CL85
C22: DECRIPTION | D22: =+CBEWIP!C12 -> CLIPS CL-85 (8000 PCS/BOX)
C23: UOM | D23: =+CBEWIP!D12 -> BOX
C24: QTY | D24: =+'WIP ENTRY'!Q37 -> 0
C29: ITEM CODE | D29: =+CBEWIP!B13 -> RML-CL12B
C30: DECRIPTION | D30: =+CBEWIP!C13 -> CLIPS CL-12B (13025 PCS/BOX)
C31: UOM | D31: =+CBEWIP!D13 -> BOX
C32: NO.OF CANE | D32: =+D33/30 -> 0
C33: QTY (30 LTRS / CANE) | D33: =+'WIP ENTRY'!R37 -> 0
C38: ITEM CODE | D38: =+CBEWIP!B14 -> RML-HR24
C39: DECRIPTION | D39: =+CBEWIP!C14 -> C-RINGS HR24 (10000 PCS/CTN)
C40: UOM | D40: =+CBEWIP!D14 -> BOX
C41: NO.OF BAGS | D41: =+D42/26 -> 0
C42: QTY (26KGS / CANE) | D42: =+'WIP ENTRY'!Y37 -> 0
C46: ITEM CODE | D46: =+CBEWIP!B28 -> RM-NWN-POS-58CMX70GSM
C47: DECRIPTION | D47: =+CBEWIP!C28 -> NON WOVEN FABRIC 70 GSM x 58 CM - GREEN
C48: UOM | D48: =+CBEWIP!D28 -> KGS
C49: QTY | D49: =+'WIP ENTRY'!S37 -> 0
C53: ITEM CODE | D53: =+CBEWIP!B29 -> RML-NWN-70GSMX76"
C54: DECRIPTION | D54: =+CBEWIP!C29 -> NON WOVEN FABRIC 70 GSM x 76 INCH - WHITE
C55: UOM | D55: =+CBEWIP!D29 -> KGS
C56: QTY | D56: =+'WIP ENTRY'!T37 -> 0
C62: ITEM CODE | D62: =+CBEWIP!B30 -> RML-NWN-70GSMX79"
C63: DECRIPTION | D63: =+CBEWIP!C30 -> NON WOVEN FABRIC 70 GSM x 79 INCH - WHITE
C64: UOM | D64: =+CBEWIP!D30 -> KGS
C65: NO.OF BUNDLES | D65: =+D66/25 -> 0
C66: QTY | D66: =+'WIP ENTRY'!U37 -> 0
C70: ITEM CODE | D70: =+CBEWIP!B31 -> RM-NWN-POS-62CMX70GSM
C71: DECRIPTION | D71: =+CBEWIP!C31 -> NON WOVEN FABRIC 70 GSM x 62 CM - WHITE
C72: UOM | D72: =+CBEWIP!D31 -> KGS
C73: QTY | D73: =+'WIP ENTRY'!V37 -> 0

Sheet CALCULATION
A1: ITEM | B1: BOX WEIGHT | C1: OPEN BOX WEIGHT | D1: NO.OF BOX OPEN BOX
A2: CL-85 | B2: 19 | D2: =+C2/B2 -> 0
A3: CL-12B | B3: 16.2 | D3: =+C3/B3 -> 0
A4: HR-24 | B4: 7.1 | D4: =+C4/B4 -> 0
A5: STRAP ROLL | B5: 4.36 | D5: =+C5/B5 -> 0
A6: MC | B6: 30 | D6: =+B6*0.97 -> 29.1
A10: 1 kg | B10: 0.97 ltr
A11: 1 kg

Sheet Sheet2

Sheet CONTTON FELT CALCULATION
B1: FIT FELT CALCULATION
B2: L | C2: W | D2: QTY | E2: WEIGHT | H2: L | I2: W | J2: SIZE
B3: 75 | C3: 36 | D3: 10 | E3: =+((B3+C3)*0.0254*0.0947)*D3 -> 2.6699718 | H3: 75 | I3: 36 | J3: =+CONCATENATE(H3,"X",I3) -> 75X36 | K3: 6
B4: 78 | C4: 36 | D4: 5 | E4: =+((B4+C4)*0.0254*0.0947)*D4 -> 1.3710666 | H4: 78 | I4: 36 | J4: =+CONCATENATE(H4,"X",I4) -> 78X36 | K4: 3
B5: 75 | C5: 36 | D5: 26 | E5: =+((B5+C5)*0.0254*0.0947)*D5 -> 6.9419267 | H5: 75 | I5: 36 | J5: =+CONCATENATE(H5,"X",I5) -> 75X36 | K5: 15
B6: 75 | C6: 60 | D6: 7 | E6: =+((B6+C6)*0.0254*0.0947)*D6 -> 2.2730841 | H6: 75 | I6: 60 | J6: =+CONCATENATE(H6,"X",I6) -> 75X60 | K6: 5
B7: 78 | C7: 60 | D7: 7 | E7: =+((B7+C7)*0.0254*0.0947)*D7 -> 2.3235971 | H7: 78 | I7: 60 | J7: =+CONCATENATE(H7,"X",I7) -> 78X60 | K7: 5
B8: 78 | C8: 60 | D8: 2 | E8: =+((B8+C8)*0.0254*0.0947)*D8 -> 0.66388488 | H8: 78 | I8: 60 | J8: =+CONCATENATE(H8,"X",I8) -> 78X60 | K8: 5
B9: 75 | C9: 60 | D9: 2 | E9: =+((B9+C9)*0.0254*0.0947)*D9 -> 0.6494526 | H9: 72 | I9: 48 | J9: =+CONCATENATE(H9,"X",I9) -> 72X48 | K9: 2
B10: 78 | C10: 60 | D10: 9 | E10: =+((B10+C10)*0.0254*0.0947)*D10 -> 2.987482 | H10: 72 | I10: 30 | J10: =+CONCATENATE(H10,"X",I10) -> 72X30 | K10: 1
B11: 75 | C11: 72 | D11: 6 | E11: =+((B11+C11)*0.0254*0.0947)*D11 -> 2.1215452 | H11: 72 | I11: 60 | J11: =+CONCATENATE(H11,"X",I11) -> 72X60 | K11: 2
B12: 78 | C12: 72 | D12: 4 | E12: =+((B12+C12)*0.0254*0.0947)*D12 -> 1.443228 | H12: 75 | I12: 48 | J12: =+CONCATENATE(H12,"X",I12) -> 75X48 | K12: 1
B13: 72 | C13: 48 | D13: 3 | E13: =+((B13+C13)*0.0254*0.0947)*D13 -> 0.8659368 | H13: 75 | I13: 48 | J13: =+CONCATENATE(H13,"X",I13) -> 75X48 | K13: 1
B14: 75 | C14: 30 | D14: 2 | E14: =+((B14+C14)*0.0254*0.0947)*D14 -> 0.5051298 | H14: 75 | I14: 36 | J14: =+CONCATENATE(H14,"X",I14) -> 75X36 | K14: 8
... B18: 75 | C18: 48 | D18: 1 | E18: =+((B18+C18)*0.0254*0.0947)*D18 -> 0.29586174 | H18: 72 | I18: 48 | J18: =+CONCATENATE(H18,"X",I18) -> 72X48 | K18: 6
D19: TOTAL | E19: =SUM(E3:E18) -> 27.811004 | H19: 78 | I19: 48 | J19: =+CONCATENATE(H19,"X",I19) -> 78X48 | K19: 4
H20: 78 | I20: 48 | J20: =+CONCATENATE(H20,"X",I20) -> 78X48 | K20: 2
H21: 75 | I21: 42 | J21: =+CONCATENATE(H21,"X",I21) -> 75X42 | K21: 2
H22: 78 | I22: 48 | J22: =+CONCATENATE(H22,"X",I22) -> 78X48 | K22: 2
H23: 75 | I23: 60 | J23: =+CONCATENATE(H23,"X",I23) -> 75X60 | K23: 2
H24: 75 | I24: 60 | J24: =+CONCATENATE(H24,"X",I24) -> 75X60 | K24: 2
H25: 78 | I25: 60 | J25: =+CONCATENATE(H25,"X",I25) -> 78X60 | K25: 2
H26: 78 | I26: 60 | J26: =+CONCATENATE(H26,"X",I26) -> 78X60 | K26: 2
H27: 75 | I27: 60 | J27: =+CONCATENATE(H27,"X",I27) -> 75X60 | K27: 2
H28: 78 | I28: 60 | J28: =+CONCATENATE(H28,"X",I28) -> 78X60 | K28: 2
H29: 78 | I29: 60 | J29: =+CONCATENATE(H29,"X",I29) -> 78X60 | K29: 10
H30: 75 | I30: 72 | J30: =+CONCATENATE(H30,"X",I30) -> 75X72 | K30: 12
H31: 75 | I31: 72 | J31: =+CONCATENATE(H31,"X",I31) -> 75X72 | K31: 2
... H36: 75 | I36: 60 | J36: =+CONCATENATE(H36,"X",I36) -> 75X60 | K36: 2
K37: =SUM(K3:K36) -> 134
